Workbook

Sheet AA业务状况表
A1: 科目层级 | B1: 科目性质 | C1: 科目代码 | D1: 科目名称 | E1: 录入粒度 | F1: 年预算公式 | G1: 年预测公式 | H1: 实际月公式 | I1: 预测月公式 | J1: 公式说明 | K1: 横向汇总 | L1: 纵向汇总 | M1: 逻辑码 | N1: 规则
A2: 一级 | B2: 收入 | C2: AA.01 | D2: 营业收入 | F2: AA.01.01+AA.01.02+AA.01.03 | K2: 是 | M2: 01
A3: 二级 | B3: 收入 | C3: AA.01.01 | D3: 利息净收入 | F3: AA.14-AA.16 | K3: 是 | M3: 01.01
A4: 三级 | B4: 收入 | C4: AA.14 | D4: 利息收入 | F4: AA.14.01+AA.14.02+AA.14.03 | K4: 是 | M4: 14
A5: 三级 | B5: 支出 | C5: AA.16 | D5: 利息支出 | F5: AA.16.01+AA.16.02 | K5: 是 | M5: 16
A6: 二级 | B6: 收入 | C6: AA.01.02 | D6: 净手续费收入 | F6: AA.18-AA.19 | K6: 是 | M6: 01.02
A7: 三级 | B7: 收入 | C7: AA.18 | D7: 手续费收入 | K7: 是 | M7: 18 | N7: SUM
A8: 三级 | B8: 支出 | C8: AA.19 | D8: 手续费支出 | K8: 是 | M8: 19 | N8: SUM
A9: 二级 | B9: 收入 | C9: AA.01.03 | D9: 其他营收 | K9: 是 | M9: 01.03 | N9: SUM
A10: 一级 | B10: 支出 | C10: AA.02 | D10: 减：资产减值损失 | F10: AA.28.01+AA.28.02 | K10: 是 | M10: 02
A11: 二级 | B11: 支出 | C11: AA.28.01 | D11: 贷款减值损失 | F11: AA.28.01.01+AA.28.01.02 | K11: 是 | M11: 28.01
A12: 三级 | B12: 支出 | C12: AA.28.01.01 | D12: 实际风险成本 | K12: 是 | M12: 28.01.01 | N12: SUM
A13: 三级 | B13: 支出 | C13: AA.28.01.02 | D13: 超额拨备 | K13: 是 | M13: 28.01.02 | N13: SUM
A14: 二级 | B14: 支出 | C14: AA.28.02 | D14: 非贷减值损失 | K14: 是 | M14: 28.02 | N14: SUM
A15: 一级 | B15: 收入 | C15: AA.03 | D15: 净收入 | F15: AA.01-AA.02 | K15: 是 | M15: 03
A16: 一级 | B16: 支出 | C16: AA.04 | D16: 减：税金及附加 | K16: 是 | M16: 04 | N16: SUM
A17: 一级 | B17: 支出 | C17: AA.29 | D17: 减：业务及管理费 | F17: AA.29.01+AA.29.02+AA.29.03 | K17: 是 | M17: 29
A18: 二级 | B18: 支出 | C18: AA.29.01 | D18: 人力费用 | F18: AA.29.01.01+AA.29.01.02+AA.29.01.03 | K18: 是 | M18: 29.01
A19: 三级 | B19: 支出 | C19: AA.29.01.01 | D19: 常规人力 | K19: 是 | M19: 29.01.01 | N19: SUM
A20: 三级 | B20: 支出 | C20: AA.29.01.02 | D20: 利润分享 | K20: 是 | M20: 29.01.02 | N20: SUM
A21: 三级 | B21: 支出 | C21: AA.29.01.03 | D21: 专项费用 | K21: 是 | M21: 29.01.03 | N21: SUM
A22: 二级 | B22: 支出 | C22: AA.05.02 | D22: 业务费用 | K22: 是 | N22: SUM
A23: 三级 | B23: 支出 | C23: AA.05.02.01 | D23: 营销费用 | K23: 是 | N23: SUM
A24: 三级 | B24: 支出 | C24: AA.05.02.02 | D24: 运营费用 | K24: 是 | N24: SUM
A25: 二级 | B25: 支出 | C25: AA.29.02 | D25: IT费用 | K25: 是 | M25: 29.02 | N25: SUM
A26: 二级 | B26: 支出 | C26: AA.29.03 | D26: 日常费用 | K26: 是 | M26: 29.03 | N26: SUM
A27: 一级 | B27: 收入 | C27: AA.06 | D27: 加：营业外净收入 | K27: 是 | M27: 06 | N27: SUM
A28: 一级 | B28: 利润 | C28: AA.09 | D28: 税前利润 | F28: AA.03-AA.04-AA.29+AA.06 | K28: 是 | M28: 09
A29: 一级 | B29: 支出 | C29: AA.30 | D29: 减：所得税 | K29: 是 | M29: 30 | N29: SUM
A30: 一级 | B30: 利润 | C30: AA.31 | D30: 净利润 | F30: AA.09-AA.30 | K30: 是 | M30: 31
A32: 一级 | B32: 资产余额 | C32: AA.10 | D32: 管理贷款余额 | F32: AA.10.01+AA.10.02+AA.10.03+AA.10.04 | K32: 是 | M32: 10
A33: 二级 | B33: 资产余额 | C33: AA.10.01 | D33: 自持余额 | F33: AA.10.01.01+AA.10.01.02 | K33: 是 | M33: 10.01
A34: 三级 | B34: 资产余额 | C34: AA.10.01.01 | D34: 一般贷款 | K34: 是 | M34: 10.01.01 | N34: LAST
A35: 三级 | B35: 资产余额 | C35: AA.10.01.02 | D35: 票据融资 | K35: 是 | M35: 10.01.02 | N35: LAST
A36: 二级 | B36: 资产余额 | C36: AA.10.02 | D36: 联贷 | K36: 是 | M36: 10.02 | N36: LAST
A37: 二级 | B37: 资产余额 | C37: AA.10.03 | D37: 流转 | K37: 是 | M37: 10.03 | N37: LAST
A38: 二级 | B38: 资产余额 | C38: AA.10.04 | D38: 银承保函 | K38: 是 | M38: 10.04 | N38: LAST
A41: 一级 | B41: 负债余额 | C41: AA.12 | D41: 管理资产余额 | F41: AA.12.01+AA.12.02+AA.12.03+AA.12.04 | K41: 是 | M41: 12
A42: 二级 | B42: 负债余额 | C42: AA.12.01 | D42: 各项存款 | K42: 是 | M42: 12.01 | N42: LAST
A43: 二级 | B43: 负债余额 | C43: AA.12.02 | D43: 代销理财 | K43: 是 | M43: 12.02 | N43: LAST
...

Sheet AA资产负债表（余额）
A1: 科目层级 | B1: 科目性质 | C1: 科目代码 | D1: 科目名称 | E1: 录入粒度 | F1: 年预算公式 | G1: 年预测公式 | H1: 实际月公式 | I1: 预测月公式 | J1: 公式说明 | K1: 横向汇总 | L1: 纵向汇总 | M1: 逻辑码 | N1: 规则
A2: 一级 | B2: 资产余额 | C2: AA.32 | D2: 总资产 | F2: AA.32.01+AA.32.02+AA.32.03 | K2: 是 | M2: 32
A3: 二级 | B3: 资产余额 | C3: AA.10.01 | D3: 各项贷款 | F3: AA.10.01.01+AA.10.01.02 | K3: 是 | M3: 10.01
A4: 三级 | B4: 资产余额 | C4: AA.10.01.01 | D4: 一般贷款 | K4: 是 | M4: 10.01.01 | N4: LAST
A5: 三级 | B5: 资产余额 | C5: AA.10.01.02 | D5: 票据融资 | K5: 是 | M5: 10.01.02 | N5: LAST
A6: 二级 | B6: 资产余额 | C6: AA.22 | D6: 存放央行 | K6: 是 | M6: 22 | N6: LAST
A7: 二级 | B7: 资产余额 | C7: AA.32.01 | D7: 同业资产 | F7: AA.24.01+AA.24.02+AA.24.03+AA.24.04+AA.24.05+AA.24.06 | K7: 是 | M7: 32.01
A8: 三级 | C8: AA.24 | D8: AA.24
A9: 三级 | B9: 资产余额 | C9: AA.24.01 | D9: 存放同业 | K9: 是 | M9: 24.01 | N9: LAST
A10: 三级 | B10: 资产余额 | C10: AA.24.02 | D10: 拆放同业 | K10: 是 | M10: 24.02 | N10: LAST
A11: 三级 | B11: 资产余额 | C11: AA.24.03 | D11: 买入返售 | K11: 是 | M11: 24.03 | N11: LAST
A12: 三级 | B12: 资产余额 | C12: AA.24.04 | D12: 债券投资 | K12: 是 | M12: 24.04 | N12: LAST
A13: 三级 | B13: 资产余额 | C13: AA.24.05 | D13: 同业存单投资 | K13: 是 | M13: 24.05 | N13: LAST
A14: 三级 | B14: 资产余额 | C14: AA.24.06 | D14: 基金 | K14: 是 | M14: 24.06 | N14: LAST
A15: 二级 | B15: 资产余额 | C15: AA.32.02 | D15: 减值准备 | K15: 是 | M15: 32.02 | N15: LAST
A16: 二级 | B16: 资产余额 | C16: AA.32.03 | D16: 其他资产 | K16: 是 | M16: 32.03 | N16: LAST
A17: 一级 | B17: 负债余额 | C17: AA.33 | D17: 总负债 | F17: AA.33.01+AA.33.02 | K17: 是 | M17: 33
A18: 二级 | B18: 负债余额 | C18: AA.12.01 | D18: 各项存款 | K18: 是 | M18: 12.01 | N18: LAST
A19: 二级 | B19: 负债余额 | C19: AA.33.01 | D19: 同业负债 | F19: AA.26.01+AA.26.02+AA.26.03+AA.26.04+AA.26.05+AA.26.06 | K19: 是 | M19: 33.01
A20: 三级 | C20: AA.26 | D20: AA.26
A21: 三级 | B21: 负债余额 | C21: AA.26.01 | D21: 向央行借款 | K21: 是 | M21: 26.01 | N21: LAST
A22: 三级 | B22: 负债余额 | C22: AA.26.02 | D22: 同业存放 | K22: 是 | M22: 26.02 | N22: LAST
A23: 三级 | B23: 负债余额 | C23: AA.26.03 | D23: 同业拆入 | K23: 是 | M23: 26.03 | N23: LAST
A24: 三级 | B24: 负债余额 | C24: AA.26.04 | D24: 转贷款 | K24: 是 | M24: 26.04 | N24: LAST
A25: 三级 | B25: 负债余额 | C25: AA.26.05 | D25: 卖出回购 | K25: 是 | M25: 26.05 | N25: LAST
A26: 三级 | B26: 负债余额 | C26: AA.26.06 | D26: 发行同业存单 | K26: 是 | M26: 26.06 | N26: LAST
A27: 二级 | B27: 负债余额 | C27: AA.33.02 | D27: 其他负债 | K27: 是 | M27: 33.02 | N27: LAST
A28: 一级 | B28: 负债余额 | C28: AA.34 | D28: 所有者权益 | F28: AA.32-AA.33 | K28: 是 | M28: 34

Sheet AA资产负债表（日均）
A1: 科目层级 | B1: 科目性质 | C1: 科目代码 | D1: 科目名称 | E1: 录入粒度 | F1: 年预算公式 | G1: 年预测公式 | H1: 实际月公式 | I1: 预测月公式 | J1: 公式说明 | K1: 横向汇总 | L1: 纵向汇总 | M1: 逻辑码 | N1: 规则
A2: 一级 | B2: 资产日均 | C2: AA.35 | D2: 总资产 | F2: AA.35.01+AA.35.02+AA.35.03 | K2: 是 | M2: 35
A3: 二级 | B3: 资产日均 | C3: AA.11.01 | D3: 各项贷款 | F3: AA.11.01.01+AA.11.01.02 | K3: 是 | M3: 11.01
A4: 三级 | B4: 资产日均 | C4: AA.11.01.01 | D4: 一般贷款 | K4: 是 | M4: 11.01.01 | N4: AVG
A5: 三级 | B5: 资产日均 | C5: AA.11.01.02 | D5: 票据融资 | K5: 是 | M5: 11.01.02 | N5: AVG
A6: 二级 | B6: 资产日均 | C6: AA.23 | D6: 存放央行 | K6: 是 | M6: 23 | N6: AVG
A7: 二级 | B7: 资产日均 | C7: AA.35.01 | D7: 同业资产 | K7: 是 | M7: 35.01 | N7: AVG
A8: 三级 | C8: AA.25 | D8: AA.25
A9: 三级 | B9: 资产日均 | C9: AA.25.01 | D9: 存放同业 | K9: 是 | M9: 25.01 | N9: AVG
A10: 三级 | B10: 资产日均 | C10: AA.25.02 | D10: 拆放同业 | K10: 是 | M10: 25.02 | N10: AVG
A11: 三级 | B11: 资产日均 | C11: AA.25.03 | D11: 买入返售 | K11: 是 | M11: 25.03 | N11: AVG
A12: 三级 | B12: 资产日均 | C12: AA.25.04 | D12: 债券投资（AC和OCI） | K12: 是 | M12: 25.04 | N12: AVG
A13: 三级 | B13: 资产日均 | C13: AA.25.05 | D13: 同业存单投资（AC和OCI） | K13: 是 | M13: 25.05 | N13: AVG
A14: 三级 | B14: 资产日均 | C14: AA.25.07 | D14: PL债券和同业存单 | K14: 是 | M14: 25.07 | N14: AVG
A15: 三级 | B15: 资产日均 | C15: AA.25.06 | D15: 基金 | K15: 是 | M15: 25.06 | N15: AVG
A16: 二级 | B16: 资产日均 | C16: AA.35.02 | D16: 减值准备 | K16: 是 | M16: 35.02 | N16: AVG
A17: 二级 | B17: 资产日均 | C17: AA.35.03 | D17: 其他资产 | K17: 是 | M17: 35.03 | N17: AVG
A18: 一级 | B18: 负债日均 | C18: AA.36 | D18: 总负债 | F18: AA.36.01+AA.36.02 | K18: 是 | M18: 36
A19: 二级 | B19: 负债日均 | C19: AA.13.01 | D19: 各项存款 | K19: 是 | M19: 13.01 | N19: AVG
A20: 二级 | B20: 负债日均 | C20: AA.36.01 | D20: 同业负债 | K20: 是 | M20: 36.01 | N20: AVG
A21: 三级 | C21: AA.27 | D21: AA.27
A22: 三级 | B22: 负债日均 | C22: AA.27.01 | D22: 向央行借款 | K22: 是 | M22: 27.01 | N22: AVG
A23: 三级 | B23: 负债日均 | C23: AA.27.02 | D23: 同业存放 | K23: 是 | M23: 27.02 | N23: AVG
A24: 三级 | B24: 负债日均 | C24: AA.27.03 | D24: 同业拆入 | K24: 是 | M24: 27.03 | N24: AVG
A25: 三级 | B25: 负债日均 | C25: AA.27.04 | D25: 转贷款 | K25: 是 | M25: 27.04 | N25: AVG
A26: 三级 | B26: 负债日均 | C26: AA.27.05 | D26: 卖出回购 | K26: 是 | M26: 27.05 | N26: AVG
A27: 三级 | B27: 负债日均 | C27: AA.27.06 | D27: 发行同业存单 | K27: 是 | M27: 27.06 | N27: AVG
A28: 二级 | B28: 负债日均 | C28: AA.36.02 | D28: 其他负债 | K28: 是 | M28: 36.02 | N28: AVG
A29: 一级 | B29: 负债日均 | C29: AA.37 | D29: 所有者权益 | K29: 是 | M29: 37 | N29: AVG

Sheet AA资产质量表
A1: 科目层级 | B1: 科目性质 | C1: 科目代码 | D1: 科目名称 | E1: 录入粒度 | F1: 年预算公式 | G1: 年预测公式 | H1: 实际月公式 | I1: 预测月公式 | J1: 公式说明 | K1: 横向汇总 | L1: 纵向汇总 | M1: 逻辑码 | N1: 规则
A2: 一级 | B2: 其他 | C2: AA.38 | D2: 风险成本率 | F2: AA.38.01+AA.38.02+AA.38.03+AA.38.04+AA.38.05 | K2: 是 | M2: 38
A3: 二级 | B3: 其他 | C3: AA.38.01 | D3: 泛微粒贷 | F3: AA.38.01.01+AA.38.01.02 | K3: 是 | M3: 38.01
A4: 三级 | B4: 其他 | C4: AA.38.01.01 | D4: 微粒贷 | K4: 是 | M4: 38.01.01 | N4: WGT
A5: 三级 | B5: 其他 | C5: AA.38.01.02 | D5: 分付 | K5: 是 | M5: 38.01.02 | N5: WGT
A6: 二级 | B6: 其他 | C6: AA.38.02 | D6: 汽车金融 | K6: 是 | M6: 38.02 | N6: WGT
A7: 二级 | B7: 其他 | C7: AA.38.03 | D7: 财富 | K7: 是 | M7: 38.03 | N7: WGT
A8: 二级 | B8: 其他 | C8: AA.38.04 | D8: 小鹅 | K8: 是 | M8: 38.04 | N8: WGT
A9: 二级 | B9: 其他 | C9: AA.38.05 | D9: 企业金融 | F9: AA.38.05.01 | K9: 是 | M9: 38.05
A10: 三级 | B10: 其他 | C10: AA.38.05.01 | D10: 一般贷款 | K10: 是 | M10: 38.05.01 | N10: WGT
A12: 一级 | B12: 支出 | C12: AA.02 | D12: 风险成本 | F12: AA.28.01+AA.28.02 | K12: 是 | M12: 02
A14: 一级 | B14: 其他 | C14: AA.39 | D14: 不良贷款率 | F14: AA.39.01+AA.39.02+AA.39.03+AA.39.04+AA.39.05 | K14: 是 | M14: 39
A15: 二级 | B15: 其他 | C15: AA.39.01 | D15: 泛微粒贷 | F15: AA.39.01.01+AA.39.01.02 | K15: 是 | M15: 39.01
A16: 三级 | B16: 其他 | C16: AA.39.01.01 | D16: 微粒贷 | K16: 是 | M16: 39.01.01 | N16: WGT
A17: 三级 | B17: 其他 | C17: AA.39.01.02 | D17: 分付 | K17: 是 | M17: 39.01.02 | N17: WGT
A18: 二级 | B18: 其他 | C18: AA.39.02 | D18: 汽车金融 | K18: 是 | M18: 39.02 | N18: WGT
A19: 二级 | B19: 其他 | C19: AA.39.03 | D19: 财富 | K19: 是 | M19: 39.03 | N19: WGT
A20: 二级 | B20: 其他 | C20: AA.39.04 | D20: 小鹅 | K20: 是 | M20: 39.04 | N20: WGT
A21: 二级 | B21: 其他 | C21: AA.39.05 | D21: 企业金融 | F21: AA.39.05.01 | K21: 是 | M21: 39.05
A22: 三级 | B22: 其他 | C22: AA.39.05.01 | D22: 一般贷款 | K22: 是 | M22: 39.05.01 | N22: WGT
A24: 一级 | B24: 资产余额 | C24: AA.40 | D24: 不良贷款余额 | F24: AA.40.01+AA.40.02+AA.40.03+AA.40.04+AA.40.05 | K24: 是 | M24: 40
A25: 二级 | B25: 资产余额 | C25: AA.40.01 | D25: 泛微粒贷 | F25: AA.40.01.01+AA.40.01.02 | K25: 是 | M25: 40.01
A26: 三级 | B26: 资产余额 | C26: AA.40.01.01 | D26: 微粒贷 | K26: 是 | M26: 40.01.01 | N26: LAST
A27: 三级 | B27: 资产余额 | C27: AA.40.01.02 | D27: 分付 | K27: 是 | M27: 40.01.02 | N27: LAST
A28: 二级 | B28: 资产余额 | C28: AA.40.02 | D28: 汽车金融 | K28: 是 | M28: 40.02 | N28: LAST
A29: 二级 | B29: 资产余额 | C29: AA.40.03 | D29: 财富 | K29: 是 | M29: 40.03 | N29: LAST
A30: 二级 | B30: 资产余额 | C30: AA.40.04 | D30: 小鹅 | K30: 是 | M30: 40.04 | N30: LAST
A31: 二级 | B31: 资产余额 | C31: AA.40.05 | D31: 企业金融 | F31: AA.40.05.01 | K31: 是 | M31: 40.05
A32: 三级 | B32: 资产余额 | C32: AA.40.05.01 | D32: 一般贷款 | K32: 是 | M32: 40.05.01 | N32: LAST
A34: 一级 | B34: 资产余额 | C34: AA.41 | D34: 不良贷款原值余额 | F34: AA.41.01+AA.41.02+AA.41.03+AA.41.04+AA.41.05 | K34: 是 | M34: 41
A35: 二级 | B35: 资产余额 | C35: AA.41.01 | D35: 泛微粒贷 | F35: AA.41.01.01+AA.41.01.02 | K35: 是 | M35: 41.01
A36: 三级 | B36: 资产余额 | C36: AA.41.01.01 | D36: 微粒贷 | K36: 是 | M36: 41.01.01 | N36: LAST
A37: 三级 | B37: 资产余额 | C37: AA.41.01.02 | D37: 分付 | K37: 是 | M37: 41.01.02 | N37: LAST
A38: 二级 | B38: 资产余额 | C38: AA.41.02 | D38: 汽车金融 | K38: 是 | M38: 41.02 | N38: LAST
A39: 二级 | B39: 资产余额 | C39: AA.41.03 | D39: 财富 | K39: 是 | M39: 41.03 | N39: LAST
A40: 二级 | B40: 资产余额 | C40: AA.41.04 | D40: 小鹅 | K40: 是 | M40: 41.04 | N40: LAST
A41: 二级 | B41: 资产余额 | C41: AA.41.05 | D41: 企业金融 | F41: AA.41.05.01 | K41: 是 | M41: 41.05
A42: 三级 | B42: 资产余额 | C42: AA.41.05.01 | D42: 一般贷款 | K42: 是 | M42: 41.05.01 | N42: LAST
A44: 一级 | B44: 资产余额 | C44: AA.42 | D44: 年初不良贷款原值余额 | F44: AA.42.01+AA.42.02+AA.42.03+AA.42.04+AA.42.05 | K44: 是 | M44: 42
A45: 二级 | B45: 资产余额 | C45: AA.42.01 | D45: 泛微粒贷 | F45: AA.42.01.01+AA.42.01.02 | K45: 是 | M45: 42.01
...

Sheet AA利息净收入表
A1: 科目层级 | B1: 科目性质 | C1: 科目代码 | D1: 科目名称 | E1: 录入粒度 | F1: 年预算公式 | G1: 年预测公式 | H1: 实际月公式 | I1: 预测月公式 | J1: 公式说明 | K1: 横向汇总 | L1: 纵向汇总 | M1: 逻辑码 | N1: 规则
A2: 一级 | B2: 资产日均 | C2: AA.50 | D2: 生息资产日均规模 | F2: AA.50.01+AA.50.02+AA.50.03+AA.50.04 | K2: 是 | M2: 50
A3: 二级 | B3: 资产日均 | C3: AA.11.01 | D3: 各项贷款 | F3: AA.11.01.01+AA.11.01.02 | K3: 是 | M3: 11.01
A4: 二级 | B4: 资产日均 | C4: AA.23 | D4: 存放央行 | K4: 是 | M4: 23 | N4: AVG
A5: 二级 | B5: 资产日均 | C5: AA.25.01 | D5: 存放同业 | K5: 是 | M5: 25.01 | N5: AVG
A6: 二级 | B6: 资产日均 | C6: AA.25.02 | D6: 拆放同业 | K6: 是 | M6: 25.02 | N6: AVG
A7: 二级 | B7: 资产日均 | C7: AA.25.03 | D7: 买入返售 | K7: 是 | M7: 25.03 | N7: AVG
A8: 二级 | B8: 资产日均 | C8: AA.25.04 | D8: 债券投资 | K8: 是 | M8: 25.04 | N8: AVG
A9: 一级 | B9: 负债日均 | C9: AA.51 | D9: 付息负债日均规模 | K9: 是 | M9: 51 | N9: AVG
A10: 二级 | B10: 负债日均 | C10: AA.13.01 | D10: 各项存款 | K10: 是 | M10: 13.01 | N10: AVG
A11: 二级 | B11: 负债日均 | C11: AA.27.01 | D11: 向央行借款 | K11: 是 | M11: 27.01 | N11: AVG
A12: 二级 | B12: 负债日均 | C12: AA.27.02 | D12: 同业存放 | K12: 是 | M12: 27.02 | N12: AVG
A13: 二级 | B13: 负债日均 | C13: AA.27.03 | D13: 同业拆入 | K13: 是 | M13: 27.03 | N13: AVG
A14: 二级 | B14: 负债日均 | C14: AA.27.04 | D14: 转贷款 | K14: 是 | M14: 27.04 | N14: AVG
A15: 二级 | B15: 负债日均 | C15: AA.27.06 | D15: 发行同业存单 | K15: 是 | M15: 27.06 | N15: AVG
A17: 一级 | B17: 收入 | C17: AA.14 | D17: 生息资产利息收入 | F17: AA.14.01+AA.14.02+AA.14.03 | K17: 是 | M17: 14
A18: 二级 | B18: 收入 | C18: AA.14.01 | D18: 各项贷款 | K18: 是 | M18: 14.01 | N18: SUM
A19: 二级 | C19: AA.14.02 | D19: AA.14.02
A20: 二级 | B20: 收入 | C20: AA.14.02.01 | D20: 存放央行 | K20: 是 | M20: 14.02.01 | N20: SUM
A21: 二级 | B21: 收入 | C21: AA.14.02.02 | D21: 存放同业 | K21: 是 | M21: 14.02.02 | N21: SUM
A22: 二级 | B22: 收入 | C22: AA.14.02.03 | D22: 拆放同业 | K22: 是 | M22: 14.02.03 | N22: SUM
A23: 二级 | B23: 收入 | C23: AA.14.02.04 | D23: 买入返售 | K23: 是 | M23: 14.02.04 | N23: SUM
A24: 二级 | B24: 收入 | C24: AA.14.03 | D24: 债券投资 | K24: 是 | M24: 14.03 | N24: SUM
A25: 二级 | B25: 收入 | C25: AA.14.02.05 | D25: 同业存单投资 | K25: 是 | M25: 14.02.05 | N25: SUM
A26: 一级 | B26: 支出 | C26: AA.16 | D26: 付息负债利息支出 | F26: AA.16.01+AA.16.02 | K26: 是 | M26: 16
A27: 二级 | B27: 支出 | C27: AA.16.01 | D27: 各项存款 | K27: 是 | M27: 16.01 | N27: SUM
A28: 二级 | C28: AA.16.02 | D28: AA.16.02
A29: 二级 | B29: 支出 | C29: AA.16.02.01 | D29: 向央行借款 | K29: 是 | M29: 16.02.01 | N29: SUM
A30: 二级 | B30: 支出 | C30: AA.16.02.02 | D30: 同业存放 | K30: 是 | M30: 16.02.02 | N30: SUM
A31: 二级 | B31: 支出 | C31: AA.16.02.03 | D31: 同业拆入 | K31: 是 | M31: 16.02.03 | N31: SUM
A32: 二级 | B32: 支出 | C32: AA.16.02.04 | D32: 转贷款 | K32: 是 | M32: 16.02.04 | N32: SUM
A33: 二级 | B33: 支出 | C33: AA.16.02.05 | D33: 卖出回购 | K33: 是 | M33: 16.02.05 | N33: SUM
A34: 二级 | B34: 支出 | C34: AA.16.02.06 | D34: 发行同业存单 | K34: 是 | M34: 16.02.06 | N34: SUM
A36: 一级 | B36: 其他 | C36: AA.52 | D36: 生息资产收息率 | F36: AA.52.01+AA.52.02+AA.52.03+AA.52.04+AA.52.05+AA.52.06+AA.52.07 | H36: =H19/H2 | I36: =I19/I2 | J36: 率年化指标 | K36: 是 | M36: 52
A37: 二级 | B37: 其他 | C37: AA.52.01 | D37: 各项贷款 | H37: =H20/H3 | I37: =I20/I3 | J37: 率年化指标 | K37: 是 | M37: 52.01 | N37: WGT
A38: 二级 | B38: 其他 | C38: AA.52.02 | D38: 存放央行 | H38: =H21/H4 | I38: =I21/I4 | J38: 率年化指标 | K38: 是 | M38: 52.02 | N38: WGT
A39: 二级 | B39: 其他 | C39: AA.52.03 | D39: 存放同业 | H39: =H22/H5 | I39: =I22/I5 | J39: 率年化指标 | K39: 是 | M39: 52.03 | N39: WGT
A40: 二级 | B40: 其他 | C40: AA.52.04 | D40: 拆放同业 | H40: =H23/H6 | I40: =I23/I6 | J40: 率年化指标 | K40: 是 | M40: 52.04 | N40: WGT
A41: 二级 | B41: 其他 | C41: AA.52.05 | D41: 买入返售 | H41: =H24/H7 | I41: =I24/I7 | J41: 率年化指标 | K41: 是 | M41: 52.05 | N41: WGT
A42: 二级 | B42: 其他 | C42: AA.52.06 | D42: 债券投资 | H42: =H25/H8 | I42: =I25/I8 | J42: 率年化指标 | K42: 是 | M42: 52.06 | N42: WGT
...

Sheet A个金群
A1: 科目层级 | B1: 科目性质 | C1: 科目代码 | D1: 科目名称 | E1: 录入粒度 | F1: 年预算公式 | G1: 年预测公式 | H1: 实际月公式 | I1: 预测月公式 | J1: 公式说明 | K1: 横向汇总 | L1: 纵向汇总 | M1: 逻辑码 | N1: 规则
A2: 一级 | B2: 收入 | C2: A.01 | D2: 营业收入 | F2: A.01.01+A.01.02+A.01.03 | K2: 是 | M2: 01
A3: 二级 | B3: 收入 | C3: A.01.01 | D3: 利息净收入 | F3: A.01.01.01+A.01.01.02 | K3: 是 | M3: 01.01
A4: 三级 | B4: 收入 | C4: A.01.01.01 | D4: 资产业务 | M4: 01.01.01 | N4: SUM
A5: 一级 | B5: 收入 | C5: A.14 | D5: 利息收入 | K5: 是 | M5: 14 | N5: SUM
A6: 一级 | B6: 支出 | C6: A.15 | D6: FTP成本 | M6: 15 | N6: SUM
A7: 三级 | B7: 收入 | C7: A.01.01.02 | D7: 负债业务 | M7: 01.01.02 | N7: SUM
A8: 一级 | B8: 支出 | C8: A.16 | D8: 利息支出 | K8: 是 | M8: 16 | N8: SUM
A9: 一级 | B9: 支出 | C9: A.17 | D9: FTP收入 | M9: 17 | N9: SUM
A10: 二级 | B10: 收入 | C10: A.01.02 | D10: 净手续费收入 | K10: 是 | M10: 01.02 | N10: SUM
A11: 一级 | B11: 收入 | C11: A.18 | D11: 手续费收入 | K11: 是 | M11: 18 | N11: SUM
A12: 一级 | B12: 支出 | C12: A.19 | D12: 手续费支出 | K12: 是 | M12: 19 | N12: SUM
A13: 二级 | B13: 收入 | C13: A.01.03 | D13: 其他营收 | K13: 是 | M13: 01.03 | N13: SUM
A14: 一级 | B14: 支出 | C14: A.02 | D14: 减：风险成本 | K14: 是 | M14: 02 | N14: SUM
A15: 一级 | B15: 收入 | C15: A.03 | D15: 净收入 | K15: 是 | M15: 03 | N15: SUM
A16: 一级 | B16: 支出 | C16: A.04 | D16: 减：税金及附加 | K16: 是 | M16: 04 | N16: SUM
A17: 一级 | B17: 支出 | C17: A.05 | D17: 减：直接费用 | F17: A.90.01+A.90.09+A.90.03+A.90.04+A.90.05 | K17: 是 | M17: 05
A18: 二级 | B18: 支出 | C18: A.05.01 | D18: 人力费用（不含IT） | F18: A.90.01.01+A.90.01.02 | K18: 是 | M18: 05.01
A19: 三级 | B19: 支出 | C19: A.05.01.01 | D19: 常规人力 | F19: A.90.01.01.01+A.90.01.01.02+A.90.01.01.03+A.90.01.01.04.001+A.90.01.01.05.001 | K19: 是 | M19: 05.01.01
A20: 三级 | B20: 支出 | C20: A.05.01.02 | D20: 特别人力 | F20: A.90.01.02.01+A.90.01.02.02+A.90.01.02.03+A.90.01.02.04.001+A.90.01.02.05.001 | K20: 是 | M20: 05.01.02
A21: 二级 | B21: 支出 | C21: A.05.02 | D21: 业务费用 | K21: 是 | N21: SUM
A22: 三级 | B22: 支出 | C22: A.05.02.01 | D22: 营销费用 | K22: 是 | N22: SUM
A23: 三级 | B23: 支出 | C23: A.05.02.02 | D23: 运营费用 | K23: 是 | N23: SUM
A24: 二级 | B24: 支出 | C24: A.05.03 | D24: IT费用 | F24: A.90.03.01+A.90.03.02+A.90.03.03+A.90.03.04 | K24: 是 | M24: 05.03
A25: 三级 | B25: 支出 | C25: A.05.03.01 | D25: IT人力 | F25: A.90.03.01.01+A.90.03.01.02 | K25: 是 | M25: 05.03.01
A26: 四级 | B26: 支出 | C26: A.05.03.01.01 | D26: IT常规人力 | K26: 是 | M26: 05.03.01.01 | N26: SUM
A27: 四级 | B27: 支出 | C27: A.05.03.01.02 | D27: IT特别人力 | K27: 是 | M27: 05.03.01.02 | N27: SUM
A28: 三级 | B28: 支出 | C28: A.05.03.02 | D28: 科技费用 | K28: 是 | M28: 05.03.02 | N28: SUM
A29: 三级 | B29: 支出 | C29: A.05.03.03 | D29: IT职场 | K29: 是 | M29: 05.03.03 | N29: SUM
A30: 三级 | B30: 支出 | C30: A.05.03.04 | D30: IT日常 | K30: 是 | M30: 05.03.04 | N30: SUM
A31: 二级 | B31: 支出 | C31: A.05.04 | D31: 职场费用 | K31: 是 | M31: 05.04 | N31: SUM
A32: 二级 | B32: 支出 | C32: A.05.05 | D32: 日常费用 | K32: 是 | M32: 05.05 | N32: SUM
A33: 一级 | B33: 收入 | C33: A.06 | D33: 加：营业外净收入 | K33: 是 | M33: 06 | N33: SUM
A34: 一级 | B34: 利润 | C34: A.07 | D34: 分摊前利润 | M34: 07 | N34: SUM
A35: 一级 | B35: 支出 | C35: A.08 | D35: 减：固定管理费 | M35: 08 | N35: SUM
A36: 一级 | B36: 利润 | C36: A.09 | D36: 税前利润 | K36: 是 | M36: 09 | N36: SUM
A38: 一级 | B38: 资产余额 | C38: A.10 | D38: 管理贷款余额 | F38: A.10.01+A.10.02+A.10.03 | M38: 10
A39: 二级 | B39: 资产余额 | C39: A.10.01 | D39: 自持余额 | F39: A.10.01.01 | M39: 10.01
A40: 三级 | B40: 资产余额 | C40: A.10.01.01 | D40: 一般贷款 | M40: 10.01.01 | N40: LAST
A41: 二级 | B41: 资产余额 | C41: A.10.02 | D41: 联贷 | M41: 10.02 | N41: LAST
...

Sheet A01泛微粒贷
A1: 科目层级 | B1: 科目性质 | C1: 科目代码 | D1: 科目名称 | E1: 录入粒度 | F1: 年预算公式 | G1: 年预测公式 | H1: 实际月公式 | I1: 预测月公式 | J1: 公式说明 | K1: 横向汇总 | L1: 纵向汇总 | M1: 逻辑码 | N1: 规则
A2: 一级 | B2: 收入 | C2: A01.01 | D2: 营业收入 | F2: A01.01.01+A01.01.02+A01.01.03 | H2: =H3+H6+H7 | I2: =I3+I6+I7 | M2: 01
A3: 二级 | B3: 收入 | C3: A01.01.01 | D3: 利息净收入 | F3: A01.01.01.01+A01.01.01.02 | H3: =H4+H5 | I3: =I4+I5 | M3: 01.01
A4: 三级 | B4: 收入 | C4: A01.01.01.01 | D4: 资产业务 | H4: =H63-H97 | I4: =I63-I97 | M4: 01.01.01 | N4: SUM
A5: 三级 | B5: 收入 | C5: A01.01.01.02 | D5: 负债业务 | H5: =H116-H109 | I5: =I116-I109 | M5: 01.01.02 | N5: SUM
A6: 二级 | B6: 收入 | C6: A01.01.02 | D6: 手续费净收入 | H6: =H123-H140 | I6: =I123-I140 | M6: 01.02 | N6: SUM
A7: 二级 | B7: 收入 | C7: A01.01.03 | D7: 其他营收 | H7: =H162+H164 | I7: =I162+I164 | M7: 01.03 | N7: SUM
A8: 一级 | B8: 支出 | C8: A01.02 | D8: 减：风险成本 | M8: 02 | N8: SUM
A9: 一级 | B9: 收入 | C9: A01.03 | D9: 净收入 | F9: A01.01-A01.02 | H9: =H2-H8 | I9: =I2-I8 | M9: 03
A10: 一级 | B10: 支出 | C10: A01.04 | D10: 减：税金及附加 | M10: 04 | N10: SUM
A11: 一级 | B11: 支出 | C11: A01.05 | D11: 减：直接费用 | F11: A01.90.01+A01.90.02+A01.90.03+A01.90.04+A01.90.05 | H11: =H12+H15+H18+H25+H26 | I11: =I12+I15+I18+I25+I26 | K11: 是 | M11: 05
A12: 二级 | B12: 支出 | C12: A01.05.01 | D12: 人力费用（不含IT） | F12: A01.90.01.01+A01.90.01.02 | H12: =H13+H14 | I12: =I13+I14 | K12: 是 | M12: 05.01
A13: 三级 | B13: 支出 | C13: A01.05.01.01 | D13: 常规人力 | F13: A01.90.01.01.01+A01.90.01.01.02+A01.90.01.01.03+A01.90.01.01.04.001+A01.90.01.01.05.001 | K13: 是 | M13: 05.01.01
A14: 三级 | B14: 支出 | C14: A01.05.01.02 | D14: 特别人力 | F14: A01.90.01.02.01+A01.90.01.02.02+A01.90.01.02.03+A01.90.01.02.04.001+A01.90.01.02.05.001 | K14: 是 | M14: 05.01.02
A15: 二级 | B15: 支出 | C15: A01.05.02 | D15: 业务费用 | F15: A01.90.02.01+A01.90.02.02+A01.90.02.09 | H15: =H16+H17 | I15: =I16+I17 | K15: 是 | M15: 05.02
A16: 三级 | B16: 支出 | C16: A01.05.02.01 | D16: 营销费用 | K16: 是 | M16: 05.02.01 | N16: SUM
A17: 三级 | B17: 支出 | C17: A01.05.02.02 | D17: 运营费用 | K17: 是 | M17: 05.02.02 | N17: SUM
A18: 二级 | B18: 支出 | C18: A01.05.03 | D18: IT费用 | F18: A01.90.03.01+A01.90.03.02+A01.90.03.03+A01.90.03.04 | H18: =H19+H22+H23+H24 | I18: =I19+I22+I23+I24 | K18: 是 | M18: 05.03
A19: 三级 | B19: 支出 | C19: A01.05.03.01 | D19: IT人力 | F19: A01.90.03.01.01+A01.90.03.01.02 | H19: =H20+H21 | I19: =I20+I21 | K19: 是 | M19: 05.03.01
A20: 四级 | B20: 支出 | C20: A01.05.03.01.01 | D20: IT常规人力 | K20: 是 | M20: 05.03.01.01 | N20: SUM
A21: 四级 | B21: 支出 | C21: A01.05.03.01.02 | D21: IT特别人力 | K21: 是 | M21: 05.03.01.02 | N21: SUM
A22: 三级 | B22: 支出 | C22: A01.05.03.02 | D22: 科技费用 | K22: 是 | M22: 05.03.02 | N22: SUM
A23: 三级 | B23: 支出 | C23: A01.05.03.03 | D23: IT职场 | K23: 是 | M23: 05.03.03 | N23: SUM
A24: 三级 | B24: 支出 | C24: A01.05.03.04 | D24: IT日常 | K24: 是 | M24: 05.03.04 | N24: SUM
A25: 二级 | B25: 支出 | C25: A01.05.04 | D25: 职场费用 | K25: 是 | M25: 05.04 | N25: SUM
A26: 二级 | B26: 支出 | C26: A01.05.05 | D26: 日常费用 | K26: 是 | M26: 05.05 | N26: SUM
A27: 一级 | B27: 收入 | C27: A01.06 | D27: 加：营业外净收入 | M27: 06 | N27: SUM
A28: 一级 | B28: 利润 | C28: A01.07 | D28: 分摊前利润 | F28: A01.03-A01.04-A01.90+A01.06 | H28: =H9-H10-H11+H27 | I28: =I9-I10-I11+I27 | M28: 07
A29: 一级 | B29: 支出 | C29: A01.08 | D29: 减：固定管理费 | M29: 08 | N29: SUM
A30: 一级 | B30: 利润 | C30: A01.09 | D30: 税前利润 | F30: A01.07-A01.08 | H30: =H28-H29 | I30: =I28-I29 | M30: 09
A32: 一级 | B32: 资产余额 | C32: A01.10 | D32: 管理贷款余额 | F32: A01.10.01+A01.10.02+A01.10.03 | H32: =H33+H38+H39 | I32: =I33+I38+I39 | M32: 10
A33: 二级 | B33: 资产余额 | C33: A01.10.01 | D33: 自持余额 | F33: A01.10.01.01 | H33: =H34 | I33: =I34 | M33: 10.01
A34: 三级 | B34: 资产余额 | C34: A01.10.01.01 | D34: 一般贷款 | F34: A01.10.01.01.01+A01.10.01.01.02 | H34: =H35+H37 | I34: =I35+I37 | M34: 10.01.01
A35: 四级 | B35: 资产余额 | C35: A01.10.01.01.01 | D35: 微粒贷 | F35: A01.10.01.01.01.01 | M35: 10.01.01.01
A36: 五级 | B36: 资产余额 | C36: A01.10.01.01.01.01 | D36: 其中：分期 | M36: 10.01.01.01.01 | N36: LAST
A37: 四级 | B37: 资产余额 | C37: A01.10.01.01.02 | D37: 分付 | M37: 10.01.01.02 | N37: LAST
A38: 二级 | B38: 资产余额 | C38: A01.10.02 | D38: 联贷 | M38: 10.02 | N38: LAST
A39: 二级 | B39: 资产余额 | C39: A01.10.03 | D39: 流转 | M39: 10.03 | N39: LAST
A40: 一级 | B40: 资产日均 | C40: A01.11 | D40: 管理贷款日均 | F40: A01.11.01+A01.11.02+A01.11.03 | H40: =H41+H46+H47 | I40: =I41+I46+I47 | M40: 11
A41: 二级 | B41: 资产日均 | C41: A01.11.01 | D41: 自持 | F41: A01.11.01.01 | H41: =H42 | I41: =I42 | M41: 11.01
...

Sheet A02微账户
A1: 科目层级 | B1: 科目性质 | C1: 科目代码 | D1: 科目名称 | E1: 录入粒度 | F1: 年预算公式 | G1: 年预测公式 | H1: 实际月公式 | I1: 预测月公式 | J1: 公式说明 | K1: 横向汇总 | L1: 纵向汇总 | M1: 逻辑码 | P1: 规则
A2: 一级 | B2: 收入 | C2: A02.01 | D2: 营业收入 | F2: A02.01.01+A02.01.02+A02.01.03 | H2: =H3+H6+H7 | I2: =I3+I6+I7 | M2: 01
A3: 二级 | B3: 收入 | C3: A02.01.01 | D3: 利息净收入 | F3: A02.01.01.01+A02.01.01.02 | H3: =H4+H5 | I3: =I4+I5 | M3: 01.01
A4: 三级 | B4: 收入 | C4: A02.01.01.01 | D4: 资产业务 | H4: =H56-H61 | I4: =I56-I61 | M4: 01.01.01 | P4: SUM
A5: 三级 | B5: 收入 | C5: A02.01.01.02 | D5: 负债业务 | H5: =H102-H69 | I5: =I102-I69 | M5: 01.01.02 | P5: SUM
A6: 二级 | B6: 收入 | C6: A02.01.02 | D6: 手续费净收入 | H6: =H125-H130 | I6: =I125-I130 | M6: 01.02 | P6: SUM
A7: 二级 | B7: 收入 | C7: A02.01.03 | D7: 其他营收 | H7: =H136+H138 | I7: =I136+I138 | M7: 01.03 | P7: SUM
A8: 一级 | B8: 支出 | C8: A02.02 | D8: 减：风险成本 | M8: 02 | P8: SUM
A9: 一级 | B9: 收入 | C9: A02.03 | D9: 净收入 | F9: A02.01-A02.02 | H9: =H2-H8 | I9: =I2-I8 | M9: 03
A10: 一级 | B10: 支出 | C10: A02.04 | D10: 减：税金及附加 | M10: 04 | P10: SUM
A11: 一级 | B11: 支出 | C11: A02.05 | D11: 减：直接费用 | F11: A02.90.01+A02.90.02+A02.90.03+A02.90.04+A02.90.05 | H11: =H12+H15+H18+H25+H26 | I11: =I12+I15+I18+I25+I26 | K11: 是 | M11: 05
A12: 二级 | B12: 支出 | C12: A02.05.01 | D12: 人力费用（不含IT） | F12: A02.90.01.01+A02.90.01.02 | H12: =H13+H14 | I12: =I13+I14 | K12: 是 | M12: 05.01
A13: 三级 | B13: 支出 | C13: A02.05.01.01 | D13: 常规人力 | F13: A02.90.01.01.01+A02.90.01.01.02+A02.90.01.01.03+A02.90.01.01.04.001+A02.90.01.01.05.001 | K13: 是 | M13: 05.01.01
A14: 三级 | B14: 支出 | C14: A02.05.01.02 | D14: 特别人力 | F14: A02.90.01.02.01+A02.90.01.02.02+A02.90.01.02.03+A02.90.01.02.04.001+A02.90.01.02.05.001 | K14: 是 | M14: 05.01.02
A15: 二级 | B15: 支出 | C15: A02.05.02 | D15: 业务费用 | F15: A02.90.02.01+A02.90.02.02+A02.90.02.09 | H15: =H16+H17 | I15: =I16+I17 | K15: 是 | M15: 05.02
A16: 三级 | B16: 支出 | C16: A02.05.02.01 | D16: 营销费用 | K16: 是 | M16: 05.02.01 | P16: SUM
A17: 三级 | B17: 支出 | C17: A02.05.02.02 | D17: 运营费用 | K17: 是 | M17: 05.02.02 | P17: SUM
A18: 二级 | B18: 支出 | C18: A02.05.03 | D18: IT费用 | F18: A02.90.03.01+A02.90.03.02+A02.90.03.03+A02.90.03.04 | H18: =H19+H22+H23+H24 | I18: =I19+I22+I23+I24 | K18: 是 | M18: 05.03
A19: 三级 | B19: 支出 | C19: A02.05.03.01 | D19: IT人力 | F19: A02.90.03.01.01+A02.90.03.01.02 | H19: =H20+H21 | I19: =I20+I21 | K19: 是 | M19: 05.03.01
A20: 四级 | B20: 支出 | C20: A02.05.03.01.01 | D20: IT常规人力 | K20: 是 | M20: 05.03.01.01 | P20: SUM
A21: 四级 | B21: 支出 | C21: A02.05.03.01.02 | D21: IT特别人力 | K21: 是 | M21: 05.03.01.02 | P21: SUM
A22: 三级 | B22: 支出 | C22: A02.05.03.02 | D22: 科技费用 | K22: 是 | M22: 05.03.02 | P22: SUM
A23: 三级 | B23: 支出 | C23: A02.05.03.03 | D23: IT职场 | K23: 是 | M23: 05.03.03 | P23: SUM
A24: 三级 | B24: 支出 | C24: A02.05.03.04 | D24: IT日常 | K24: 是 | M24: 05.03.04 | P24: SUM
A25: 二级 | B25: 支出 | C25: A02.05.04 | D25: 职场费用 | K25: 是 | M25: 05.04 | P25: SUM
A26: 二级 | B26: 支出 | C26: A02.05.05 | D26: 日常费用 | K26: 是 | M26: 05.05 | P26: SUM
A27: 一级 | B27: 收入 | C27: A02.06 | D27: 加：营业外净收入 | M27: 06 | P27: SUM
A28: 一级 | B28: 利润 | C28: A02.07 | D28: 分摊前利润 | F28: A02.03-A02.04-A02.90+A02.06 | H28: =H9-H10-H11+H27 | I28: =I9-I10-I11+I27 | M28: 07
A29: 一级 | B29: 支出 | C29: A02.08 | D29: 减：固定管理费 | M29: 08 | P29: SUM
A30: 一级 | B30: 利润 | C30: A02.09 | D30: 税前利润 | F30: A02.07-A02.08 | H30: =H28-H29 | I30: =I28-I29 | M30: 09
A32: 一级 | B32: 负债余额 | C32: A02.12 | D32: 管理资产余额 | F32: A02.12.01+A02.12.02+A02.12.03+A02.12.04 | H32: =H33+H36+H37+H38 | I32: =I33+I36+I37+I38 | M32: 12
A33: 二级 | B33: 负债余额 | C33: A02.12.01 | D33: 零钱+ | F33: A02.12.01.01 | H33: =H34+H35 | I33: =I34+I35 | M33: 12.01
A34: 三级 | B34: 负债余额 | C34: A02.12.01.01 | D34: 经营部分 | M34: 12.01.01 | P34: LAST
A35: 三级 | B35: 负债余额 | C35: A02.17.01.01.04 | D35: 流动性专项备付 | F35: A02.17.01.01.04.01+A02.17.01.01.04.02
A36: 二级 | B36: 负债余额 | C36: A02.12.02 | D36: 零钱通 | M36: 12.02 | P36: LAST
A37: 二级 | B37: 负债余额 | C37: A02.12.03 | D37: 商户结算便利应付款 | M37: 12.03 | P37: LAST
A38: 二级 | B38: 负债余额 | C38: A02.12.04 | D38: 存款服务 | M38: 12.04 | P38: LAST
A39: 一级 | B39: 负债日均 | C39: A02.13 | D39: 管理资产日均 | F39: A02.13.01+A02.13.02+A02.13.03+A02.13.04 | H39: =H40+H43+H44+H45 | I39: =I40+I43+I44+I45 | M39: 13
A40: 二级 | B40: 负债日均 | C40: A02.13.01 | D40: 零钱+ | F40: A02.13.01.01+A02.13.01.02 | H40: =H41+H42 | I40: =I41+I42 | M40: 13.01
A41: 三级 | B41: 负债日均 | C41: A02.13.01.01 | D41: 经营部分 | M41: 13.01.01 | P41: AVG
...

Sheet A03汽车金融
A1: 科目层级 | B1: 科目性质 | C1: 科目代码 | D1: 科目名称 | E1: 录入粒度 | F1: 年预算公式 | G1: 年预测公式 | H1: 实际月公式 | I1: 预测月公式 | J1: 公式说明 | K1: 横向汇总 | L1: 纵向汇总 | M1: 逻辑码 | P1: 规则
A2: 一级 | B2: 收入 | C2: A03.01 | D2: 营业收入 | F2: A03.01.01+A03.01.02+A03.01.03 | H2: =H3+H6+H7 | I2: =I3+I6+I7 | M2: 01
A3: 二级 | B3: 收入 | C3: A03.01.01 | D3: 利息净收入 | F3: A03.01.01.01+A03.01.01.02 | H3: =H4+H5 | I3: =I4+I5 | M3: 01.01
A4: 三级 | B4: 收入 | C4: A03.01.01.01 | D4: 资产业务 | H4: =H53-H57 | I4: =I53-I57 | M4: 01.01.01 | P4: SUM
A5: 三级 | B5: 收入 | C5: A03.01.01.02 | D5: 负债业务 | H5: =H70-H63 | I5: =I70-I63 | M5: 01.01.02 | P5: SUM
A6: 二级 | B6: 收入 | C6: A03.01.02 | D6: 手续费净收入 | H6: =H82-H88 | I6: =I82-I88 | M6: 01.02 | P6: SUM
A7: 二级 | B7: 收入 | C7: A03.01.03 | D7: 其他营收 | H7: =H102+H104 | I7: =I102+I104 | M7: 01.03 | P7: SUM
A8: 一级 | B8: 支出 | C8: A03.02 | D8: 减：风险成本 | M8: 02 | P8: SUM
A9: 一级 | B9: 收入 | C9: A03.03 | D9: 净收入 | F9: A03.01-A03.02 | H9: =H2-H8 | I9: =I2-I8 | M9: 03
A10: 一级 | B10: 支出 | C10: A03.04 | D10: 减：税金及附加 | M10: 04 | P10: SUM
A11: 一级 | B11: 支出 | C11: A03.05 | D11: 减：直接费用 | F11: A03.90.01+A03.90.02+A03.90.03+A03.90.04+A03.90.05 | H11: =H12+H15+H18+H25+H26 | I11: =I12+I15+I18+I25+I26 | K11: 是 | M11: 05
A12: 二级 | B12: 支出 | C12: A03.05.01 | D12: 人力费用（不含IT） | F12: A03.90.01.01+A03.90.01.02 | H12: =H13+H14 | I12: =I13+I14 | K12: 是 | M12: 05.01
A13: 三级 | B13: 支出 | C13: A03.05.01.01 | D13: 常规人力 | F13: A03.90.01.01.01+A03.90.01.01.02+A03.90.01.01.03+A03.90.01.01.04.001+A03.90.01.01.05.001 | K13: 是 | M13: 05.01.01
A14: 三级 | B14: 支出 | C14: A03.05.01.02 | D14: 特别人力 | F14: A03.90.01.02.01+A03.90.01.02.02+A03.90.01.02.03+A03.90.01.02.04.001+A03.90.01.02.05.001 | K14: 是 | M14: 05.01.02
A15: 二级 | B15: 支出 | C15: A03.05.02 | D15: 业务费用 | F15: A03.90.02.01+A03.90.02.02+A03.90.02.09 | H15: =H16+H17 | I15: =I16+I17 | K15: 是 | M15: 05.02
A16: 三级 | B16: 支出 | C16: A03.05.02.01 | D16: 营销费用 | K16: 是 | M16: 05.02.01 | P16: SUM
A17: 三级 | B17: 支出 | C17: A03.05.02.02 | D17: 运营费用 | K17: 是 | M17: 05.02.02 | P17: SUM
A18: 二级 | B18: 支出 | C18: A03.05.03 | D18: IT费用 | F18: A03.90.03.01+A03.90.03.02+A03.90.03.03+A03.90.03.04 | H18: =H19+H22+H23+H24 | I18: =I19+I22+I23+I24 | K18: 是 | M18: 05.03
A19: 三级 | B19: 支出 | C19: A03.05.03.01 | D19: IT人力 | F19: A03.90.03.01.01+A03.90.03.01.02 | H19: =H20+H21 | I19: =I20+I21 | K19: 是 | M19: 05.03.01
A20: 四级 | B20: 支出 | C20: A03.05.03.01.01 | D20: IT常规人力 | K20: 是 | M20: 05.03.01.01 | P20: SUM
A21: 四级 | B21: 支出 | C21: A03.05.03.01.02 | D21: IT特别人力 | K21: 是 | M21: 05.03.01.02 | P21: SUM
A22: 三级 | B22: 支出 | C22: A03.05.03.02 | D22: 科技费用 | K22: 是 | M22: 05.03.02 | P22: SUM
A23: 三级 | B23: 支出 | C23: A03.05.03.03 | D23: IT职场 | K23: 是 | M23: 05.03.03 | P23: SUM
A24: 三级 | B24: 支出 | C24: A03.05.03.04 | D24: IT日常 | K24: 是 | M24: 05.03.04 | P24: SUM
A25: 二级 | B25: 支出 | C25: A03.05.04 | D25: 职场费用 | K25: 是 | M25: 05.04 | P25: SUM
A26: 二级 | B26: 支出 | C26: A03.05.05 | D26: 日常费用 | K26: 是 | M26: 05.05 | P26: SUM
A27: 一级 | B27: 收入 | C27: A03.06 | D27: 加：营业外净收入 | M27: 06 | P27: SUM
A28: 一级 | B28: 利润 | C28: A03.07 | D28: 分摊前利润 | F28: A03.03-A03.04-A03.90+A03.06 | H28: =H9-H10-H11+H27 | I28: =I9-I10-I11+I27 | M28: 07
A29: 一级 | B29: 支出 | C29: A03.08 | D29: 减：固定管理费 | M29: 08 | P29: SUM
A30: 一级 | B30: 利润 | C30: A03.09 | D30: 税前利润 | F30: A03.07-A03.08 | H30: =H28-H29 | I30: =I28-I29 | M30: 09
A32: 一级 | B32: 资产余额 | C32: A03.10 | D32: 管理贷款 | F32: A03.10.01+A03.10.02+A03.10.03 | H32: =H33+H35+H36 | I32: =I33+I35+I36 | M32: 10
A33: 二级 | B33: 资产余额 | C33: A03.10.01 | D33: 自持 | F33: A03.10.01.01 | H33: =H34 | I33: =I34 | M33: 10.01
A34: 三级 | B34: 资产余额 | C34: A03.10.01.01 | D34: 一般贷款 | M34: 10.01.01 | P34: LAST
A35: 二级 | B35: 资产余额 | C35: A03.10.02 | D35: 联贷 | M35: 10.02 | P35: LAST
A36: 二级 | B36: 资产余额 | C36: A03.10.03 | D36: 流转 | M36: 10.03 | P36: LAST
A37: 一级 | B37: 资产日均 | C37: A03.11 | D37: 管理贷款日均 | F37: A03.11.01+A03.11.02+A03.11.03 | H37: =H38+H40+H41 | I37: =I38+I40+I41 | M37: 11
A38: 二级 | B38: 资产日均 | C38: A03.11.01 | D38: 自持 | F38: A03.11.01.01 | H38: =H39 | I38: =I39 | M38: 11.01
A39: 三级 | B39: 资产日均 | C39: A03.11.01.01 | D39: 一般贷款 | M39: 11.01.01 | P39: AVG
A40: 二级 | B40: 资产日均 | C40: A03.11.02 | D40: 联贷 | M40: 11.02 | P40: AVG
A41: 二级 | B41: 资产日均 | C41: A03.11.03 | D41: 流转 | M41: 11.03 | P41: AVG
...

Sheet A04财富
A1: 科目层级 | B1: 科目性质 | C1: 科目代码 | D1: 科目名称 | E1: 录入粒度 | F1: 年预算公式 | G1: 年预测公式 | H1: 实际月公式 | I1: 预测月公式 | J1: 公式说明 | K1: 横向汇总 | L1: 纵向汇总 | M1: 逻辑码 | P1: 规则
A2: 一级 | B2: 收入 | C2: A04.01 | D2: 营业收入 | F2: A04.01.01+A04.01.02+A04.01.03 | H2: =H3+H6+H7 | I2: =I3+I6+I7 | M2: 01
A3: 二级 | B3: 收入 | C3: A04.01.01 | D3: 利息净收入 | F3: A04.01.01.01+A04.01.01.02 | H3: =H4+H5 | I3: =I4+I5 | M3: 01.01
A4: 三级 | B4: 收入 | C4: A04.01.01.01 | D4: 资产业务 | H4: =H63-H71 | I4: =I63-I71 | M4: 01.01.01 | P4: SUM
A5: 三级 | B5: 收入 | C5: A04.01.01.02 | D5: 负债业务 | H5: =H91-H80 | I5: =I91-I80 | M5: 01.01.02 | P5: SUM
A6: 二级 | B6: 收入 | C6: A04.01.02 | D6: 手续费净收入 | H6: =H105-H110 | I6: =I105-I110 | M6: 01.02 | P6: SUM
A7: 二级 | B7: 收入 | C7: A04.01.03 | D7: 其他营收 | H7: =H117+H119 | I7: =I117+I119 | M7: 01.03 | P7: SUM
A8: 一级 | B8: 支出 | C8: A04.02 | D8: 减：风险成本 | M8: 02 | P8: SUM
A9: 一级 | B9: 收入 | C9: A04.03 | D9: 净收入 | F9: A04.01-A04.02 | H9: =H2-H8 | I9: =I2-I8 | M9: 03
A10: 一级 | B10: 支出 | C10: A04.04 | D10: 减：税金及附加 | M10: 04 | P10: SUM
A11: 一级 | B11: 支出 | C11: A04.05 | D11: 减：直接费用 | F11: A04.90.01+A04.90.02+A04.90.03+A04.90.04+A04.90.05 | H11: =H12+H15+H18+H25+H26 | I11: =I12+I15+I18+I25+I26 | K11: 是 | M11: 05
A12: 二级 | B12: 支出 | C12: A04.05.01 | D12: 人力费用（不含IT） | F12: A04.90.01.01+A04.90.01.02 | H12: =H13+H14 | I12: =I13+I14 | K12: 是 | M12: 05.01
A13: 三级 | B13: 支出 | C13: A04.05.01.01 | D13: 常规人力 | F13: A04.90.01.01.01+A04.90.01.01.02+A04.90.01.01.03+A04.90.01.01.04.001+A04.90.01.01.05.001 | K13: 是 | M13: 05.01.01
A14: 三级 | B14: 支出 | C14: A04.05.01.02 | D14: 特别人力 | F14: A04.90.01.02.01+A04.90.01.02.02+A04.90.01.02.03+A04.90.01.02.04.001+A04.90.01.02.05.001 | K14: 是 | M14: 05.01.02
A15: 二级 | B15: 支出 | C15: A04.05.02 | D15: 业务费用 | F15: A04.90.02.01+A04.90.02.02+A04.90.02.09 | H15: =H16+H17 | I15: =I16+I17 | K15: 是 | M15: 05.02
A16: 三级 | B16: 支出 | C16: A04.05.02.01 | D16: 营销费用 | K16: 是 | M16: 05.02.01 | P16: SUM
A17: 三级 | B17: 支出 | C17: A04.05.02.02 | D17: 运营费用 | K17: 是 | M17: 05.02.02 | P17: SUM
A18: 二级 | B18: 支出 | C18: A04.05.03 | D18: IT费用 | F18: A04.90.03.01+A04.90.03.02+A04.90.03.03+A04.90.03.04 | H18: =H19+H22+H23+H24 | I18: =I19+I22+I23+I24 | K18: 是 | M18: 05.03
A19: 三级 | B19: 支出 | C19: A04.05.03.01 | D19: IT人力 | F19: A04.90.03.01.01+A04.90.03.01.02 | H19: =H20+H21 | I19: =I20+I21 | K19: 是 | M19: 05.03.01
A20: 四级 | B20: 支出 | C20: A04.05.03.01.01 | D20: IT常规人力 | K20: 是 | M20: 05.03.01.01 | P20: SUM
A21: 四级 | B21: 支出 | C21: A04.05.03.01.02 | D21: IT特别人力 | K21: 是 | M21: 05.03.01.02 | P21: SUM
A22: 三级 | B22: 支出 | C22: A04.05.03.02 | D22: 科技费用 | K22: 是 | M22: 05.03.02 | P22: SUM
A23: 三级 | B23: 支出 | C23: A04.05.03.03 | D23: IT职场 | K23: 是 | M23: 05.03.03 | P23: SUM
A24: 三级 | B24: 支出 | C24: A04.05.03.04 | D24: IT日常 | K24: 是 | M24: 05.03.04 | P24: SUM
A25: 二级 | B25: 支出 | C25: A04.05.04 | D25: 职场费用 | K25: 是 | M25: 05.04 | P25: SUM
A26: 二级 | B26: 支出 | C26: A04.05.05 | D26: 日常费用 | K26: 是 | M26: 05.05 | P26: SUM
A27: 一级 | B27: 收入 | C27: A04.06 | D27: 加：营业外净收入 | M27: 06 | P27: SUM
A28: 一级 | B28: 利润 | C28: A04.07 | D28: 分摊前利润 | F28: A04.03-A04.04-A04.90+A04.06 | H28: =H9-H10-H11+H27 | I28: =I9-I10-I11+I27 | M28: 07
A29: 一级 | B29: 支出 | C29: A04.08 | D29: 减：固定管理费 | M29: 08 | P29: SUM
A30: 一级 | B30: 利润 | C30: A04.09 | D30: 税前利润 | F30: A04.07-A04.08 | H30: =H28-H29 | I30: =I28-I29 | M30: 09
A32: 一级 | B32: 资产余额 | C32: A04.10 | D32: 管理贷款余额 | F32: A04.10.01+A04.10.02+A04.10.03 | H32: =H33+H35+H36 | I32: =I33+I35+I36 | M32: 10
A33: 二级 | B33: 资产余额 | C33: A04.10.01 | D33: 自持 | F33: A04.10.01.01 | H33: =H34 | I33: =I34 | M33: 10.01
A34: 三级 | B34: 资产余额 | C34: A04.10.01.01 | D34: 一般贷款 | M34: 10.01.01 | P34: LAST
A35: 二级 | B35: 资产余额 | C35: A04.10.02 | D35: 联贷 | M35: 10.02 | P35: LAST
A36: 二级 | B36: 资产余额 | C36: A04.10.03 | D36: 流转 | M36: 10.03 | P36: LAST
A37: 一级 | B37: 资产日均 | C37: A04.11 | D37: 管理贷款日均 | F37: A04.11.01+A04.11.02+A04.11.03 | H37: =H38+H40+H41 | I37: =I38+I40+I41 | M37: 11
A38: 二级 | B38: 资产日均 | C38: A04.11.01 | D38: 自持 | F38: A04.11.01.01 | H38: =H39 | I38: =I39 | M38: 11.01
A39: 三级 | B39: 资产日均 | C39: A04.11.01.01 | D39: 一般贷款 | M39: 11.01.01 | P39: AVG
A40: 二级 | B40: 资产日均 | C40: A04.11.02 | D40: 联贷 | M40: 11.02 | P40: AVG
A41: 二级 | B41: 资产日均 | C41: A04.11.03 | D41: 流转 | M41: 11.03 | P41: AVG
...

Sheet A05小鹅
A1: 科目层级 | B1: 科目性质 | C1: 科目代码 | D1: 科目名称 | E1: 录入粒度 | F1: 年预算公式 | G1: 年预测公式 | H1: 实际月公式 | I1: 预测月公式 | J1: 公式说明 | K1: 横向汇总 | L1: 纵向汇总 | M1: 逻辑码 | P1: 规则
A2: 一级 | B2: 收入 | C2: A05.01 | D2: 营业收入 | F2: A05.01.01+A05.01.02+A05.01.03 | H2: =H3+H6+H7 | I2: =I3+I6+I7 | M2: 01
A3: 二级 | B3: 收入 | C3: A05.01.01 | D3: 利息净收入 | F3: A05.01.01.01+A05.01.01.02 | H3: =H4+H5 | I3: =I4+I5 | M3: 01.01
A4: 三级 | B4: 收入 | C4: A05.01.01.01 | D4: 资产业务 | H4: =H48-H52 | I4: =I48-I52 | M4: 01.01.01 | P4: SUM
A5: 三级 | B5: 收入 | C5: A05.01.01.02 | D5: 负债业务 | H5: =H62-H58 | I5: =I62-I58 | M5: 01.01.02 | P5: SUM
A6: 二级 | B6: 收入 | C6: A05.01.02 | D6: 手续费净收入 | H6: =H66-H69 | I6: =I66-I69 | M6: 01.02 | P6: SUM
A7: 二级 | B7: 收入 | C7: A05.01.03 | D7: 其他营收 | H7: =H80+H82 | I7: =I80+I82 | M7: 01.03 | P7: SUM
A8: 一级 | B8: 支出 | C8: A05.02 | D8: 减：风险成本 | M8: 02 | P8: SUM
A9: 一级 | B9: 收入 | C9: A05.03 | D9: 净收入 | F9: A05.01-A05.02 | H9: =H2-H8 | I9: =I2-I8 | M9: 03
A10: 一级 | B10: 支出 | C10: A05.04 | D10: 减：税金及附加 | M10: 04 | P10: SUM
A11: 一级 | B11: 支出 | C11: A05.05 | D11: 减：直接费用 | F11: A05.90.01+A05.90.02+A05.90.03+A05.90.04+A05.90.05 | H11: =H12+H15+H18+H25+H26 | I11: =I12+I15+I18+I25+I26 | K11: 是 | M11: 05
A12: 二级 | B12: 支出 | C12: A05.05.01 | D12: 人力费用（不含IT） | F12: A05.90.01.01+A05.90.01.02 | H12: =H13+H14 | I12: =I13+I14 | K12: 是 | M12: 05.01
A13: 三级 | B13: 支出 | C13: A05.05.01.01 | D13: 常规人力 | F13: A05.90.01.01.01+A05.90.01.01.02+A05.90.01.01.03+A05.90.01.01.04.001+A05.90.01.01.05.001 | K13: 是 | M13: 05.01.01
A14: 三级 | B14: 支出 | C14: A05.05.01.02 | D14: 特别人力 | F14: A05.90.01.02.01+A05.90.01.02.02+A05.90.01.02.03+A05.90.01.02.04.001+A05.90.01.02.05.001 | K14: 是 | M14: 05.01.02
A15: 二级 | B15: 支出 | C15: A05.05.02 | D15: 业务费用 | F15: A05.90.02.01+A05.90.02.02+A05.90.02.09 | H15: =H16+H17 | I15: =I16+I17 | K15: 是 | M15: 05.02
A16: 三级 | B16: 支出 | C16: A05.05.02.01 | D16: 营销费用 | K16: 是 | M16: 05.02.01 | P16: SUM
A17: 三级 | B17: 支出 | C17: A05.05.02.02 | D17: 运营费用 | K17: 是 | M17: 05.02.02 | P17: SUM
A18: 二级 | B18: 支出 | C18: A05.05.03 | D18: IT费用 | F18: A05.90.03.01+A05.90.03.02+A05.90.03.03+A05.90.03.04 | H18: =H19+H22+H23+H24 | I18: =I19+I22+I23+I24 | K18: 是 | M18: 05.03
A19: 三级 | B19: 支出 | C19: A05.05.03.01 | D19: IT人力 | F19: A05.90.03.01.01+A05.90.03.01.02 | H19: =H20+H21 | I19: =I20+I21 | K19: 是 | M19: 05.03.01
A20: 四级 | B20: 支出 | C20: A05.05.03.01.01 | D20: IT常规人力 | K20: 是 | M20: 05.03.01.01 | P20: SUM
A21: 四级 | B21: 支出 | C21: A05.05.03.01.02 | D21: IT特别人力 | K21: 是 | M21: 05.03.01.02 | P21: SUM
A22: 三级 | B22: 支出 | C22: A05.05.03.02 | D22: 科技费用 | K22: 是 | M22: 05.03.02 | P22: SUM
A23: 三级 | B23: 支出 | C23: A05.05.03.03 | D23: IT职场 | K23: 是 | M23: 05.03.03 | P23: SUM
A24: 三级 | B24: 支出 | C24: A05.05.03.04 | D24: IT日常 | K24: 是 | M24: 05.03.04 | P24: SUM
A25: 二级 | B25: 支出 | C25: A05.05.04 | D25: 职场费用 | K25: 是 | M25: 05.04 | P25: SUM
A26: 二级 | B26: 支出 | C26: A05.05.05 | D26: 日常费用 | K26: 是 | M26: 05.05 | P26: SUM
A27: 一级 | B27: 收入 | C27: A05.06 | D27: 加：营业外净收入 | M27: 06 | P27: SUM
A28: 一级 | B28: 利润 | C28: A05.07 | D28: 分摊前利润 | F28: A05.03-A05.04-A05.90+A05.06 | H28: =H9-H10-H11+H27 | I28: =I9-I10-I11+I27 | M28: 07
A29: 一级 | B29: 支出 | C29: A05.08 | D29: 减：固定管理费 | M29: 08 | P29: SUM
A30: 一级 | B30: 利润 | C30: A05.09 | D30: 税前利润 | F30: A05.07-A05.08 | H30: =H28-H29 | I30: =I28-I29 | M30: 09
A32: 一级 | B32: 资产余额 | C32: A05.10 | D32: 管理贷款余额 | F32: A05.10.01+A05.10.02+A05.10.03 | H32: =H33+H35+H36 | I32: =I33+I35+I36 | M32: 10
A33: 二级 | B33: 资产余额 | C33: A05.10.01 | D33: 自持 | F33: A05.10.01.01 | H33: =H34 | I33: =I34 | M33: 10.01
A34: 三级 | B34: 资产余额 | C34: A05.10.01.01 | D34: 一般贷款 | M34: 10.01.01 | P34: LAST
A35: 二级 | B35: 资产余额 | C35: A05.10.02 | D35: 联贷 | M35: 10.02 | P35: LAST
A36: 二级 | B36: 资产余额 | C36: A05.10.03 | D36: 流转 | M36: 10.03 | P36: LAST
A37: 一级 | B37: 资产日均 | C37: A05.11 | D37: 管理贷款日均 | F37: A05.11.01+A05.11.02+A05.11.03 | H37: =H38+H40+H41 | I37: =I38+I40+I41 | M37: 11
A38: 二级 | B38: 资产日均 | C38: A05.11.01 | D38: 自持 | F38: A05.11.01.01 | H38: =H39 | I38: =I39 | M38: 11.01
A39: 三级 | B39: 资产日均 | C39: A05.11.01.01 | D39: 一般贷款 | M39: 11.01.01 | P39: AVG
A40: 二级 | B40: 资产日均 | C40: A05.11.02 | D40: 联贷 | M40: 11.02 | P40: AVG
A41: 二级 | B41: 资产日均 | C41: A05.11.03 | D41: 流转 | M41: 11.03 | P41: AVG
...

Sheet B企金群
A1: 科目层级 | B1: 科目性质 | C1: 科目代码 | D1: 科目名称 | E1: 录入粒度 | F1: 年预算公式 | G1: 年预测公式 | H1: 实际月公式 | I1: 预测月公式 | J1: 公式说明 | K1: 横向汇总 | L1: 纵向汇总 | M1: 逻辑码 | N1: 规则
A2: 一级 | B2: 收入 | C2: B.01 | D2: 营业收入 | F2: B.01.01+B.01.02+B.01.03 | K2: 是 | M2: 01
A3: 二级 | B3: 收入 | C3: B.01.01 | D3: 利息净收入 | F3: B.01.01.01+B.01.01.02 | K3: 是 | M3: 01.01
A4: 三级 | B4: 收入 | C4: B.01.01.01 | D4: 资产业务 | M4: 01.01.01 | N4: SUM
A5: 一级 | B5: 收入 | C5: B.14 | D5: 利息收入 | K5: 是 | M5: 14 | N5: SUM
A6: 一级 | B6: 支出 | C6: B.15 | D6: FTP成本 | M6: 15 | N6: SUM
A7: 三级 | B7: 收入 | C7: B.01.01.02 | D7: 负债业务 | M7: 01.01.02 | N7: SUM
A8: 一级 | B8: 支出 | C8: B.16 | D8: 利息支出 | K8: 是 | M8: 16 | N8: SUM
A9: 一级 | B9: 支出 | C9: B.17 | D9: FTP收入 | M9: 17 | N9: SUM
A10: 二级 | B10: 收入 | C10: B.01.02 | D10: 净手续费收入 | K10: 是 | M10: 01.02 | N10: SUM
A11: 一级 | B11: 收入 | C11: B.18 | D11: 手续费收入 | K11: 是 | M11: 18 | N11: SUM
A12: 一级 | B12: 支出 | C12: B.19 | D12: 手续费支出 | K12: 是 | M12: 19 | N12: SUM
A13: 二级 | B13: 收入 | C13: B.01.03 | D13: 其他营收 | K13: 是 | M13: 01.03 | N13: SUM
A14: 一级 | B14: 支出 | C14: B.02 | D14: 减：风险成本 | K14: 是 | M14: 02 | N14: SUM
A15: 一级 | B15: 收入 | C15: B.03 | D15: 净收入 | K15: 是 | M15: 03 | N15: SUM
A16: 一级 | B16: 支出 | C16: B.04 | D16: 减：税金及附加 | K16: 是 | M16: 04 | N16: SUM
A17: 一级 | B17: 支出 | C17: B.05 | D17: 减：直接费用 | F17: B.90.01+B.90.09+B.90.03+B.90.04+B.90.05 | K17: 是 | M17: 05
A18: 二级 | B18: 支出 | C18: B.05.01 | D18: 人力费用（不含IT） | F18: B.90.01.01+B.90.01.02 | K18: 是 | M18: 05.01
A19: 三级 | B19: 支出 | C19: B.05.01.01 | D19: 常规人力 | F19: B.90.01.01.01+B.90.01.01.02+B.90.01.01.03+B.90.01.01.04.001+B.90.01.01.05.001 | K19: 是 | M19: 05.01.01
A20: 三级 | B20: 支出 | C20: B.05.01.02 | D20: 特别人力 | F20: B.90.01.02.01+B.90.01.02.02+B.90.01.02.03+B.90.01.02.04.001+B.90.01.02.05.001 | K20: 是 | M20: 05.01.02
A21: 二级 | B21: 支出 | C21: B.05.02 | D21: 业务费用 | K21: 是 | N21: SUM
A22: 三级 | B22: 支出 | C22: B.05.02.01 | D22: 营销费用 | K22: 是 | N22: SUM
A23: 三级 | B23: 支出 | C23: B.05.02.02 | D23: 运营费用 | K23: 是 | N23: SUM
A24: 二级 | B24: 支出 | C24: B.05.03 | D24: IT费用 | F24: B.90.03.01+B.90.03.02+B.90.03.03+B.90.03.04 | K24: 是 | M24: 05.03
A25: 三级 | B25: 支出 | C25: B.05.03.01 | D25: IT人力 | F25: B.90.03.01.01+B.90.03.01.02 | K25: 是 | M25: 05.03.01
A26: 四级 | B26: 支出 | C26: B.05.03.01.01 | D26: IT常规人力 | K26: 是 | M26: 05.03.01.01 | N26: SUM
A27: 四级 | B27: 支出 | C27: B.05.03.01.02 | D27: IT特别人力 | K27: 是 | M27: 05.03.01.02 | N27: SUM
A28: 三级 | B28: 支出 | C28: B.05.03.02 | D28: 科技费用 | K28: 是 | M28: 05.03.02 | N28: SUM
A29: 三级 | B29: 支出 | C29: B.05.03.03 | D29: IT职场 | K29: 是 | M29: 05.03.03 | N29: SUM
A30: 三级 | B30: 支出 | C30: B.05.03.04 | D30: IT日常 | K30: 是 | M30: 05.03.04 | N30: SUM
A31: 二级 | B31: 支出 | C31: B.05.04 | D31: 职场费用 | K31: 是 | M31: 05.04 | N31: SUM
A32: 二级 | B32: 支出 | C32: B.05.05 | D32: 日常费用 | K32: 是 | M32: 05.05 | N32: SUM
A33: 一级 | B33: 收入 | C33: B.06 | D33: 加：营业外净收入 | K33: 是 | M33: 06 | N33: SUM
A34: 一级 | B34: 利润 | C34: B.07 | D34: 分摊前利润 | M34: 07 | N34: SUM
A35: 一级 | B35: 支出 | C35: B.08 | D35: 减：固定管理费 | M35: 08 | N35: SUM
A36: 一级 | B36: 利润 | C36: B.09 | D36: 税前利润 | K36: 是 | M36: 09 | N36: SUM
A38: 一级 | B38: 资产余额 | C38: B.10 | D38: 管理贷款余额 | F38: B.10.01+B.10.02+B.10.03+B.10.04 | M38: 10
A39: 二级 | B39: 资产余额 | C39: B.10.01 | D39: 自持余额 | F39: B.10.01.01+B.10.01.02 | M39: 10.01
A40: 三级 | B40: 资产余额 | C40: B.10.01.01 | D40: 一般贷款 | M40: 10.01.01 | N40: LAST
A41: 三级 | B41: 资产余额 | C41: B.10.01.02 | D41: 票据融资 | M41: 10.01.02 | N41: LAST
...

Sheet B01企业金融
A1: 科目层级 | B1: 科目性质 | C1: 科目代码 | D1: 科目名称 | E1: 录入粒度 | F1: 年预算公式 | G1: 年预测公式 | H1: 实际月公式 | I1: 预测月公式 | J1: 公式说明 | K1: 横向汇总 | L1: 纵向汇总 | M1: 逻辑码 | P1: 规则
A2: 一级 | B2: 收入 | C2: B01.01 | D2: 营业收入 | F2: B01.01.01+B01.01.02+B01.01.03 | H2: =H3+H6+H7 | I2: =I3+I6+I7 | M2: 01
A3: 二级 | B3: 收入 | C3: B01.01.01 | D3: 利息净收入 | F3: B01.01.01.01+B01.01.01.02 | H3: =H4+H5 | I3: =I4+I5 | M3: 01.01
A4: 三级 | B4: 收入 | C4: B01.01.01.01 | D4: 资产业务 | H4: =H89-H125 | I4: =I89-I125 | M4: 01.01.01 | P4: SUM
A5: 三级 | B5: 收入 | C5: B01.01.01.02 | D5: 负债业务 | H5: =H162-H149 | I5: =I162-I149 | M5: 01.01.02 | P5: SUM
A6: 二级 | B6: 收入 | C6: B01.01.02 | D6: 手续费净收入 | H6: =H177-H193 | I6: =I177-I193 | M6: 01.02 | P6: SUM
A7: 二级 | B7: 收入 | C7: B01.01.03 | D7: 其他营收 | H7: =H206+H210 | I7: =I206+I210 | M7: 01.03 | P7: SUM
A8: 一级 | B8: 支出 | C8: B01.02 | D8: 减：风险成本 | M8: 02 | P8: SUM
A9: 一级 | B9: 收入 | C9: B01.03 | D9: 净收入 | F9: B01.01-B01.02 | H9: =H2-H8 | I9: =I2-I8 | M9: 03
A10: 一级 | B10: 支出 | C10: B01.04 | D10: 减：税金及附加 | M10: 04 | P10: SUM
A11: 一级 | B11: 支出 | C11: B01.05 | D11: 减：直接费用 | F11: B01.90.01+B01.90.02+B01.90.03+B01.90.04+B01.90.05 | H11: =H12+H15+H18+H25+H26 | I11: =I12+I15+I18+I25+I26 | K11: 是 | M11: 05
A12: 二级 | B12: 支出 | C12: B01.05.01 | D12: 人力费用（不含IT） | F12: B01.90.01.01+B01.90.01.02 | H12: =H13+H14 | I12: =I13+I14 | K12: 是 | M12: 05.01
A13: 三级 | B13: 支出 | C13: B01.05.01.01 | D13: 常规人力 | F13: B01.90.01.01.01+B01.90.01.01.02+B01.90.01.01.03+B01.90.01.01.04.001+B01.90.01.01.05.001 | K13: 是 | M13: 05.01.01
A14: 三级 | B14: 支出 | C14: B01.05.01.02 | D14: 特别人力 | F14: B01.90.01.02.01+B01.90.01.02.02+B01.90.01.02.03+B01.90.01.02.04.001+B01.90.01.02.05.001 | K14: 是 | M14: 05.01.02
A15: 二级 | B15: 支出 | C15: B01.05.02 | D15: 业务费用 | F15: B01.90.02.01+B01.90.02.02+B01.90.02.09 | H15: =H16+H17 | I15: =I16+I17 | K15: 是 | M15: 05.02
A16: 三级 | B16: 支出 | C16: B01.05.02.01 | D16: 营销费用 | K16: 是 | M16: 05.02.01 | P16: SUM
A17: 三级 | B17: 支出 | C17: B01.05.02.02 | D17: 运营费用 | K17: 是 | M17: 05.02.02 | P17: SUM
A18: 二级 | B18: 支出 | C18: B01.05.03 | D18: IT费用 | F18: B01.90.03.01+B01.90.03.02+B01.90.03.03+B01.90.03.04 | H18: =H19+H22+H23+H24 | I18: =I19+I22+I23+I24 | K18: 是 | M18: 05.03
A19: 三级 | B19: 支出 | C19: B01.05.03.01 | D19: IT人力 | F19: B01.90.03.01.01+B01.90.03.01.02 | H19: =H20+H21 | I19: =I20+I21 | K19: 是 | M19: 05.03.01
A20: 四级 | B20: 支出 | C20: B01.05.03.01.01 | D20: IT常规人力 | K20: 是 | M20: 05.03.01.01 | P20: SUM
A21: 四级 | B21: 支出 | C21: B01.05.03.01.02 | D21: IT特别人力 | K21: 是 | M21: 05.03.01.02 | P21: SUM
A22: 三级 | B22: 支出 | C22: B01.05.03.02 | D22: 科技费用 | K22: 是 | M22: 05.03.02 | P22: SUM
A23: 三级 | B23: 支出 | C23: B01.05.03.03 | D23: IT职场 | K23: 是 | M23: 05.03.03 | P23: SUM
A24: 三级 | B24: 支出 | C24: B01.05.03.04 | D24: IT日常 | K24: 是 | M24: 05.03.04 | P24: SUM
A25: 二级 | B25: 支出 | C25: B01.05.04 | D25: 职场费用 | K25: 是 | M25: 05.04 | P25: SUM
A26: 二级 | B26: 支出 | C26: B01.05.05 | D26: 日常费用 | K26: 是 | M26: 05.05 | P26: SUM
A27: 一级 | B27: 收入 | C27: B01.06 | D27: 加：营业外净收入 | M27: 06 | P27: SUM
A28: 一级 | B28: 利润 | C28: B01.07 | D28: 分摊前利润 | F28: B01.03-B01.04-B01.90+B01.06 | H28: =H9-H10-H11+H27 | I28: =I9-I10-I11+I27 | M28: 07
A29: 一级 | B29: 支出 | C29: B01.08 | D29: 减：固定管理费 | M29: 08 | P29: SUM
A30: 一级 | B30: 利润 | C30: B01.09 | D30: 税前利润 | F30: B01.07-B01.08 | H30: =H28-H29 | I30: =I28-I29 | M30: 09
A32: 一级 | B32: 资产余额 | C32: B01.10 | D32: 管理贷款余额 | F32: B01.10.01+B01.10.02+B01.10.03+B01.10.04 | H32: =H33+H40+H41+H45 | I32: =I33+I40+I41+I45 | M32: 10
A33: 二级 | B33: 资产余额 | C33: B01.10.01 | D33: 自持余额 | F33: B01.10.01.01+B01.10.01.02 | H33: =H34+H37 | I33: =I34+I37 | M33: 10.01
A34: 三级 | B34: 资产余额 | C34: B01.10.01.01 | D34: 一般贷款 | F34: B01.10.01.01.01+B01.10.01.01.02 | H34: =H35+H36 | I34: =I35+I36 | M34: 10.01.01
A35: 四级 | B35: 资产余额 | C35: B01.10.01.01.01 | D35: 常规部分 | M35: 10.01.01.01 | P35: LAST
A36: 四级 | B36: 资产余额 | C36: B01.10.01.01.02 | D36: 战略部分 | M36: 10.01.01.02 | P36: LAST
A37: 三级 | B37: 资产余额 | C37: B01.10.01.02 | D37: 票据融资 | F37: B01.10.01.02.01+B01.10.01.02.02 | H37: =H38+H39 | I37: =I38+I39 | M37: 10.01.02
A38: 四级 | B38: 资产余额 | C38: B01.10.01.02.01 | D38: 票据贴现 | M38: 10.01.02.01 | P38: LAST
A39: 四级 | B39: 资产余额 | C39: B01.10.01.02.02 | D39: 贸易融资 | M39: 10.01.02.02 | P39: LAST
A40: 二级 | B40: 资产余额 | C40: B01.10.02 | D40: 联贷 | M40: 10.02 | P40: LAST
A41: 二级 | B41: 资产余额 | C41: B01.10.03 | D41: 流转 | F41: B01.10.03.01+B01.10.03.02+B01.10.03.03 | H41: =H42+H43+H44 | I41: =I42+I43+I44 | M41: 10.03
...

Sheet B02金融市场
A1: 科目层级 | B1: 科目性质 | C1: 科目代码 | D1: 科目名称 | E1: 录入粒度 | F1: 年预算公式 | G1: 年预测公式 | H1: 实际月公式 | I1: 预测月公式 | J1: 公式说明 | K1: 横向汇总 | L1: 纵向汇总 | M1: 逻辑码 | R1: 规则
A2: 一级 | B2: 收入 | C2: B02.01 | D2: 营业收入 | F2: B02.01.01+B02.01.02+B02.01.03 | H2: =H3+H6+H7 | I2: =I3+I6+I7 | M2: 01
A3: 二级 | B3: 收入 | C3: B02.01.01 | D3: 利息净收入 | F3: B02.01.01.01+B02.01.01.02 | H3: =H4+H5 | I3: =I4+I5 | M3: 01.01
A4: 三级 | B4: 收入 | C4: B02.01.01.01 | D4: 资产业务 | H4: =H112-H150 | I4: =I112-I150 | M4: 01.01.01 | R4: SUM
A5: 三级 | B5: 收入 | C5: B02.01.01.02 | D5: 负债业务 | H5: =H205-H192 | I5: =I205-I192 | M5: 01.01.02 | R5: SUM
A6: 二级 | B6: 收入 | C6: B02.01.02 | D6: 手续费净收入 | H6: =H220-H223 | I6: =I220-I223 | M6: 01.02 | R6: SUM
A7: 二级 | B7: 收入 | C7: B02.01.03 | D7: 其他营收 | H7: =H226+H257 | I7: =I226+I257 | M7: 01.03 | R7: SUM
A8: 一级 | B8: 支出 | C8: B02.02 | D8: 减：风险成本 | M8: 02 | R8: SUM
A9: 一级 | B9: 收入 | C9: B02.03 | D9: 净收入 | F9: B02.01-B02.02 | H9: =H2-H8 | I9: =I2-I8 | M9: 03
A10: 一级 | B10: 支出 | C10: B02.04 | D10: 减：税金及附加 | M10: 04 | R10: SUM
A11: 一级 | B11: 支出 | C11: B02.05 | D11: 减：直接费用 | F11: B02.90.01+B02.90.02+B02.90.03+B02.90.04+B02.90.05 | H11: =H12+H15+H18+H25+H26 | I11: =I12+I15+I18+I25+I26 | K11: 是 | M11: 05
A12: 二级 | B12: 支出 | C12: B02.05.01 | D12: 人力费用（不含IT） | F12: B02.90.01.01+B02.90.01.02 | H12: =H13+H14 | I12: =I13+I14 | K12: 是 | M12: 05.01
A13: 三级 | B13: 支出 | C13: B02.05.01.01 | D13: 常规人力 | F13: B02.90.01.01.01+B02.90.01.01.02+B02.90.01.01.03+B02.90.01.01.04.001+B02.90.01.01.05.001 | K13: 是 | M13: 05.01.01
A14: 三级 | B14: 支出 | C14: B02.05.01.02 | D14: 特别人力 | F14: B02.90.01.02.01+B02.90.01.02.02+B02.90.01.02.03+B02.90.01.02.04.001+B02.90.01.02.05.001 | K14: 是 | M14: 05.01.02
A15: 二级 | B15: 支出 | C15: B02.05.02 | D15: 业务费用 | F15: B02.90.02.01+B02.90.02.02+B02.90.02.09 | H15: =H16+H17 | I15: =I16+I17 | K15: 是 | M15: 05.02
A16: 三级 | B16: 支出 | C16: B02.05.02.01 | D16: 营销费用 | K16: 是 | M16: 05.02.01 | R16: SUM
A17: 三级 | B17: 支出 | C17: B02.05.02.02 | D17: 运营费用 | K17: 是 | M17: 05.02.02 | R17: SUM
A18: 二级 | B18: 支出 | C18: B02.05.03 | D18: IT费用 | F18: B02.90.03.01+B02.90.03.02+B02.90.03.03+B02.90.03.04 | H18: =H19+H22+H23+H24 | I18: =I19+I22+I23+I24 | K18: 是 | M18: 05.03
A19: 三级 | B19: 支出 | C19: B02.05.03.01 | D19: IT人力 | F19: B02.90.03.01.01+B02.90.03.01.02 | H19: =H20+H21 | I19: =I20+I21 | K19: 是 | M19: 05.03.01
A20: 四级 | B20: 支出 | C20: B02.05.03.01.01 | D20: IT常规人力 | K20: 是 | M20: 05.03.01.01 | R20: SUM
A21: 四级 | B21: 支出 | C21: B02.05.03.01.02 | D21: IT特别人力 | K21: 是 | M21: 05.03.01.02 | R21: SUM
A22: 三级 | B22: 支出 | C22: B02.05.03.02 | D22: 科技费用 | K22: 是 | M22: 05.03.02 | R22: SUM
A23: 三级 | B23: 支出 | C23: B02.05.03.03 | D23: IT职场 | K23: 是 | M23: 05.03.03 | R23: SUM
A24: 三级 | B24: 支出 | C24: B02.05.03.04 | D24: IT日常 | K24: 是 | M24: 05.03.04 | R24: SUM
A25: 二级 | B25: 支出 | C25: B02.05.04 | D25: 职场费用 | K25: 是 | M25: 05.04 | R25: SUM
A26: 二级 | B26: 支出 | C26: B02.05.05 | D26: 日常费用 | K26: 是 | M26: 05.05 | R26: SUM
A27: 一级 | B27: 收入 | C27: B02.06 | D27: 加：营业外净收入 | M27: 06 | R27: SUM
A28: 一级 | B28: 利润 | C28: B02.07 | D28: 分摊前利润 | F28: B02.03-B02.04-B02.90+B02.06 | H28: =H9-H10-H11+H27 | I28: =I9-I10-I11+I27 | M28: 07
A29: 一级 | B29: 支出 | C29: B02.08 | D29: 减：固定管理费 | M29: 08 | R29: SUM
A30: 一级 | B30: 利润 | C30: B02.09 | D30: 税前利润 | F30: B02.07-B02.08 | H30: =H28-H29 | I30: =I28-I29 | M30: 09
A32: 一级 | B32: 资产余额 | C32: B02.10 | D32: 管理贷款 | F32: B02.10.01 | H32: =H33 | I32: =I33 | M32: 10
A33: 二级 | B33: 资产余额 | C33: B02.10.01 | D33: 自持 | F33: B02.10.01.02 | H33: =H34 | I33: =I34 | M33: 10.01
A34: 三级 | B34: 资产余额 | C34: B02.10.01.02 | D34: 票据融资 | M34: 10.01.02 | R34: LAST
A35: 一级 | B35: 资产日均 | C35: B02.11 | D35: 管理贷款日均 | F35: B02.11.01 | H35: =H36 | I35: =I36 | M35: 11
A36: 二级 | B36: 资产日均 | C36: B02.11.01 | D36: 自持 | F36: B02.11.01.02 | H36: =H37 | I36: =I37 | M36: 11.01
A37: 三级 | B37: 资产日均 | C37: B02.11.01.02 | D37: 票据融资 | M37: 11.01.02 | R37: AVG
A39: 一级 | B39: 资产余额 | C39: B02.22 | D39: 存放央行余额 | F39: B02.22.01+B02.22.02 | H39: =H40+H41 | I39: =I40+I41 | M39: 22
A40: 二级 | B40: 资产余额 | C40: B02.22.01 | D40: 法准 | M40: 22.01 | R40: LAST
A41: 二级 | B41: 资产余额 | C41: B02.22.02 | D41: 超备 | M41: 22.02 | R41: LAST
A42: 一级 | B42: 资产日均 | C42: B02.23 | D42: 存放央行日均 | F42: B02.23.01+B02.23.02 | H42: =H43+H44 | I42: =I43+I44 | M42: 23
...

Sheet C数字金融
A1: 科目层级 | B1: 科目性质 | C1: 科目代码 | D1: 科目名称 | E1: 录入粒度 | F1: 年预算公式 | G1: 年预测公式 | H1: 实际月公式 | I1: 预测月公式 | J1: 公式说明 | K1: 横向汇总 | L1: 纵向汇总 | M1: 逻辑码 | N1: 规则
A2: 一级 | B2: 收入 | C2: C.01 | D2: 营业收入 | F2: C.01.01+C.01.02+C.01.03 | K2: 是 | M2: 01
A3: 二级 | B3: 收入 | C3: C.01.01 | D3: 利息净收入 | F3: C.01.01.01+C.01.01.02 | K3: 是 | M3: 01.01
A4: 三级 | B4: 收入 | C4: C.01.01.01 | D4: 资产业务 | M4: 01.01.01 | N4: SUM
A5: 一级 | B5: 收入 | C5: C.14 | D5: 利息收入 | K5: 是 | M5: 14 | N5: SUM
A6: 一级 | B6: 支出 | C6: C.15 | D6: FTP成本 | M6: 15 | N6: SUM
A7: 三级 | B7: 收入 | C7: C.01.01.02 | D7: 负债业务 | M7: 01.01.02 | N7: SUM
A8: 一级 | B8: 支出 | C8: C.16 | D8: 利息支出 | K8: 是 | M8: 16 | N8: SUM
A9: 一级 | B9: 支出 | C9: C.17 | D9: FTP收入 | M9: 17 | N9: SUM
A10: 二级 | B10: 收入 | C10: C.01.02 | D10: 净手续费收入 | K10: 是 | M10: 01.02 | N10: SUM
A11: 一级 | B11: 收入 | C11: C.18 | D11: 手续费收入 | K11: 是 | M11: 18 | N11: SUM
A12: 一级 | B12: 支出 | C12: C.19 | D12: 手续费支出 | K12: 是 | M12: 19 | N12: SUM
A13: 二级 | B13: 收入 | C13: C.01.03 | D13: 其他营收 | K13: 是 | M13: 01.03 | N13: SUM
A14: 一级 | B14: 支出 | C14: C.02 | D14: 减：风险成本 | K14: 是 | M14: 02 | N14: SUM
A15: 一级 | B15: 收入 | C15: C.03 | D15: 净收入 | K15: 是 | M15: 03 | N15: SUM
A16: 一级 | B16: 支出 | C16: C.04 | D16: 减：税金及附加 | K16: 是 | M16: 04 | N16: SUM
A17: 一级 | B17: 支出 | C17: C.05 | D17: 减：直接费用 | F17: C.90.01+C.90.09+C.90.03+C.90.04+C.90.05 | K17: 是 | M17: 05
A18: 二级 | B18: 支出 | C18: C.05.01 | D18: 人力费用（不含IT） | F18: C.90.01.01+C.90.01.02 | K18: 是 | M18: 05.01
A19: 三级 | B19: 支出 | C19: C.05.01.01 | D19: 常规人力 | F19: C.90.01.01.01+C.90.01.01.02+C.90.01.01.03+C.90.01.01.04.001+C.90.01.01.05.001 | K19: 是 | M19: 05.01.01
A20: 三级 | B20: 支出 | C20: C.05.01.02 | D20: 特别人力 | F20: C.90.01.02.01+C.90.01.02.02+C.90.01.02.03+C.90.01.02.04.001+C.90.01.02.05.001 | K20: 是 | M20: 05.01.02
A21: 二级 | B21: 支出 | C21: C.05.02 | D21: 业务费用 | K21: 是 | N21: SUM
A22: 三级 | B22: 支出 | C22: C.05.02.01 | D22: 营销费用 | K22: 是 | N22: SUM
A23: 三级 | B23: 支出 | C23: C.05.02.02 | D23: 运营费用 | K23: 是 | N23: SUM
A24: 二级 | B24: 支出 | C24: C.05.03 | D24: IT费用 | F24: C.90.03.01+C.90.03.02+C.90.03.03+C.90.03.04 | K24: 是 | M24: 05.03
A25: 三级 | B25: 支出 | C25: C.05.03.01 | D25: IT人力 | F25: C.90.03.01.01+C.90.03.01.02 | K25: 是 | M25: 05.03.01
A26: 四级 | B26: 支出 | C26: C.05.03.01.01 | D26: IT常规人力 | K26: 是 | M26: 05.03.01.01 | N26: SUM
A27: 四级 | B27: 支出 | C27: C.05.03.01.02 | D27: IT特别人力 | K27: 是 | M27: 05.03.01.02 | N27: SUM
A28: 三级 | B28: 支出 | C28: C.05.03.02 | D28: 科技费用 | K28: 是 | M28: 05.03.02 | N28: SUM
A29: 三级 | B29: 支出 | C29: C.05.03.03 | D29: IT职场 | K29: 是 | M29: 05.03.03 | N29: SUM
A30: 三级 | B30: 支出 | C30: C.05.03.04 | D30: IT日常 | K30: 是 | M30: 05.03.04 | N30: SUM
A31: 二级 | B31: 支出 | C31: C.05.04 | D31: 职场费用 | K31: 是 | M31: 05.04 | N31: SUM
A32: 二级 | B32: 支出 | C32: C.05.05 | D32: 日常费用 | K32: 是 | M32: 05.05 | N32: SUM
A33: 一级 | B33: 收入 | C33: C.06 | D33: 加：营业外净收入 | K33: 是 | M33: 06 | N33: SUM
A34: 一级 | B34: 利润 | C34: C.07 | D34: 分摊前利润 | M34: 07 | N34: SUM
A35: 一级 | B35: 支出 | C35: C.08 | D35: 减：固定管理费 | M35: 08 | N35: SUM
A36: 一级 | B36: 利润 | C36: C.09 | D36: 税前利润 | K36: 是 | M36: 09 | N36: SUM
A38: 一级 | B38: 负债余额 | C38: C.12 | D38: 管理资产余额 | F38: C.12.01 | M38: 12
A39: 二级 | B39: 负债余额 | C39: C.12.01 | D39: 存款余额 | M39: 12.01 | N39: LAST
A40: 一级 | B40: 负债日均 | C40: C.13 | D40: 管理资产日均 | F40: C.13.01 | M40: 13
A41: 二级 | B41: 负债日均 | C41: C.13.01 | D41: 存款日均 | M41: 13.01 | N41: AVG
...

Sheet C01国内业务
A1: 科目层级 | B1: 科目性质 | C1: 科目代码 | D1: 科目名称 | E1: 录入粒度 | F1: 年预算公式 | G1: 年预测公式 | H1: 实际月公式 | I1: 预测月公式 | J1: 公式说明 | K1: 横向汇总 | L1: 纵向汇总 | M1: 逻辑码 | P1: 规则
A2: 一级 | B2: 收入 | C2: C01.01 | D2: 营业收入 | F2: C01.01.01+C01.01.02+C01.01.03 | H2: =H3+H6+H7 | I2: =I3+I6+I7 | M2: 01
A3: 二级 | B3: 收入 | C3: C01.01.01 | D3: 利息净收入 | F3: C01.01.01.01+C01.01.01.02 | H3: =H4+H5 | I3: =I4+I5 | M3: 01.01
A4: 三级 | B4: 收入 | C4: C01.01.01.01 | D4: 资产业务 | M4: 01.01.01 | P4: SUM
A5: 三级 | B5: 收入 | C5: C01.01.01.02 | D5: 负债业务 | H5: =H41-H37 | I5: =I41-I37 | M5: 01.01.02 | P5: SUM
A6: 二级 | B6: 收入 | C6: C01.01.02 | D6: 净手续费收入 | H6: =H45-H48 | I6: =I45-I48 | M6: 01.02 | P6: SUM
A7: 二级 | B7: 收入 | C7: C01.01.03 | D7: 其他营收 | H7: =H51+H53 | I7: =I51+I53 | M7: 01.03 | P7: SUM
A8: 一级 | B8: 支出 | C8: C01.02 | D8: 减：风险成本 | M8: 02 | P8: SUM
A9: 一级 | B9: 收入 | C9: C01.03 | D9: 净收入 | F9: C01.01-C01.02 | H9: =H2-H8 | I9: =I2-I8 | M9: 03
A10: 一级 | B10: 支出 | C10: C01.04 | D10: 减：税金及附加 | M10: 04 | P10: SUM
A11: 一级 | B11: 支出 | C11: C01.05 | D11: 减：直接费用 | F11: C01.90.01+C01.90.02+C01.90.03+C01.90.04+C01.90.05 | H11: =H12+H15+H18+H25+H26 | I11: =I12+I15+I18+I25+I26 | K11: 是 | M11: 05
A12: 二级 | B12: 支出 | C12: C01.05.01 | D12: 人力费用（不含IT） | F12: C01.90.01.01+C01.90.01.02 | H12: =H13+H14 | I12: =I13+I14 | K12: 是 | M12: 05.01
A13: 三级 | B13: 支出 | C13: C01.05.01.01 | D13: 常规人力 | F13: C01.90.01.01.01+C01.90.01.01.02+C01.90.01.01.03+C01.90.01.01.04.001+C01.90.01.01.05.001 | K13: 是 | M13: 05.01.01
A14: 三级 | B14: 支出 | C14: C01.05.01.02 | D14: 特别人力 | F14: C01.90.01.02.01+C01.90.01.02.02+C01.90.01.02.03+C01.90.01.02.04.001+C01.90.01.02.05.001 | K14: 是 | M14: 05.01.02
A15: 二级 | B15: 支出 | C15: C01.05.02 | D15: 业务费用 | F15: C01.90.02.01+C01.90.02.02+C01.90.02.09 | H15: =H16+H17 | I15: =I16+I17 | K15: 是 | M15: 05.02
A16: 三级 | B16: 支出 | C16: C01.05.02.01 | D16: 营销费用 | K16: 是 | M16: 05.02.01 | P16: SUM
A17: 三级 | B17: 支出 | C17: C01.05.02.02 | D17: 运营费用 | K17: 是 | M17: 05.02.02 | P17: SUM
A18: 二级 | B18: 支出 | C18: C01.05.03 | D18: IT费用 | F18: C01.90.03.01+C01.90.03.02+C01.90.03.03+C01.90.03.04 | H18: =H19+H22+H23+H24 | I18: =I19+I22+I23+I24 | K18: 是 | M18: 05.03
A19: 三级 | B19: 支出 | C19: C01.05.03.01 | D19: IT人力 | F19: C01.90.03.01.01+C01.90.03.01.02 | H19: =H20+H21 | I19: =I20+I21 | K19: 是 | M19: 05.03.01
A20: 四级 | B20: 支出 | C20: C01.05.03.01.01 | D20: IT常规人力 | K20: 是 | M20: 05.03.01.01 | P20: SUM
A21: 四级 | B21: 支出 | C21: C01.05.03.01.02 | D21: IT特别人力 | K21: 是 | M21: 05.03.01.02 | P21: SUM
A22: 三级 | B22: 支出 | C22: C01.05.03.02 | D22: 科技费用 | K22: 是 | M22: 05.03.02 | P22: SUM
A23: 三级 | B23: 支出 | C23: C01.05.03.03 | D23: IT职场 | K23: 是 | M23: 05.03.03 | P23: SUM
A24: 三级 | B24: 支出 | C24: C01.05.03.04 | D24: IT日常 | K24: 是 | M24: 05.03.04 | P24: SUM
A25: 二级 | B25: 支出 | C25: C01.05.04 | D25: 职场费用 | K25: 是 | M25: 05.04 | P25: SUM
A26: 二级 | B26: 支出 | C26: C01.05.05 | D26: 日常费用 | K26: 是 | M26: 05.05 | P26: SUM
A27: 一级 | B27: 收入 | C27: C01.06 | D27: 加：营业外净收入 | M27: 06 | P27: SUM
A28: 一级 | B28: 利润 | C28: C01.07 | D28: 分摊前利润 | F28: C01.03-C01.04-C01.90+C01.06 | H28: =H9-H10-H11+H27 | I28: =I9-I10-I11+I27 | M28: 07
A29: 一级 | B29: 支出 | C29: C01.08 | D29: 减：固定管理费 | M29: 08 | P29: SUM
A30: 一级 | B30: 利润 | C30: C01.09 | D30: 税前利润 | F30: C01.07-C01.08 | H30: =H28-H29 | I30: =I28-I29 | M30: 09
A32: 一级 | B32: 负债余额 | C32: C01.12 | D32: 管理资产余额 | F32: C01.12.01 | H32: =H33 | I32: =I33 | M32: 12
A33: 二级 | B33: 负债余额 | C33: C01.12.01 | D33: 存款余额 | M33: 12.01 | P33: LAST
A34: 一级 | B34: 负债日均 | C34: C01.13 | D34: 管理资产日均 | F34: C01.13.01 | H34: =H35 | I34: =I35 | M34: 13
A35: 二级 | B35: 负债日均 | C35: C01.13.01 | D35: 存款日均 | M35: 13.01 | P35: AVG
A37: 一级 | B37: 支出 | C37: C01.16 | D37: 利息支出 | F37: C01.16.01 | H37: =H38 | I37: =I38 | M37: 16
A38: 二级 | B38: 支出 | C38: C01.16.01 | D38: 存款利息支出 | F38: C01.16.01.01 | I38: =I35*I39 | J38: 收支月化指标 | M38: 16.01
A39: 三级 | B39: 其他 | C39: C01.16.01.01 | D39: 存款付息率 | H39: =H38/H35 | J39: 率年化指标 | M39: 16.01.01 | P39: WGT
A41: 一级 | B41: 收入 | C41: C01.17 | D41: FTP收入 | F41: C01.17.01 | H41: =H42 | I41: =I42 | M41: 17
A42: 二级 | B42: 收入 | C42: C01.17.01 | D42: 存款FTP收入 | F42: C01.17.01.01 | I42: =I35*I43 | J42: 收支月化指标 | M42: 17.01
A43: 三级 | B43: 其他 | C43: C01.17.01.01 | D43: 存款FTP | H43: =H42/H35 | J43: 率年化指标 | M43: 17.01.01 | P43: WGT
...

