Workbook
Name \A: #REF!
Name \B: #REF!
Name _1._总资产: #REF!
Name aa: #REF!
Name ada: #REF!
Name adi: #REF!
Name AI项目组IT: #REF!
Name AI项目组人力: #REF!
Name AI项目组日常: #REF!
Name AI项目组营销: #REF!
Name AI项目组运营: #REF!
Name AI项目组征信: #REF!
Name AI项目组职场: #REF!
Name Basel: #REF!
Name bb: #REF!
Name bpr: #REF!
Name Br: #REF!
Name Branch: #REF!
Name BS_ARRAY: #REF!
Name CC: #REF!
Name COST_ARRAY: #REF!
Name COST_M_ARRAY: #REF!
Name D01_2: #REF!
Name D02_1: #REF!
Name d02_1_4: #REF!
Name D02_1_5: #REF!
Name D02_25_50: #REF!
Name D02_5_25: #REF!
Name D02_50: #REF!
Name D12_1: #REF!
Name D12_1_5: #REF!
Name D12_25_50: #REF!
Name D12_5_25: #REF!
Name D12_50: #REF!
Name data: #REF!
Name days_m: #REF!
Name days_r: #REF!
Name days_y: #REF!
Name days_year: #REF!
Name dd: #REF!
Name Dept: #REF!
Name DL_ARRAY: #REF!
Name do1_1: #REF!
Name Education: #REF!
Name employment: #REF!
Name FEE_ARRAY: #REF!
Name FEE_M_ARRAY: #REF!
Name Function: OFFSET(#REF!,1,MATCH(#REF!,#REF!,0)-1,COUNTA(OFFSET(#REF!,0,MATCH(#REF!,#REF!,0)-1,100,1))-1,1)
Name Grade: #REF!
Name IQ_CH: 110000
Name IQ_CQ: 5000
Name IQ_CY: 10000
Name IQ_DAILY: 500000
Name IQ_FH: 100000
Name IQ_FQ: 500
Name IQ_FY: 1000
Name IQ_LTM: 2000
Name IQ_MONTH: 15000
Name IQ_NTM: 6000
Name IQ_WEEK: 50000

Sheet 26年2月（全行）
I1: 直接费用 | J1: 直接费用 | K1: 直接费用 | L1: 直接费用 | M1: 直接费用 | N1: 直接费用 | O1: 直接费用 | P1: 直接费用 | Q1: 直接费用 | R1: 直接费用 | S1: 直接费用 | T1: 间接费用 | U1: 间接费用 | V1: 间接费用 | W1: 间接费用 | X1: 间接费用 | Y1: 间接费用 | Z1: 间接费用 | AA1: 间接费用 | AB1: 间接费用 | AC1: 间接费用 | AD1: 间接费用 | AE1: 间接费用
A2: 开始日期：2025-05-31 结束日期：2025-05-31 | I2: 微粒贷 | J2: 微账户 | K2: 汽车金融 | L2: 企业金融 | M2: 财富业务 | N2: 数字金融 | O2: 金融市场 | P2: 小鹅花钱 | Q2: 国际业务 | R2: 流量经营项目 | S2: 其他 | T2: 间接费用 | U2: 间接费用 | V2: 间接费用 | W2: 间接费用 | X2: 间接费用 | Y2: 间接费用 | Z2: 间接费用 | AA2: 间接费用 | AB2: 间接费用 | AC2: 间接费用 | AD2: 间接费用 | AE2: 间接费用
A3: 一级机构 | C3: 费用大类 | E3: 业务分类 | G3: 金额 | I3: 直接费用 | T3: 间接费用 | V3: 间接费用 | BD3: =SUM(BC:BC) -> 0
E4: 科目名称 | G4: 自身费用 | H4: 摊出费用 | I4: 消费金融 | J4: 微账户 | K4: 汽车金融 | L4: 企业金融 | M4: 财富业务 | N4: 数字金融 | O4: 金融市场及同业 | P4: 生活金融 | Q4: 国际业务 | R4: 创新孵化项目 | S4: 其他 | T4: 消费金融 | U4: 微账户 | V4: 汽车金融 | W4: 企业金融 | X4: 财富业务 | Y4: 数字金融 | Z4: 金融市场及同业 | AA4: 生活金融 | AB4: 司库 | AC4: 国际业务 | AD4: 创新孵化项目 | AE4: 其他 | AU4: 部门 | AV4: 管会口径 | AW4: 预算口径 | AX4: 预算口径（人力拆分） | AY4: 预算口径（拆分） | AZ4: 直接费用 | BA4: 间接费用 | BB4: 合计 | BC4: 合计 | BF4: CHECK
B5: 风险及运营管理部 | AT5: =AX5&F5 | AU5: =IF(B5="",AU4,B5) -> 风险及运营管理部 | AV5: =IF(B5<>"","",IF(D5="",AV4,D5)) | AW5: =IFERROR(VLOOKUP(AV5,[1]字段!A:B,2,0),"") | AX5: =IF(AW5="人力费用",IF(E5="","",VLOOKUP(E5,[1]字段!D:E,2,0)),AW5) | AY5: =IF(AT5="","",VLOOKUP(AT5,[1]字段!H:I,2,0)) | AZ5: =IF($E5="",0,SUMIF($G$1:$AB$1,AZ$4,$G5:$AB5)) -> 0 | BA5: =IF($E5="",0,SUMIF($G$1:$AE$1,BA$4,$G5:$AE5)) -> 0 | BB5: =AZ5+BA5 -> 0 | BC5: =IF(E5="",0,SUM(G5:AE5)-AZ5-BA5) -> 0
C6: 01 | D6: 人力费用 | AT6: =AX6&F6 | AU6: =IF(B6="",AU5,B6) -> 风险及运营管理部 | AV6: =IF(B6<>"","",IF(D6="",AV5,D6)) -> 人力费用 | AW6: =IFERROR(VLOOKUP(AV6,[1]字段!A:B,2,0),"") -> 人力费用 | AX6: =IF(AW6="人力费用",IF(E6="","",VLOOKUP(E6,[1]字段!D:E,2,0)),AW6) | AY6: =IF(AT6="","",VLOOKUP(AT6,[1]字段!H:I,2,0)) | AZ6: =IF($E6="",0,SUMIF($G$1:$AB$1,AZ$4,$G6:$AB6)) -> 0 | BA6: =IF($E6="",0,SUMIF($G$1:$AE$1,BA$4,$G6:$AE6)) -> 0 | BB6: =AZ6+BA6 -> 0 | BC6: =IF(E6="",0,SUM(G6:AE6)-AZ6-BA6) -> 0 | BF6: =ISBLANK(AY6) -> FALSE
E7: 55010101 | F7: 基础工资 | AT7: =AX7&F7 -> 1.0倍人力基础工资 | AU7: =IF(B7="",AU6,B7) -> 风险及运营管理部 | AV7: =IF(B7<>"","",IF(D7="",AV6,D7)) -> 人力费用 | AW7: =IFERROR(VLOOKUP(AV7,[1]字段!A:B,2,0),"") -> 人力费用 | AX7: =IF(AW7="人力费用",IF(E7="","",VLOOKUP(E7,[1]字段!D:E,2,0)),AW7) -> 1.0倍人力 | AY7: =IF(AT7="","",VLOOKUP(AT7,[1]字段!H:I,2,0)) -> 1.0倍人力 | AZ7: =IF($E7="",0,SUMIF($G$1:$AB$1,AZ$4,$G7:$AB7)) -> 0 | BA7: =IF($E7="",0,SUMIF($G$1:$AE$1,BA$4,$G7:$AE7)) -> 0 | BB7: =AZ7+BA7 -> 0 | BC7: =IF(E7="",0,SUM(G7:AE7)-AZ7-BA7) -> 0
E8: 5501010602 | AT8: =AX8&F8 -> 利润分享 | AU8: =IF(B8="",AU7,B8) -> 风险及运营管理部 | AV8: =IF(B8<>"","",IF(D8="",AV7,D8)) -> 人力费用 | AW8: =IFERROR(VLOOKUP(AV8,[1]字段!A:B,2,0),"") -> 人力费用 | AX8: =IF(AW8="人力费用",IF(E8="","",VLOOKUP(E8,[1]字段!D:E,2,0)),AW8) -> 利润分享 | AY8: =IF(AT8="","",VLOOKUP(AT8,[1]字段!H:I,2,0)) -> 利润分享 | AZ8: =IF($E8="",0,SUMIF($G$1:$AB$1,AZ$4,$G8:$AB8)) -> 0 | BA8: =IF($E8="",0,SUMIF($G$1:$AE$1,BA$4,$G8:$AE8)) -> 0 | BB8: =AZ8+BA8 -> 0 | BC8: =IF(E8="",0,SUM(G8:AE8)-AZ8-BA8) -> 0
E9: 5501010603 | AT9: =AX9&F9 -> 留任奖励 | AU9: =IF(B9="",AU8,B9) -> 风险及运营管理部 | AV9: =IF(B9<>"","",IF(D9="",AV8,D9)) -> 人力费用 | AW9: =IFERROR(VLOOKUP(AV9,[1]字段!A:B,2,0),"") -> 人力费用 | AX9: =IF(AW9="人力费用",IF(E9="","",VLOOKUP(E9,[1]字段!D:E,2,0)),AW9) -> 留任奖励 | AY9: =IF(AT9="","",VLOOKUP(AT9,[1]字段!H:I,2,0)) -> 留任奖励 | AZ9: =IF($E9="",0,SUMIF($G$1:$AB$1,AZ$4,$G9:$AB9)) -> 0 | BA9: =IF($E9="",0,SUMIF($G$1:$AE$1,BA$4,$G9:$AE9)) -> 0 | BB9: =AZ9+BA9 -> 0 | BC9: =IF(E9="",0,SUM(G9:AE9)-AZ9-BA9) -> 0
E10: 5501010604 | AT10: =AX10&F10 -> 1.0倍人力 | AU10: =IF(B10="",AU9,B10) -> 风险及运营管理部 | AV10: =IF(B10<>"","",IF(D10="",AV9,D10)) -> 人力费用 | AW10: =IFERROR(VLOOKUP(AV10,[1]字段!A:B,2,0),"") -> 人力费用 | AX10: =IF(AW10="人力费用",IF(E10="","",VLOOKUP(E10,[1]字段!D:E,2,0)),AW10) -> 1.0倍人力 | AY10: =IF(AT10="","",VLOOKUP(AT10,[1]字段!H:I,2,0)) -> 1.0倍人力 | AZ10: =IF($E10="",0,SUMIF($G$1:$AB$1,AZ$4,$G10:$AB10)) -> 0 | BA10: =IF($E10="",0,SUMIF($G$1:$AE$1,BA$4,$G10:$AE10)) -> 0 | BB10: =AZ10+BA10 -> 0 | BC10: =IF(E10="",0,SUM(G10:AE10)-AZ10-BA10) -> 0
E11: 55010201 | F11: 团队建设费 | AT11: =AX11&F11 -> 1.0倍人力团队建设费 | AU11: =IF(B11="",AU10,B11) -> 风险及运营管理部 | AV11: =IF(B11<>"","",IF(D11="",AV10,D11)) -> 人力费用 | AW11: =IFERROR(VLOOKUP(AV11,[1]字段!A:B,2,0),"") -> 人力费用 | AX11: =IF(AW11="人力费用",IF(E11="","",VLOOKUP(E11,[1]字段!D:E,2,0)),AW11) -> 1.0倍人力 | AY11: =IF(AT11="","",VLOOKUP(AT11,[1]字段!H:I,2,0)) -> 1.0倍人力 | AZ11: =IF($E11="",0,SUMIF($G$1:$AB$1,AZ$4,$G11:$AB11)) -> 0 | BA11: =IF($E11="",0,SUMIF($G$1:$AE$1,BA$4,$G11:$AE11)) -> 0 | BB11: =AZ11+BA11 -> 0 | BC11: =IF(E11="",0,SUM(G11:AE11)-AZ11-BA11) -> 0
E12: 55010299 | F12: 其他职工福利费 | AT12: =AX12&F12 -> 1.0倍人力其他职工福利费 | AU12: =IF(B12="",AU11,B12) -> 风险及运营管理部 | AV12: =IF(B12<>"","",IF(D12="",AV11,D12)) -> 人力费用 | AW12: =IFERROR(VLOOKUP(AV12,[1]字段!A:B,2,0),"") -> 人力费用 | AX12: =IF(AW12="人力费用",IF(E12="","",VLOOKUP(E12,[1]字段!D:E,2,0)),AW12) -> 1.0倍人力 | AY12: =IF(AT12="","",VLOOKUP(AT12,[1]字段!H:I,2,0)) -> 1.0倍人力 | AZ12: =IF($E12="",0,SUMIF($G$1:$AB$1,AZ$4,$G12:$AB12)) -> 0 | BA12: =IF($E12="",0,SUMIF($G$1:$AE$1,BA$4,$G12:$AE12)) -> 0 | BB12: =AZ12+BA12 -> 0 | BC12: =IF(E12="",0,SUM(G12:AE12)-AZ12-BA12) -> 0
E13: 55010301 | F13: 工会经费 | AT13: =AX13&F13 -> 1.0倍人力工会经费 | AU13: =IF(B13="",AU12,B13) -> 风险及运营管理部 | AV13: =IF(B13<>"","",IF(D13="",AV12,D13)) -> 人力费用 | AW13: =IFERROR(VLOOKUP(AV13,[1]字段!A:B,2,0),"") -> 人力费用 | AX13: =IF(AW13="人力费用",IF(E13="","",VLOOKUP(E13,[1]字段!D:E,2,0)),AW13) -> 1.0倍人力 | AY13: =IF(AT13="","",VLOOKUP(AT13,[1]字段!H:I,2,0)) -> 1.0倍人力 | AZ13: =IF($E13="",0,SUMIF($G$1:$AB$1,AZ$4,$G13:$AB13)) -> 0 | BA13: =IF($E13="",0,SUMIF($G$1:$AE$1,BA$4,$G13:$AE13)) -> 0 | BB13: =AZ13+BA13 -> 0 | BC13: =IF(E13="",0,SUM(G13:AE13)-AZ13-BA13) -> 0
E14: 55010501 | F14: 基本养老保险 | AT14: =AX14&F14 -> 1.0倍人力基本养老保险 | AU14: =IF(B14="",AU13,B14) -> 风险及运营管理部 | AV14: =IF(B14<>"","",IF(D14="",AV13,D14)) -> 人力费用 | AW14: =IFERROR(VLOOKUP(AV14,[1]字段!A:B,2,0),"") -> 人力费用 | AX14: =IF(AW14="人力费用",IF(E14="","",VLOOKUP(E14,[1]字段!D:E,2,0)),AW14) -> 1.0倍人力 | AY14: =IF(AT14="","",VLOOKUP(AT14,[1]字段!H:I,2,0)) -> 1.0倍人力 | AZ14: =IF($E14="",0,SUMIF($G$1:$AB$1,AZ$4,$G14:$AB14)) -> 0 | BA14: =IF($E14="",0,SUMIF($G$1:$AE$1,BA$4,$G14:$AE14)) -> 0 | BB14: =AZ14+BA14 -> 0 | BC14: =IF(E14="",0,SUM(G14:AE14)-AZ14-BA14) -> 0
E15: 55010601 | F15: 基本医疗保险 | AT15: =AX15&F15 -> 1.0倍人力基本医疗保险 | AU15: =IF(B15="",AU14,B15) -> 风险及运营管理部 | AV15: =IF(B15<>"","",IF(D15="",AV14,D15)) -> 人力费用 | AW15: =IFERROR(VLOOKUP(AV15,[1]字段!A:B,2,0),"") -> 人力费用 | AX15: =IF(AW15="人力费用",IF(E15="","",VLOOKUP(E15,[1]字段!D:E,2,0)),AW15) -> 1.0倍人力 | AY15: =IF(AT15="","",VLOOKUP(AT15,[1]字段!H:I,2,0)) -> 1.0倍人力 | AZ15: =IF($E15="",0,SUMIF($G$1:$AB$1,AZ$4,$G15:$AB15)) -> 0 | BA15: =IF($E15="",0,SUMIF($G$1:$AE$1,BA$4,$G15:$AE15)) -> 0 | BB15: =AZ15+BA15 -> 0 | BC15: =IF(E15="",0,SUM(G15:AE15)-AZ15-BA15) -> 0
E16: 55010801 | F16: 工伤保险 | AT16: =AX16&F16 -> 1.0倍人力工伤保险 | AU16: =IF(B16="",AU15,B16) -> 风险及运营管理部 | AV16: =IF(B16<>"","",IF(D16="",AV15,D16)) -> 人力费用 | AW16: =IFERROR(VLOOKUP(AV16,[1]字段!A:B,2,0),"") -> 人力费用 | AX16: =IF(AW16="人力费用",IF(E16="","",VLOOKUP(E16,[1]字段!D:E,2,0)),AW16) -> 1.0倍人力 | AY16: =IF(AT16="","",VLOOKUP(AT16,[1]字段!H:I,2,0)) -> 1.0倍人力 | AZ16: =IF($E16="",0,SUMIF($G$1:$AB$1,AZ$4,$G16:$AB16)) -> 0 | BA16: =IF($E16="",0,SUMIF($G$1:$AE$1,BA$4,$G16:$AE16)) -> 0 | BB16: =AZ16+BA16 -> 0 | BC16: =IF(E16="",0,SUM(G16:AE16)-AZ16-BA16) -> 0
E17: 55010901 | F17: 生育保险 | AT17: =AX17&F17 -> 1.0倍人力生育保险 | AU17: =IF(B17="",AU16,B17) -> 风险及运营管理部 | AV17: =IF(B17<>"","",IF(D17="",AV16,D17)) -> 人力费用 | AW17: =IFERROR(VLOOKUP(AV17,[1]字段!A:B,2,0),"") -> 人力费用 | AX17: =IF(AW17="人力费用",IF(E17="","",VLOOKUP(E17,[1]字段!D:E,2,0)),AW17) -> 1.0倍人力 | AY17: =IF(AT17="","",VLOOKUP(AT17,[1]字段!H:I,2,0)) -> 1.0倍人力 | AZ17: =IF($E17="",0,SUMIF($G$1:$AB$1,AZ$4,$G17:$AB17)) -> 0 | BA17: =IF($E17="",0,SUMIF($G$1:$AE$1,BA$4,$G17:$AE17)) -> 0 | BB17: =AZ17+BA17 -> 0 | BC17: =IF(E17="",0,SUM(G17:AE17)-AZ17-BA17) -> 0
E18: 55011001 | F18: 失业保险 | AT18: =AX18&F18 -> 1.0倍人力失业保险 | AU18: =IF(B18="",AU17,B18) -> 风险及运营管理部 | AV18: =IF(B18<>"","",IF(D18="",AV17,D18)) -> 人力费用 | AW18: =IFERROR(VLOOKUP(AV18,[1]字段!A:B,2,0),"") -> 人力费用 | AX18: =IF(AW18="人力费用",IF(E18="","",VLOOKUP(E18,[1]字段!D:E,2,0)),AW18) -> 1.0倍人力 | AY18: =IF(AT18="","",VLOOKUP(AT18,[1]字段!H:I,2,0)) -> 1.0倍人力 | AZ18: =IF($E18="",0,SUMIF($G$1:$AB$1,AZ$4,$G18:$AB18)) -> 0 | BA18: =IF($E18="",0,SUMIF($G$1:$AE$1,BA$4,$G18:$AE18)) -> 0 | BB18: =AZ18+BA18 -> 0 | BC18: =IF(E18="",0,SUM(G18:AE18)-AZ18-BA18) -> 0
E19: 55011101 | F19: 住房公积金 | AT19: =AX19&F19 -> 1.0倍人力住房公积金 | AU19: =IF(B19="",AU18,B19) -> 风险及运营管理部 | AV19: =IF(B19<>"","",IF(D19="",AV18,D19)) -> 人力费用 | AW19: =IFERROR(VLOOKUP(AV19,[1]字段!A:B,2,0),"") -> 人力费用 | AX19: =IF(AW19="人力费用",IF(E19="","",VLOOKUP(E19,[1]字段!D:E,2,0)),AW19) -> 1.0倍人力 | AY19: =IF(AT19="","",VLOOKUP(AT19,[1]字段!H:I,2,0)) -> 1.0倍人力 | AZ19: =IF($E19="",0,SUMIF($G$1:$AB$1,AZ$4,$G19:$AB19)) -> 0 | BA19: =IF($E19="",0,SUMIF($G$1:$AE$1,BA$4,$G19:$AE19)) -> 0 | BB19: =AZ19+BA19 -> 0 | BC19: =IF(E19="",0,SUM(G19:AE19)-AZ19-BA19) -> 0
C20: 0605 | D20: IT运营费用 | AT20: =AX20&F20 -> 运营费用 | AU20: =IF(B20="",AU19,B20) -> 风险及运营管理部 | AV20: =IF(B20<>"","",IF(D20="",AV19,D20)) -> IT运营费用 | AW20: =IFERROR(VLOOKUP(AV20,[1]字段!A:B,2,0),"") -> 运营费用 | AX20: =IF(AW20="人力费用",IF(E20="","",VLOOKUP(E20,[1]字段!D:E,2,0)),AW20) -> 运营费用 | AY20: =IF(AT20="","",VLOOKUP(AT20,[1]字段!H:I,2,0)) -> 0 | AZ20: =IF($E20="",0,SUMIF($G$1:$AB$1,AZ$4,$G20:$AB20)) -> 0 | BA20: =IF($E20="",0,SUMIF($G$1:$AE$1,BA$4,$G20:$AE20)) -> 0 | BB20: =AZ20+BA20 -> 0 | BC20: =IF(E20="",0,SUM(G20:AE20)-AZ20-BA20) -> 0
E21: 55015001 | F21: 信息资料费 | AT21: =AX21&F21 -> 运营费用信息资料费 | AU21: =IF(B21="",AU20,B21) -> 风险及运营管理部 | AV21: =IF(B21<>"","",IF(D21="",AV20,D21)) -> IT运营费用 | AW21: =IFERROR(VLOOKUP(AV21,[1]字段!A:B,2,0),"") -> 运营费用 | AX21: =IF(AW21="人力费用",IF(E21="","",VLOOKUP(E21,[1]字段!D:E,2,0)),AW21) -> 运营费用 | AY21: =IF(AT21="","",VLOOKUP(AT21,[1]字段!H:I,2,0)) -> 运营费用-运营其他 | AZ21: =IF($E21="",0,SUMIF($G$1:$AB$1,AZ$4,$G21:$AB21)) -> 0 | BA21: =IF($E21="",0,SUMIF($G$1:$AE$1,BA$4,$G21:$AE21)) -> 0 | BB21: =AZ21+BA21 -> 0 | BC21: =IF(E21="",0,SUM(G21:AE21)-AZ21-BA21) -> 0
C22: 0606 | D22: IT科技费用 | AT22: =AX22&F22 -> IT费用 | AU22: =IF(B22="",AU21,B22) -> 风险及运营管理部 | AV22: =IF(B22<>"","",IF(D22="",AV21,D22)) -> IT科技费用 | AW22: =IFERROR(VLOOKUP(AV22,[1]字段!A:B,2,0),"") -> IT费用 | AX22: =IF(AW22="人力费用",IF(E22="","",VLOOKUP(E22,[1]字段!D:E,2,0)),AW22) -> IT费用 | AY22: =IF(AT22="","",VLOOKUP(AT22,[1]字段!H:I,2,0)) -> 0 | AZ22: =IF($E22="",0,SUMIF($G$1:$AB$1,AZ$4,$G22:$AB22)) -> 0 | BA22: =IF($E22="",0,SUMIF($G$1:$AE$1,BA$4,$G22:$AE22)) -> 0 | BB22: =AZ22+BA22 -> 0 | BC22: =IF(E22="",0,SUM(G22:AE22)-AZ22-BA22) -> 0
E23: 55012104 | F23: 一般运营设备折旧费 | AT23: =AX23&F23 -> IT费用一般运营设备折旧费 | AU23: =IF(B23="",AU22,B23) -> 风险及运营管理部 | AV23: =IF(B23<>"","",IF(D23="",AV22,D23)) -> IT科技费用 | AW23: =IFERROR(VLOOKUP(AV23,[1]字段!A:B,2,0),"") -> IT费用 | AX23: =IF(AW23="人力费用",IF(E23="","",VLOOKUP(E23,[1]字段!D:E,2,0)),AW23) -> IT费用 | AY23: =IF(AT23="","",VLOOKUP(AT23,[1]字段!H:I,2,0)) -> IT费用 | AZ23: =IF($E23="",0,SUMIF($G$1:$AB$1,AZ$4,$G23:$AB23)) -> 0 | BA23: =IF($E23="",0,SUMIF($G$1:$AE$1,BA$4,$G23:$AE23)) -> 0 | BB23: =AZ23+BA23 -> 0 | BC23: =IF(E23="",0,SUM(G23:AE23)-AZ23-BA23) -> 0
E24: 55012105 | F24: 移动终端折旧费 | AT24: =AX24&F24 -> IT费用移动终端折旧费 | AU24: =IF(B24="",AU23,B24) -> 风险及运营管理部 | AV24: =IF(B24<>"","",IF(D24="",AV23,D24)) -> IT科技费用 | AW24: =IFERROR(VLOOKUP(AV24,[1]字段!A:B,2,0),"") -> IT费用 | AX24: =IF(AW24="人力费用",IF(E24="","",VLOOKUP(E24,[1]字段!D:E,2,0)),AW24) -> IT费用 | AY24: =IF(AT24="","",VLOOKUP(AT24,[1]字段!H:I,2,0)) -> IT费用 | AZ24: =IF($E24="",0,SUMIF($G$1:$AB$1,AZ$4,$G24:$AB24)) -> 0 | BA24: =IF($E24="",0,SUMIF($G$1:$AE$1,BA$4,$G24:$AE24)) -> 0 | BB24: =AZ24+BA24 -> 0 | BC24: =IF(E24="",0,SUM(G24:AE24)-AZ24-BA24) -> 0
E25: 55012106 | F25: 办公IT设备折旧费 | AT25: =AX25&F25 -> IT费用办公IT设备折旧费 | AU25: =IF(B25="",AU24,B25) -> 风险及运营管理部 | AV25: =IF(B25<>"","",IF(D25="",AV24,D25)) -> IT科技费用 | AW25: =IFERROR(VLOOKUP(AV25,[1]字段!A:B,2,0),"") -> IT费用 | AX25: =IF(AW25="人力费用",IF(E25="","",VLOOKUP(E25,[1]字段!D:E,2,0)),AW25) -> IT费用 | AY25: =IF(AT25="","",VLOOKUP(AT25,[1]字段!H:I,2,0)) -> IT费用 | AZ25: =IF($E25="",0,SUMIF($G$1:$AB$1,AZ$4,$G25:$AB25)) -> 0 | BA25: =IF($E25="",0,SUMIF($G$1:$AE$1,BA$4,$G25:$AE25)) -> 0 | BB25: =AZ25+BA25 -> 0 | BC25: =IF(E25="",0,SUM(G25:AE25)-AZ25-BA25) -> 0
E26: 55012202 | F26: 计算机软件摊销 | AT26: =AX26&F26 -> IT费用计算机软件摊销 | AU26: =IF(B26="",AU25,B26) -> 风险及运营管理部 | AV26: =IF(B26<>"","",IF(D26="",AV25,D26)) -> IT科技费用 | AW26: =IFERROR(VLOOKUP(AV26,[1]字段!A:B,2,0),"") -> IT费用 | AX26: =IF(AW26="人力费用",IF(E26="","",VLOOKUP(E26,[1]字段!D:E,2,0)),AW26) -> IT费用 | AY26: =IF(AT26="","",VLOOKUP(AT26,[1]字段!H:I,2,0)) -> IT费用 | AZ26: =IF($E26="",0,SUMIF($G$1:$AB$1,AZ$4,$G26:$AB26)) -> 0 | BA26: =IF($E26="",0,SUMIF($G$1:$AE$1,BA$4,$G26:$AE26)) -> 0 | BB26: =AZ26+BA26 -> 0 | BC26: =IF(E26="",0,SUM(G26:AE26)-AZ26-BA26) -> 0
E27: 55012207 | F27: 数据资源摊销 | AT27: =AX27&F27 -> IT费用数据资源摊销 | AU27: =IF(B27="",AU26,B27) -> 风险及运营管理部 | AV27: =IF(B27<>"","",IF(D27="",AV26,D27)) -> IT科技费用 | AW27: =IFERROR(VLOOKUP(AV27,[1]字段!A:B,2,0),"") -> IT费用 | AX27: =IF(AW27="人力费用",IF(E27="","",VLOOKUP(E27,[1]字段!D:E,2,0)),AW27) -> IT费用 | AY27: =IF(AT27="","",VLOOKUP(AT27,[1]字段!H:I,2,0)) -> IT费用 | AZ27: =IF($E27="",0,SUMIF($G$1:$AB$1,AZ$4,$G27:$AB27)) -> 0 | BA27: =IF($E27="",0,SUMIF($G$1:$AE$1,BA$4,$G27:$AE27)) -> 0 | BB27: =AZ27+BA27 -> 0 | BC27: =IF(E27="",0,SUM(G27:AE27)-AZ27-BA27) -> 0
E28: 55014101 | F28: 咨询费 | AT28: =AX28&F28 -> IT费用咨询费 | AU28: =IF(B28="",AU27,B28) -> 风险及运营管理部 | AV28: =IF(B28<>"","",IF(D28="",AV27,D28)) -> IT科技费用 | AW28: =IFERROR(VLOOKUP(AV28,[1]字段!A:B,2,0),"") -> IT费用 | AX28: =IF(AW28="人力费用",IF(E28="","",VLOOKUP(E28,[1]字段!D:E,2,0)),AW28) -> IT费用 | AY28: =IF(AT28="","",VLOOKUP(AT28,[1]字段!H:I,2,0)) -> IT费用 | AZ28: =IF($E28="",0,SUMIF($G$1:$AB$1,AZ$4,$G28:$AB28)) -> 0 | BA28: =IF($E28="",0,SUMIF($G$1:$AE$1,BA$4,$G28:$AE28)) -> 0 | BB28: =AZ28+BA28 -> 0 | BC28: =IF(E28="",0,SUM(G28:AE28)-AZ28-BA28) -> 0
E29: 55014601 | F29: 网络通讯费 | AT29: =AX29&F29 -> IT费用网络通讯费 | AU29: =IF(B29="",AU28,B29) -> 风险及运营管理部 | AV29: =IF(B29<>"","",IF(D29="",AV28,D29)) -> IT科技费用 | AW29: =IFERROR(VLOOKUP(AV29,[1]字段!A:B,2,0),"") -> IT费用 | AX29: =IF(AW29="人力费用",IF(E29="","",VLOOKUP(E29,[1]字段!D:E,2,0)),AW29) -> IT费用 | AY29: =IF(AT29="","",VLOOKUP(AT29,[1]字段!H:I,2,0)) -> IT费用 | AZ29: =IF($E29="",0,SUMIF($G$1:$AB$1,AZ$4,$G29:$AB29)) -> 0 | BA29: =IF($E29="",0,SUMIF($G$1:$AE$1,BA$4,$G29:$AE29)) -> 0 | BB29: =AZ29+BA29 -> 0 | BC29: =IF(E29="",0,SUM(G29:AE29)-AZ29-BA29) -> 0
E30: 55015601 | F30: 电子设备运转费 | AT30: =AX30&F30 -> IT费用电子设备运转费 | AU30: =IF(B30="",AU29,B30) -> 风险及运营管理部 | AV30: =IF(B30<>"","",IF(D30="",AV29,D30)) -> IT科技费用 | AW30: =IFERROR(VLOOKUP(AV30,[1]字段!A:B,2,0),"") -> IT费用 | AX30: =IF(AW30="人力费用",IF(E30="","",VLOOKUP(E30,[1]字段!D:E,2,0)),AW30) -> IT费用 | AY30: =IF(AT30="","",VLOOKUP(AT30,[1]字段!H:I,2,0)) -> IT费用 | AZ30: =IF($E30="",0,SUMIF($G$1:$AB$1,AZ$4,$G30:$AB30)) -> 0 | BA30: =IF($E30="",0,SUMIF($G$1:$AE$1,BA$4,$G30:$AE30)) -> 0 | BB30: =AZ30+BA30 -> 0 | BC30: =IF(E30="",0,SUM(G30:AE30)-AZ30-BA30) -> 0
E31: 55016403 | F31: 其他外包服务费 | AT31: =AX31&F31 -> IT费用其他外包服务费 | AU31: =IF(B31="",AU30,B31) -> 风险及运营管理部 | AV31: =IF(B31<>"","",IF(D31="",AV30,D31)) -> IT科技费用 | AW31: =IFERROR(VLOOKUP(AV31,[1]字段!A:B,2,0),"") -> IT费用 | AX31: =IF(AW31="人力费用",IF(E31="","",VLOOKUP(E31,[1]字段!D:E,2,0)),AW31) -> IT费用 | AY31: =IF(AT31="","",VLOOKUP(AT31,[1]字段!H:I,2,0)) -> IT费用 | AZ31: =IF($E31="",0,SUMIF($G$1:$AB$1,AZ$4,$G31:$AB31)) -> 0 | BA31: =IF($E31="",0,SUMIF($G$1:$AE$1,BA$4,$G31:$AE31)) -> 0 | BB31: =AZ31+BA31 -> 0 | BC31: =IF(E31="",0,SUM(G31:AE31)-AZ31-BA31) -> 0
C32: 0608 | D32: IT日常费用 | AT32: =AX32&F32 -> 日常费用 | AU32: =IF(B32="",AU31,B32) -> 风险及运营管理部 | AV32: =IF(B32<>"","",IF(D32="",AV31,D32)) -> IT日常费用 | AW32: =IFERROR(VLOOKUP(AV32,[1]字段!A:B,2,0),"") -> 日常费用 | AX32: =IF(AW32="人力费用",IF(E32="","",VLOOKUP(E32,[1]字段!D:E,2,0)),AW32) -> 日常费用 | AY32: =IF(AT32="","",VLOOKUP(AT32,[1]字段!H:I,2,0)) -> 0 | AZ32: =IF($E32="",0,SUMIF($G$1:$AB$1,AZ$4,$G32:$AB32)) -> 0 | BA32: =IF($E32="",0,SUMIF($G$1:$AE$1,BA$4,$G32:$AE32)) -> 0 | BB32: =AZ32+BA32 -> 0 | BC32: =IF(E32="",0,SUM(G32:AE32)-AZ32-BA32) -> 0
E33: 55012102 | F33: 办公OA设备折旧费 | AT33: =AX33&F33 -> 日常费用办公OA设备折旧费 | AU33: =IF(B33="",AU32,B33) -> 风险及运营管理部 | AV33: =IF(B33<>"","",IF(D33="",AV32,D33)) -> IT日常费用 | AW33: =IFERROR(VLOOKUP(AV33,[1]字段!A:B,2,0),"") -> 日常费用 | AX33: =IF(AW33="人力费用",IF(E33="","",VLOOKUP(E33,[1]字段!D:E,2,0)),AW33) -> 日常费用 | AY33: =IF(AT33="","",VLOOKUP(AT33,[1]字段!H:I,2,0)) -> 日常费用-其他 | AZ33: =IF($E33="",0,SUMIF($G$1:$AB$1,AZ$4,$G33:$AB33)) -> 0 | BA33: =IF($E33="",0,SUMIF($G$1:$AE$1,BA$4,$G33:$AE33)) -> 0 | BB33: =AZ33+BA33 -> 0 | BC33: =IF(E33="",0,SUM(G33:AE33)-AZ33-BA33) -> 0
E34: 55012107 | F34: 办公家具折旧费 | AT34: =AX34&F34 -> 日常费用办公家具折旧费 | AU34: =IF(B34="",AU33,B34) -> 风险及运营管理部 | AV34: =IF(B34<>"","",IF(D34="",AV33,D34)) -> IT日常费用 | AW34: =IFERROR(VLOOKUP(AV34,[1]字段!A:B,2,0),"") -> 日常费用 | AX34: =IF(AW34="人力费用",IF(E34="","",VLOOKUP(E34,[1]字段!D:E,2,0)),AW34) -> 日常费用 | AY34: =IF(AT34="","",VLOOKUP(AT34,[1]字段!H:I,2,0)) -> 日常费用-其他 | AZ34: =IF($E34="",0,SUMIF($G$1:$AB$1,AZ$4,$G34:$AB34)) -> 0 | BA34: =IF($E34="",0,SUMIF($G$1:$AE$1,BA$4,$G34:$AE34)) -> 0 | BB34: =AZ34+BA34 -> 0 | BC34: =IF(E34="",0,SUM(G34:AE34)-AZ34-BA34) -> 0
E35: 55015101 | F35: 办公费用 | AT35: =AX35&F35 -> 日常费用办公费用 | AU35: =IF(B35="",AU34,B35) -> 风险及运营管理部 | AV35: =IF(B35<>"","",IF(D35="",AV34,D35)) -> IT日常费用 | AW35: =IFERROR(VLOOKUP(AV35,[1]字段!A:B,2,0),"") -> 日常费用 | AX35: =IF(AW35="人力费用",IF(E35="","",VLOOKUP(E35,[1]字段!D:E,2,0)),AW35) -> 日常费用 | AY35: =IF(AT35="","",VLOOKUP(AT35,[1]字段!H:I,2,0)) -> 日常费用-其他 | AZ35: =IF($E35="",0,SUMIF($G$1:$AB$1,AZ$4,$G35:$AB35)) -> 0 | BA35: =IF($E35="",0,SUMIF($G$1:$AE$1,BA$4,$G35:$AE35)) -> 0 | BB35: =AZ35+BA35 -> 0 | BC35: =IF(E35="",0,SUM(G35:AE35)-AZ35-BA35) -> 0
C36: 08 | D36: 日常费用 | AT36: =AX36&F36 -> 日常费用 | AU36: =IF(B36="",AU35,B36) -> 风险及运营管理部 | AV36: =IF(B36<>"","",IF(D36="",AV35,D36)) -> 日常费用 | AW36: =IFERROR(VLOOKUP(AV36,[1]字段!A:B,2,0),"") -> 日常费用 | AX36: =IF(AW36="人力费用",IF(E36="","",VLOOKUP(E36,[1]字段!D:E,2,0)),AW36) -> 日常费用 | AY36: =IF(AT36="","",VLOOKUP(AT36,[1]字段!H:I,2,0)) -> 0 | AZ36: =IF($E36="",0,SUMIF($G$1:$AB$1,AZ$4,$G36:$AB36)) -> 0 | BA36: =IF($E36="",0,SUMIF($G$1:$AE$1,BA$4,$G36:$AE36)) -> 0 | BB36: =AZ36+BA36 -> 0 | BC36: =IF(E36="",0,SUM(G36:AE36)-AZ36-BA36) -> 0
E37: 55016403 | F37: 其他外包服务费 | AT37: =AX37&F37 -> 日常费用其他外包服务费 | AU37: =IF(B37="",AU36,B37) -> 风险及运营管理部 | AV37: =IF(B37<>"","",IF(D37="",AV36,D37)) -> 日常费用 | AW37: =IFERROR(VLOOKUP(AV37,[1]字段!A:B,2,0),"") -> 日常费用 | AX37: =IF(AW37="人力费用",IF(E37="","",VLOOKUP(E37,[1]字段!D:E,2,0)),AW37) -> 日常费用 | AY37: =IF(AT37="","",VLOOKUP(AT37,[1]字段!H:I,2,0)) -> 日常费用-外包服务费 | AZ37: =IF($E37="",0,SUMIF($G$1:$AB$1,AZ$4,$G37:$AB37)) -> 0 | BA37: =IF($E37="",0,SUMIF($G$1:$AE$1,BA$4,$G37:$AE37)) -> 0 | BB37: =AZ37+BA37 -> 0 | BC37: =IF(E37="",0,SUM(G37:AE37)-AZ37-BA37) -> 0
E38: 55018201 | F38: 业务招待费 | AT38: =AX38&F38 -> 日常费用业务招待费 | AU38: =IF(B38="",AU37,B38) -> 风险及运营管理部 | AV38: =IF(B38<>"","",IF(D38="",AV37,D38)) -> 日常费用 | AW38: =IFERROR(VLOOKUP(AV38,[1]字段!A:B,2,0),"") -> 日常费用 | AX38: =IF(AW38="人力费用",IF(E38="","",VLOOKUP(E38,[1]字段!D:E,2,0)),AW38) -> 日常费用 | AY38: =IF(AT38="","",VLOOKUP(AT38,[1]字段!H:I,2,0)) -> 日常费用-其他 | AZ38: =IF($E38="",0,SUMIF($G$1:$AB$1,AZ$4,$G38:$AB38)) -> 0 | BA38: =IF($E38="",0,SUMIF($G$1:$AE$1,BA$4,$G38:$AE38)) -> 0 | BB38: =AZ38+BA38 -> 0 | BC38: =IF(E38="",0,SUM(G38:AE38)-AZ38-BA38) -> 0
B39: 人力资源部 | AT39: =AX39&F39 | AU39: =IF(B39="",AU38,B39) -> 人力资源部 | AV39: =IF(B39<>"","",IF(D39="",AV38,D39)) | AW39: =IFERROR(VLOOKUP(AV39,[1]字段!A:B,2,0),"") | AX39: =IF(AW39="人力费用",IF(E39="","",VLOOKUP(E39,[1]字段!D:E,2,0)),AW39) | AY39: =IF(AT39="","",VLOOKUP(AT39,[1]字段!H:I,2,0)) | AZ39: =IF($E39="",0,SUMIF($G$1:$AB$1,AZ$4,$G39:$AB39)) -> 0 | BA39: =IF($E39="",0,SUMIF($G$1:$AE$1,BA$4,$G39:$AE39)) -> 0 | BB39: =AZ39+BA39 -> 0 | BC39: =IF(E39="",0,SUM(G39:AE39)-AZ39-BA39) -> 0
C40: 01 | D40: 人力费用 | AT40: =AX40&F40 | AU40: =IF(B40="",AU39,B40) -> 人力资源部 | AV40: =IF(B40<>"","",IF(D40="",AV39,D40)) -> 人力费用 | AW40: =IFERROR(VLOOKUP(AV40,[1]字段!A:B,2,0),"") -> 人力费用 | AX40: =IF(AW40="人力费用",IF(E40="","",VLOOKUP(E40,[1]字段!D:E,2,0)),AW40) | AY40: =IF(AT40="","",VLOOKUP(AT40,[1]字段!H:I,2,0)) | AZ40: =IF($E40="",0,SUMIF($G$1:$AB$1,AZ$4,$G40:$AB40)) -> 0 | BA40: =IF($E40="",0,SUMIF($G$1:$AE$1,BA$4,$G40:$AE40)) -> 0 | BB40: =AZ40+BA40 -> 0 | BC40: =IF(E40="",0,SUM(G40:AE40)-AZ40-BA40) -> 0
...
