Workbook

Sheet AA业务状况表
A1: 科目层级 | B1: 科目性质 | C1: 科目名称 | D1: 科目代码 | E1: 录入粒度 | F1: 实际月公式 | G1: 预测月公式 | H1: 公式说明
A2: 一级 | B2: 收入 | C2: 营业收入 | D2: AA01
A3: 二级 | B3: 收入 | C3: 利息净收入 | D3: AA0101
A4: 三级 | B4: 收入 | C4: 利息收入 | D4: AA010101
A5: 三级 | B5: 支出 | C5: 利息支出 | D5: AA010101
A6: 二级 | B6: 收入 | C6: 净手续费收入 | D6: AA0102
A7: 三级 | B7: 收入 | C7: 手续费收入 | D7: AA010201
A8: 三级 | B8: 支出 | C8: 手续费支出 | D8: AA010202
A9: 二级 | B9: 收入 | C9: 其他营收 | D9: AA0103
A10: 一级 | B10: 支出 | C10: 减：资产减值损失 | D10: AA02
A11: 二级 | B11: 支出 | C11: 贷款减值损失 | D11: AA0201
A12: 三级 | B12: 支出 | C12: 实际风险成本 | D12: AA020101
A13: 三级 | B13: 支出 | C13: 超额拨备 | D13: AA020102
... A86: 二级 | B86: 负债余额 | C86: 商户结算便利应付款 | D86: AA1603
A88: 一级 | C88: 不良贷款率 | D88: AA17
A89: 一级 | B89: 资产余额 | C89: 不良贷款余额 | D89: AA18
A90: 二级 | B90: 资产余额 | C90: 泛微粒贷 | D90: AA1801
A91: 三级 | B91: 资产余额 | C91: 微粒贷 | D91: AA180101
A92: 三级 | B92: 资产余额 | C92: 分付 | D92: AA180102
A93: 二级 | B93: 资产余额 | C93: 汽车金融 | D93: AA1802
A94: 二级 | B94: 资产余额 | C94: 财富 | D94: AA1803
A95: 二级 | B95: 资产余额 | C95: 小鹅 | D95: AA1804
A96: 二级 | B96: 资产余额 | C96: 企业金融 | D96: AA1805
A97: 一级 | B97: 支出 | C97: 核销净额 | D97: AA19
A98: 一级 | B98: 支出 | C98: 实际损失 | D98: AA20
A99: 二级 | B99: 支出 | C99: 泛微粒贷 | D99: AA2001
A100: 三级 | B100: 支出 | C100: 微粒贷 | D100: AA200101
... A129: 二级 | B129: 其他 | C129: 成本收入比 | D129: AA2605

Sheet AA损益表
A1: 科目层级 | B1: 科目性质 | C1: 科目名称 | D1: 科目代码 | E1: 录入粒度 | F1: 实际月公式 | G1: 预测月公式 | H1: 公式说明
A2: 一级 | B2: 收入 | C2: 营业收入 | D2: AA46
A3: 二级 | B3: 收入 | C3: 利息净收入 | D3: AA4601
A4: 三级 | B4: 收入 | C4: 利息收入 | D4: AA460101
A5: 三级 | B5: 支出 | C5: 利息支出 | D5: AA460101
A6: 二级 | B6: 收入 | C6: 净手续费收入 | D6: AA4602
A7: 三级 | B7: 收入 | C7: 手续费收入 | D7: AA460201
A8: 三级 | B8: 支出 | C8: 手续费支出 | D8: AA460202
A9: 二级 | B9: 收入 | C9: 其他营收 | D9: AA4603
A10: 一级 | B10: 支出 | C10: 减：资产减值损失 | D10: AA47
A11: 二级 | B11: 支出 | C11: 贷款减值损失 | D11: AA4701
A12: 三级 | B12: 支出 | C12: 实际风险成本 | D12: AA470101
A13: 三级 | B13: 支出 | C13: 超额拨备 | D13: AA470102
... A30: 一级 | B30: 利润 | C30: 净利润 | D30: AA54

Sheet AA资产负债表（余额）
A1: 科目层级 | B1: 科目性质 | C1: 科目名称 | D1: 科目代码 | E1: 录入粒度 | F1: 实际月公式 | G1: 预测月公式 | H1: 公式说明
A2: 一级 | B2: 资产余额 | C2: 总资产 | D2: AA27
A3: 二级 | B3: 资产余额 | C3: 各项贷款 | D3: AA2701
A4: 三级 | B4: 资产余额 | C4: 泛微粒贷 | D4: AA270101
A5: 四级 | B5: 资产余额 | C5: 微粒贷 | D5: AA27010101
A6: 四级 | B6: 资产余额 | C6: 分付 | D6: AA27010102
A7: 三级 | B7: 资产余额 | C7: 企业金融 | D7: AA270102
A8: 四级 | B8: 资产余额 | C8: 一般贷款 | D8: AA27010201
A9: 四级 | B9: 资产余额 | C9: 票据贴现 | D9: AA27010202
A10: 四级 | B10: 资产余额 | C10: 贸易融资 | D10: AA27010203
A11: 三级 | B11: 资产余额 | C11: 汽车金融 | D11: AA270103
A12: 三级 | B12: 资产余额 | C12: 财富 | D12: AA270104
A13: 三级 | B13: 资产余额 | C13: 小鹅 | D13: AA270105
... A66: 一级 | B66: 负债余额 | C66: 所有者权益 | D66: AA29

Sheet AA资产负债表（日均）
A1: 科目层级 | B1: 科目性质 | C1: 科目名称 | D1: 科目代码 | E1: 录入粒度 | F1: 实际月公式 | G1: 预测月公式 | H1: 公式说明
A2: 一级 | B2: 资产日均 | C2: 总资产 | D2: AA30
A3: 二级 | B3: 资产日均 | C3: 各项贷款 | D3: AA3001
A4: 三级 | B4: 资产日均 | C4: 泛微粒贷 | D4: AA300101
A5: 四级 | B5: 资产日均 | C5: 微粒贷 | D5: AA30010101
A6: 四级 | B6: 资产日均 | C6: 分付 | D6: AA30010102
A7: 三级 | B7: 资产日均 | C7: 企业金融 | D7: AA300102
A8: 四级 | B8: 资产日均 | C8: 一般贷款 | D8: AA30010201
A9: 四级 | B9: 资产日均 | C9: 票据贴现 | D9: AA30010202
A10: 四级 | B10: 资产日均 | C10: 贸易融资 | D10: AA30010203
A11: 三级 | B11: 资产日均 | C11: 汽车金融 | D11: AA300103
A12: 三级 | B12: 资产日均 | C12: 财富 | D12: AA300104
A13: 三级 | B13: 资产日均 | C13: 小鹅 | D13: AA300105
... A66: 一级 | B66: 负债日均 | C66: 所有者权益 | D66: AA32

Sheet AA资产质量表
A1: 科目层级 | B1: 科目性质 | C1: 科目名称 | D1: 科目代码 | E1: 录入粒度 | F1: 实际月公式 | G1: 预测月公式 | H1: 公式说明
A2: 一级 | B2: 其他 | C2: 风险成本率 | D2: AA33
A3: 二级 | B3: 其他 | C3: 泛微粒贷 | D3: AA3301
A4: 三级 | B4: 其他 | C4: 微粒贷 | D4: AA330101
A5: 三级 | B5: 其他 | C5: 分付 | D5: AA330102
A6: 二级 | B6: 其他 | C6: 汽车金融 | D6: AA3302
A7: 二级 | B7: 其他 | C7: 财富 | D7: AA3303
A8: 二级 | B8: 其他 | C8: 小鹅 | D8: AA3304
A9: 二级 | B9: 其他 | C9: 企业金融 | D9: AA3305
A10: 三级 | B10: 其他 | C10: 一般贷款 | D10: AA330501
A12: 一级 | B12: 支出 | C12: 风险成本 | D12: AA34
A13: 二级 | B13: 支出 | C13: 泛微粒贷 | D13: AA3401
A14: 三级 | B14: 支出 | C14: 微粒贷 | D14: AA340101
... A69: 三级 | B69: 支出 | C69: 企金不良转让净额 | D69: AA390501

Sheet AA利息净收入表
A1: 科目层级 | B1: 科目性质 | C1: 科目名称 | D1: 科目代码 | E1: 录入粒度 | F1: 实际月公式 | G1: 预测月公式 | H1: 公式说明
A2: 一级 | B2: 资产日均 | C2: 生息资产日均规模 | D2: AA40
A3: 二级 | B3: 资产日均 | C3: 各项贷款 | D3: AA4001
A4: 三级 | B4: 资产日均 | C4: 微粒贷 | D4: AA400101
A5: 三级 | B5: 资产日均 | C5: 分付 | D5: AA400102
A6: 三级 | B6: 资产日均 | C6: 汽车金融 | D6: AA400103
A7: 三级 | B7: 资产日均 | C7: 财富 | D7: AA400104
A8: 三级 | B8: 资产日均 | C8: 小鹅 | D8: AA400105
A9: 三级 | B9: 资产日均 | C9: 企业金融 | D9: AA400106
A10: 四级 | B10: 资产日均 | C10: 一般贷款 | D10: AA40010601
A11: 四级 | B11: 资产日均 | C11: 票据 | D11: AA40010602
A12: 二级 | B12: 资产日均 | C12: 存放央行 | D12: AA4002
A13: 二级 | B13: 资产日均 | C13: 存放同业 | D13: AA4003
... A90: 二级 | B90: 其他 | C90: 发行同业存单 | D90: AA4507

Sheet A个金群
A1: 科目层级 | B1: 科目性质 | C1: 科目名称 | D1: 科目代码 | E1: 录入粒度 | F1: 实际月公式 | G1: 预测月公式 | H1: 公式说明
A2: 一级 | B2: 收入 | C2: A01 | D2: 营业收入 | F2: =A01泛微粒贷!F2+A02微账户!F2+A03汽车金融!F2+A04财富!F2+A05小鹅!F2 -> 0 | G2: =A01泛微粒贷!G2+A02微账户!G2+A03汽车金融!G2+A04财富!G2+A05小鹅!G2 -> #DIV/0!
A3: 二级 | B3: 收入 | C3: A0101 | D3: 利息净收入 | F3: =A01泛微粒贷!F3+A02微账户!F3+A03汽车金融!F3+A04财富!F3+A05小鹅!F3 -> 0 | G3: =A01泛微粒贷!G3+A02微账户!G3+A03汽车金融!G3+A04财富!G3+A05小鹅!G3 -> #NAME?
A4: 三级 | B4: 收入 | C4: A010101 | D4: 资产业务 | F4: =A01泛微粒贷!F4+A02微账户!F4+A03汽车金融!F4+A04财富!F4+A05小鹅!F4 -> 0 | G4: =A01泛微粒贷!G4+A02微账户!G4+A03汽车金融!G4+A04财富!G4+A05小鹅!G4 -> 0
A5: 四级 | B5: 收入 | C5: A01010101 | D5: 利息收入 | F5: =A01泛微粒贷!#REF!+A02微账户!F5+A03汽车金融!#REF!+A04财富!#REF!+A05小鹅!#REF! -> #REF! | G5: =A01泛微粒贷!#REF!+A02微账户!G5+A03汽车金融!#REF!+A04财富!#REF!+A05小鹅!#REF! -> #REF!
A6: 四级 | B6: 支出 | C6: A01010102 | D6: FTP成本 | F6: =A01泛微粒贷!#REF!+A02微账户!F6+A03汽车金融!#REF!+A04财富!#REF!+A05小鹅!#REF! -> #REF! | G6: =A01泛微粒贷!#REF!+A02微账户!G6+A03汽车金融!#REF!+A04财富!#REF!+A05小鹅!#REF! -> #REF!
A7: 三级 | B7: 收入 | C7: A010102 | D7: 负债业务 | F7: =A01泛微粒贷!F5+A02微账户!F7+A03汽车金融!F5+A04财富!F5+A05小鹅!F5 -> 0 | G7: =A01泛微粒贷!G5+A02微账户!G7+A03汽车金融!G5+A04财富!G5+A05小鹅!G5 -> 0
A8: 四级 | B8: 支出 | C8: A01010201 | D8: 利息支出 | F8: =A01泛微粒贷!#REF!+A02微账户!F8+A03汽车金融!#REF!+A04财富!#REF!+A05小鹅!#REF! -> #REF! | G8: =A01泛微粒贷!#REF!+A02微账户!G8+A03汽车金融!#REF!+A04财富!#REF!+A05小鹅!#REF! -> #REF!
A9: 四级 | B9: 收入 | C9: A01010202 | D9: FTP收入 | F9: =A01泛微粒贷!#REF!+A02微账户!F9+A03汽车金融!#REF!+A04财富!#REF!+A05小鹅!#REF! -> #REF! | G9: =A01泛微粒贷!#REF!+A02微账户!G9+A03汽车金融!#REF!+A04财富!#REF!+A05小鹅!#REF! -> #REF!
A10: 二级 | B10: 收入 | C10: A0102 | D10: 净手续费收入 | F10: =A01泛微粒贷!F6+A02微账户!F10+A03汽车金融!F6+A04财富!F6+A05小鹅!F6 -> 0 | G10: =A01泛微粒贷!G6+A02微账户!G10+A03汽车金融!G6+A04财富!G6+A05小鹅!G6 -> #DIV/0!
A11: 三级 | B11: 收入 | C11: A010201 | D11: 手续费收入 | F11: =A01泛微粒贷!#REF!+A02微账户!F11+A03汽车金融!#REF!+A04财富!#REF!+A05小鹅!#REF! -> #REF! | G11: =A01泛微粒贷!#REF!+A02微账户!G11+A03汽车金融!#REF!+A04财富!#REF!+A05小鹅!#REF! -> #REF!
A12: 三级 | B12: 支出 | C12: A010202 | D12: 手续费支出 | F12: =A01泛微粒贷!#REF!+A02微账户!F12+A03汽车金融!#REF!+A04财富!#REF!+A05小鹅!#REF! -> #REF! | G12: =A01泛微粒贷!#REF!+A02微账户!G12+A03汽车金融!#REF!+A04财富!#REF!+A05小鹅!#REF! -> #REF!
A13: 二级 | B13: 收入 | C13: A0103 | D13: 其他营收 | F13: =A01泛微粒贷!F7+A02微账户!F13+A03汽车金融!F7+A04财富!F7+A05小鹅!F7 -> 0 | G13: =A01泛微粒贷!G7+A02微账户!G13+A03汽车金融!G7+A04财富!G7+A05小鹅!G7 -> 0
A14: 一级 | B14: 支出 | C14: A02 | D14: 减：风险成本 | F14: =A01泛微粒贷!F8+A02微账户!F14+A03汽车金融!F8+A04财富!F8+A05小鹅!F8 -> 0 | G14: =A01泛微粒贷!G8+A02微账户!G14+A03汽车金融!G8+A04财富!G8+A05小鹅!G8 -> 0
A15: 一级 | B15: 收入 | C15: A03 | D15: 净收入 | F15: =A01泛微粒贷!F9+A02微账户!F15+A03汽车金融!F9+A04财富!F9+A05小鹅!F9 -> 0 | G15: =A01泛微粒贷!G9+A02微账户!G15+A03汽车金融!G9+A04财富!G9+A05小鹅!G9 -> #DIV/0!
A16: 一级 | B16: 支出 | C16: A04 | D16: 减：税金及附加 | F16: =A01泛微粒贷!F10+A02微账户!F16+A03汽车金融!F10+A04财富!F10+A05小鹅!F10 -> 0 | G16: =A01泛微粒贷!G10+A02微账户!G16+A03汽车金融!G10+A04财富!G10+A05小鹅!G10 -> 0
A17: 一级 | B17: 支出 | C17: A05 | D17: 减：直接费用 | F17: =A01泛微粒贷!F11+A02微账户!F17+A03汽车金融!F11+A04财富!F11+A05小鹅!F11 -> 0 | G17: =A01泛微粒贷!G11+A02微账户!G17+A03汽车金融!G11+A04财富!G11+A05小鹅!G11 -> 0
A18: 二级 | B18: 支出 | C18: A0501 | D18: 人力费用（不含IT） | F18: =A01泛微粒贷!F12+A02微账户!F18+A03汽车金融!F12+A04财富!F12+A05小鹅!F12 -> 0 | G18: =A01泛微粒贷!G12+A02微账户!G18+A03汽车金融!G12+A04财富!G12+A05小鹅!G12 -> 0
A19: 三级 | B19: 支出 | C19: A050101 | D19: 常规人力 | F19: =A01泛微粒贷!F13+A02微账户!F19+A03汽车金融!F13+A04财富!F13+A05小鹅!F13 -> 0 | G19: =A01泛微粒贷!G13+A02微账户!G19+A03汽车金融!G13+A04财富!G13+A05小鹅!G13 -> 0
A20: 三级 | B20: 支出 | C20: A050102 | D20: 特别人力 | F20: =A01泛微粒贷!F14+A02微账户!F20+A03汽车金融!F14+A04财富!F14+A05小鹅!F14 -> 0 | G20: =A01泛微粒贷!G14+A02微账户!G20+A03汽车金融!G14+A04财富!G14+A05小鹅!G14 -> 0
A21: 二级 | B21: 支出 | C21: A0502 | D21: 业务费用 | F21: =A01泛微粒贷!F15+A02微账户!F21+A03汽车金融!F15+A04财富!F15+A05小鹅!F15 -> 0 | G21: =A01泛微粒贷!G15+A02微账户!G21+A03汽车金融!G15+A04财富!G15+A05小鹅!G15 -> 0
A22: 三级 | B22: 支出 | C22: A050201 | D22: 营销费用 | F22: =A01泛微粒贷!F16+A02微账户!F22+A03汽车金融!F16+A04财富!F16+A05小鹅!F16 -> 0 | G22: =A01泛微粒贷!G16+A02微账户!G22+A03汽车金融!G16+A04财富!G16+A05小鹅!G16 -> 0
A23: 三级 | B23: 支出 | C23: A050202 | D23: 运营费用 | F23: =A01泛微粒贷!F17+A02微账户!F23+A03汽车金融!F17+A04财富!F17+A05小鹅!F17 -> 0 | G23: =A01泛微粒贷!G17+A02微账户!G23+A03汽车金融!G17+A04财富!G17+A05小鹅!G17 -> 0
A24: 二级 | B24: 支出 | C24: A0503 | D24: IT费用 | F24: =A01泛微粒贷!F18+A02微账户!F24+A03汽车金融!F18+A04财富!F18+A05小鹅!F18 -> 0 | G24: =A01泛微粒贷!G18+A02微账户!G24+A03汽车金融!G18+A04财富!G18+A05小鹅!G18 -> 0
... A30: 三级 | B30: 支出 | C30: A050304 | D30: IT日常 | F30: =A01泛微粒贷!F24+A02微账户!F30+A03汽车金融!F24+A04财富!F24+A05小鹅!F24 -> 0 | G30: =A01泛微粒贷!G24+A02微账户!G30+A03汽车金融!G24+A04财富!G24+A05小鹅!G24 -> #NAME?
A31: 二级 | B31: 支出 | C31: A0504 | D31: 职场费用 | F31: =A01泛微粒贷!F25+A02微账户!#REF!+A03汽车金融!F25+A04财富!F25+A05小鹅!F25 -> #REF! | G31: =A01泛微粒贷!G25+A02微账户!#REF!+A03汽车金融!G25+A04财富!G25+A05小鹅!G25 -> #REF!
A32: 二级 | B32: 支出 | C32: A0505 | D32: 日常费用 | F32: =A01泛微粒贷!F26+A02微账户!#REF!+A03汽车金融!F26+A04财富!F26+A05小鹅!F26 -> #REF! | G32: =A01泛微粒贷!G26+A02微账户!#REF!+A03汽车金融!G26+A04财富!G26+A05小鹅!G26 -> #REF!
A33: 一级 | B33: 收入 | C33: A06 | D33: 加：营业外净收入 | F33: =A01泛微粒贷!F27+A02微账户!#REF!+A03汽车金融!F27+A04财富!F27+A05小鹅!F27 -> #REF! | G33: =A01泛微粒贷!G27+A02微账户!#REF!+A03汽车金融!G27+A04财富!G27+A05小鹅!G27 -> #REF!
A34: 一级 | B34: 利润 | C34: A07 | D34: 分摊前利润 | F34: =A01泛微粒贷!F28+A02微账户!#REF!+A03汽车金融!F28+A04财富!F28+A05小鹅!F28 -> #REF! | G34: =A01泛微粒贷!G28+A02微账户!#REF!+A03汽车金融!G28+A04财富!G28+A05小鹅!G28 -> #DIV/0!
A35: 一级 | B35: 支出 | C35: A08 | D35: 减：固定管理费 | F35: =A01泛微粒贷!F29+A02微账户!#REF!+A03汽车金融!F29+A04财富!F29+A05小鹅!F29 -> #REF! | G35: =A01泛微粒贷!G29+A02微账户!#REF!+A03汽车金融!G29+A04财富!G29+A05小鹅!G29 -> #REF!
A36: 一级 | B36: 利润 | C36: A09 | D36: 税前利润 | F36: =A01泛微粒贷!F30+A02微账户!#REF!+A03汽车金融!F30+A04财富!F30+A05小鹅!F30 -> #REF! | G36: =A01泛微粒贷!G30+A02微账户!#REF!+A03汽车金融!G30+A04财富!G30+A05小鹅!G30 -> #DIV/0!

Sheet A01泛微粒贷
A1: 科目层级 | B1: 科目性质 | C1: 科目名称 | D1: 科目代码 | E1: 录入粒度 | F1: 实际月公式 | G1: 预测月公式 | H1: 公式说明
A2: 一级 | B2: 收入 | C2: A01.01 | D2: 营业收入 | F2: =F3+F6+F7 -> 0 | G2: =G3+G6+G7 -> #DIV/0!
A3: 二级 | B3: 收入 | C3: A01.01.01 | D3: 利息净收入 | F3: =F4+F5 -> 0 | G3: =G4+G5 -> 0
A4: 三级 | B4: 收入 | C4: A01.01.01.01 | D4: 资产业务 | F4: =F54-F90 -> 0 | G4: =G54-G90 -> 0
A5: 三级 | B5: 收入 | C5: A01.01.01.02 | D5: 负债业务 | F5: =F111-F102 -> 0 | G5: =G111-G102 -> 0
A6: 二级 | B6: 收入 | C6: A01.01.02 | D6: 手续费净收入 | F6: =F118-F135 -> 0 | G6: =G118-G135 -> #DIV/0!
A7: 二级 | B7: 收入 | C7: A01.01.03 | D7: 其他营收 | F7: =F157+F159 -> 0 | G7: =G157+G159 -> 0
A8: 一级 | B8: 支出 | C8: A01.02 | D8: 减：风险成本
A9: 一级 | B9: 收入 | C9: A01.03 | D9: 净收入 | F9: =F2-F8 -> 0 | G9: =G2-G8 -> #DIV/0!
A10: 一级 | B10: 支出 | C10: A01.04 | D10: 减：税金及附加
A11: 一级 | B11: 支出 | C11: A01.05 | D11: 减：直接费用 | F11: =F12+F15+F18+F25+F26 -> 0 | G11: =G12+G15+G18+G25+G26 -> 0
A12: 二级 | B12: 支出 | C12: A01.05.01 | D12: 人力费用（不含IT） | F12: =F13+F14 -> 0 | G12: =G13+G14 -> 0
A13: 三级 | B13: 支出 | C13: A01.05.01.01 | D13: 常规人力
A14: 三级 | B14: 支出 | C14: A01.05.01.02 | D14: 特别人力
A15: 二级 | B15: 支出 | C15: A01.05.02 | D15: 业务费用 | F15: =F16+F17 -> 0 | G15: =G16+G17 -> 0
A16: 三级 | B16: 支出 | C16: A01.05.02.01 | D16: 营销费用
A17: 三级 | B17: 支出 | C17: A01.05.02.02 | D17: 运营费用
A18: 二级 | B18: 支出 | C18: A01.05.03 | D18: IT费用 | F18: =F19+F22+F23+F24 -> 0 | G18: =G19+G22+G23+G24 -> 0
A19: 三级 | B19: 支出 | C19: A01.05.03.01 | D19: IT人力 | F19: =F20+F21 -> 0 | G19: =G20+G21 -> 0
A20: 四级 | B20: 支出 | C20: A01.05.03.01.01 | D20: IT常规人力
A21: 四级 | B21: 支出 | C21: A01.05.03.01.02 | D21: IT特别人力
A22: 三级 | B22: 支出 | C22: A01.05.03.02 | D22: 科技费用
A23: 三级 | B23: 支出 | C23: A01.05.03.03 | D23: IT职场
A24: 三级 | B24: 支出 | C24: A01.05.03.04 | D24: IT日常
A25: 二级 | B25: 支出 | C25: A01.05.04 | D25: 职场费用
A26: 二级 | B26: 支出 | C26: A01.05.05 | D26: 日常费用
A27: 一级 | B27: 收入 | C27: A01.06 | D27: 加：营业外净收入
A28: 一级 | B28: 利润 | C28: A01.07 | D28: 分摊前利润 | F28: =F9-F10-F11+F27 -> 0 | G28: =G9-G10-G11+G27 -> #DIV/0!
A29: 一级 | B29: 支出 | C29: A01.08 | D29: 减：固定管理费
A30: 一级 | B30: 利润 | C30: A01.09 | D30: 税前利润 | F30: =F28-F29 -> 0 | G30: =G28-G29 -> #DIV/0!
A32: 一级 | B32: 资产余额 | C32: A01.10 | D32: 管理贷款余额 | F32: =F33+F38+F39 -> 0 | G32: =G33+G38+G39 -> 0
A33: 二级 | B33: 资产余额 | C33: A01.10.01 | D33: 自持余额 | F33: =F34 -> 0 | G33: =G34 -> 0
A34: 三级 | B34: 资产余额 | C34: A01.10.01.01 | D34: 一般贷款 | F34: =F35+F37 -> 0 | G34: =G35+G37 -> 0
A35: 四级 | B35: 资产余额 | C35: A01.10.01.01.01 | D35: 微粒贷
A36: 五级 | B36: 资产余额 | C36: A01.10.01.01.01.01 | D36: 其中：分期
A37: 四级 | B37: 资产余额 | C37: A01.10.01.01.02 | D37: 分付
A38: 二级 | B38: 资产余额 | C38: A01.10.02 | D38: 联贷
A39: 二级 | B39: 资产余额 | C39: A01.10.03 | D39: 流转
A40: 一级 | B40: 资产日均 | C40: A01.11 | D40: 管理贷款日均 | F40: =F41+F46+F47 -> 0 | G40: =G41+G46+G47 -> 0
A41: 二级 | B41: 资产日均 | C41: A01.11.01 | D41: 自持 | F41: =F42 -> 0 | G41: =G42 -> 0
...

Sheet A02微账户
A1: 科目层级 | B1: 科目性质 | C1: 科目名称 | D1: 科目代码 | E1: 录入粒度 | F1: 实际月公式 | G1: 预测月公式 | H1: 公式说明
A2: 一级 | B2: 收入 | C2: A02.01 | D2: 营业收入 | F2: =F3+F6+F7 -> 0 | G2: =G3+G6+G7 -> #NAME?
A3: 二级 | B3: 收入 | C3: A02.01.01 | D3: 利息净收入 | F3: =F4+F5 -> 0 | G3: =G4+G5 -> #NAME?
A4: 三级 | B4: 收入 | C4: A02.01.01.01 | D4: 资产业务 | F4: =F47-F54 -> 0 | G4: =G47-G54 -> 0
A5: 三级 | B5: 收入 | C5: A02.01.01.02 | D5: 负债业务 | F5: =F97-F62 -> 0 | G5: =G97-G62 -> #NAME?
A6: 二级 | B6: 收入 | C6: A02.01.02 | D6: 手续费净收入 | F6: =F120-F125 -> 0 | G6: =G120-G125 -> 0
A7: 二级 | B7: 收入 | C7: A02.01.03 | D7: 其他营收 | F7: =F131+F133 -> 0 | G7: =G131+G133 -> 0
A8: 一级 | B8: 支出 | C8: A02.02 | D8: 减：风险成本
A9: 一级 | B9: 收入 | C9: A02.03 | D9: 净收入 | F9: =F2-F8 -> 0 | G9: =G2-G8 -> #NAME?
A10: 一级 | B10: 支出 | C10: A02.04 | D10: 减：税金及附加
A11: 一级 | B11: 支出 | C11: A02.05 | D11: 减：直接费用 | F11: =F12+F15+F18+F25+F26 -> 0 | G11: =G12+G15+G18+G25+G26 -> 0
A12: 二级 | B12: 支出 | C12: A02.05.01 | D12: 人力费用（不含IT） | F12: =F13+F14 -> 0 | G12: =G13+G14 -> 0
A13: 三级 | B13: 支出 | C13: A02.05.01.01 | D13: 常规人力
A14: 三级 | B14: 支出 | C14: A02.05.01.02 | D14: 特别人力
A15: 二级 | B15: 支出 | C15: A02.05.02 | D15: 业务费用 | F15: =F16+F17 -> 0 | G15: =G16+G17 -> 0
A16: 三级 | B16: 支出 | C16: A02.05.02.01 | D16: 营销费用
A17: 三级 | B17: 支出 | C17: A02.05.02.02 | D17: 运营费用
A18: 二级 | B18: 支出 | C18: A02.05.03 | D18: IT费用 | F18: =F19+F22+F23+F24 -> 0 | G18: =G19+G22+G23+G24 -> 0
A19: 三级 | B19: 支出 | C19: A02.05.03.01 | D19: IT人力 | F19: =F20+F21 -> 0 | G19: =G20+G21 -> 0
A20: 四级 | B20: 支出 | C20: A02.05.03.01.01 | D20: IT常规人力
A21: 四级 | B21: 支出 | C21: A02.05.03.01.02 | D21: IT特别人力
A22: 三级 | B22: 支出 | C22: A02.05.03.02 | D22: 科技费用
A23: 三级 | B23: 支出 | C23: A02.05.03.03 | D23: IT职场
A24: 三级 | B24: 支出 | C24: A02.05.03.04 | D24: IT日常
A25: 二级 | B25: 支出 | C25: A02.05.04 | D25: 职场费用
A26: 二级 | B26: 支出 | C26: A02.05.05 | D26: 日常费用
A27: 一级 | B27: 收入 | C27: A02.06 | D27: 加：营业外净收入
A28: 一级 | B28: 利润 | C28: A02.07 | D28: 分摊前利润 | F28: =F9-F10-F11+F27 -> 0 | G28: =G9-G10-G11+G27 -> #NAME?
A29: 一级 | B29: 支出 | C29: A02.08 | D29: 减：固定管理费
A30: 一级 | B30: 利润 | C30: A02.09 | D30: 税前利润 | F30: =F28-F29 -> 0 | G30: =G28-G29 -> #NAME?
A32: 一级 | B32: 负债余额 | C32: A02.12 | D32: 管理资产余额 | F32: =F33+F36+F37+F38 -> 0 | G32: =G33+G36+G37+G38 -> 0
A33: 二级 | B33: 负债余额 | C33: A02.12.01 | D33: 零钱+ | F33: =F34+F35 -> 0 | G33: =G34+G35 -> 0
A34: 三级 | B34: 负债余额 | C34: A02.12.01.01 | D34: 经营部分
A35: 三级 | B35: 负债余额 | C35: A02.1201.02 | D35: 流动性专项备付
A36: 二级 | B36: 负债余额 | C36: A02.12.02 | D36: 零钱通
A37: 二级 | B37: 负债余额 | C37: A02.12.03 | D37: 商户结算便利应付款
A38: 二级 | B38: 负债余额 | C38: A02.12.04 | D38: 存款服务
A39: 一级 | B39: 负债日均 | C39: A02.13 | D39: 管理资产日均 | F39: =F40+F43+F44+F45 -> 0 | G39: =G40+G43+G44+G45 -> 0
A40: 二级 | B40: 负债日均 | C40: A02.13.01 | D40: 零钱+ | F40: =F41+F42 -> 0 | G40: =G41+G42 -> 0
A41: 三级 | B41: 负债日均 | C41: A02.13.01.01 | D41: 经营部分
...

Sheet A03汽车金融
A1: 科目层级 | B1: 科目性质 | C1: 科目名称 | D1: 科目代码 | E1: 录入粒度 | F1: 实际月公式 | G1: 预测月公式 | H1: 公式说明
A2: 一级 | B2: 收入 | C2: A03.01 | D2: 营业收入 | F2: =F3+F6+F7 -> 0 | G2: =G3+G6+G7 -> 0
A3: 二级 | B3: 收入 | C3: A03.01.01 | D3: 利息净收入 | F3: =F4+F5 -> 0 | G3: =G4+G5 -> 0
A4: 三级 | B4: 收入 | C4: A03.01.01.01 | D4: 资产业务 | F4: =F48-F52 -> 0 | G4: =G48-G52 -> 0
A5: 三级 | B5: 收入 | C5: A03.01.01.02 | D5: 负债业务 | F5: =F67-F58 -> 0 | G5: =G67-G58 -> 0
A6: 二级 | B6: 收入 | C6: A03.01.02 | D6: 手续费净收入 | F6: =F79-F85 -> 0 | G6: =G79-G85 -> 0
A7: 二级 | B7: 收入 | C7: A03.01.03 | D7: 其他营收 | F7: =F99+F101 -> 0 | G7: =G99+G101 -> 0
A8: 一级 | B8: 支出 | C8: A03.02 | D8: 减：风险成本
A9: 一级 | B9: 收入 | C9: A03.03 | D9: 净收入 | F9: =F2-F8 -> 0 | G9: =G2-G8 -> 0
A10: 一级 | B10: 支出 | C10: A03.04 | D10: 减：税金及附加
A11: 一级 | B11: 支出 | C11: A03.05 | D11: 减：直接费用 | F11: =F12+F15+F18+F25+F26 -> 0 | G11: =G12+G15+G18+G25+G26 -> 0
A12: 二级 | B12: 支出 | C12: A03.05.01 | D12: 人力费用（不含IT） | F12: =F13+F14 -> 0 | G12: =G13+G14 -> 0
A13: 三级 | B13: 支出 | C13: A03.05.01.01 | D13: 常规人力
A14: 三级 | B14: 支出 | C14: A03.05.01.02 | D14: 特别人力
A15: 二级 | B15: 支出 | C15: A03.05.02 | D15: 业务费用 | F15: =F16+F17 -> 0 | G15: =G16+G17 -> 0
A16: 三级 | B16: 支出 | C16: A03.05.02.01 | D16: 营销费用
A17: 三级 | B17: 支出 | C17: A03.05.02.02 | D17: 运营费用
A18: 二级 | B18: 支出 | C18: A03.05.03 | D18: IT费用 | F18: =F19+F22+F23+F24 -> 0 | G18: =G19+G22+G23+G24 -> 0
A19: 三级 | B19: 支出 | C19: A03.05.03.01 | D19: IT人力 | F19: =F20+F21 -> 0 | G19: =G20+G21 -> 0
A20: 四级 | B20: 支出 | C20: A03.05.03.01.01 | D20: IT常规人力
A21: 四级 | B21: 支出 | C21: A03.05.03.01.02 | D21: IT特别人力
A22: 三级 | B22: 支出 | C22: A03.05.03.02 | D22: 科技费用
A23: 三级 | B23: 支出 | C23: A03.05.03.03 | D23: IT职场
A24: 三级 | B24: 支出 | C24: A03.05.03.04 | D24: IT日常
A25: 二级 | B25: 支出 | C25: A03.05.04 | D25: 职场费用
A26: 二级 | B26: 支出 | C26: A03.05.05 | D26: 日常费用
A27: 一级 | B27: 收入 | C27: A03.06 | D27: 加：营业外净收入
A28: 一级 | B28: 利润 | C28: A03.07 | D28: 分摊前利润 | F28: =F9-F10-F11+F27 -> 0 | G28: =G9-G10-G11+G27 -> 0
A29: 一级 | B29: 支出 | C29: A03.08 | D29: 减：固定管理费
A30: 一级 | B30: 利润 | C30: A03.09 | D30: 税前利润 | F30: =F28-F29 -> 0 | G30: =G28-G29 -> 0
A32: 一级 | B32: 资产余额 | C32: A03.10 | D32: 管理贷款 | F32: =F33+F35+F36 -> 0 | G32: =G33+G35+G36 -> 0
A33: 二级 | B33: 资产余额 | C33: A03.10.01 | D33: 自持 | F33: =F34 -> 0 | G33: =G34 -> 0
A34: 三级 | B34: 资产余额 | C34: A03.10.01.01 | D34: 一般贷款
A35: 二级 | B35: 资产余额 | C35: A03.10.02 | D35: 联贷
A36: 二级 | B36: 资产余额 | C36: A03.10.03 | D36: 流转
A37: 一级 | B37: 资产日均 | C37: A03.11 | D37: 管理贷款日均 | F37: =F38+F40+F41 -> 0 | G37: =G38+G40+G41 -> 0
A38: 二级 | B38: 资产日均 | C38: A03.11.01 | D38: 自持 | F38: =F39 -> 0 | G38: =G39 -> 0
A39: 三级 | B39: 资产日均 | C39: A03.11.01.01 | D39: 一般贷款
A40: 二级 | B40: 资产日均 | C40: A03.11.02 | D40: 联贷
A41: 二级 | B41: 资产日均 | C41: A03.11.03 | D41: 流转
...

Sheet A04财富
A1: 科目层级 | B1: 科目性质 | C1: 科目名称 | D1: 科目代码 | E1: 录入粒度 | F1: 实际月公式 | G1: 预测月公式 | H1: 公式说明
A2: 一级 | B2: 收入 | C2: A04.01 | D2: 营业收入 | F2: =F3+F6+F7 -> 0 | G2: =G3+G6+G7 -> 0
A3: 二级 | B3: 收入 | C3: A04.01.01 | D3: 利息净收入 | F3: =F4+F5 -> 0 | G3: =G4+G5 -> 0
A4: 三级 | B4: 收入 | C4: A04.01.01.01 | D4: 资产业务 | F4: =F54-F64 -> 0 | G4: =G54-G64 -> 0
A5: 三级 | B5: 收入 | C5: A04.01.01.02 | D5: 负债业务 | F5: =F86-F73 -> 0 | G5: =G86-G73 -> 0
A6: 二级 | B6: 收入 | C6: A04.01.02 | D6: 手续费净收入 | F6: =F100-F105 -> 0 | G6: =G100-G105 -> 0
A7: 二级 | B7: 收入 | C7: A04.01.03 | D7: 其他营收 | F7: =F112+F114 -> 0 | G7: =G112+G114 -> 0
A8: 一级 | B8: 支出 | C8: A04.02 | D8: 减：风险成本
A9: 一级 | B9: 收入 | C9: A04.03 | D9: 净收入 | F9: =F2-F8 -> 0 | G9: =G2-G8 -> 0
A10: 一级 | B10: 支出 | C10: A04.04 | D10: 减：税金及附加
A11: 一级 | B11: 支出 | C11: A04.05 | D11: 减：直接费用 | F11: =F12+F15+F18+F25+F26 -> 0 | G11: =G12+G15+G18+G25+G26 -> 0
A12: 二级 | B12: 支出 | C12: A04.05.01 | D12: 人力费用（不含IT） | F12: =F13+F14 -> 0 | G12: =G13+G14 -> 0
A13: 三级 | B13: 支出 | C13: A04.05.01.01 | D13: 常规人力
A14: 三级 | B14: 支出 | C14: A04.05.01.02 | D14: 特别人力
A15: 二级 | B15: 支出 | C15: A04.05.02 | D15: 业务费用 | F15: =F16+F17 -> 0 | G15: =G16+G17 -> 0
A16: 三级 | B16: 支出 | C16: A04.05.02.01 | D16: 营销费用
A17: 三级 | B17: 支出 | C17: A04.05.02.02 | D17: 运营费用
A18: 二级 | B18: 支出 | C18: A04.05.03 | D18: IT费用 | F18: =F19+F22+F23+F24 -> 0 | G18: =G19+G22+G23+G24 -> 0
A19: 三级 | B19: 支出 | C19: A04.05.03.01 | D19: IT人力 | F19: =F20+F21 -> 0 | G19: =G20+G21 -> 0
A20: 四级 | B20: 支出 | C20: A04.05.03.01.01 | D20: IT常规人力
A21: 四级 | B21: 支出 | C21: A04.05.03.01.02 | D21: IT特别人力
A22: 三级 | B22: 支出 | C22: A04.05.03.02 | D22: 科技费用
A23: 三级 | B23: 支出 | C23: A04.05.03.03 | D23: IT职场
A24: 三级 | B24: 支出 | C24: A04.05.03.04 | D24: IT日常
A25: 二级 | B25: 支出 | C25: A04.05.04 | D25: 职场费用
A26: 二级 | B26: 支出 | C26: A04.05.05 | D26: 日常费用
A27: 一级 | B27: 收入 | C27: A04.06 | D27: 加：营业外净收入
A28: 一级 | B28: 利润 | C28: A04.07 | D28: 分摊前利润 | F28: =F9-F10-F11+F27 -> 0 | G28: =G9-G10-G11+G27 -> 0
A29: 一级 | B29: 支出 | C29: A04.08 | D29: 减：固定管理费
A30: 一级 | B30: 利润 | C30: A04.09 | D30: 税前利润 | F30: =F28-F29 -> 0 | G30: =G28-G29 -> 0
A32: 一级 | B32: 资产余额 | C32: A04.10 | D32: 管理贷款余额 | F32: =F33+F35+F36 -> 0 | G32: =G33+G35+G36 -> 0
A33: 二级 | B33: 资产余额 | C33: A04.10.01 | D33: 自持 | F33: =F34 -> 0 | G33: =G34 -> 0
A34: 三级 | B34: 资产余额 | C34: A04.10.01.01 | D34: 一般贷款
A35: 二级 | B35: 资产余额 | C35: A04.10.02 | D35: 联贷
A36: 二级 | B36: 资产余额 | C36: A04.10.03 | D36: 流转
A37: 一级 | B37: 资产日均 | C37: A04.11 | D37: 管理贷款日均 | F37: =F38+F40+F41 -> 0 | G37: =G38+G40+G41 -> 0
A38: 二级 | B38: 资产日均 | C38: A04.11.01 | D38: 自持 | F38: =F39 -> 0 | G38: =G39 -> 0
A39: 三级 | B39: 资产日均 | C39: A04.11.01.01 | D39: 一般贷款
A40: 二级 | B40: 资产日均 | C40: A04.11.02 | D40: 联贷
A41: 二级 | B41: 资产日均 | C41: A04.11.03 | D41: 流转
...

Sheet A05小鹅
A1: 科目层级 | B1: 科目性质 | C1: 科目名称 | D1: 科目代码 | E1: 录入粒度 | F1: 实际月公式 | G1: 预测月公式 | H1: 公式说明
A2: 一级 | B2: 收入 | C2: A05.01 | D2: 营业收入 | F2: =F3+F6+F7 -> 0 | G2: =G3+G6+G7 -> 0
A3: 二级 | B3: 收入 | C3: A05.01.01 | D3: 利息净收入 | F3: =F4+F5 -> 0 | G3: =G4+G5 -> 0
A4: 三级 | B4: 收入 | C4: A05.01.01.01 | D4: 资产业务 | F4: =F48-F52 -> 0 | G4: =G48-G52 -> 0
A5: 三级 | B5: 收入 | C5: A05.01.01.02 | D5: 负债业务 | F5: =F62-F58 -> 0 | G5: =G62-G58 -> 0
A6: 二级 | B6: 收入 | C6: A05.01.02 | D6: 手续费净收入 | F6: =F66-F69 -> 0 | G6: =G66-G69 -> 0
A7: 二级 | B7: 收入 | C7: A05.01.03 | D7: 其他营收 | F7: =F80+F82 -> 0 | G7: =G80+G82 -> 0
A8: 一级 | B8: 支出 | C8: A05.02 | D8: 减：风险成本
A9: 一级 | B9: 收入 | C9: A05.03 | D9: 净收入 | F9: =F2-F8 -> 0 | G9: =G2-G8 -> 0
A10: 一级 | B10: 支出 | C10: A05.04 | D10: 减：税金及附加
A11: 一级 | B11: 支出 | C11: A05.05 | D11: 减：直接费用 | F11: =F12+F15+F18+F25+F26 -> 0 | G11: =G12+G15+G18+G25+G26 -> 0
A12: 二级 | B12: 支出 | C12: A05.05.01 | D12: 人力费用（不含IT） | F12: =F13+F14 -> 0 | G12: =G13+G14 -> 0
A13: 三级 | B13: 支出 | C13: A05.05.01.01 | D13: 常规人力
A14: 三级 | B14: 支出 | C14: A05.05.01.02 | D14: 特别人力
A15: 二级 | B15: 支出 | C15: A05.05.02 | D15: 业务费用 | F15: =F16+F17 -> 0 | G15: =G16+G17 -> 0
A16: 三级 | B16: 支出 | C16: A05.05.02.01 | D16: 营销费用
A17: 三级 | B17: 支出 | C17: A05.05.02.02 | D17: 运营费用
A18: 二级 | B18: 支出 | C18: A05.05.03 | D18: IT费用 | F18: =F19+F22+F23+F24 -> 0 | G18: =G19+G22+G23+G24 -> 0
A19: 三级 | B19: 支出 | C19: A05.05.03.01 | D19: IT人力 | F19: =F20+F21 -> 0 | G19: =G20+G21 -> 0
A20: 四级 | B20: 支出 | C20: A05.05.03.01.01 | D20: IT常规人力
A21: 四级 | B21: 支出 | C21: A05.05.03.01.02 | D21: IT特别人力
A22: 三级 | B22: 支出 | C22: A05.05.03.02 | D22: 科技费用
A23: 三级 | B23: 支出 | C23: A05.05.03.03 | D23: IT职场
A24: 三级 | B24: 支出 | C24: A05.05.03.04 | D24: IT日常
A25: 二级 | B25: 支出 | C25: A05.05.04 | D25: 职场费用
A26: 二级 | B26: 支出 | C26: A05.05.05 | D26: 日常费用
A27: 一级 | B27: 收入 | C27: A05.06 | D27: 加：营业外净收入
A28: 一级 | B28: 利润 | C28: A05.07 | D28: 分摊前利润 | F28: =F9-F10-F11+F27 -> 0 | G28: =G9-G10-G11+G27 -> 0
A29: 一级 | B29: 支出 | C29: A05.08 | D29: 减：固定管理费
A30: 一级 | B30: 利润 | C30: A05.09 | D30: 税前利润 | F30: =F28-F29 -> 0 | G30: =G28-G29 -> 0
A32: 一级 | B32: 资产余额 | C32: A05.10 | D32: 管理贷款余额 | F32: =F33+F35+F36 -> 0 | G32: =G33+G35+G36 -> 0
A33: 二级 | B33: 资产余额 | C33: A05.10.01 | D33: 自持 | F33: =F34 -> 0 | G33: =G34 -> 0
A34: 三级 | B34: 资产余额 | C34: A05.10.01.01 | D34: 一般贷款
A35: 二级 | B35: 资产余额 | C35: A05.10.02 | D35: 联贷
A36: 二级 | B36: 资产余额 | C36: A05.10.03 | D36: 流转
A37: 一级 | B37: 资产日均 | C37: A05.11 | D37: 管理贷款日均 | F37: =F38+F40+F41 -> 0 | G37: =G38+G40+G41 -> 0
A38: 二级 | B38: 资产日均 | C38: A05.11.01 | D38: 自持 | F38: =F39 -> 0 | G38: =G39 -> 0
A39: 三级 | B39: 资产日均 | C39: A05.11.01.01 | D39: 一般贷款
A40: 二级 | B40: 资产日均 | C40: A05.11.02 | D40: 联贷
A41: 二级 | B41: 资产日均 | C41: A05.11.03 | D41: 流转
...

Sheet B企金群
A1: 科目层级 | B1: 科目性质 | C1: 科目名称 | D1: 科目代码 | E1: 录入粒度 | F1: 实际月公式 | G1: 预测月公式 | H1: 公式说明
A2: 一级 | B2: 收入 | C2: B01 | D2: 营业收入 | F2: =B01企业金融!F2+B02金融市场!F2 -> 0 | G2: =B01企业金融!G2+B02金融市场!G2 -> 0
A3: 二级 | B3: 收入 | C3: B0101 | D3: 利息净收入 | F3: =B01企业金融!F3+B02金融市场!F3 -> 0 | G3: =B01企业金融!G3+B02金融市场!G3 -> 0
A4: 三级 | B4: 收入 | C4: B010101 | D4: 资产业务 | F4: =B01企业金融!F4+B02金融市场!F4 -> 0 | G4: =B01企业金融!G4+B02金融市场!G4 -> 0
A5: 四级 | B5: 收入 | C5: B01010101 | D5: 利息收入 | F5: =B01企业金融!#REF!+B02金融市场!#REF! -> #REF! | G5: =B01企业金融!#REF!+B02金融市场!#REF! -> #REF!
A6: 四级 | B6: 支出 | C6: B01010102 | D6: FTP成本 | F6: =B01企业金融!#REF!+B02金融市场!#REF! -> #REF! | G6: =B01企业金融!#REF!+B02金融市场!#REF! -> #REF!
A7: 三级 | B7: 收入 | C7: B010102 | D7: 负债业务 | F7: =B01企业金融!F5+B02金融市场!F5 -> 0 | G7: =B01企业金融!G5+B02金融市场!G5 -> 0
A8: 四级 | B8: 支出 | C8: B01010201 | D8: 利息支出 | F8: =B01企业金融!#REF!+B02金融市场!#REF! -> #REF! | G8: =B01企业金融!#REF!+B02金融市场!#REF! -> #REF!
A9: 四级 | B9: 收入 | C9: B01010202 | D9: FTP收入 | F9: =B01企业金融!#REF!+B02金融市场!#REF! -> #REF! | G9: =B01企业金融!#REF!+B02金融市场!#REF! -> #REF!
A10: 二级 | B10: 收入 | C10: B0102 | D10: 净手续费收入 | F10: =B01企业金融!F6+B02金融市场!F6 -> 0 | G10: =B01企业金融!G6+B02金融市场!G6 -> 0
A11: 三级 | B11: 收入 | C11: B010201 | D11: 手续费收入 | F11: =B01企业金融!#REF!+B02金融市场!#REF! -> #REF! | G11: =B01企业金融!#REF!+B02金融市场!#REF! -> #REF!
A12: 三级 | B12: 支出 | C12: B010202 | D12: 手续费支出 | F12: =B01企业金融!#REF!+B02金融市场!#REF! -> #REF! | G12: =B01企业金融!#REF!+B02金融市场!#REF! -> #REF!
A13: 二级 | B13: 收入 | C13: B0103 | D13: 其他营收 | F13: =B01企业金融!F7+B02金融市场!F7 -> 0 | G13: =B01企业金融!G7+B02金融市场!G7 -> 0
A14: 一级 | B14: 支出 | C14: B02 | D14: 减：风险成本 | F14: =B01企业金融!F8+B02金融市场!F8 -> 0 | G14: =B01企业金融!G8+B02金融市场!G8 -> 0
A15: 一级 | B15: 收入 | C15: B03 | D15: 净收入 | F15: =B01企业金融!F9+B02金融市场!F9 -> 0 | G15: =B01企业金融!G9+B02金融市场!G9 -> 0
A16: 一级 | B16: 支出 | C16: B04 | D16: 减：税金及附加 | F16: =B01企业金融!F10+B02金融市场!F10 -> 0 | G16: =B01企业金融!G10+B02金融市场!G10 -> 0
A17: 一级 | B17: 支出 | C17: B05 | D17: 减：直接费用 | F17: =B01企业金融!F11+B02金融市场!F11 -> 0 | G17: =B01企业金融!G11+B02金融市场!G11 -> 0
A18: 二级 | B18: 支出 | C18: B0501 | D18: 人力费用（不含IT） | F18: =B01企业金融!F12+B02金融市场!F12 -> 0 | G18: =B01企业金融!G12+B02金融市场!G12 -> 0
A19: 三级 | B19: 支出 | C19: B050101 | D19: 常规人力 | F19: =B01企业金融!F13+B02金融市场!F13 -> 0 | G19: =B01企业金融!G13+B02金融市场!G13 -> 0
A20: 三级 | B20: 支出 | C20: B050102 | D20: 特别人力 | F20: =B01企业金融!F14+B02金融市场!F14 -> 0 | G20: =B01企业金融!G14+B02金融市场!G14 -> 0
A21: 二级 | B21: 支出 | C21: B0502 | D21: 业务费用 | F21: =B01企业金融!F15+B02金融市场!F15 -> 0 | G21: =B01企业金融!G15+B02金融市场!G15 -> 0
A22: 三级 | B22: 支出 | C22: B050201 | D22: 营销费用 | F22: =B01企业金融!F16+B02金融市场!F16 -> 0 | G22: =B01企业金融!G16+B02金融市场!G16 -> 0
A23: 三级 | B23: 支出 | C23: B050202 | D23: 运营费用 | F23: =B01企业金融!F17+B02金融市场!F17 -> 0 | G23: =B01企业金融!G17+B02金融市场!G17 -> 0
A24: 二级 | B24: 支出 | C24: B0503 | D24: IT费用 | F24: =B01企业金融!F18+B02金融市场!F18 -> 0 | G24: =B01企业金融!G18+B02金融市场!G18 -> 0
... A33: 一级 | B33: 收入 | C33: B06 | D33: 加：营业外净收入 | F33: =B01企业金融!F27+B02金融市场!F27 -> 0 | G33: =B01企业金融!G27+B02金融市场!G27 -> 0
A34: 一级 | C34: B07 | D34: 分摊前利润 | F34: =B01企业金融!F28+B02金融市场!F28 -> 0 | G34: =B01企业金融!G28+B02金融市场!G28 -> 0
A35: 一级 | B35: 支出 | C35: B08 | D35: 减：固定管理费 | F35: =B01企业金融!F29+B02金融市场!F29 -> 0 | G35: =B01企业金融!G29+B02金融市场!G29 -> 0
A36: 一级 | C36: B09 | D36: 税前利润 | F36: =B01企业金融!F30+B02金融市场!F30 -> 0 | G36: =B01企业金融!G30+B02金融市场!G30 -> 0

Sheet B01企业金融
A1: 科目层级 | B1: 科目性质 | C1: 科目名称 | D1: 科目代码 | E1: 录入粒度 | F1: 实际月公式 | G1: 预测月公式 | H1: 公式说明
A2: 一级 | B2: 收入 | C2: B01.01 | D2: 营业收入 | F2: =F3+F6+F7 -> 0 | G2: =G3+G6+G7 -> 0
A3: 二级 | B3: 收入 | C3: B01.01.01 | D3: 利息净收入 | F3: =F4+F5 -> 0 | G3: =G4+G5 -> 0
A4: 三级 | B4: 收入 | C4: B01.01.01.01 | D4: 资产业务 | F4: =F72-F114 -> 0 | G4: =G72-G114 -> 0
A5: 三级 | B5: 收入 | C5: B01.01.01.02 | D5: 负债业务 | F5: =F155-F138 -> 0 | G5: =G155-G138 -> 0
A6: 二级 | B6: 收入 | C6: B01.01.02 | D6: 手续费净收入 | F6: =F170-F186 -> 0 | G6: =G170-G186 -> 0
A7: 二级 | B7: 收入 | C7: B01.01.03 | D7: 其他营收 | F7: =F199+F203 -> 0 | G7: =G199+G203 -> 0
A8: 一级 | B8: 支出 | C8: B01.02 | D8: 减：风险成本
A9: 一级 | B9: 收入 | C9: B01.03 | D9: 净收入 | F9: =F2-F8 -> 0 | G9: =G2-G8 -> 0
A10: 一级 | B10: 支出 | C10: B01.04 | D10: 减：税金及附加
A11: 一级 | B11: 支出 | C11: B01.05 | D11: 减：直接费用 | F11: =F12+F15+F18+F25+F26 -> 0 | G11: =G12+G15+G18+G25+G26 -> 0
A12: 二级 | B12: 支出 | C12: B01.05.01 | D12: 人力费用（不含IT） | F12: =F13+F14 -> 0 | G12: =G13+G14 -> 0
A13: 三级 | B13: 支出 | C13: B01.05.01.01 | D13: 常规人力
A14: 三级 | B14: 支出 | C14: B01.05.01.02 | D14: 特别人力
A15: 二级 | B15: 支出 | C15: B01.05.02 | D15: 业务费用 | F15: =F16+F17 -> 0 | G15: =G16+G17 -> 0
A16: 三级 | B16: 支出 | C16: B01.05.02.01 | D16: 营销费用
A17: 三级 | B17: 支出 | C17: B01.05.02.02 | D17: 运营费用
A18: 二级 | B18: 支出 | C18: B01.05.03 | D18: IT费用 | F18: =F19+F22+F23+F24 -> 0 | G18: =G19+G22+G23+G24 -> 0
A19: 三级 | B19: 支出 | C19: B01.05.03.01 | D19: IT人力 | F19: =F20+F21 -> 0 | G19: =G20+G21 -> 0
A20: 四级 | B20: 支出 | C20: B01.05.03.01.01 | D20: IT常规人力
A21: 四级 | B21: 支出 | C21: B01.05.03.01.02 | D21: IT特别人力
A22: 三级 | B22: 支出 | C22: B01.05.03.02 | D22: 科技费用
A23: 三级 | B23: 支出 | C23: B01.05.03.03 | D23: IT职场
A24: 三级 | B24: 支出 | C24: B01.05.03.04 | D24: IT日常
A25: 二级 | B25: 支出 | C25: B01.05.04 | D25: 职场费用
A26: 二级 | B26: 支出 | C26: B01.05.05 | D26: 日常费用
A27: 一级 | B27: 收入 | C27: B01.06 | D27: 加：营业外净收入
A28: 一级 | B28: 利润 | C28: B01.07 | D28: 分摊前利润 | F28: =F9-F10-F11+F27 -> 0 | G28: =G9-G10-G11+G27 -> 0
A29: 一级 | B29: 支出 | C29: B01.08 | D29: 减：固定管理费
A30: 一级 | B30: 利润 | C30: B01.09 | D30: 税前利润 | F30: =F28-F29 -> 0 | G30: =G28-G29 -> 0
A32: 一级 | B32: 资产余额 | C32: B01.10 | D32: 管理贷款余额 | F32: =F33+F40+F41+F45 -> 0 | G32: =G33+G40+G41+G45 -> 0
A33: 二级 | B33: 资产余额 | C33: B01.10.01 | D33: 自持余额 | F33: =F34+F37 -> 0 | G33: =G34+G37 -> 0
A34: 三级 | B34: 资产余额 | C34: B01.10.01.01 | D34: 一般贷款 | F34: =F35+F36 -> 0 | G34: =G35+G36 -> 0
A35: 四级 | B35: 资产余额 | C35: B01.10.01.01.01 | D35: 常规部分
A36: 四级 | B36: 资产余额 | C36: B01.10.01.01.02 | D36: 战略部分
A37: 三级 | B37: 资产余额 | C37: B01.10.01.02 | D37: 票据融资 | F37: =F38+F39 -> 0 | G37: =G38+G39 -> 0
A38: 四级 | B38: 资产余额 | C38: B01.10.01.02.01 | D38: 票据贴现
A39: 四级 | B39: 资产余额 | C39: B01.10.01.02.02 | D39: 贸易融资
A40: 二级 | B40: 资产余额 | C40: B01.10.02 | D40: 联贷
A41: 二级 | B41: 资产余额 | C41: B01.10.03 | D41: 流转 | F41: =F42+F43+F44 -> 0 | G41: =G42+G43+G44 -> 0
...

Sheet B02金融市场
A1: 科目层级 | B1: 科目性质 | C1: 科目名称 | D1: 科目代码 | E1: 录入粒度 | F1: 实际月公式 | G1: 预测月公式 | H1: 公式说明 | I1: 横向汇总 | J1: 纵向汇总 | K1: 逻辑码
A2: 一级 | B2: 收入 | C2: B02.01 | D2: 营业收入 | F2: =F3+F6+F7 -> 0 | G2: =G3+G6+G7 -> 0
A3: 二级 | B3: 收入 | C3: B02.01.01 | D3: 利息净收入 | F3: =F4+F5 -> 0 | G3: =G4+G5 -> 0
A4: 三级 | B4: 收入 | C4: B02.01.01.01 | D4: 资产业务
A5: 三级 | B5: 收入 | C5: B02.01.01.02 | D5: 负债业务
A6: 二级 | B6: 收入 | C6: B02.01.02 | D6: 手续费净收入 | F6: =F187-F190 -> 0 | G6: =G187-G190 -> 0
A7: 二级 | B7: 收入 | C7: B02.01.03 | D7: 其他营收 | F7: =F193+F234 -> 0 | G7: =G193+G234 -> 0
A8: 一级 | B8: 支出 | C8: B02.02 | D8: 减：风险成本
A9: 一级 | B9: 收入 | C9: B02.03 | D9: 净收入 | F9: =F2-F8 -> 0 | G9: =G2-G8 -> 0
A10: 一级 | B10: 支出 | C10: B02.04 | D10: 减：税金及附加
A11: 一级 | B11: 支出 | C11: B02.05 | D11: 减：直接费用 | F11: =F12+F15+F18+F25+F26 -> 0 | G11: =G12+G15+G18+G25+G26 -> 0
A12: 二级 | B12: 支出 | C12: B02.05.01 | D12: 人力费用（不含IT） | F12: =F13+F14 -> 0 | G12: =G13+G14 -> 0
A13: 三级 | B13: 支出 | C13: B02.05.01.01 | D13: 常规人力
A14: 三级 | B14: 支出 | C14: B02.05.01.02 | D14: 特别人力
A15: 二级 | B15: 支出 | C15: B02.05.02 | D15: 业务费用 | F15: =F16+F17 -> 0 | G15: =G16+G17 -> 0
A16: 三级 | B16: 支出 | C16: B02.05.02.01 | D16: 营销费用
A17: 三级 | B17: 支出 | C17: B02.05.02.02 | D17: 运营费用
A18: 二级 | B18: 支出 | C18: B02.05.03 | D18: IT费用 | F18: =F19+F22+F23+F24 -> 0 | G18: =G19+G22+G23+G24 -> 0
A19: 三级 | B19: 支出 | C19: B02.05.03.01 | D19: IT人力 | F19: =F20+F21 -> 0 | G19: =G20+G21 -> 0
A20: 四级 | B20: 支出 | C20: B02.05.03.01.01 | D20: IT常规人力
A21: 四级 | B21: 支出 | C21: B02.05.03.01.02 | D21: IT特别人力
A22: 三级 | B22: 支出 | C22: B02.05.03.02 | D22: 科技费用
A23: 三级 | B23: 支出 | C23: B02.05.03.03 | D23: IT职场
A24: 三级 | B24: 支出 | C24: B02.05.03.04 | D24: IT日常
A25: 二级 | B25: 支出 | C25: B02.05.04 | D25: 职场费用
A26: 二级 | B26: 支出 | C26: B02.05.05 | D26: 日常费用
A27: 一级 | B27: 收入 | C27: B02.06 | D27: 加：营业外净收入
A28: 一级 | B28: 利润 | C28: B02.07 | D28: 分摊前利润 | F28: =F9-F10-F11+F27 -> 0 | G28: =G9-G10-G11+G27 -> 0
A29: 一级 | B29: 支出 | C29: B02.08 | D29: 减：固定管理费
A30: 一级 | B30: 利润 | C30: B02.09 | D30: 税前利润 | F30: =F28-F29 -> 0 | G30: =G28-G29 -> 0
A32: 一级 | B32: 资产余额 | C32: B02.10 | D32: 管理贷款 | F32: =F33 -> 0 | G32: =G33 -> 0
A33: 二级 | B33: 资产余额 | C33: B02.10.01 | D33: 自持 | F33: =F34 -> 0 | G33: =G34 -> 0
A34: 三级 | B34: 资产余额 | C34: B02.10.01.02 | D34: 票据融资
A35: 一级 | B35: 资产日均 | C35: B02.11 | D35: 管理贷款日均 | F35: =F36 -> 0 | G35: =G36 -> 0
A36: 二级 | B36: 资产日均 | C36: B02.11.01 | D36: 自持 | F36: =F37 -> 0 | G36: =G37 -> 0
A37: 三级 | B37: 资产日均 | C37: B02.11.01.02 | D37: 票据融资
A39: 一级 | B39: 收入 | C39: B02.14 | D39: 利息收入 | F39: =F40+F43+F65 -> 0 | G39: =G40+G43+G65 -> 0
A40: 二级 | B40: 收入 | C40: B02.14.01 | D40: 贷款利息收入 | G40: =G36*G41 -> 0 | H40: 收支月化指标
A41: 三级 | B41: 其他 | C41: B02.14.01.01 | D41: 贷款收息率 | F41: =F40/F36 -> #DIV/0! | H41: 率年化指标
A43: 二级 | B43: 收入 | C43: B02.14.02 | D43: 金融机构往来利息收入 | F43: =F44+F48+F52+F56+F60 -> 0 | G43: =G44+G48+G52+G56+G60 -> 0
...

Sheet C数字金融
A1: 科目层级 | B1: 科目性质 | C1: 科目名称 | D1: 科目代码 | E1: 录入粒度 | F1: 实际月公式 | G1: 预测月公式 | H1: 公式说明
A2: 一级 | B2: 收入 | C2: C01 | D2: 营业收入 | F2: ='C01国内业务'!F2+'C02国内研发'!F2 -> 0 | G2: ='C01国内业务'!G2+'C02国内研发'!G2 -> 0
A3: 二级 | B3: 收入 | C3: C0101 | D3: 利息净收入 | F3: ='C01国内业务'!F3+'C02国内研发'!F3 -> 0 | G3: ='C01国内业务'!G3+'C02国内研发'!G3 -> 0
A4: 三级 | B4: 收入 | C4: C010101 | D4: 资产业务 | F4: ='C01国内业务'!F4+'C02国内研发'!F4 -> 0 | G4: ='C01国内业务'!G4+'C02国内研发'!G4 -> 0
A5: 四级 | B5: 收入 | C5: C01010101 | D5: 利息收入 | F5: ='C01国内业务'!F5+'C02国内研发'!F5 -> 0 | G5: ='C01国内业务'!G5+'C02国内研发'!G5 -> 0
A6: 四级 | B6: 支出 | C6: C01010102 | D6: FTP成本 | F6: ='C01国内业务'!F6+'C02国内研发'!F6 -> 0 | G6: ='C01国内业务'!G6+'C02国内研发'!G6 -> 0
A7: 三级 | B7: 收入 | C7: C010102 | D7: 负债业务 | F7: ='C01国内业务'!F7+'C02国内研发'!F7 -> 0 | G7: ='C01国内业务'!G7+'C02国内研发'!G7 -> 0
A8: 四级 | B8: 支出 | C8: C01010201 | D8: 利息支出 | F8: ='C01国内业务'!F8+'C02国内研发'!F8 -> 0 | G8: ='C01国内业务'!G8+'C02国内研发'!G8 -> 0
A9: 四级 | B9: 收入 | C9: C01010202 | D9: FTP收入 | F9: ='C01国内业务'!F9+'C02国内研发'!F9 -> 0 | G9: ='C01国内业务'!G9+'C02国内研发'!G9 -> 0
A10: 二级 | B10: 收入 | C10: C0102 | D10: 净手续费收入 | F10: ='C01国内业务'!F10+'C02国内研发'!F10 -> 0 | G10: ='C01国内业务'!G10+'C02国内研发'!G10 -> 0
A11: 三级 | B11: 收入 | C11: C010201 | D11: 手续费收入 | F11: ='C01国内业务'!F11+'C02国内研发'!F11 -> 0 | G11: ='C01国内业务'!G11+'C02国内研发'!G11 -> 0
A12: 三级 | B12: 支出 | C12: C010202 | D12: 手续费支出 | F12: ='C01国内业务'!F12+'C02国内研发'!F12 -> 0 | G12: ='C01国内业务'!G12+'C02国内研发'!G12 -> 0
A13: 二级 | B13: 收入 | C13: C0103 | D13: 其他营收 | F13: ='C01国内业务'!F13+'C02国内研发'!F13 -> 0 | G13: ='C01国内业务'!G13+'C02国内研发'!G13 -> 0
... A33: 一级 | B33: 收入 | C33: C06 | D33: 加：营业外净收入 | F33: ='C01国内业务'!F33+'C02国内研发'!F33 -> 0 | G33: ='C01国内业务'!G33+'C02国内研发'!G33 -> 0
A34: 一级 | C34: C07 | D34: 分摊前利润 | F34: ='C01国内业务'!F34+'C02国内研发'!F34 -> 0 | G34: ='C01国内业务'!G34+'C02国内研发'!G34 -> 0
A35: 一级 | B35: 支出 | C35: C08 | D35: 减：固定管理费 | F35: ='C01国内业务'!F35+'C02国内研发'!F35 -> 0 | G35: ='C01国内业务'!G35+'C02国内研发'!G35 -> 0
A36: 一级 | C36: C09 | D36: 税前利润 | F36: ='C01国内业务'!F36+'C02国内研发'!F36 -> 0 | G36: ='C01国内业务'!G36+'C02国内研发'!G36 -> 0

Sheet C01国内业务
A1: 科目层级 | B1: 科目性质 | C1: 科目名称 | D1: 科目代码 | E1: 录入粒度 | F1: 实际月公式 | G1: 预测月公式 | H1: 公式说明
A2: 一级 | B2: 收入 | C2: C0101 | D2: 营业收入
A3: 二级 | B3: 收入 | C3: C010101 | D3: 利息净收入
A4: 三级 | B4: 收入 | C4: C01010101 | D4: 资产业务
A5: 四级 | B5: 收入 | C5: C0101010101 | D5: 利息收入
A6: 四级 | B6: 支出 | C6: C0101010102 | D6: FTP成本
A7: 三级 | B7: 收入 | C7: C01010102 | D7: 负债业务
A8: 四级 | B8: 支出 | C8: C0101010201 | D8: 利息支出
A9: 四级 | B9: 收入 | C9: C0101010202 | D9: FTP收入
A10: 二级 | B10: 收入 | C10: C010102 | D10: 净手续费收入
A11: 三级 | B11: 收入 | C11: C01010201 | D11: 手续费收入
A12: 三级 | B12: 支出 | C12: C01010202 | D12: 手续费支出
A13: 二级 | B13: 收入 | C13: C010103 | D13: 其他营收
... A33: 一级 | B33: 收入 | C33: C0106 | D33: 加：营业外净收入
A34: 一级 | C34: C0107 | D34: 分摊前利润
A35: 一级 | B35: 支出 | C35: C0108 | D35: 减：固定管理费
A36: 一级 | C36: C0109 | D36: 税前利润
A38: 一级 | B38: 支出 | C38: C0117 | D38: 存款利息支出
A39: 二级 | B39: 支出 | C39: C011701 | D39: 科技存款利息支出
A40: 三级 | B40: 负债余额 | C40: C01170101 | D40: 余额
A41: 三级 | B41: 负债日均 | C41: C01170102 | D41: 日均
A42: 三级 | B42: 支出 | C42: C01170103 | D42: 利息支出
A43: 三级 | C43: C01170104 | D43: 付息率
A44: 三级 | B44: 收入 | C44: C01170105 | D44: FTP收入
A45: 三级 | C45: C01170106 | D45: FTP
A47: 一级 | B47: 收入 | C47: C0121 | D47: 手续费收入
A48: 二级 | B48: 收入 | C48: C012101 | D48: 手续费收入
A50: 一级 | B50: 支出 | C50: C0122 | D50: 手续费支出
A51: 二级 | B51: 支出 | C51: C012201 | D51: 手续费支出
A53: 一级 | B53: 收入 | C53: C0123 | D53: 其他营收
A55: 一级 | B55: 收入 | C55: C0124 | D55: 内部营业净收入

Sheet C02国内研发
A1: 科目层级 | B1: 科目性质 | C1: 科目名称 | D1: 科目代码 | E1: 录入粒度 | F1: 实际月公式 | G1: 预测月公式 | H1: 公式说明
A2: 一级 | B2: 收入 | C2: C0201 | D2: 营业收入
A3: 二级 | B3: 收入 | C3: C020101 | D3: 利息净收入
A4: 三级 | B4: 收入 | C4: C02010101 | D4: 资产业务
A5: 四级 | B5: 收入 | C5: C0201010101 | D5: 利息收入
A6: 四级 | B6: 支出 | C6: C0201010102 | D6: FTP成本
A7: 三级 | B7: 收入 | C7: C02010102 | D7: 负债业务
A8: 四级 | B8: 支出 | C8: C0201010201 | D8: 利息支出
A9: 四级 | B9: 收入 | C9: C0201010202 | D9: FTP收入
A10: 二级 | B10: 收入 | C10: C020102 | D10: 净手续费收入
A11: 三级 | B11: 收入 | C11: C02010201 | D11: 手续费收入
A12: 三级 | B12: 支出 | C12: C02010202 | D12: 手续费支出
A13: 二级 | B13: 收入 | C13: C020103 | D13: 其他营收
... A33: 一级 | B33: 收入 | C33: C0206 | D33: 加：营业外净收入
A34: 一级 | C34: C0207 | D34: 分摊前利润
A35: 一级 | B35: 支出 | C35: C0208 | D35: 减：固定管理费
A36: 一级 | C36: C0209 | D36: 税前利润
A38: 一级 | B38: 收入 | C38: C0221 | D38: 手续费收入
A39: 二级 | B39: 收入 | C39: C022101 | D39: 手续费收入
A41: 一级 | B41: 支出 | C41: C0222 | D41: 手续费支出
A42: 二级 | B42: 支出 | C42: C022201 | D42: 手续费支出
A44: 一级 | B44: 收入 | C44: C0223 | D44: 其他营收
A46: 一级 | B46: 收入 | C46: C0224 | D46: 内部营业净收入

Sheet D国际业务
A1: 科目层级 | B1: 科目性质 | C1: 科目名称 | D1: 科目代码 | E1: 录入粒度 | F1: 实际月公式 | G1: 预测月公式 | H1: 公式说明
A2: 一级 | B2: 收入 | C2: D01 | D2: 营业收入
A3: 二级 | B3: 收入 | C3: D0101 | D3: 利息净收入
A4: 三级 | B4: 收入 | C4: D010101 | D4: 资产业务
A5: 四级 | B5: 收入 | C5: D01010101 | D5: 利息收入
A6: 四级 | B6: 支出 | C6: D01010102 | D6: FTP成本
A7: 三级 | B7: 收入 | C7: D010102 | D7: 负债业务
A8: 四级 | B8: 支出 | C8: D01010201 | D8: 利息支出
A9: 四级 | B9: 收入 | C9: D01010202 | D9: FTP收入
A10: 二级 | B10: 收入 | C10: D0102 | D10: 净手续费收入
A11: 三级 | B11: 收入 | C11: D010201 | D11: 手续费收入
A12: 三级 | B12: 支出 | C12: D010202 | D12: 手续费支出
A13: 二级 | B13: 收入 | C13: D0103 | D13: 其他营收
... A33: 一级 | B33: 收入 | C33: D06 | D33: 加：营业外净收入
A34: 一级 | C34: D07 | D34: 分摊前利润
A35: 一级 | B35: 支出 | C35: D08 | D35: 减：固定管理费
A36: 一级 | C36: D09 | D36: 税前利润

Sheet D01国际业务
A1: 科目层级 | B1: 科目性质 | C1: 科目名称 | D1: 科目代码 | E1: 录入粒度 | F1: 实际月公式 | G1: 预测月公式 | H1: 公式说明
A2: 一级 | B2: 收入 | C2: D0101 | D2: 营业收入
A3: 二级 | B3: 收入 | C3: D010101 | D3: 利息净收入
A4: 三级 | B4: 收入 | C4: D01010101 | D4: 资产业务
A5: 四级 | B5: 收入 | C5: D0101010101 | D5: 利息收入
A6: 四级 | B6: 支出 | C6: D0101010102 | D6: FTP成本
A7: 三级 | B7: 收入 | C7: D01010102 | D7: 负债业务
A8: 四级 | B8: 支出 | C8: D0101010201 | D8: 利息支出
A9: 四级 | B9: 收入 | C9: D0101010202 | D9: FTP收入
A10: 二级 | B10: 收入 | C10: D010102 | D10: 净手续费收入
A11: 三级 | B11: 收入 | C11: D01010201 | D11: 手续费收入
A12: 三级 | B12: 支出 | C12: D01010202 | D12: 手续费支出
A13: 二级 | B13: 收入 | C13: D010103 | D13: 其他营收
... A33: 一级 | B33: 收入 | C33: D0106 | D33: 加：营业外净收入
A34: 一级 | C34: D0107 | D34: 分摊前利润
A35: 一级 | B35: 支出 | C35: D0108 | D35: 减：固定管理费
A36: 一级 | C36: D0109 | D36: 税前利润
A38: 一级 | B38: 收入 | C38: D0121 | D38: 手续费收入
A39: 二级 | B39: 收入 | C39: D012101 | D39: 手续费收入
A41: 一级 | B41: 支出 | C41: D0122 | D41: 手续费支出
A42: 二级 | B42: 支出 | C42: D012201 | D42: 手续费支出
A44: 一级 | B44: 收入 | C44: D0123 | D44: 其他营收
A46: 一级 | B46: 收入 | C46: D0124 | D46: 内部营业净收入

Sheet E小鹅导流
A1: 科目层级 | B1: 科目性质 | C1: 科目名称 | D1: 科目代码 | E1: 录入粒度 | F1: 实际月公式 | G1: 预测月公式 | H1: 公式说明
A2: 一级 | B2: 收入 | C2: E01 | D2: 营业收入
A3: 二级 | B3: 收入 | C3: E0101 | D3: 利息净收入
A4: 三级 | B4: 收入 | C4: E010101 | D4: 资产业务
A5: 四级 | B5: 收入 | C5: E01010101 | D5: 利息收入
A6: 四级 | B6: 支出 | C6: E01010102 | D6: FTP成本
A7: 三级 | B7: 收入 | C7: E010102 | D7: 负债业务
A8: 四级 | B8: 支出 | C8: E01010201 | D8: 利息支出
A9: 四级 | B9: 收入 | C9: E01010202 | D9: FTP收入
A10: 二级 | B10: 收入 | C10: E0102 | D10: 净手续费收入
A11: 三级 | B11: 收入 | C11: E010201 | D11: 手续费收入
A12: 三级 | B12: 支出 | C12: E010202 | D12: 手续费支出
A13: 二级 | B13: 收入 | C13: E0103 | D13: 其他营收
... A33: 一级 | B33: 收入 | C33: E06 | D33: 加：营业外净收入
A34: 一级 | C34: E07 | D34: 分摊前利润
A35: 一级 | B35: 支出 | C35: E08 | D35: 减：固定管理费
A36: 一级 | C36: E09 | D36: 税前利润

Sheet E01小鹅导流
A1: 科目层级 | B1: 科目性质 | C1: 科目名称 | D1: 科目代码 | E1: 录入粒度 | F1: 实际月公式 | G1: 预测月公式 | H1: 公式说明
A2: 一级 | B2: 收入 | C2: E0101 | D2: 营业收入
A3: 二级 | B3: 收入 | C3: E010101 | D3: 利息净收入
A4: 三级 | B4: 收入 | C4: E01010101 | D4: 资产业务
A5: 四级 | B5: 收入 | C5: E0101010101 | D5: 利息收入
A6: 四级 | B6: 支出 | C6: E0101010102 | D6: FTP成本
A7: 三级 | B7: 收入 | C7: E01010102 | D7: 负债业务
A8: 四级 | B8: 支出 | C8: E0101010201 | D8: 利息支出
A9: 四级 | B9: 收入 | C9: E0101010202 | D9: FTP收入
A10: 二级 | B10: 收入 | C10: E010102 | D10: 净手续费收入
A11: 三级 | B11: 收入 | C11: E01010201 | D11: 手续费收入
A12: 三级 | B12: 支出 | C12: E01010202 | D12: 手续费支出
A13: 二级 | B13: 收入 | C13: E010103 | D13: 其他营收
... A33: 一级 | B33: 收入 | C33: E0106 | D33: 加：营业外净收入
A34: 一级 | C34: E0107 | D34: 分摊前利润
A35: 一级 | B35: 支出 | C35: E0108 | D35: 减：固定管理费
A36: 一级 | C36: E0109 | D36: 税前利润
A38: 一级 | B38: 收入 | C38: E0121 | D38: 手续费收入
A39: 二级 | B39: 收入 | C39: E012101 | D39: 手续费收入
A41: 一级 | B41: 支出 | C41: E0122 | D41: 手续费支出
A42: 二级 | B42: 支出 | C42: E012201 | D42: 手续费支出
A44: 一级 | B44: 收入 | C44: E0123 | D44: 其他营收
A46: 一级 | B46: 收入 | C46: E0124 | D46: 内部营业净收入

Sheet F司库及其他
A1: 科目层级 | B1: 科目性质 | C1: 科目名称 | D1: 科目代码 | E1: 录入粒度 | F1: 实际月公式 | G1: 预测月公式 | H1: 公式说明
A2: 一级 | B2: 收入 | C2: F01 | D2: 营业收入
A3: 二级 | B3: 收入 | C3: F0101 | D3: 利息净收入
A4: 三级 | B4: 收入 | C4: F010101 | D4: 资产业务
A5: 四级 | B5: 收入 | C5: F01010101 | D5: 利息收入
A6: 四级 | B6: 支出 | C6: F01010102 | D6: FTP成本
A7: 三级 | B7: 收入 | C7: F010102 | D7: 负债业务
A8: 四级 | B8: 支出 | C8: F01010201 | D8: 利息支出
A9: 四级 | B9: 收入 | C9: F01010202 | D9: FTP收入
A10: 二级 | B10: 收入 | C10: F0102 | D10: 净手续费收入
A11: 三级 | B11: 收入 | C11: F010201 | D11: 手续费收入
A12: 三级 | B12: 支出 | C12: F010202 | D12: 手续费支出
A13: 二级 | B13: 收入 | C13: F0103 | D13: 其他营收
... A33: 一级 | B33: 收入 | C33: F06 | D33: 加：营业外净收入
A34: 一级 | C34: F07 | D34: 分摊前利润
A35: 一级 | B35: 支出 | C35: F08 | D35: 减：固定管理费
A36: 一级 | C36: F09 | D36: 税前利润

Sheet F01司库及其他
A1: 科目层级 | B1: 科目性质 | C1: 科目名称 | D1: 科目代码 | E1: 录入粒度 | F1: 实际月公式 | G1: 预测月公式 | H1: 公式说明
A2: 一级 | B2: 收入 | C2: F0101 | D2: 营业收入
A3: 二级 | B3: 收入 | C3: F010101 | D3: 利息净收入
A4: 三级 | B4: 收入 | C4: F01010101 | D4: 资产业务
A5: 四级 | B5: 收入 | C5: F0101010101 | D5: 利息收入
A6: 四级 | B6: 支出 | C6: F0101010102 | D6: FTP成本
A7: 三级 | B7: 收入 | C7: F01010102 | D7: 负债业务
A8: 四级 | B8: 支出 | C8: F0101010201 | D8: 利息支出
A9: 四级 | B9: 收入 | C9: F0101010202 | D9: FTP收入
A10: 二级 | B10: 收入 | C10: F010102 | D10: 净手续费收入
A11: 三级 | B11: 收入 | C11: F01010201 | D11: 手续费收入
A12: 三级 | B12: 支出 | C12: F01010202 | D12: 手续费支出
A13: 二级 | B13: 收入 | C13: F010103 | D13: 其他营收
... A33: 一级 | B33: 收入 | C33: F0106 | D33: 加：营业外净收入
A34: 一级 | C34: F0107 | D34: 分摊前利润
A35: 一级 | B35: 支出 | C35: F0108 | D35: 减：固定管理费
A36: 一级 | C36: F0109 | D36: 税前利润
A38: 一级 | B38: 资产余额 | C38: F0110 | D38: 管理贷款
A39: 二级 | B39: 资产余额 | C39: F011001 | D39: 自持
A40: 一级 | B40: 资产日均 | C40: F0111 | D40: 管理贷款日均
A41: 二级 | B41: 资产日均 | C41: F011101 | D41: 自持
A43: 一级 | B43: 收入 | C43: F0114 | D43: 贷款利息收入
A44: 二级 | B44: 收入 | C44: F011401 | D44: 票据贴现利息收入
A45: 三级 | B45: 资产余额 | C45: F01140101 | D45: 余额
A46: 三级 | B46: 资产日均 | C46: F01140102 | D46: 日均
A47: 三级 | B47: 收入 | C47: F01140103 | D47: 利息收入
A48: 三级 | C48: F01140104 | D48: 收息率
A50: 一级 | B50: 收入 | C50: F0115 | D50: 金融机构往来利息收入
A51: 二级 | B51: 收入 | C51: F011501 | D51: 存放央行
A52: 三级 | B52: 资产余额 | C52: F01150101 | D52: 余额
A53: 三级 | B53: 资产日均 | C53: F01150102 | D53: 日均
A54: 三级 | B54: 收入 | C54: F01150103 | D54: 利息收入
A55: 三级 | C55: F01150104 | D55: 收息率
A56: 二级 | B56: 收入 | C56: F011502 | D56: 存放同业
A57: 三级 | B57: 资产余额 | C57: F01150201 | D57: 余额
A58: 三级 | B58: 资产日均 | C58: F01150202 | D58: 日均
A59: 三级 | B59: 收入 | C59: F01150203 | D59: 利息收入
A60: 三级 | C60: F01150204 | D60: 收息率
A61: 二级 | B61: 收入 | C61: F011503 | D61: 拆放同业
A62: 三级 | B62: 资产余额 | C62: F01150301 | D62: 余额
...

Sheet AB微众科技
A1: 科目层级 | B1: 科目性质 | C1: 科目名称 | D1: 科目代码 | E1: 录入粒度 | F1: 实际月公式 | G1: 预测月公式 | H1: 公式说明
