Workbook

Sheet B01企业金融业务状况表
A1: 科目层级 | B1: 科目性质 | C1: 科目代码 | D1: 科目名称 | E1: 25年实际 | F1: 26年预算 | G1: 26年预测 | H1: 26年1月实际 | I1: 26年2月实际 | J1: 26年3月实际 | K1: 26年4月预测 | L1: 26年5月预测 | M1: 26年6月预测 | N1: 26年7月预测 | O1: 26年8月预测 | P1: 26年9月预测 | Q1: 26年10月预测 | R1: 26年11月预测 | S1: 26年12月预测
A2: 二级 | B2: 收入 | C2: B01.01 | D2: 营业收入 | G2: =H2+I2+J2+K2+L2+M2+N2+O2+P2+Q2+R2+S2 -> 9770027202 | H2: =H3+H6+H7 -> 695074548 | I2: =I3+I6+I7 -> 660981004 | J2: =J3+J6+J7 -> 771586838 | K2: =K3+K6+K7 -> 788847484 | L2: =L3+L6+L7 -> 808397044 | M2: =M3+M6+M7 -> 835432542 | N2: =N3+N6+N7 -> 860179132 | O2: =O3+O6+O7 -> 848115660 | ... S2: =S3+S6+S7 -> 910291960
A3: 三级 | B3: 收入 | C3: B01.01.01 | D3: 利息净收入 | G3: =H3+I3+J3+K3+L3+M3+N3+O3+P3+Q3+R3+S3 -> 888184280 | H3: =H4+H5 -> 63188594 | I3: =I4+I5 -> 60089182 | J3: =J4+J5 -> 70144258 | K3: =K4+K5 -> 71713406 | L3: =L4+L5 -> 73490640 | M3: =M4+M5 -> 75948412 | N3: =N4+N5 -> 78198102 | O3: =O4+O5 -> 77101422 | ... S3: =S4+S5 -> 82753814
A4: 四级 | B4: 收入 | C4: B01.01.01.01 | D4: 资产业务 | G4: =H4+I4+J4+K4+L4+M4+N4+O4+P4+Q4+R4+S4 -> 444092140 | H4: 31594297 | I4: 30044591 | J4: 35072129 | K4: 35856703 | L4: 36745320 | M4: 37974206 | N4: 39099051 | O4: 38550711 | P4: 37662095 | Q4: 40280221 | R4: 39835909 | S4: 41376907
A5: 四级 | B5: 收入 | C5: B01.01.01.02 | D5: 负债业务 | G5: =H5+I5+J5+K5+L5+M5+N5+O5+P5+Q5+R5+S5 -> 444092140 | H5: 31594297 | I5: 30044591 | J5: 35072129 | K5: 35856703 | L5: 36745320 | M5: 37974206 | N5: 39099051 | O5: 38550711 | P5: 37662095 | Q5: 40280221 | R5: 39835909 | S5: 41376907
A6: 三级 | B6: 收入 | C6: B01.01.02 | D6: 手续费净收入 | G6: =H6+I6+J6+K6+L6+M6+N6+O6+P6+Q6+R6+S6 -> 4440921461 | H6: 315942977 | I6: 300445911 | J6: 350721290 | K6: 358567039 | L6: 367453202 | M6: 379742065 | N6: 390990515 | O6: 385507119 | P6: 376620957 | Q6: 402802214 | R6: 398359099 | S6: 413769073
A7: 三级 | B7: 收入 | C7: B01.01.03 | D7: 其他营收 | G7: =H7+I7+J7+K7+L7+M7+N7+O7+P7+Q7+R7+S7 -> 4440921461 | H7: 315942977 | I7: 300445911 | J7: 350721290 | K7: 358567039 | L7: 367453202 | M7: 379742065 | N7: 390990515 | O7: 385507119 | P7: 376620957 | Q7: 402802214 | R7: 398359099 | S7: 413769073
A8: 二级 | B8: 支出 | C8: B01.02 | D8: 减:风险成本 | G8: =H8+I8+J8+K8+L8+M8+N8+O8+P8+Q8+R8+S8 -> 3150000000 | H8: 220500000 | I8: 204750000 | J8: 245700000 | K8: 252000000 | L8: 258300000 | M8: 267750000 | N8: 277200000 | O8: 274050000 | P8: 267750000 | Q8: 292950000 | R8: 289800000 | S8: 299250000
A9: 二级 | B9: 收入 | C9: B01.03 | D9: 净收入 | G9: =H9+I9+J9+K9+L9+M9+N9+O9+P9+Q9+R9+S9 -> 4440921461 | H9: 315942977 | I9: 300445911 | J9: 350721290 | K9: 358567039 | L9: 367453202 | M9: 379742065 | N9: 390990515 | O9: 385507119 | P9: 376620957 | Q9: 402802214 | R9: 398359099 | S9: 413769073
A10: 二级 | B10: 支出 | C10: B01.04 | D10: 减:税金及附加 | G10: =H10+I10+J10+K10+L10+M10+N10+O10+P10+Q10+R10+S10 -> 150000000 | H10: 10500000 | I10: 9750000 | J10: 11700000 | K10: 12000000 | L10: 12300000 | M10: 12750000 | N10: 13200000 | O10: 13050000 | P10: 12750000 | Q10: 13950000 | R10: 13800000 | S10: 14250000
A11: 二级 | B11: 支出 | C11: B01.05 | D11: 减:直接费用 | G11: =H11+I11+J11+K11+L11+M11+N11+O11+P11+Q11+R11+S11 -> 2070000000 | H11: =H12+H15+H18+H25+H26 -> 144900000 | I11: =I12+I15+I18+I25+I26 -> 134550000 | J11: =J12+J15+J18+J25+J26 -> 161460000 | K11: =K12+K15+K18+K25+K26 -> 165600000 | L11: =L12+L15+L18+L25+L26 -> 169740000 | M11: =M12+M15+M18+M25+M26 -> 175950000 | N11: =N12+N15+N18+N25+N26 -> 182160000 | O11: =O12+O15+O18+O25+O26 -> 180090000 | ... S11: =S12+S15+S18+S25+S26 -> 196650000
A12: 三级 | B12: 支出 | C12: B01.05.01 | D12: 人力费用(不含IT) | G12: =H12+I12+J12+K12+L12+M12+N12+O12+P12+Q12+R12+S12 -> 810000000 | H12: =H13+H14 -> 56700000 | I12: =I13+I14 -> 52650000 | J12: =J13+J14 -> 63180000 | K12: =K13+K14 -> 64800000 | L12: =L13+L14 -> 66420000 | M12: =M13+M14 -> 68850000 | N12: =N13+N14 -> 71280000 | O12: =O13+O14 -> 70470000 | ... S12: =S13+S14 -> 76950000
A13: 四级 | B13: 支出 | C13: B01.05.01.01 | D13: 常规人力 | G13: =H13+I13+J13+K13+L13+M13+N13+O13+P13+Q13+R13+S13 -> 540000000 | H13: 37800000 | I13: 35100000 | J13: 42120000 | K13: 43200000 | L13: 44280000 | M13: 45900000 | N13: 47520000 | O13: 46980000 | P13: 45900000 | Q13: 50220000 | R13: 49680000 | S13: 51300000
A14: 四级 | B14: 支出 | C14: B01.05.01.02 | D14: 特别人力 | G14: =H14+I14+J14+K14+L14+M14+N14+O14+P14+Q14+R14+S14 -> 270000000 | H14: 18900000 | I14: 17550000 | J14: 21060000 | K14: 21600000 | L14: 22140000 | M14: 22950000 | N14: 23760000 | O14: 23490000 | P14: 22950000 | Q14: 25110000 | R14: 24840000 | S14: 25650000
A15: 三级 | B15: 支出 | C15: B01.05.02 | D15: 业务费用 | G15: =H15+I15+J15+K15+L15+M15+N15+O15+P15+Q15+R15+S15 -> 540000000 | H15: =H16+H17 -> 37800000 | I15: =I16+I17 -> 35100000 | J15: =J16+J17 -> 42120000 | K15: =K16+K17 -> 43200000 | L15: =L16+L17 -> 44280000 | M15: =M16+M17 -> 45900000 | N15: =N16+N17 -> 47520000 | O15: =O16+O17 -> 46980000 | ... S15: =S16+S17 -> 51300000
A16: 四级 | B16: 支出 | C16: B01.05.02.01 | D16: 营销费用 | G16: =H16+I16+J16+K16+L16+M16+N16+O16+P16+Q16+R16+S16 -> 320000000 | H16: 22400000 | I16: 20800000 | J16: 24960000 | K16: 25600000 | L16: 26240000 | M16: 27200000 | N16: 28160000 | O16: 27840000 | P16: 27200000 | Q16: 29760000 | R16: 29440000 | S16: 30400000
A17: 四级 | B17: 支出 | C17: B01.05.02.02 | D17: 运营费用 | G17: =H17+I17+J17+K17+L17+M17+N17+O17+P17+Q17+R17+S17 -> 220000000 | H17: 15400000 | I17: 14300000 | J17: 17160000 | K17: 17600000 | L17: 18040000 | M17: 18700000 | N17: 19360000 | O17: 19140000 | P17: 18700000 | Q17: 20460000 | R17: 20240000 | S17: 20900000
A18: 三级 | B18: 支出 | C18: B01.05.03 | D18: IT费用 | G18: =H18+I18+J18+K18+L18+M18+N18+O18+P18+Q18+R18+S18 -> 450000000 | H18: =H19+H22+H23+H24 -> 31500000 | I18: =I19+I22+I23+I24 -> 29250000 | J18: =J19+J22+J23+J24 -> 35100000 | K18: =K19+K22+K23+K24 -> 36000000 | L18: =L19+L22+L23+L24 -> 36900000 | M18: =M19+M22+M23+M24 -> 38250000 | N18: =N19+N22+N23+N24 -> 39600000 | O18: =O19+O22+O23+O24 -> 39150000 | ... S18: =S19+S22+S23+S24 -> 42750000
A19: 四级 | B19: 支出 | C19: B01.05.03.01 | D19: IT人力 | G19: =H19+I19+J19+K19+L19+M19+N19+O19+P19+Q19+R19+S19 -> 220000000 | H19: =H20+H21 -> 15400000 | I19: =I20+I21 -> 14300000 | J19: =J20+J21 -> 17160000 | K19: =K20+K21 -> 17600000 | L19: =L20+L21 -> 18040000 | M19: =M20+M21 -> 18700000 | N19: =N20+N21 -> 19360000 | O19: =O20+O21 -> 19140000 | ... S19: =S20+S21 -> 20900000
A20: 五级 | B20: 支出 | C20: B01.05.03.01.01 | D20: IT常规人力 | G20: =H20+I20+J20+K20+L20+M20+N20+O20+P20+Q20+R20+S20 -> 130000000 | H20: 9100000 | I20: 8450000 | J20: 10140000 | K20: 10400000 | L20: 10660000 | M20: 11050000 | N20: 11440000 | O20: 11310000 | P20: 11050000 | Q20: 12090000 | R20: 11960000 | S20: 12350000
A21: 五级 | B21: 支出 | C21: B01.05.03.01.02 | D21: IT特别人力 | G21: =H21+I21+J21+K21+L21+M21+N21+O21+P21+Q21+R21+S21 -> 90000000 | H21: 6300000 | I21: 5850000 | J21: 7020000 | K21: 7200000 | L21: 7380000 | M21: 7650000 | N21: 7920000 | O21: 7830000 | P21: 7650000 | Q21: 8370000 | R21: 8280000 | S21: 8550000
A22: 四级 | B22: 支出 | C22: B01.05.03.02 | D22: 科技费用 | G22: =H22+I22+J22+K22+L22+M22+N22+O22+P22+Q22+R22+S22 -> 90000000 | H22: 6300000 | I22: 5850000 | J22: 7020000 | K22: 7200000 | L22: 7380000 | M22: 7650000 | N22: 7920000 | O22: 7830000 | P22: 7650000 | Q22: 8370000 | R22: 8280000 | S22: 8550000
A23: 四级 | B23: 支出 | C23: B01.05.03.03 | D23: IT职场 | G23: =H23+I23+J23+K23+L23+M23+N23+O23+P23+Q23+R23+S23 -> 70000000 | H23: 4900000 | I23: 4550000 | J23: 5460000 | K23: 5600000 | L23: 5740000 | M23: 5950000 | N23: 6160000 | O23: 6090000 | P23: 5950000 | Q23: 6510000 | R23: 6440000 | S23: 6650000
A24: 四级 | B24: 支出 | C24: B01.05.03.04 | D24: IT日常 | G24: =H24+I24+J24+K24+L24+M24+N24+O24+P24+Q24+R24+S24 -> 70000000 | H24: 4900000 | I24: 4550000 | J24: 5460000 | K24: 5600000 | L24: 5740000 | M24: 5950000 | N24: 6160000 | O24: 6090000 | P24: 5950000 | Q24: 6510000 | R24: 6440000 | S24: 6650000
A25: 三级 | B25: 支出 | C25: B01.05.04 | D25: 职场费用 | G25: =H25+I25+J25+K25+L25+M25+N25+O25+P25+Q25+R25+S25 -> 140000000 | H25: 9800000 | I25: 9100000 | J25: 10920000 | K25: 11200000 | L25: 11480000 | M25: 11900000 | N25: 12320000 | O25: 12180000 | P25: 11900000 | Q25: 13020000 | R25: 12880000 | S25: 13300000
A26: 三级 | B26: 支出 | C26: B01.05.05 | D26: 日常费用 | G26: =H26+I26+J26+K26+L26+M26+N26+O26+P26+Q26+R26+S26 -> 130000000 | H26: 9100000 | I26: 8450000 | J26: 10140000 | K26: 10400000 | L26: 10660000 | M26: 11050000 | N26: 11440000 | O26: 11310000 | P26: 11050000 | Q26: 12090000 | R26: 11960000 | S26: 12350000
A27: 二级 | B27: 收入 | C27: B01.06 | D27: 加:营业外净收入 | G27: =H27+I27+J27+K27+L27+M27+N27+O27+P27+Q27+R27+S27 -> 60000000 | H27: 4200000 | I27: 3900000 | J27: 4680000 | K27: 4800000 | L27: 4920000 | M27: 5100000 | N27: 5280000 | O27: 5220000 | P27: 5100000 | Q27: 5580000 | R27: 5520000 | S27: 5700000
A28: 二级 | B28: 利润 | C28: B01.07 | D28: 分摊前利润 | G28: =H28+I28+J28+K28+L28+M28+N28+O28+P28+Q28+R28+S28 -> 4440921461 | H28: 315942977 | I28: 300445911 | J28: 350721290 | K28: 358567039 | L28: 367453202 | M28: 379742065 | N28: 390990515 | O28: 385507119 | P28: 376620957 | Q28: 402802214 | R28: 398359099 | S28: 413769073
A29: 二级 | B29: 支出 | C29: B01.08 | D29: 减:固定管理费 | G29: =H29+I29+J29+K29+L29+M29+N29+O29+P29+Q29+R29+S29 -> 300000000 | H29: 21000000 | I29: 19500000 | J29: 23400000 | K29: 24000000 | L29: 24600000 | M29: 25500000 | N29: 26400000 | O29: 26100000 | P29: 25500000 | Q29: 27900000 | R29: 27600000 | S29: 28500000
A30: 二级 | B30: 利润 | C30: B01.09 | D30: 税前利润 | G30: =H30+I30+J30+K30+L30+M30+N30+O30+P30+Q30+R30+S30 -> 4440921461 | H30: 315942977 | I30: 300445911 | J30: 350721290 | K30: 358567039 | L30: 367453202 | M30: 379742065 | N30: 390990515 | O30: 385507119 | P30: 376620957 | Q30: 402802214 | R30: 398359099 | S30: 413769073
A31: 二级 | B31: 资产余额 | C31: B01.10 | D31: 管理贷款余额 | G31: =H31+I31+J31+K31+L31+M31+N31+O31+P31+Q31+R31+S31 -> 97932276420 | H31: =H32+H39+H40+H44 -> 7339782891 | I31: =I32+I39+I40+I44 -> 7624933773 | J31: =J32+J39+J40+J44 -> 8026416387 | K31: =K32+K39+K40+K44 -> 8125370109 | L31: =L32+L39+L40+L44 -> 8321235960 | M31: =M32+M39+M40+M44 -> 8518122618 | N31: =N32+N39+N40+N44 -> 8618097153 | O31: =O32+O39+O40+O44 -> 8423252133 | ... S31: =S32+S39+S40+S44 -> 8528330721
A32: 三级 | B32: 资产余额 | C32: B01.10.01 | D32: 自持余额 | G32: =H32+I32+J32+K32+L32+M32+N32+O32+P32+Q32+R32+S32 -> 73500000000 | H32: =H33+H36 -> 5512500000 | I32: =I33+I36 -> 5733000000 | J32: =J33+J36 -> 6027000000 | K32: =K33+K36 -> 6100500000 | L32: =L33+L36 -> 6247500000 | M32: =M33+M36 -> 6394500000 | N32: =N33+N36 -> 6468000000 | O32: =O33+O36 -> 6321000000 | ... S32: =S33+S36 -> 6394500000
A33: 四级 | B33: 资产余额 | C33: B01.10.01.01 | D33: 一般贷款 | G33: =H33+I33+J33+K33+L33+M33+N33+O33+P33+Q33+R33+S33 -> 63000000000 | H33: =H34+H35 -> 4725000000 | I33: =I34+I35 -> 4914000000 | J33: =J34+J35 -> 5166000000 | K33: =K34+K35 -> 5229000000 | L33: =L34+L35 -> 5355000000 | M33: =M34+M35 -> 5481000000 | N33: =N34+N35 -> 5544000000 | O33: =O34+O35 -> 5418000000 | ... S33: =S34+S35 -> 5481000000
A34: 五级 | B34: 资产余额 | C34: B01.10.01.01.01 | D34: 常规部分 | G34: =H34+I34+J34+K34+L34+M34+N34+O34+P34+Q34+R34+S34 -> 36750000000 | H34: 2756250000 | I34: 2866500000 | J34: 3013500000 | K34: 3050250000 | L34: 3123750000 | M34: 3197250000 | N34: 3234000000 | O34: 3160500000 | P34: 3087000000 | Q34: 3050250000 | R34: 3013500000 | S34: 3197250000
A35: 五级 | B35: 资产余额 | C35: B01.10.01.01.02 | D35: 战略部分 | G35: =H35+I35+J35+K35+L35+M35+N35+O35+P35+Q35+R35+S35 -> 26250000000 | H35: 1968750000 | I35: 2047500000 | J35: 2152500000 | K35: 2178750000 | L35: 2231250000 | M35: 2283750000 | N35: 2310000000 | O35: 2257500000 | P35: 2205000000 | Q35: 2178750000 | R35: 2152500000 | S35: 2283750000
A36: 四级 | B36: 资产余额 | C36: B01.10.01.02 | D36: 票据融资 | G36: =H36+I36+J36+K36+L36+M36+N36+O36+P36+Q36+R36+S36 -> 10500000000 | H36: =H37+H38 -> 787500000 | I36: =I37+I38 -> 819000000 | J36: =J37+J38 -> 861000000 | K36: =K37+K38 -> 871500000 | L36: =L37+L38 -> 892500000 | M36: =M37+M38 -> 913500000 | N36: =N37+N38 -> 924000000 | O36: =O37+O38 -> 903000000 | ... S36: =S37+S38 -> 913500000
A37: 五级 | B37: 资产余额 | C37: B01.10.01.02.01 | D37: 票据贴现 | G37: =H37+I37+J37+K37+L37+M37+N37+O37+P37+Q37+R37+S37 -> 6300000000 | H37: 472500000 | I37: 491400000 | J37: 516600000 | K37: 522900000 | L37: 535500000 | M37: 548100000 | N37: 554400000 | O37: 541800000 | P37: 529200000 | Q37: 522900000 | R37: 516600000 | S37: 548100000
A38: 五级 | B38: 资产余额 | C38: B01.10.01.02.02 | D38: 贸易融资 | G38: =H38+I38+J38+K38+L38+M38+N38+O38+P38+Q38+R38+S38 -> 4200000000 | H38: 315000000 | I38: 327600000 | J38: 344400000 | K38: 348600000 | L38: 357000000 | M38: 365400000 | N38: 369600000 | O38: 361200000 | P38: 352800000 | Q38: 348600000 | R38: 344400000 | S38: 365400000
A39: 三级 | B39: 资产余额 | C39: B01.10.02 | D39: 联贷 | G39: =H39+I39+J39+K39+L39+M39+N39+O39+P39+Q39+R39+S39 -> 15750000000 | H39: 1181250000 | I39: 1228500000 | J39: 1291500000 | K39: 1307250000 | L39: 1338750000 | M39: 1370250000 | N39: 1386000000 | O39: 1354500000 | P39: 1323000000 | Q39: 1307250000 | R39: 1291500000 | S39: 1370250000
A40: 三级 | B40: 资产余额 | C40: B01.10.03 | D40: 流转 | G40: =H40+I40+J40+K40+L40+M40+N40+O40+P40+Q40+R40+S40 -> 1332276420 | H40: =H41+H42+H43 -> 94782891 | I40: =I41+I42+I43 -> 90133773 | J40: =J41+J42+J43 -> 105216387 | K40: =K41+K42+K43 -> 107570109 | L40: =L41+L42+L43 -> 110235960 | M40: =M41+M42+M43 -> 113922618 | N40: =N41+N42+N43 -> 117297153 | O40: =O41+O42+O43 -> 115652133 | ... S40: =S41+S42+S43 -> 124130721
...

Sheet B01企业金融业务支出评估
A1: 科目层级 | B1: 科目性质 | C1: 科目代码 | D1: 科目名称 | E1: 25年实际 | F1: 26年预算 | G1: 26年预测 | H1: 26年1月实际 | I1: 26年2月实际 | J1: 26年3月实际 | K1: 26年4月预测 | L1: 26年5月预测 | M1: 26年6月预测 | N1: 26年7月预测 | O1: 26年8月预测 | P1: 26年9月预测 | Q1: 26年10月预测 | R1: 26年11月预测 | S1: 26年12月预测
A2: 一级 | B2: 其他 | C2: B01.91 | D2: 业务支出评估 | G2: =H2+I2+J2+K2+L2+M2+N2+O2+P2+Q2+R2+S2 -> 638620000000 | H2: =H3 -> 45803400000 | I2: =I3 -> 44370300000 | J2: =J3 -> 50692360000 | K2: =K3 -> 51749600000 | L2: =L3 -> 53026840000 | M2: =M3 -> 54722700000 | N2: =N3 -> 56198560000 | O2: =O3 -> 55339940000 | ... S2: =S3 -> 58908900000
A3: 二级 | B3: 其他 | C3: B01.91.01 | D3: 客户经营指标 | G3: =H3+I3+J3+K3+L3+M3+N3+O3+P3+Q3+R3+S3 -> 638620000000 | H3: =H4+H9+H24 -> 45803400000 | I3: =I4+I9+I24 -> 44370300000 | J3: =J4+J9+J24 -> 50692360000 | K3: =K4+K9+K24 -> 51749600000 | L3: =L4+L9+L24 -> 53026840000 | M3: =M4+M9+M24 -> 54722700000 | N3: =N4+N9+N24 -> 56198560000 | O3: =O4+O9+O24 -> 55339940000 | ... S3: =S4+S9+S24 -> 58908900000
A4: 三级 | B4: 其他 | C4: B01.91.01.01 | D4: 客户营销与投入 | G4: =H4+I4+J4+K4+L4+M4+N4+O4+P4+Q4+R4+S4 -> 720000000 | H4: =H5+H6+H7+H8 -> 50400000 | I4: =I5+I6+I7+I8 -> 46800000 | J4: =J5+J6+J7+J8 -> 56160000 | K4: =K5+K6+K7+K8 -> 57600000 | L4: =L5+L6+L7+L8 -> 59040000 | M4: =M5+M6+M7+M8 -> 61200000 | N4: =N5+N6+N7+N8 -> 63360000 | O4: =O5+O6+O7+O8 -> 62640000 | ... S4: =S5+S6+S7+S8 -> 68400000
A5: 四级 | B5: 其他 | C5: B01.91.01.01.001 | D5: 新客营销支出 | G5: =H5+I5+J5+K5+L5+M5+N5+O5+P5+Q5+R5+S5 -> 300000000 | H5: 21000000 | I5: 19500000 | J5: 23400000 | K5: 24000000 | L5: 24600000 | M5: 25500000 | N5: 26400000 | O5: 26100000 | P5: 25500000 | Q5: 27900000 | R5: 27600000 | S5: 28500000
A6: 四级 | B6: 其他 | C6: B01.91.01.01.002 | D6: 存客营销支出 | G6: =H6+I6+J6+K6+L6+M6+N6+O6+P6+Q6+R6+S6 -> 200000000 | H6: 14000000 | I6: 13000000 | J6: 15600000 | K6: 16000000 | L6: 16400000 | M6: 17000000 | N6: 17600000 | O6: 17400000 | P6: 17000000 | Q6: 18600000 | R6: 18400000 | S6: 19000000
A7: 四级 | B7: 其他 | C7: B01.91.01.01.003 | D7: 新开通客户投入 | G7: =H7+I7+J7+K7+L7+M7+N7+O7+P7+Q7+R7+S7 -> 120000000 | H7: 8400000 | I7: 7800000 | J7: 9360000 | K7: 9600000 | L7: 9840000 | M7: 10200000 | N7: 10560000 | O7: 10440000 | P7: 10200000 | Q7: 11160000 | R7: 11040000 | S7: 11400000
A8: 四级 | B8: 其他 | C8: B01.91.01.01.004 | D8: 新发放投入 | G8: =H8+I8+J8+K8+L8+M8+N8+O8+P8+Q8+R8+S8 -> 100000000 | H8: 7000000 | I8: 6500000 | J8: 7800000 | K8: 8000000 | L8: 8200000 | M8: 8500000 | N8: 8800000 | O8: 8700000 | P8: 8500000 | Q8: 9300000 | R8: 9200000 | S8: 9500000
A9: 三级 | B9: 其他 | C9: B01.91.01.02 | D9: 客户规模与数量 | G9: =H9+I9+J9+K9+L9+M9+N9+O9+P9+Q9+R9+S9 -> 637000000000 | H9: =H10+H11+H12+H13+H14+H15+H16+H17+H18+H19+H20+H21+H22+H23 -> 45690000000 | I9: =I10+I11+I12+I13+I14+I15+I16+I17+I18+I19+I20+I21+I22+I23 -> 44265000000 | J9: =J10+J11+J12+J13+J14+J15+J16+J17+J18+J19+J20+J21+J22+J23 -> 50566000000 | K9: =K10+K11+K12+K13+K14+K15+K16+K17+K18+K19+K20+K21+K22+K23 -> 51620000000 | L9: =L10+L11+L12+L13+L14+L15+L16+L17+L18+L19+L20+L21+L22+L23 -> 52894000000 | M9: =M10+M11+M12+M13+M14+M15+M16+M17+M18+M19+M20+M21+M22+M23 -> 54585000000 | N9: =N10+N11+N12+N13+N14+N15+N16+N17+N18+N19+N20+N21+N22+N23 -> 56056000000 | O9: =O10+O11+O12+O13+O14+O15+O16+O17+O18+O19+O20+O21+O22+O23 -> 55199000000 | ... S9: =S10+S11+S12+S13+S14+S15+S16+S17+S18+S19+S20+S21+S22+S23 -> 58755000000
A10: 四级 | B10: 其他 | C10: B01.91.01.02.101 | D10: LUM规模 | G10: =H10+I10+J10+K10+L10+M10+N10+O10+P10+Q10+R10+S10 -> 80000000000 | H10: 6000000000 | I10: 6240000000 | J10: 6560000000 | K10: 6640000000 | L10: 6800000000 | M10: 6960000000 | N10: 7040000000 | O10: 6880000000 | P10: 6720000000 | Q10: 6640000000 | R10: 6560000000 | S10: 6960000000
A11: 四级 | B11: 其他 | C11: B01.91.01.02.001 | D11: 新客日均LUM | G11: =H11+I11+J11+K11+L11+M11+N11+O11+P11+Q11+R11+S11 -> 30000000000 | H11: 2100000000 | I11: 1950000000 | J11: 2340000000 | K11: 2400000000 | L11: 2460000000 | M11: 2550000000 | N11: 2640000000 | O11: 2610000000 | P11: 2550000000 | Q11: 2790000000 | R11: 2760000000 | S11: 2850000000
A12: 四级 | B12: 其他 | C12: B01.91.01.02.002 | D12: 存客日均LUM | G12: =H12+I12+J12+K12+L12+M12+N12+O12+P12+Q12+R12+S12 -> 50000000000 | H12: 3500000000 | I12: 3250000000 | J12: 3900000000 | K12: 4000000000 | L12: 4100000000 | M12: 4250000000 | N12: 4400000000 | O12: 4350000000 | P12: 4250000000 | Q12: 4650000000 | R12: 4600000000 | S12: 4750000000
A13: 四级 | B13: 其他 | C13: B01.91.01.02.005 | D13: 新发放LUM | G13: =H13+I13+J13+K13+L13+M13+N13+O13+P13+Q13+R13+S13 -> 12000000000 | H13: 840000000 | I13: 780000000 | J13: 936000000 | K13: 960000000 | L13: 984000000 | M13: 1020000000 | N13: 1056000000 | O13: 1044000000 | P13: 1020000000 | Q13: 1116000000 | R13: 1104000000 | S13: 1140000000
A14: 四级 | B14: 其他 | C14: B01.91.01.02.006 | D14: 新发放LUM(标服) | G14: =H14+I14+J14+K14+L14+M14+N14+O14+P14+Q14+R14+S14 -> 5000000000 | H14: 350000000 | I14: 325000000 | J14: 390000000 | K14: 400000000 | L14: 410000000 | M14: 425000000 | N14: 440000000 | O14: 435000000 | P14: 425000000 | Q14: 465000000 | R14: 460000000 | S14: 475000000
A15: 四级 | B15: 其他 | C15: B01.91.01.02.010 | D15: 日均LUM | G15: =H15+I15+J15+K15+L15+M15+N15+O15+P15+Q15+R15+S15 -> 80000000000 | H15: 5600000000 | I15: 5200000000 | J15: 6240000000 | K15: 6400000000 | L15: 6560000000 | M15: 6800000000 | N15: 7040000000 | O15: 6960000000 | P15: 6800000000 | Q15: 7440000000 | R15: 7360000000 | S15: 7600000000
A16: 四级 | B16: 其他 | C16: B01.91.01.02.102 | D16: AuM规模 | G16: =H16+I16+J16+K16+L16+M16+N16+O16+P16+Q16+R16+S16 -> 60000000000 | H16: 4500000000 | I16: 4680000000 | J16: 4920000000 | K16: 4980000000 | L16: 5100000000 | M16: 5220000000 | N16: 5280000000 | O16: 5160000000 | P16: 5040000000 | Q16: 4980000000 | R16: 4920000000 | S16: 5220000000
A17: 四级 | B17: 其他 | C17: B01.91.01.02.007 | D17: 存客日均AuM | G17: =H17+I17+J17+K17+L17+M17+N17+O17+P17+Q17+R17+S17 -> 35000000000 | H17: 2450000000 | I17: 2275000000 | J17: 2730000000 | K17: 2800000000 | L17: 2870000000 | M17: 2975000000 | N17: 3080000000 | O17: 3045000000 | P17: 2975000000 | Q17: 3255000000 | R17: 3220000000 | S17: 3325000000
A18: 四级 | B18: 其他 | C18: B01.91.01.02.008 | D18: 新客AuM余额 | G18: =H18+I18+J18+K18+L18+M18+N18+O18+P18+Q18+R18+S18 -> 15000000000 | H18: 1050000000 | I18: 975000000 | J18: 1170000000 | K18: 1200000000 | L18: 1230000000 | M18: 1275000000 | N18: 1320000000 | O18: 1305000000 | P18: 1275000000 | Q18: 1395000000 | R18: 1380000000 | S18: 1425000000
A19: 四级 | B19: 其他 | C19: B01.91.01.02.011 | D19: 日均AuM | G19: =H19+I19+J19+K19+L19+M19+N19+O19+P19+Q19+R19+S19 -> 60000000000 | H19: 4200000000 | I19: 3900000000 | J19: 4680000000 | K19: 4800000000 | L19: 4920000000 | M19: 5100000000 | N19: 5280000000 | O19: 5220000000 | P19: 5100000000 | Q19: 5580000000 | R19: 5520000000 | S19: 5700000000
A20: 四级 | B20: 其他 | C20: B01.91.01.02.103 | D20: 客户数量 | G20: =H20+I20+J20+K20+L20+M20+N20+O20+P20+Q20+R20+S20 -> 80000000000 | H20: 6000000000 | I20: 6240000000 | J20: 6560000000 | K20: 6640000000 | L20: 6800000000 | M20: 6960000000 | N20: 7040000000 | O20: 6880000000 | P20: 6720000000 | Q20: 6640000000 | R20: 6560000000 | S20: 6960000000
A21: 四级 | B21: 其他 | C21: B01.91.01.02.003 | D21: 新开通客户数 | G21: =H21+I21+J21+K21+L21+M21+N21+O21+P21+Q21+R21+S21 -> 20000000000 | H21: 1400000000 | I21: 1300000000 | J21: 1560000000 | K21: 1600000000 | L21: 1640000000 | M21: 1700000000 | N21: 1760000000 | O21: 1740000000 | P21: 1700000000 | Q21: 1860000000 | R21: 1840000000 | S21: 1900000000
... A23: 四级 | B23: 其他 | C23: B01.91.01.02.009 | D23: MFAU客户数 | G23: =H23+I23+J23+K23+L23+M23+N23+O23+P23+Q23+R23+S23 -> 50000000000 | H23: 3500000000 | I23: 3250000000 | J23: 3900000000 | K23: 4000000000 | L23: 4100000000 | M23: 4250000000 | N23: 4400000000 | O23: 4350000000 | P23: 4250000000 | Q23: 4650000000 | R23: 4600000000 | S23: 4750000000
A24: 三级 | B24: 其他 | C24: B01.91.01.03 | D24: 客户回收与催收 | G24: =H24+I24+J24+K24+L24+M24+N24+O24+P24+Q24+R24+S24 -> 900000000 | H24: =H25+H26+H27 -> 63000000 | I24: =I25+I26+I27 -> 58500000 | J24: =J25+J26+J27 -> 70200000 | K24: =K25+K26+K27 -> 72000000 | L24: =L25+L26+L27 -> 73800000 | M24: =M25+M26+M27 -> 76500000 | N24: =N25+N26+N27 -> 79200000 | O24: =O25+O26+O27 -> 78300000 | ... S24: =S25+S26+S27 -> 85500000
A25: 四级 | B25: 其他 | C25: B01.91.01.03.001 | D25: 内催回收额 | G25: =H25+I25+J25+K25+L25+M25+N25+O25+P25+Q25+R25+S25 -> 500000000 | H25: 35000000 | I25: 32500000 | J25: 39000000 | K25: 40000000 | L25: 41000000 | M25: 42500000 | N25: 44000000 | O25: 43500000 | P25: 42500000 | Q25: 46500000 | R25: 46000000 | S25: 47500000
A26: 四级 | B26: 其他 | C26: B01.91.01.03.002 | D26: M6-压降金额 | G26: =H26+I26+J26+K26+L26+M26+N26+O26+P26+Q26+R26+S26 -> 250000000 | H26: 17500000 | I26: 16250000 | J26: 19500000 | K26: 20000000 | L26: 20500000 | M26: 21250000 | N26: 22000000 | O26: 21750000 | P26: 21250000 | Q26: 23250000 | R26: 23000000 | S26: 23750000
A27: 四级 | B27: 其他 | C27: B01.91.01.03.003 | D27: M7+现金回收额 | G27: =H27+I27+J27+K27+L27+M27+N27+O27+P27+Q27+R27+S27 -> 150000000 | H27: 10500000 | I27: 9750000 | J27: 11700000 | K27: 12000000 | L27: 12300000 | M27: 12750000 | N27: 13200000 | O27: 13050000 | P27: 12750000 | Q27: 13950000 | R27: 13800000 | S27: 14250000

Sheet AA微众银行业务状况表
A1: 科目层级 | B1: 科目性质 | C1: 科目代码 | D1: 科目名称 | E1: 25年实际 | F1: 26年预算 | G1: 26年预测 | H1: 26年1月实际 | I1: 26年2月实际 | J1: 26年3月实际 | K1: 26年4月预测 | L1: 26年5月预测 | M1: 26年6月预测 | N1: 26年7月预测 | O1: 26年8月预测 | P1: 26年9月预测 | Q1: 26年10月预测 | R1: 26年11月预测 | S1: 26年12月预测
A2: 二级 | B2: 收入 | C2: AA.01 | D2: 营业收入 | G2: =H2+I2+J2+K2+L2+M2+N2+O2+P2+Q2+R2+S2 -> 41725591568 | H2: =H3+H6+H9 -> 2948948970 | I2: =I3+I6+I9 -> 2782705536 | J2: =J3+J6+J9 -> 3268312726 | K2: =K3+K6+K9 -> 3355590174 | L2: =L3+L6+L9 -> 3438013270 | M2: =M3+M6+M9 -> 3556968830 | N2: =N3+N6+N9 -> 3671738766 | O2: =O3+O6+O9 -> 3620431090 | ... S2: =S3+S6+S9 -> 3925334780
A3: 三级 | B3: 收入 | C3: AA.01.01 | D3: 利息净收入 | G3: =H3+I3+J3+K3+L3+M3+N3+O3+P3+Q3+R3+S3 -> 18362795784 | H3: 1299474485 | I3: 1228852768 | J3: 1439156363 | K3: 1477795087 | L3: 1514006635 | M3: 1565984415 | N3: 1615869383 | O3: 1592715545 | P3: 1558341374 | Q3: 1684783438 | R3: 1660648901 | S3: 1725167390
A4: 二级 | B4: 收入 | C4: AA.14 | D4: 利息收入 | G4: =H4+I4+J4+K4+L4+M4+N4+O4+P4+Q4+R4+S4 -> 37800000000 | H4: 2646000000 | I4: 2457000000 | J4: 2948400000 | K4: 3024000000 | L4: 3099600000 | M4: 3213000000 | N4: 3326400000 | O4: 3288600000 | P4: 3213000000 | Q4: 3515400000 | R4: 3477600000 | S4: 3591000000
A5: 二级 | B5: 支出 | C5: AA.16 | D5: 利息支出 | G5: =H5+I5+J5+K5+L5+M5+N5+O5+P5+Q5+R5+S5 -> 16800000000 | H5: 1176000000 | I5: 1092000000 | J5: 1310400000 | K5: 1344000000 | L5: 1377600000 | M5: 1428000000 | N5: 1478400000 | O5: 1461600000 | P5: 1428000000 | Q5: 1562400000 | R5: 1545600000 | S5: 1596000000
A6: 三级 | B6: 收入 | C6: AA.01.02 | D6: 净手续费收入 | G6: =H6+I6+J6+K6+L6+M6+N6+O6+P6+Q6+R6+S6 -> 18362795784 | H6: 1299474485 | I6: 1228852768 | J6: 1439156363 | K6: 1477795087 | L6: 1514006635 | M6: 1565984415 | N6: 1615869383 | O6: 1592715545 | P6: 1558341374 | Q6: 1684783438 | R6: 1660648901 | S6: 1725167390
A7: 二级 | B7: 收入 | C7: AA.18 | D7: 手续费收入 | G7: =H7+I7+J7+K7+L7+M7+N7+O7+P7+Q7+R7+S7 -> 15000000000 | H7: 1050000000 | I7: 975000000 | J7: 1170000000 | K7: 1200000000 | L7: 1230000000 | M7: 1275000000 | N7: 1320000000 | O7: 1305000000 | P7: 1275000000 | Q7: 1395000000 | R7: 1380000000 | S7: 1425000000
A8: 二级 | B8: 支出 | C8: AA.19 | D8: 手续费支出 | G8: =H8+I8+J8+K8+L8+M8+N8+O8+P8+Q8+R8+S8 -> 3000000000 | H8: 210000000 | I8: 195000000 | J8: 234000000 | K8: 240000000 | L8: 246000000 | M8: 255000000 | N8: 264000000 | O8: 261000000 | P8: 255000000 | Q8: 279000000 | R8: 276000000 | S8: 285000000
A9: 三级 | B9: 收入 | C9: AA.01.03 | D9: 其他营收 | G9: =H9+I9+J9+K9+L9+M9+N9+O9+P9+Q9+R9+S9 -> 5000000000 | H9: 350000000 | I9: 325000000 | J9: 390000000 | K9: 400000000 | L9: 410000000 | M9: 425000000 | N9: 440000000 | O9: 435000000 | P9: 425000000 | Q9: 465000000 | R9: 460000000 | S9: 475000000
A10: 二级 | B10: 支出 | C10: AA.02 | D10: 减:资产减值损失 | G10: =H10+I10+J10+K10+L10+M10+N10+O10+P10+Q10+R10+S10 -> 12000000000 | H10: =H11+H14 -> 840000000 | I10: =I11+I14 -> 780000000 | J10: =J11+J14 -> 936000000 | K10: =K11+K14 -> 960000000 | L10: =L11+L14 -> 984000000 | M10: =M11+M14 -> 1020000000 | N10: =N11+N14 -> 1056000000 | O10: =O11+O14 -> 1044000000 | ... S10: =S11+S14 -> 1140000000
A11: 三级 | B11: 支出 | C11: AA.02.01 | D11: 贷款减值损失 | G11: =H11+I11+J11+K11+L11+M11+N11+O11+P11+Q11+R11+S11 -> 11400000000 | H11: =H12+H13 -> 798000000 | I11: =I12+I13 -> 741000000 | J11: =J12+J13 -> 889200000 | K11: =K12+K13 -> 912000000 | L11: =L12+L13 -> 934800000 | M11: =M12+M13 -> 969000000 | N11: =N12+N13 -> 1003200000 | O11: =O12+O13 -> 991800000 | ... S11: =S12+S13 -> 1083000000
A12: 四级 | B12: 支出 | C12: AA.02.01.01 | D12: 实际风险成本 | G12: =H12+I12+J12+K12+L12+M12+N12+O12+P12+Q12+R12+S12 -> 10200000000 | H12: 714000000 | I12: 663000000 | J12: 795600000 | K12: 816000000 | L12: 836400000 | M12: 867000000 | N12: 897600000 | O12: 887400000 | P12: 867000000 | Q12: 948600000 | R12: 938400000 | S12: 969000000
A13: 四级 | B13: 支出 | C13: AA.02.01.02 | D13: 超额拨备 | G13: =H13+I13+J13+K13+L13+M13+N13+O13+P13+Q13+R13+S13 -> 1200000000 | H13: 84000000 | I13: 78000000 | J13: 93600000 | K13: 96000000 | L13: 98400000 | M13: 102000000 | N13: 105600000 | O13: 104400000 | P13: 102000000 | Q13: 111600000 | R13: 110400000 | S13: 114000000
A14: 三级 | B14: 支出 | C14: AA.02.02 | D14: 非贷减值损失 | G14: =H14+I14+J14+K14+L14+M14+N14+O14+P14+Q14+R14+S14 -> 600000000 | H14: 42000000 | I14: 39000000 | J14: 46800000 | K14: 48000000 | L14: 49200000 | M14: 51000000 | N14: 52800000 | O14: 52200000 | P14: 51000000 | Q14: 55800000 | R14: 55200000 | S14: 57000000
A15: 二级 | B15: 收入 | C15: AA.03 | D15: 净收入 | G15: =H15+I15+J15+K15+L15+M15+N15+O15+P15+Q15+R15+S15 -> 18362795784 | H15: 1299474485 | I15: 1228852768 | J15: 1439156363 | K15: 1477795087 | L15: 1514006635 | M15: 1565984415 | N15: 1615869383 | O15: 1592715545 | P15: 1558341374 | Q15: 1684783438 | R15: 1660648901 | S15: 1725167390
A16: 二级 | B16: 支出 | C16: AA.04 | D16: 减:税金及附加 | G16: =H16+I16+J16+K16+L16+M16+N16+O16+P16+Q16+R16+S16 -> 500000000 | H16: 35000000 | I16: 32500000 | J16: 39000000 | K16: 40000000 | L16: 41000000 | M16: 42500000 | N16: 44000000 | O16: 43500000 | P16: 42500000 | Q16: 46500000 | R16: 46000000 | S16: 47500000
A17: 二级 | B17: 支出 | C17: AA.05 | D17: 减:业务及管理费 | G17: =H17+I17+J17+K17+L17+M17+N17+O17+P17+Q17+R17+S17 -> 6000000000 | H17: =H18+H22+H25 -> 420000000 | I17: =I18+I22+I25 -> 390000000 | J17: =J18+J22+J25 -> 468000000 | K17: =K18+K22+K25 -> 480000000 | L17: =L18+L22+L25 -> 492000000 | M17: =M18+M22+M25 -> 510000000 | N17: =N18+N22+N25 -> 528000000 | O17: =O18+O22+O25 -> 522000000 | ... S17: =S18+S22+S25 -> 570000000
A18: 三级 | B18: 支出 | C18: AA.05.01 | D18: 人力费用 | G18: =H18+I18+J18+K18+L18+M18+N18+O18+P18+Q18+R18+S18 -> 3000000000 | H18: =H19+H20+H21 -> 210000000 | I18: =I19+I20+I21 -> 195000000 | J18: =J19+J20+J21 -> 234000000 | K18: =K19+K20+K21 -> 240000000 | L18: =L19+L20+L21 -> 246000000 | M18: =M19+M20+M21 -> 255000000 | N18: =N19+N20+N21 -> 264000000 | O18: =O19+O20+O21 -> 261000000 | ... S18: =S19+S20+S21 -> 285000000
A19: 四级 | B19: 支出 | C19: AA.05.01.01 | D19: 常规人力 | G19: =H19+I19+J19+K19+L19+M19+N19+O19+P19+Q19+R19+S19 -> 2100000000 | H19: 147000000 | I19: 136500000 | J19: 163800000 | K19: 168000000 | L19: 172200000 | M19: 178500000 | N19: 184800000 | O19: 182700000 | P19: 178500000 | Q19: 195300000 | R19: 193200000 | S19: 199500000
A20: 四级 | B20: 支出 | C20: AA.05.01.02 | D20: 利润分享 | G20: =H20+I20+J20+K20+L20+M20+N20+O20+P20+Q20+R20+S20 -> 600000000 | H20: 42000000 | I20: 39000000 | J20: 46800000 | K20: 48000000 | L20: 49200000 | M20: 51000000 | N20: 52800000 | O20: 52200000 | P20: 51000000 | Q20: 55800000 | R20: 55200000 | S20: 57000000
A21: 四级 | B21: 支出 | C21: AA.05.01.03 | D21: 专项费用 | G21: =H21+I21+J21+K21+L21+M21+N21+O21+P21+Q21+R21+S21 -> 300000000 | H21: 21000000 | I21: 19500000 | J21: 23400000 | K21: 24000000 | L21: 24600000 | M21: 25500000 | N21: 26400000 | O21: 26100000 | P21: 25500000 | Q21: 27900000 | R21: 27600000 | S21: 28500000
A22: 三级 | B22: 支出 | C22: AA.05.02 | D22: 业务费用 | G22: =H22+I22+J22+K22+L22+M22+N22+O22+P22+Q22+R22+S22 -> 1800000000 | H22: =H23+H24 -> 126000000 | I22: =I23+I24 -> 117000000 | J22: =J23+J24 -> 140400000 | K22: =K23+K24 -> 144000000 | L22: =L23+L24 -> 147600000 | M22: =M23+M24 -> 153000000 | N22: =N23+N24 -> 158400000 | O22: =O23+O24 -> 156600000 | ... S22: =S23+S24 -> 171000000
A23: 四级 | B23: 支出 | C23: AA.05.02.01 | D23: 营销费用 | G23: =H23+I23+J23+K23+L23+M23+N23+O23+P23+Q23+R23+S23 -> 1080000000 | H23: 75600000 | I23: 70200000 | J23: 84240000 | K23: 86400000 | L23: 88560000 | M23: 91800000 | N23: 95040000 | O23: 93960000 | P23: 91800000 | Q23: 100440000 | R23: 99360000 | S23: 102600000
A24: 四级 | B24: 支出 | C24: AA.05.02.02 | D24: 运营费用 | G24: =H24+I24+J24+K24+L24+M24+N24+O24+P24+Q24+R24+S24 -> 720000000 | H24: 50400000 | I24: 46800000 | J24: 56160000 | K24: 57600000 | L24: 59040000 | M24: 61200000 | N24: 63360000 | O24: 62640000 | P24: 61200000 | Q24: 66960000 | R24: 66240000 | S24: 68400000
A25: 三级 | B25: 支出 | C25: AA.05.03 | D25: 日常费用 | G25: =H25+I25+J25+K25+L25+M25+N25+O25+P25+Q25+R25+S25 -> 1200000000 | H25: 84000000 | I25: 78000000 | J25: 93600000 | K25: 96000000 | L25: 98400000 | M25: 102000000 | N25: 105600000 | O25: 104400000 | P25: 102000000 | Q25: 111600000 | R25: 110400000 | S25: 114000000
A26: 二级 | B26: 收入 | C26: AA.06 | D26: 加:营业外净收入 | G26: =H26+I26+J26+K26+L26+M26+N26+O26+P26+Q26+R26+S26 -> 200000000 | H26: 14000000 | I26: 13000000 | J26: 15600000 | K26: 16000000 | L26: 16400000 | M26: 17000000 | N26: 17600000 | O26: 17400000 | P26: 17000000 | Q26: 18600000 | R26: 18400000 | S26: 19000000
A27: 二级 | B27: 利润 | C27: AA.09 | D27: 税前利润 | G27: =H27+I27+J27+K27+L27+M27+N27+O27+P27+Q27+R27+S27 -> 18362795784 | H27: 1299474485 | I27: 1228852768 | J27: 1439156363 | K27: 1477795087 | L27: 1514006635 | M27: 1565984415 | N27: 1615869383 | O27: 1592715545 | P27: 1558341374 | Q27: 1684783438 | R27: 1660648901 | S27: 1725167390
A28: 二级 | B28: 支出 | C28: AA.30 | D28: 减:所得税 | G28: =H28+I28+J28+K28+L28+M28+N28+O28+P28+Q28+R28+S28 -> 4920000000 | H28: 344400000 | I28: 319800000 | J28: 383760000 | K28: 393600000 | L28: 403440000 | M28: 418200000 | N28: 432960000 | O28: 428040000 | P28: 418200000 | Q28: 457560000 | R28: 452640000 | S28: 467400000
A29: 二级 | B29: 利润 | C29: AA.31 | D29: 净利润 | G29: =H29+I29+J29+K29+L29+M29+N29+O29+P29+Q29+R29+S29 -> 18362795784 | H29: 1299474485 | I29: 1228852768 | J29: 1439156363 | K29: 1477795087 | L29: 1514006635 | M29: 1565984415 | N29: 1615869383 | O29: 1592715545 | P29: 1558341374 | Q29: 1684783438 | R29: 1660648901 | S29: 1725167390
A30: 二级 | B30: 资产余额 | C30: AA.10 | D30: 管理贷款余额 | G30: =H30+I30+J30+K30+L30+M30+N30+O30+P30+Q30+R30+S30 -> 350000000000 | H30: =H31+H34+H35+H36 -> 26250000000 | I30: =I31+I34+I35+I36 -> 27300000000 | J30: =J31+J34+J35+J36 -> 28700000000 | K30: =K31+K34+K35+K36 -> 29050000000 | L30: =L31+L34+L35+L36 -> 29750000000 | M30: =M31+M34+M35+M36 -> 30450000000 | N30: =N31+N34+N35+N36 -> 30800000000 | O30: =O31+O34+O35+O36 -> 30100000000 | ... S30: =S31+S34+S35+S36 -> 30450000000
A31: 三级 | B31: 资产余额 | C31: AA.10.01 | D31: 自持余额 | G31: =H31+I31+J31+K31+L31+M31+N31+O31+P31+Q31+R31+S31 -> 245000000000 | H31: =H32+H33 -> 18375000000 | I31: =I32+I33 -> 19110000000 | J31: =J32+J33 -> 20090000000 | K31: =K32+K33 -> 20335000000 | L31: =L32+L33 -> 20825000000 | M31: =M32+M33 -> 21315000000 | N31: =N32+N33 -> 21560000000 | O31: =O32+O33 -> 21070000000 | ... S31: =S32+S33 -> 21315000000
A32: 四级 | B32: 资产余额 | C32: AA.10.01.01 | D32: 一般贷款 | G32: =H32+I32+J32+K32+L32+M32+N32+O32+P32+Q32+R32+S32 -> 210000000000 | H32: 15750000000 | I32: 16380000000 | J32: 17220000000 | K32: 17430000000 | L32: 17850000000 | M32: 18270000000 | N32: 18480000000 | O32: 18060000000 | P32: 17640000000 | Q32: 17430000000 | R32: 17220000000 | S32: 18270000000
A33: 四级 | B33: 资产余额 | C33: AA.10.01.02 | D33: 票据融资 | G33: =H33+I33+J33+K33+L33+M33+N33+O33+P33+Q33+R33+S33 -> 35000000000 | H33: 2625000000 | I33: 2730000000 | J33: 2870000000 | K33: 2905000000 | L33: 2975000000 | M33: 3045000000 | N33: 3080000000 | O33: 3010000000 | P33: 2940000000 | Q33: 2905000000 | R33: 2870000000 | S33: 3045000000
A34: 三级 | B34: 资产余额 | C34: AA.10.02 | D34: 联贷 | G34: =H34+I34+J34+K34+L34+M34+N34+O34+P34+Q34+R34+S34 -> 63000000000 | H34: 4725000000 | I34: 4914000000 | J34: 5166000000 | K34: 5229000000 | L34: 5355000000 | M34: 5481000000 | N34: 5544000000 | O34: 5418000000 | P34: 5292000000 | Q34: 5229000000 | R34: 5166000000 | S34: 5481000000
A35: 三级 | B35: 资产余额 | C35: AA.10.03 | D35: 流转 | G35: =H35+I35+J35+K35+L35+M35+N35+O35+P35+Q35+R35+S35 -> 28000000000 | H35: 2100000000 | I35: 2184000000 | J35: 2296000000 | K35: 2324000000 | L35: 2380000000 | M35: 2436000000 | N35: 2464000000 | O35: 2408000000 | P35: 2352000000 | Q35: 2324000000 | R35: 2296000000 | S35: 2436000000
A36: 三级 | B36: 资产余额 | C36: AA.10.04 | D36: 银承保函 | G36: =H36+I36+J36+K36+L36+M36+N36+O36+P36+Q36+R36+S36 -> 14000000000 | H36: 1050000000 | I36: 1092000000 | J36: 1148000000 | K36: 1162000000 | L36: 1190000000 | M36: 1218000000 | N36: 1232000000 | O36: 1204000000 | P36: 1176000000 | Q36: 1162000000 | R36: 1148000000 | S36: 1218000000
A37: 二级 | B37: 负债余额 | C37: AA.12 | D37: 管理资产余额 | G37: =H37+I37+J37+K37+L37+M37+N37+O37+P37+Q37+R37+S37 -> 500000000000 | H37: =H38+H39+H40+H41 -> 37500000000 | I37: =I38+I39+I40+I41 -> 39000000000 | J37: =J38+J39+J40+J41 -> 41000000000 | K37: =K38+K39+K40+K41 -> 41500000000 | L37: =L38+L39+L40+L41 -> 42500000000 | M37: =M38+M39+M40+M41 -> 43500000000 | N37: =N38+N39+N40+N41 -> 44000000000 | O37: =O38+O39+O40+O41 -> 43000000000 | ... S37: =S38+S39+S40+S41 -> 43500000000
A38: 三级 | B38: 负债余额 | C38: AA.12.01 | D38: 各项存款 | G38: =H38+I38+J38+K38+L38+M38+N38+O38+P38+Q38+R38+S38 -> 450000000000 | H38: 33750000000 | I38: 35100000000 | J38: 36900000000 | K38: 37350000000 | L38: 38250000000 | M38: 39150000000 | N38: 39600000000 | O38: 38700000000 | P38: 37800000000 | Q38: 37350000000 | R38: 36900000000 | S38: 39150000000
A39: 三级 | B39: 负债余额 | C39: AA.12.02 | D39: 代销理财 | G39: =H39+I39+J39+K39+L39+M39+N39+O39+P39+Q39+R39+S39 -> 30000000000 | H39: 2250000000 | I39: 2340000000 | J39: 2460000000 | K39: 2490000000 | L39: 2550000000 | M39: 2610000000 | N39: 2640000000 | O39: 2580000000 | P39: 2520000000 | Q39: 2490000000 | R39: 2460000000 | S39: 2610000000
A40: 三级 | B40: 负债余额 | C40: AA.12.03 | D40: 商户结算便利应付款 | G40: =H40+I40+J40+K40+L40+M40+N40+O40+P40+Q40+R40+S40 -> 10000000000 | H40: 750000000 | I40: 780000000 | J40: 820000000 | K40: 830000000 | L40: 850000000 | M40: 870000000 | N40: 880000000 | O40: 860000000 | P40: 840000000 | Q40: 830000000 | R40: 820000000 | S40: 870000000
...

Sheet AA微众银行业务支出评估
A1: 科目层级 | B1: 科目性质 | C1: 科目代码 | D1: 科目名称 | E1: 25年实际 | F1: 26年预算 | G1: 26年预测 | H1: 26年1月实际 | I1: 26年2月实际 | J1: 26年3月实际 | K1: 26年4月预测 | L1: 26年5月预测 | M1: 26年6月预测 | N1: 26年7月预测 | O1: 26年8月预测 | P1: 26年9月预测 | Q1: 26年10月预测 | R1: 26年11月预测 | S1: 26年12月预测
A2: 一级 | B2: 其他 | C2: AA.91 | D2: 业务支出评估 | G2: =H2+I2+J2+K2+L2+M2+N2+O2+P2+Q2+R2+S2 -> 26709858 | H2: =H3 -> 1801800 | I2: =I3 -> 2007600 | J2: =J3 -> 2100000 | K2: =K3 -> 2146200 | L2: =L3 -> 2200800 | M2: =M3 -> 2274300 | N2: =N3 -> 2341500 | O2: =O3 -> 2307900 | ... S2: =S3 -> 2478000
A3: 二级 | B3: 其他 | C3: AA.91.01 | D3: 客户经营指标 | G3: =H3+I3+J3+K3+L3+M3+N3+O3+P3+Q3+R3+S3 -> 26709858 | H3: =H4+H9+H24 -> 1801800 | I3: =I4+I9+I24 -> 2007600 | J3: =J4+J9+J24 -> 2100000 | K3: =K4+K9+K24 -> 2146200 | L3: =L4+L9+L24 -> 2200800 | M3: =M4+M9+M24 -> 2274300 | N3: =N4+N9+N24 -> 2341500 | O3: =O4+O9+O24 -> 2307900 | ... S3: =S4+S9+S24 -> 2478000
A4: 三级 | B4: 其他 | C4: AA.91.01.01 | D4: 客户营销与投入 | G4: =H4+I4+J4+K4+L4+M4+N4+O4+P4+Q4+R4+S4 -> 5087592 | H4: =H5+H6+H7+H8 -> 343200 | I4: =I5+I6+I7+I8 -> 382400 | J4: =J5+J6+J7+J8 -> 400000 | K4: =K5+K6+K7+K8 -> 408800 | L4: =L5+L6+L7+L8 -> 419200 | M4: =M5+M6+M7+M8 -> 433200 | N4: =N5+N6+N7+N8 -> 446000 | O4: =O5+O6+O7+O8 -> 439600 | ... S4: =S5+S6+S7+S8 -> 472000
A5: 四级 | B5: 其他 | C5: AA.91.01.01.001 | D5: 新客营销支出 | G5: =H5+I5+J5+K5+L5+M5+N5+O5+P5+Q5+R5+S5 -> 1271898 | H5: 85800 | I5: 95600 | J5: 100000 | K5: 102200 | L5: 104800 | M5: 108300 | N5: 111500 | O5: 109900 | P5: 107400 | Q5: 114799 | R5: 113599 | S5: 118000
A6: 四级 | B6: 其他 | C6: AA.91.01.01.002 | D6: 存客营销支出 | G6: =H6+I6+J6+K6+L6+M6+N6+O6+P6+Q6+R6+S6 -> 1271898 | H6: 85800 | I6: 95600 | J6: 100000 | K6: 102200 | L6: 104800 | M6: 108300 | N6: 111500 | O6: 109900 | P6: 107400 | Q6: 114799 | R6: 113599 | S6: 118000
A7: 四级 | B7: 其他 | C7: AA.91.01.01.003 | D7: 新开通客户投入 | G7: =H7+I7+J7+K7+L7+M7+N7+O7+P7+Q7+R7+S7 -> 1271898 | H7: 85800 | I7: 95600 | J7: 100000 | K7: 102200 | L7: 104800 | M7: 108300 | N7: 111500 | O7: 109900 | P7: 107400 | Q7: 114799 | R7: 113599 | S7: 118000
A8: 四级 | B8: 其他 | C8: AA.91.01.01.004 | D8: 新发放投入 | G8: =H8+I8+J8+K8+L8+M8+N8+O8+P8+Q8+R8+S8 -> 1271898 | H8: 85800 | I8: 95600 | J8: 100000 | K8: 102200 | L8: 104800 | M8: 108300 | N8: 111500 | O8: 109900 | P8: 107400 | Q8: 114799 | R8: 113599 | S8: 118000
A9: 三级 | B9: 其他 | C9: AA.91.01.02 | D9: 客户规模与数量 | G9: =H9+I9+J9+K9+L9+M9+N9+O9+P9+Q9+R9+S9 -> 17806572 | H9: =H10+H11+H12+H13+H14+H15+H16+H17+H18+H19+H20+H21+H22+H23 -> 1201200 | I9: =I10+I11+I12+I13+I14+I15+I16+I17+I18+I19+I20+I21+I22+I23 -> 1338400 | J9: =J10+J11+J12+J13+J14+J15+J16+J17+J18+J19+J20+J21+J22+J23 -> 1400000 | K9: =K10+K11+K12+K13+K14+K15+K16+K17+K18+K19+K20+K21+K22+K23 -> 1430800 | L9: =L10+L11+L12+L13+L14+L15+L16+L17+L18+L19+L20+L21+L22+L23 -> 1467200 | M9: =M10+M11+M12+M13+M14+M15+M16+M17+M18+M19+M20+M21+M22+M23 -> 1516200 | N9: =N10+N11+N12+N13+N14+N15+N16+N17+N18+N19+N20+N21+N22+N23 -> 1561000 | O9: =O10+O11+O12+O13+O14+O15+O16+O17+O18+O19+O20+O21+O22+O23 -> 1538600 | ... S9: =S10+S11+S12+S13+S14+S15+S16+S17+S18+S19+S20+S21+S22+S23 -> 1652000
A10: 四级 | B10: 其他 | C10: AA.91.01.02.101 | D10: LUM规模 | G10: =H10+I10+J10+K10+L10+M10+N10+O10+P10+Q10+R10+S10 -> 1271898 | H10: 85800 | I10: 95600 | J10: 100000 | K10: 102200 | L10: 104800 | M10: 108300 | N10: 111500 | O10: 109900 | P10: 107400 | Q10: 114799 | R10: 113599 | S10: 118000
A11: 四级 | B11: 其他 | C11: AA.91.01.02.001 | D11: 新客日均LUM | G11: =H11+I11+J11+K11+L11+M11+N11+O11+P11+Q11+R11+S11 -> 1271898 | H11: 85800 | I11: 95600 | J11: 100000 | K11: 102200 | L11: 104800 | M11: 108300 | N11: 111500 | O11: 109900 | P11: 107400 | Q11: 114799 | R11: 113599 | S11: 118000
A12: 四级 | B12: 其他 | C12: AA.91.01.02.002 | D12: 存客日均LUM | G12: =H12+I12+J12+K12+L12+M12+N12+O12+P12+Q12+R12+S12 -> 1271898 | H12: 85800 | I12: 95600 | J12: 100000 | K12: 102200 | L12: 104800 | M12: 108300 | N12: 111500 | O12: 109900 | P12: 107400 | Q12: 114799 | R12: 113599 | S12: 118000
A13: 四级 | B13: 其他 | C13: AA.91.01.02.005 | D13: 新发放LUM | G13: =H13+I13+J13+K13+L13+M13+N13+O13+P13+Q13+R13+S13 -> 1271898 | H13: 85800 | I13: 95600 | J13: 100000 | K13: 102200 | L13: 104800 | M13: 108300 | N13: 111500 | O13: 109900 | P13: 107400 | Q13: 114799 | R13: 113599 | S13: 118000
A14: 四级 | B14: 其他 | C14: AA.91.01.02.006 | D14: 新发放LUM(标服) | G14: =H14+I14+J14+K14+L14+M14+N14+O14+P14+Q14+R14+S14 -> 1271898 | H14: 85800 | I14: 95600 | J14: 100000 | K14: 102200 | L14: 104800 | M14: 108300 | N14: 111500 | O14: 109900 | P14: 107400 | Q14: 114799 | R14: 113599 | S14: 118000
A15: 四级 | B15: 其他 | C15: AA.91.01.02.010 | D15: 日均LUM | G15: =H15+I15+J15+K15+L15+M15+N15+O15+P15+Q15+R15+S15 -> 1271898 | H15: 85800 | I15: 95600 | J15: 100000 | K15: 102200 | L15: 104800 | M15: 108300 | N15: 111500 | O15: 109900 | P15: 107400 | Q15: 114799 | R15: 113599 | S15: 118000
A16: 四级 | B16: 其他 | C16: AA.91.01.02.102 | D16: AuM规模 | G16: =H16+I16+J16+K16+L16+M16+N16+O16+P16+Q16+R16+S16 -> 1271898 | H16: 85800 | I16: 95600 | J16: 100000 | K16: 102200 | L16: 104800 | M16: 108300 | N16: 111500 | O16: 109900 | P16: 107400 | Q16: 114799 | R16: 113599 | S16: 118000
A17: 四级 | B17: 其他 | C17: AA.91.01.02.007 | D17: 存客日均AuM | G17: =H17+I17+J17+K17+L17+M17+N17+O17+P17+Q17+R17+S17 -> 1271898 | H17: 85800 | I17: 95600 | J17: 100000 | K17: 102200 | L17: 104800 | M17: 108300 | N17: 111500 | O17: 109900 | P17: 107400 | Q17: 114799 | R17: 113599 | S17: 118000
A18: 四级 | B18: 其他 | C18: AA.91.01.02.008 | D18: 新客AuM余额 | G18: =H18+I18+J18+K18+L18+M18+N18+O18+P18+Q18+R18+S18 -> 1271898 | H18: 85800 | I18: 95600 | J18: 100000 | K18: 102200 | L18: 104800 | M18: 108300 | N18: 111500 | O18: 109900 | P18: 107400 | Q18: 114799 | R18: 113599 | S18: 118000
A19: 四级 | B19: 其他 | C19: AA.91.01.02.011 | D19: 日均AuM | G19: =H19+I19+J19+K19+L19+M19+N19+O19+P19+Q19+R19+S19 -> 1271898 | H19: 85800 | I19: 95600 | J19: 100000 | K19: 102200 | L19: 104800 | M19: 108300 | N19: 111500 | O19: 109900 | P19: 107400 | Q19: 114799 | R19: 113599 | S19: 118000
A20: 四级 | B20: 其他 | C20: AA.91.01.02.103 | D20: 客户数量 | G20: =H20+I20+J20+K20+L20+M20+N20+O20+P20+Q20+R20+S20 -> 1271898 | H20: 85800 | I20: 95600 | J20: 100000 | K20: 102200 | L20: 104800 | M20: 108300 | N20: 111500 | O20: 109900 | P20: 107400 | Q20: 114799 | R20: 113599 | S20: 118000
A21: 四级 | B21: 其他 | C21: AA.91.01.02.003 | D21: 新开通客户数 | G21: =H21+I21+J21+K21+L21+M21+N21+O21+P21+Q21+R21+S21 -> 1271898 | H21: 85800 | I21: 95600 | J21: 100000 | K21: 102200 | L21: 104800 | M21: 108300 | N21: 111500 | O21: 109900 | P21: 107400 | Q21: 114799 | R21: 113599 | S21: 118000
... A23: 四级 | B23: 其他 | C23: AA.91.01.02.009 | D23: MFAU客户数 | G23: =H23+I23+J23+K23+L23+M23+N23+O23+P23+Q23+R23+S23 -> 1271898 | H23: 85800 | I23: 95600 | J23: 100000 | K23: 102200 | L23: 104800 | M23: 108300 | N23: 111500 | O23: 109900 | P23: 107400 | Q23: 114799 | R23: 113599 | S23: 118000
A24: 三级 | B24: 其他 | C24: AA.91.01.03 | D24: 客户回收与催收 | G24: =H24+I24+J24+K24+L24+M24+N24+O24+P24+Q24+R24+S24 -> 3815694 | H24: =H25+H26+H27 -> 257400 | I24: =I25+I26+I27 -> 286800 | J24: =J25+J26+J27 -> 300000 | K24: =K25+K26+K27 -> 306600 | L24: =L25+L26+L27 -> 314400 | M24: =M25+M26+M27 -> 324900 | N24: =N25+N26+N27 -> 334500 | O24: =O25+O26+O27 -> 329700 | ... S24: =S25+S26+S27 -> 354000
A25: 四级 | B25: 其他 | C25: AA.91.01.03.001 | D25: 内催回收额 | G25: =H25+I25+J25+K25+L25+M25+N25+O25+P25+Q25+R25+S25 -> 1271898 | H25: 85800 | I25: 95600 | J25: 100000 | K25: 102200 | L25: 104800 | M25: 108300 | N25: 111500 | O25: 109900 | P25: 107400 | Q25: 114799 | R25: 113599 | S25: 118000
A26: 四级 | B26: 其他 | C26: AA.91.01.03.002 | D26: M6-压降金额 | G26: =H26+I26+J26+K26+L26+M26+N26+O26+P26+Q26+R26+S26 -> 1271898 | H26: 85800 | I26: 95600 | J26: 100000 | K26: 102200 | L26: 104800 | M26: 108300 | N26: 111500 | O26: 109900 | P26: 107400 | Q26: 114799 | R26: 113599 | S26: 118000
A27: 四级 | B27: 其他 | C27: AA.91.01.03.003 | D27: M7+现金回收额 | G27: =H27+I27+J27+K27+L27+M27+N27+O27+P27+Q27+R27+S27 -> 1271898 | H27: 85800 | I27: 95600 | J27: 100000 | K27: 102200 | L27: 104800 | M27: 108300 | N27: 111500 | O27: 109900 | P27: 107400 | Q27: 114799 | R27: 113599 | S27: 118000

Sheet AA微众银行损益表
A1: 科目层级 | B1: 科目性质 | C1: 科目代码 | D1: 科目名称 | E1: 25年实际 | F1: 26年预算 | G1: 26年预测 | H1: 26年1月实际 | I1: 26年2月实际 | J1: 26年3月实际 | K1: 26年4月预测 | L1: 26年5月预测 | M1: 26年6月预测 | N1: 26年7月预测 | O1: 26年8月预测 | P1: 26年9月预测 | Q1: 26年10月预测 | R1: 26年11月预测 | S1: 26年12月预测
A2: 一级 | B2: 其他 | C2: AA.46 | D2: 营业收入 | G2: =H2+I2+J2+K2+L2+M2+N2+O2+P2+Q2+R2+S2 -> 3.51 | H2: 0.25 | I2: 0.23 | J2: 0.27 | K2: 0.28 | L2: 0.29 | M2: 0.3 | N2: 0.31 | O2: 0.3 | P2: 0.3 | Q2: 0.33 | R2: 0.32 | S2: 0.33
A3: 一级 | B3: 资产余额 | C3: AA.47 | D3: 减:资产减值损失 | G3: =H3+I3+J3+K3+L3+M3+N3+O3+P3+Q3+R3+S3 -> 2450000000 | H3: =H4+H6 -> 171500000 | I3: =I4+I6 -> 159250000 | J3: =J4+J6 -> 191100000 | K3: =K4+K6 -> 196000000 | L3: =L4+L6 -> 200900000 | M3: =M4+M6 -> 208250000 | N3: =N4+N6 -> 215600000 | O3: =O4+O6 -> 213150000 | ... S3: =S4+S6 -> 232750000
A4: 二级 | B4: 资产余额 | C4: AA.47.01 | D4: 贷款减值损失 | G4: =H4+I4+J4+K4+L4+M4+N4+O4+P4+Q4+R4+S4 -> 1750000000 | H4: =H5 -> 122500000 | I4: =I5 -> 113750000 | J4: =J5 -> 136500000 | K4: =K5 -> 140000000 | L4: =L5 -> 143500000 | M4: =M5 -> 148750000 | N4: =N5 -> 154000000 | O4: =O5 -> 152250000 | ... S4: =S5 -> 166250000
A5: 三级 | B5: 资产余额 | C5: AA.47.01.01 | D5: 实际风险成本 | G5: =H5+I5+J5+K5+L5+M5+N5+O5+P5+Q5+R5+S5 -> 1750000000 | H5: 122500000 | I5: 113750000 | J5: 136500000 | K5: 140000000 | L5: 143500000 | M5: 148750000 | N5: 154000000 | O5: 152250000 | P5: 148750000 | Q5: 162750000 | R5: 161000000 | S5: 166250000
A6: 二级 | B6: 资产余额 | C6: AA.47.02 | D6: 非贷减值损失 | G6: =H6+I6+J6+K6+L6+M6+N6+O6+P6+Q6+R6+S6 -> 700000000 | H6: 49000000 | I6: 45500000 | J6: 54600000 | K6: 56000000 | L6: 57400000 | M6: 59500000 | N6: 61600000 | O6: 60900000 | P6: 59500000 | Q6: 65100000 | R6: 64400000 | S6: 66500000

Sheet AA微众银行资产质量表
A1: 科目层级 | B1: 科目性质 | C1: 科目代码 | D1: 科目名称 | E1: 25年实际 | F1: 26年预算 | G1: 26年预测 | H1: 26年1月实际 | I1: 26年2月实际 | J1: 26年3月实际 | K1: 26年4月预测 | L1: 26年5月预测 | M1: 26年6月预测 | N1: 26年7月预测 | O1: 26年8月预测 | P1: 26年9月预测 | Q1: 26年10月预测 | R1: 26年11月预测 | S1: 26年12月预测
A2: 二级 | B2: 其他 | C2: AA.38 | D2: 风险成本率 | G2: =H2+I2+J2+K2+L2+M2+N2+O2+P2+Q2+R2+S2 -> 39565565196 | H2: =H3+H6+H7+H8+H9 -> 2967417390 | I2: =I3+I6+I7+I8+I9 -> 3097408692 | J2: =J3+J6+J7+J8+J9 -> 3247200000 | K2: =K3+K6+K7+K8+K9 -> 3267000000 | L2: =L3+L6+L7+L8+L9 -> 3377191302 | M2: =M3+M6+M7+M8+M9 -> 3416791302 | N2: =N3+N6+N7+N8+N9 -> 3507182604 | O2: =O3+O6+O7+O8+O9 -> 3396991302 | ... S2: =S3+S6+S7+S8+S9 -> 3416791302
A3: 三级 | B3: 其他 | C3: AA.38.01 | D3: 泛微粒贷 | G3: =H3+I3+J3+K3+L3+M3+N3+O3+P3+Q3+R3+S3 -> 2397913036 | H3: =H4+H5 -> 179843478 | I3: =I4+I5 -> 187721738 | J3: =J4+J5 -> 196800000 | K3: =K4+K5 -> 198000000 | L3: =L4+L5 -> 204678260 | M3: =M4+M5 -> 207078260 | N3: =N4+N5 -> 212556520 | O3: =O4+O5 -> 205878260 | ... S3: =S4+S5 -> 207078260
A4: 四级 | B4: 其他 | C4: AA.38.01.01 | D4: 微粒贷 | G4: =H4+I4+J4+K4+L4+M4+N4+O4+P4+Q4+R4+S4 -> 1198956518 | H4: 89921739 | I4: 93860869 | J4: 98400000 | K4: 99000000 | L4: 102339130 | M4: 103539130 | N4: 106278260 | O4: 102939130 | P4: 101739130 | Q4: 99000000 | R4: 98400000 | S4: 103539130
A5: 四级 | B5: 其他 | C5: AA.38.01.02 | D5: 分付 | G5: =H5+I5+J5+K5+L5+M5+N5+O5+P5+Q5+R5+S5 -> 1198956518 | H5: 89921739 | I5: 93860869 | J5: 98400000 | K5: 99000000 | L5: 102339130 | M5: 103539130 | N5: 106278260 | O5: 102939130 | P5: 101739130 | Q5: 99000000 | R5: 98400000 | S5: 103539130
A6: 三级 | B6: 其他 | C6: AA.38.02 | D6: 汽车金融 | G6: =H6+I6+J6+K6+L6+M6+N6+O6+P6+Q6+R6+S6 -> 11989565214 | H6: 899217391 | I6: 938608695 | J6: 984000000 | K6: 990000000 | L6: 1023391304 | M6: 1035391304 | N6: 1062782608 | O6: 1029391304 | P6: 1017391304 | Q6: 990000000 | R6: 984000000 | S6: 1035391304
A7: 三级 | B7: 其他 | C7: AA.38.03 | D7: 财富 | G7: =H7+I7+J7+K7+L7+M7+N7+O7+P7+Q7+R7+S7 -> 11989565214 | H7: 899217391 | I7: 938608695 | J7: 984000000 | K7: 990000000 | L7: 1023391304 | M7: 1035391304 | N7: 1062782608 | O7: 1029391304 | P7: 1017391304 | Q7: 990000000 | R7: 984000000 | S7: 1035391304
A8: 三级 | B8: 其他 | C8: AA.38.04 | D8: 小鹅 | G8: =H8+I8+J8+K8+L8+M8+N8+O8+P8+Q8+R8+S8 -> 11989565214 | H8: 899217391 | I8: 938608695 | J8: 984000000 | K8: 990000000 | L8: 1023391304 | M8: 1035391304 | N8: 1062782608 | O8: 1029391304 | P8: 1017391304 | Q8: 990000000 | R8: 984000000 | S8: 1035391304
A9: 三级 | B9: 其他 | C9: AA.38.05 | D9: 企业金融 | G9: =H9+I9+J9+K9+L9+M9+N9+O9+P9+Q9+R9+S9 -> 1198956518 | H9: =H10 -> 89921739 | I9: =I10 -> 93860869 | J9: =J10 -> 98400000 | K9: =K10 -> 99000000 | L9: =L10 -> 102339130 | M9: =M10 -> 103539130 | N9: =N10 -> 106278260 | O9: =O10 -> 102939130 | ... S9: =S10 -> 103539130
A10: 四级 | B10: 其他 | C10: AA.38.05.01 | D10: 一般贷款 | G10: =H10+I10+J10+K10+L10+M10+N10+O10+P10+Q10+R10+S10 -> 1198956518 | H10: 89921739 | I10: 93860869 | J10: 98400000 | K10: 99000000 | L10: 102339130 | M10: 103539130 | N10: 106278260 | O10: 102939130 | P10: 101739130 | Q10: 99000000 | R10: 98400000 | S10: 103539130
A11: 二级 | B11: 支出 | C11: AA.02 | D11: 风险成本 | G11: =H11+I11+J11+K11+L11+M11+N11+O11+P11+Q11+R11+S11 -> 12000000000 | H11: 900000000 | I11: 936000000 | J11: 984000000 | K11: 996000000 | L11: 1020000000 | M11: 1044000000 | N11: 1056000000 | O11: 1032000000 | P11: 1008000000 | Q11: 996000000 | R11: 984000000 | S11: 1044000000
A12: 二级 | B12: 其他 | C12: AA.39 | D12: 不良贷款率 | G12: =H12+I12+J12+K12+L12+M12+N12+O12+P12+Q12+R12+S12 -> 39565565196 | H12: =H13+H16+H17+H18+H19 -> 2967417390 | I12: =I13+I16+I17+I18+I19 -> 3097408692 | J12: =J13+J16+J17+J18+J19 -> 3247200000 | K12: =K13+K16+K17+K18+K19 -> 3267000000 | L12: =L13+L16+L17+L18+L19 -> 3377191302 | M12: =M13+M16+M17+M18+M19 -> 3416791302 | N12: =N13+N16+N17+N18+N19 -> 3507182604 | O12: =O13+O16+O17+O18+O19 -> 3396991302 | ... S12: =S13+S16+S17+S18+S19 -> 3416791302
A13: 三级 | B13: 其他 | C13: AA.39.01 | D13: 泛微粒贷 | G13: =H13+I13+J13+K13+L13+M13+N13+O13+P13+Q13+R13+S13 -> 2397913036 | H13: =H14+H15 -> 179843478 | I13: =I14+I15 -> 187721738 | J13: =J14+J15 -> 196800000 | K13: =K14+K15 -> 198000000 | L13: =L14+L15 -> 204678260 | M13: =M14+M15 -> 207078260 | N13: =N14+N15 -> 212556520 | O13: =O14+O15 -> 205878260 | ... S13: =S14+S15 -> 207078260
A14: 四级 | B14: 其他 | C14: AA.39.01.01 | D14: 微粒贷 | G14: =H14+I14+J14+K14+L14+M14+N14+O14+P14+Q14+R14+S14 -> 1198956518 | H14: 89921739 | I14: 93860869 | J14: 98400000 | K14: 99000000 | L14: 102339130 | M14: 103539130 | N14: 106278260 | O14: 102939130 | P14: 101739130 | Q14: 99000000 | R14: 98400000 | S14: 103539130
A15: 四级 | B15: 其他 | C15: AA.39.01.02 | D15: 分付 | G15: =H15+I15+J15+K15+L15+M15+N15+O15+P15+Q15+R15+S15 -> 1198956518 | H15: 89921739 | I15: 93860869 | J15: 98400000 | K15: 99000000 | L15: 102339130 | M15: 103539130 | N15: 106278260 | O15: 102939130 | P15: 101739130 | Q15: 99000000 | R15: 98400000 | S15: 103539130
A16: 三级 | B16: 其他 | C16: AA.39.02 | D16: 汽车金融 | G16: =H16+I16+J16+K16+L16+M16+N16+O16+P16+Q16+R16+S16 -> 11989565214 | H16: 899217391 | I16: 938608695 | J16: 984000000 | K16: 990000000 | L16: 1023391304 | M16: 1035391304 | N16: 1062782608 | O16: 1029391304 | P16: 1017391304 | Q16: 990000000 | R16: 984000000 | S16: 1035391304
A17: 三级 | B17: 其他 | C17: AA.39.03 | D17: 财富 | G17: =H17+I17+J17+K17+L17+M17+N17+O17+P17+Q17+R17+S17 -> 11989565214 | H17: 899217391 | I17: 938608695 | J17: 984000000 | K17: 990000000 | L17: 1023391304 | M17: 1035391304 | N17: 1062782608 | O17: 1029391304 | P17: 1017391304 | Q17: 990000000 | R17: 984000000 | S17: 1035391304
A18: 三级 | B18: 其他 | C18: AA.39.04 | D18: 小鹅 | G18: =H18+I18+J18+K18+L18+M18+N18+O18+P18+Q18+R18+S18 -> 11989565214 | H18: 899217391 | I18: 938608695 | J18: 984000000 | K18: 990000000 | L18: 1023391304 | M18: 1035391304 | N18: 1062782608 | O18: 1029391304 | P18: 1017391304 | Q18: 990000000 | R18: 984000000 | S18: 1035391304
A19: 三级 | B19: 其他 | C19: AA.39.05 | D19: 企业金融 | G19: =H19+I19+J19+K19+L19+M19+N19+O19+P19+Q19+R19+S19 -> 1198956518 | H19: =H20 -> 89921739 | I19: =I20 -> 93860869 | J19: =J20 -> 98400000 | K19: =K20 -> 99000000 | L19: =L20 -> 102339130 | M19: =M20 -> 103539130 | N19: =N20 -> 106278260 | O19: =O20 -> 102939130 | ... S19: =S20 -> 103539130
A20: 四级 | B20: 其他 | C20: AA.39.05.01 | D20: 一般贷款 | G20: =H20+I20+J20+K20+L20+M20+N20+O20+P20+Q20+R20+S20 -> 1198956518 | H20: 89921739 | I20: 93860869 | J20: 98400000 | K20: 99000000 | L20: 102339130 | M20: 103539130 | N20: 106278260 | O20: 102939130 | P20: 101739130 | Q20: 99000000 | R20: 98400000 | S20: 103539130
A21: 二级 | B21: 资产余额 | C21: AA.40 | D21: 不良贷款余额 | G21: =H21+I21+J21+K21+L21+M21+N21+O21+P21+Q21+R21+S21 -> 39565565196 | H21: =H22+H25+H26+H27+H28 -> 2967417390 | I21: =I22+I25+I26+I27+I28 -> 3097408692 | J21: =J22+J25+J26+J27+J28 -> 3247200000 | K21: =K22+K25+K26+K27+K28 -> 3267000000 | L21: =L22+L25+L26+L27+L28 -> 3377191302 | M21: =M22+M25+M26+M27+M28 -> 3416791302 | N21: =N22+N25+N26+N27+N28 -> 3507182604 | O21: =O22+O25+O26+O27+O28 -> 3396991302 | ... S21: =S22+S25+S26+S27+S28 -> 3416791302
A22: 三级 | B22: 资产余额 | C22: AA.40.01 | D22: 泛微粒贷 | G22: =H22+I22+J22+K22+L22+M22+N22+O22+P22+Q22+R22+S22 -> 2397913036 | H22: =H23+H24 -> 179843478 | I22: =I23+I24 -> 187721738 | J22: =J23+J24 -> 196800000 | K22: =K23+K24 -> 198000000 | L22: =L23+L24 -> 204678260 | M22: =M23+M24 -> 207078260 | N22: =N23+N24 -> 212556520 | O22: =O23+O24 -> 205878260 | ... S22: =S23+S24 -> 207078260
A23: 四级 | B23: 资产余额 | C23: AA.40.01.01 | D23: 微粒贷 | G23: =H23+I23+J23+K23+L23+M23+N23+O23+P23+Q23+R23+S23 -> 1198956518 | H23: 89921739 | I23: 93860869 | J23: 98400000 | K23: 99000000 | L23: 102339130 | M23: 103539130 | N23: 106278260 | O23: 102939130 | P23: 101739130 | Q23: 99000000 | R23: 98400000 | S23: 103539130
A24: 四级 | B24: 资产余额 | C24: AA.40.01.02 | D24: 分付 | G24: =H24+I24+J24+K24+L24+M24+N24+O24+P24+Q24+R24+S24 -> 1198956518 | H24: 89921739 | I24: 93860869 | J24: 98400000 | K24: 99000000 | L24: 102339130 | M24: 103539130 | N24: 106278260 | O24: 102939130 | P24: 101739130 | Q24: 99000000 | R24: 98400000 | S24: 103539130
A25: 三级 | B25: 资产余额 | C25: AA.40.02 | D25: 汽车金融 | G25: =H25+I25+J25+K25+L25+M25+N25+O25+P25+Q25+R25+S25 -> 11989565214 | H25: 899217391 | I25: 938608695 | J25: 984000000 | K25: 990000000 | L25: 1023391304 | M25: 1035391304 | N25: 1062782608 | O25: 1029391304 | P25: 1017391304 | Q25: 990000000 | R25: 984000000 | S25: 1035391304
A26: 三级 | B26: 资产余额 | C26: AA.40.03 | D26: 财富 | G26: =H26+I26+J26+K26+L26+M26+N26+O26+P26+Q26+R26+S26 -> 11989565214 | H26: 899217391 | I26: 938608695 | J26: 984000000 | K26: 990000000 | L26: 1023391304 | M26: 1035391304 | N26: 1062782608 | O26: 1029391304 | P26: 1017391304 | Q26: 990000000 | R26: 984000000 | S26: 1035391304
A27: 三级 | B27: 资产余额 | C27: AA.40.04 | D27: 小鹅 | G27: =H27+I27+J27+K27+L27+M27+N27+O27+P27+Q27+R27+S27 -> 11989565214 | H27: 899217391 | I27: 938608695 | J27: 984000000 | K27: 990000000 | L27: 1023391304 | M27: 1035391304 | N27: 1062782608 | O27: 1029391304 | P27: 1017391304 | Q27: 990000000 | R27: 984000000 | S27: 1035391304
A28: 三级 | B28: 资产余额 | C28: AA.40.05 | D28: 企业金融 | G28: =H28+I28+J28+K28+L28+M28+N28+O28+P28+Q28+R28+S28 -> 1198956518 | H28: =H29 -> 89921739 | I28: =I29 -> 93860869 | J28: =J29 -> 98400000 | K28: =K29 -> 99000000 | L28: =L29 -> 102339130 | M28: =M29 -> 103539130 | N28: =N29 -> 106278260 | O28: =O29 -> 102939130 | ... S28: =S29 -> 103539130
A29: 四级 | B29: 资产余额 | C29: AA.40.05.01 | D29: 一般贷款 | G29: =H29+I29+J29+K29+L29+M29+N29+O29+P29+Q29+R29+S29 -> 1198956518 | H29: 89921739 | I29: 93860869 | J29: 98400000 | K29: 99000000 | L29: 102339130 | M29: 103539130 | N29: 106278260 | O29: 102939130 | P29: 101739130 | Q29: 99000000 | R29: 98400000 | S29: 103539130
A30: 二级 | B30: 资产余额 | C30: AA.41 | D30: 不良贷款原值余额 | G30: =H30+I30+J30+K30+L30+M30+N30+O30+P30+Q30+R30+S30 -> 39565565196 | H30: =H31+H34+H35+H36+H37 -> 2967417390 | I30: =I31+I34+I35+I36+I37 -> 3097408692 | J30: =J31+J34+J35+J36+J37 -> 3247200000 | K30: =K31+K34+K35+K36+K37 -> 3267000000 | L30: =L31+L34+L35+L36+L37 -> 3377191302 | M30: =M31+M34+M35+M36+M37 -> 3416791302 | N30: =N31+N34+N35+N36+N37 -> 3507182604 | O30: =O31+O34+O35+O36+O37 -> 3396991302 | ... S30: =S31+S34+S35+S36+S37 -> 3416791302
A31: 三级 | B31: 资产余额 | C31: AA.41.01 | D31: 泛微粒贷 | G31: =H31+I31+J31+K31+L31+M31+N31+O31+P31+Q31+R31+S31 -> 2397913036 | H31: =H32+H33 -> 179843478 | I31: =I32+I33 -> 187721738 | J31: =J32+J33 -> 196800000 | K31: =K32+K33 -> 198000000 | L31: =L32+L33 -> 204678260 | M31: =M32+M33 -> 207078260 | N31: =N32+N33 -> 212556520 | O31: =O32+O33 -> 205878260 | ... S31: =S32+S33 -> 207078260
A32: 四级 | B32: 资产余额 | C32: AA.41.01.01 | D32: 微粒贷 | G32: =H32+I32+J32+K32+L32+M32+N32+O32+P32+Q32+R32+S32 -> 1198956518 | H32: 89921739 | I32: 93860869 | J32: 98400000 | K32: 99000000 | L32: 102339130 | M32: 103539130 | N32: 106278260 | O32: 102939130 | P32: 101739130 | Q32: 99000000 | R32: 98400000 | S32: 103539130
A33: 四级 | B33: 资产余额 | C33: AA.41.01.02 | D33: 分付 | G33: =H33+I33+J33+K33+L33+M33+N33+O33+P33+Q33+R33+S33 -> 1198956518 | H33: 89921739 | I33: 93860869 | J33: 98400000 | K33: 99000000 | L33: 102339130 | M33: 103539130 | N33: 106278260 | O33: 102939130 | P33: 101739130 | Q33: 99000000 | R33: 98400000 | S33: 103539130
A34: 三级 | B34: 资产余额 | C34: AA.41.02 | D34: 汽车金融 | G34: =H34+I34+J34+K34+L34+M34+N34+O34+P34+Q34+R34+S34 -> 11989565214 | H34: 899217391 | I34: 938608695 | J34: 984000000 | K34: 990000000 | L34: 1023391304 | M34: 1035391304 | N34: 1062782608 | O34: 1029391304 | P34: 1017391304 | Q34: 990000000 | R34: 984000000 | S34: 1035391304
A35: 三级 | B35: 资产余额 | C35: AA.41.03 | D35: 财富 | G35: =H35+I35+J35+K35+L35+M35+N35+O35+P35+Q35+R35+S35 -> 11989565214 | H35: 899217391 | I35: 938608695 | J35: 984000000 | K35: 990000000 | L35: 1023391304 | M35: 1035391304 | N35: 1062782608 | O35: 1029391304 | P35: 1017391304 | Q35: 990000000 | R35: 984000000 | S35: 1035391304
A36: 三级 | B36: 资产余额 | C36: AA.41.04 | D36: 小鹅 | G36: =H36+I36+J36+K36+L36+M36+N36+O36+P36+Q36+R36+S36 -> 11989565214 | H36: 899217391 | I36: 938608695 | J36: 984000000 | K36: 990000000 | L36: 1023391304 | M36: 1035391304 | N36: 1062782608 | O36: 1029391304 | P36: 1017391304 | Q36: 990000000 | R36: 984000000 | S36: 1035391304
A37: 三级 | B37: 资产余额 | C37: AA.41.05 | D37: 企业金融 | G37: =H37+I37+J37+K37+L37+M37+N37+O37+P37+Q37+R37+S37 -> 1198956518 | H37: =H38 -> 89921739 | I37: =I38 -> 93860869 | J37: =J38 -> 98400000 | K37: =K38 -> 99000000 | L37: =L38 -> 102339130 | M37: =M38 -> 103539130 | N37: =N38 -> 106278260 | O37: =O38 -> 102939130 | ... S37: =S38 -> 103539130
A38: 四级 | B38: 资产余额 | C38: AA.41.05.01 | D38: 一般贷款 | G38: =H38+I38+J38+K38+L38+M38+N38+O38+P38+Q38+R38+S38 -> 1198956518 | H38: 89921739 | I38: 93860869 | J38: 98400000 | K38: 99000000 | L38: 102339130 | M38: 103539130 | N38: 106278260 | O38: 102939130 | P38: 101739130 | Q38: 99000000 | R38: 98400000 | S38: 103539130
A39: 二级 | B39: 资产余额 | C39: AA.42 | D39: 年初不良贷款原值余额 | G39: =H39+I39+J39+K39+L39+M39+N39+O39+P39+Q39+R39+S39 -> 39565565196 | H39: =H40+H43+H44+H45+H46 -> 2967417390 | I39: =I40+I43+I44+I45+I46 -> 3097408692 | J39: =J40+J43+J44+J45+J46 -> 3247200000 | K39: =K40+K43+K44+K45+K46 -> 3267000000 | L39: =L40+L43+L44+L45+L46 -> 3377191302 | M39: =M40+M43+M44+M45+M46 -> 3416791302 | N39: =N40+N43+N44+N45+N46 -> 3507182604 | O39: =O40+O43+O44+O45+O46 -> 3396991302 | ... S39: =S40+S43+S44+S45+S46 -> 3416791302
A40: 三级 | B40: 资产余额 | C40: AA.42.01 | D40: 泛微粒贷 | G40: =H40+I40+J40+K40+L40+M40+N40+O40+P40+Q40+R40+S40 -> 2397913036 | H40: =H41+H42 -> 179843478 | I40: =I41+I42 -> 187721738 | J40: =J41+J42 -> 196800000 | K40: =K41+K42 -> 198000000 | L40: =L41+L42 -> 204678260 | M40: =M41+M42 -> 207078260 | N40: =N41+N42 -> 212556520 | O40: =O41+O42 -> 205878260 | ... S40: =S41+S42 -> 207078260
...

Sheet AA微众银行利息净收入表
A1: 科目层级 | B1: 科目性质 | C1: 科目代码 | D1: 科目名称 | E1: 25年实际 | F1: 26年预算 | G1: 26年预测 | H1: 26年1月实际 | I1: 26年2月实际 | J1: 26年3月实际 | K1: 26年4月预测 | L1: 26年5月预测 | M1: 26年6月预测 | N1: 26年7月预测 | O1: 26年8月预测 | P1: 26年9月预测 | Q1: 26年10月预测 | R1: 26年11月预测 | S1: 26年12月预测
