Workbook

Sheet B01企业金融业务状况表
A1: 科目层级 | B1: 科目性质 | C1: 科目代码 | D1: 科目名称 | E1: 25年实际 | F1: 26年预算 | G1: 26年预测 | H1: 26年1月实际 | I1: 26年2月实际 | J1: 26年3月实际 | K1: 26年4月预测 | L1: 26年5月预测 | M1: 26年6月预测 | N1: 26年7月预测 | O1: 26年8月预测 | P1: 26年9月预测 | Q1: 26年10月预测 | R1: 26年11月预测 | S1: 26年12月预测
A2: 二级 | B2: 收入 | C2: B01.01 | D2: 营业收入 | H2: =H3+H6+H7 -> 646100000 | I2: =I3+I6+I7 -> 599950000 | J2: =J3+J6+J7 -> 719940000 | K2: =K3+K6+K7 -> 148000000 | L2: =L3+L6+L7 -> 151700000 | M2: =M3+M6+M7 -> 157250000 | N2: =N3+N6+N7 -> 162800000 | O2: =O3+O6+O7 -> 160950000 | ... S2: =S3+S6+S7 -> 175750000
A3: 三级 | B3: 收入 | C3: B01.01.01 | D3: 利息净收入 | H3: =H4+H5 -> 486500000 | I3: =I4+I5 -> 451750000 | J3: =J4+J5 -> 542100000 | K3: =K4+K5 -> 0 | L3: =L4+L5 -> 0 | M3: =M4+M5 -> 0 | N3: =N4+N5 -> 0 | O3: =O4+O5 -> 0 | ... S3: =S4+S5 -> 0
A4: 四级 | B4: 收入 | C4: B01.01.01.01 | D4: 资产业务 | H4: =H85-H118 -> 612500000 | I4: =I85-I118 -> 568750000 | J4: =J85-J118 -> 682500000 | K4: =K85-K118 -> 0 | L4: =L85-L118 -> 0 | M4: =M85-M118 -> 0 | N4: =N85-N118 -> 0 | O4: =O85-O118 -> 0 | ... S4: =S85-S118 -> 0
A5: 四级 | B5: 收入 | C5: B01.01.01.02 | D5: 负债业务 | H5: =H152-H140 -> -126000000 | I5: =I152-I140 -> -117000000 | J5: =J152-J140 -> -140400000 | K5: =K152-K140 -> 0 | L5: =L152-L140 -> 0 | M5: =M152-M140 -> 0 | N5: =N152-N140 -> 0 | O5: =O152-O140 -> 0 | ... S5: =S152-S140 -> 0
A6: 三级 | B6: 收入 | C6: B01.01.02 | D6: 手续费净收入 | H6: =H166-H181 -> 159600000 | I6: =I166-I181 -> 148200000 | J6: =J166-J181 -> 177840000 | K6: =K166-K181 -> 148000000 | L6: =L166-L181 -> 151700000 | M6: =M166-M181 -> 157250000 | N6: =N166-N181 -> 162800000 | O6: =O166-O181 -> 160950000 | ... S6: =S166-S181 -> 175750000
A7: 三级 | B7: 收入 | C7: B01.01.03 | D7: 其他营收 | H7: =H193+H196 -> 0 | I7: =I193+I196 -> 0 | J7: =J193+J196 -> 0 | K7: =K193+K196 -> 0 | L7: =L193+L196 -> 0 | M7: =M193+M196 -> 0 | N7: =N193+N196 -> 0 | O7: =O193+O196 -> 0 | ... S7: =S193+S196 -> 0
A8: 二级 | B8: 支出 | C8: B01.02 | D8: 减:风险成本 | H8: 220500000 | I8: 204750000 | J8: 245700000 | K8: 252000000 | L8: 258300000 | M8: 267750000 | N8: 277200000 | O8: 274050000 | P8: 267750000 | Q8: 292950000 | R8: 289800000 | S8: 299250000
A9: 二级 | B9: 收入 | C9: B01.03 | D9: 净收入 | H9: =H2-H8 -> 425600000 | I9: =I2-I8 -> 395200000 | J9: =J2-J8 -> 474240000 | K9: =K2-K8 -> -104000000 | L9: =L2-L8 -> -106600000 | M9: =M2-M8 -> -110500000 | N9: =N2-N8 -> -114400000 | O9: =O2-O8 -> -113100000 | ... S9: =S2-S8 -> -123500000
A10: 二级 | B10: 支出 | C10: B01.04 | D10: 减:税金及附加 | H10: 10500000 | I10: 9750000 | J10: 11700000 | K10: 12000000 | L10: 12300000 | M10: 12750000 | N10: 13200000 | O10: 13050000 | P10: 12750000 | Q10: 13950000 | R10: 13800000 | S10: 14250000
A11: 二级 | B11: 支出 | C11: B01.05 | D11: 减:直接费用 | H11: =H12+H15+H18+H25+H26 -> 144900000 | I11: =I12+I15+I18+I25+I26 -> 134550000 | J11: =J12+J15+J18+J25+J26 -> 161460000 | K11: =K12+K15+K18+K25+K26 -> 165600000 | L11: =L12+L15+L18+L25+L26 -> 169740000 | M11: =M12+M15+M18+M25+M26 -> 175950000 | N11: =N12+N15+N18+N25+N26 -> 182160000 | O11: =O12+O15+O18+O25+O26 -> 180090000 | ... S11: =S12+S15+S18+S25+S26 -> 196650000
A12: 三级 | B12: 支出 | C12: B01.05.01 | D12: 人力费用(不含IT) | H12: =H13+H14 -> 56700000 | I12: =I13+I14 -> 52650000 | J12: =J13+J14 -> 63180000 | K12: =K13+K14 -> 64800000 | L12: =L13+L14 -> 66420000 | M12: =M13+M14 -> 68850000 | N12: =N13+N14 -> 71280000 | O12: =O13+O14 -> 70470000 | ... S12: =S13+S14 -> 76950000
A13: 四级 | B13: 支出 | C13: B01.05.01.01 | D13: 常规人力 | H13: 37800000 | I13: 35100000 | J13: 42120000 | K13: 43200000 | L13: 44280000 | M13: 45900000 | N13: 47520000 | O13: 46980000 | P13: 45900000 | Q13: 50220000 | R13: 49680000 | S13: 51300000
A14: 四级 | B14: 支出 | C14: B01.05.01.02 | D14: 特别人力 | H14: 18900000 | I14: 17550000 | J14: 21060000 | K14: 21600000 | L14: 22140000 | M14: 22950000 | N14: 23760000 | O14: 23490000 | P14: 22950000 | Q14: 25110000 | R14: 24840000 | S14: 25650000
A15: 三级 | B15: 支出 | C15: B01.05.02 | D15: 业务费用 | H15: =H16+H17 -> 37800000 | I15: =I16+I17 -> 35100000 | J15: =J16+J17 -> 42120000 | K15: =K16+K17 -> 43200000 | L15: =L16+L17 -> 44280000 | M15: =M16+M17 -> 45900000 | N15: =N16+N17 -> 47520000 | O15: =O16+O17 -> 46980000 | ... S15: =S16+S17 -> 51300000
A16: 四级 | B16: 支出 | C16: B01.05.02.01 | D16: 营销费用 | H16: 22400000 | I16: 20800000 | J16: 24960000 | K16: 25600000 | L16: 26240000 | M16: 27200000 | N16: 28160000 | O16: 27840000 | P16: 27200000 | Q16: 29760000 | R16: 29440000 | S16: 30400000
A17: 四级 | B17: 支出 | C17: B01.05.02.02 | D17: 运营费用 | H17: 15400000 | I17: 14300000 | J17: 17160000 | K17: 17600000 | L17: 18040000 | M17: 18700000 | N17: 19360000 | O17: 19140000 | P17: 18700000 | Q17: 20460000 | R17: 20240000 | S17: 20900000
A18: 三级 | B18: 支出 | C18: B01.05.03 | D18: IT费用 | H18: =H19+H22+H23+H24 -> 31500000 | I18: =I19+I22+I23+I24 -> 29250000 | J18: =J19+J22+J23+J24 -> 35100000 | K18: =K19+K22+K23+K24 -> 36000000 | L18: =L19+L22+L23+L24 -> 36900000 | M18: =M19+M22+M23+M24 -> 38250000 | N18: =N19+N22+N23+N24 -> 39600000 | O18: =O19+O22+O23+O24 -> 39150000 | ... S18: =S19+S22+S23+S24 -> 42750000
A19: 四级 | B19: 支出 | C19: B01.05.03.01 | D19: IT人力 | H19: =H20+H21 -> 15400000 | I19: =I20+I21 -> 14300000 | J19: =J20+J21 -> 17160000 | K19: =K20+K21 -> 17600000 | L19: =L20+L21 -> 18040000 | M19: =M20+M21 -> 18700000 | N19: =N20+N21 -> 19360000 | O19: =O20+O21 -> 19140000 | ... S19: =S20+S21 -> 20900000
A20: 五级 | B20: 支出 | C20: B01.05.03.01.01 | D20: IT常规人力 | H20: 9100000 | I20: 8450000 | J20: 10140000 | K20: 10400000 | L20: 10660000 | M20: 11050000 | N20: 11440000 | O20: 11310000 | P20: 11050000 | Q20: 12090000 | R20: 11960000 | S20: 12350000
A21: 五级 | B21: 支出 | C21: B01.05.03.01.02 | D21: IT特别人力 | H21: 6300000 | I21: 5850000 | J21: 7020000 | K21: 7200000 | L21: 7380000 | M21: 7650000 | N21: 7920000 | O21: 7830000 | P21: 7650000 | Q21: 8370000 | R21: 8280000 | S21: 8550000
A22: 四级 | B22: 支出 | C22: B01.05.03.02 | D22: 科技费用 | H22: 6300000 | I22: 5850000 | J22: 7020000 | K22: 7200000 | L22: 7380000 | M22: 7650000 | N22: 7920000 | O22: 7830000 | P22: 7650000 | Q22: 8370000 | R22: 8280000 | S22: 8550000
A23: 四级 | B23: 支出 | C23: B01.05.03.03 | D23: IT职场 | H23: 4900000 | I23: 4550000 | J23: 5460000 | K23: 5600000 | L23: 5740000 | M23: 5950000 | N23: 6160000 | O23: 6090000 | P23: 5950000 | Q23: 6510000 | R23: 6440000 | S23: 6650000
A24: 四级 | B24: 支出 | C24: B01.05.03.04 | D24: IT日常 | H24: 4900000 | I24: 4550000 | J24: 5460000 | K24: 5600000 | L24: 5740000 | M24: 5950000 | N24: 6160000 | O24: 6090000 | P24: 5950000 | Q24: 6510000 | R24: 6440000 | S24: 6650000
A25: 三级 | B25: 支出 | C25: B01.05.04 | D25: 职场费用 | H25: 9800000 | I25: 9100000 | J25: 10920000 | K25: 11200000 | L25: 11480000 | M25: 11900000 | N25: 12320000 | O25: 12180000 | P25: 11900000 | Q25: 13020000 | R25: 12880000 | S25: 13300000
A26: 三级 | B26: 支出 | C26: B01.05.05 | D26: 日常费用 | H26: 9100000 | I26: 8450000 | J26: 10140000 | K26: 10400000 | L26: 10660000 | M26: 11050000 | N26: 11440000 | O26: 11310000 | P26: 11050000 | Q26: 12090000 | R26: 11960000 | S26: 12350000
A27: 二级 | B27: 收入 | C27: B01.06 | D27: 加:营业外净收入 | H27: 4200000 | I27: 3900000 | J27: 4680000 | K27: 4800000 | L27: 4920000 | M27: 5100000 | N27: 5280000 | O27: 5220000 | P27: 5100000 | Q27: 5580000 | R27: 5520000 | S27: 5700000
A28: 二级 | B28: 利润 | C28: B01.07 | D28: 分摊前利润 | H28: =H9-H10-H11+H27 -> 274400000 | I28: =I9-I10-I11+I27 -> 254800000 | J28: =J9-J10-J11+J27 -> 305760000 | K28: =K9-K10-K11+K27 -> -276800000 | L28: =L9-L10-L11+L27 -> -283720000 | M28: =M9-M10-M11+M27 -> -294100000 | N28: =N9-N10-N11+N27 -> -304480000 | O28: =O9-O10-O11+O27 -> -301020000 | ... S28: =S9-S10-S11+S27 -> -328700000
A29: 二级 | B29: 支出 | C29: B01.08 | D29: 减:固定管理费 | H29: 21000000 | I29: 19500000 | J29: 23400000 | K29: 24000000 | L29: 24600000 | M29: 25500000 | N29: 26400000 | O29: 26100000 | P29: 25500000 | Q29: 27900000 | R29: 27600000 | S29: 28500000
A30: 二级 | B30: 利润 | C30: B01.09 | D30: 税前利润 | H30: =H28-H29 -> 253400000 | I30: =I28-I29 -> 235300000 | J30: =J28-J29 -> 282360000 | K30: =K28-K29 -> -300800000 | L30: =L28-L29 -> -308320000 | M30: =M28-M29 -> -319600000 | N30: =N28-N29 -> -330880000 | O30: =O28-O29 -> -327120000 | ... S30: =S28-S29 -> -357200000
A31: 二级 | B31: 资产余额 | C31: B01.10 | D31: 管理贷款余额 | H31: =H32+H39+H40+H44 -> 7245000000 | I31: =I32+I39+I40+I44 -> 7534800000 | J31: =J32+J39+J40+J44 -> 7921200000 | K31: =K32+K39+K40+K44 -> 8017800000 | L31: =L32+L39+L40+L44 -> 8211000000 | M31: =M32+M39+M40+M44 -> 8404200000 | N31: =N32+N39+N40+N44 -> 8500800000 | O31: =O32+O39+O40+O44 -> 8307600000 | ... S31: =S32+S39+S40+S44 -> 8404200000
A32: 三级 | B32: 资产余额 | C32: B01.10.01 | D32: 自持余额 | H32: =H33+H36 -> 5512500000 | I32: =I33+I36 -> 5733000000 | J32: =J33+J36 -> 6027000000 | K32: =K33+K36 -> 6100500000 | L32: =L33+L36 -> 6247500000 | M32: =M33+M36 -> 6394500000 | N32: =N33+N36 -> 6468000000 | O32: =O33+O36 -> 6321000000 | ... S32: =S33+S36 -> 6394500000
A33: 四级 | B33: 资产余额 | C33: B01.10.01.01 | D33: 一般贷款 | H33: =H34+H35 -> 4725000000 | I33: =I34+I35 -> 4914000000 | J33: =J34+J35 -> 5166000000 | K33: =K34+K35 -> 5229000000 | L33: =L34+L35 -> 5355000000 | M33: =M34+M35 -> 5481000000 | N33: =N34+N35 -> 5544000000 | O33: =O34+O35 -> 5418000000 | ... S33: =S34+S35 -> 5481000000
A34: 五级 | B34: 资产余额 | C34: B01.10.01.01.01 | D34: 常规部分 | H34: 2756250000 | I34: 2866500000 | J34: 3013500000 | K34: 3050250000 | L34: 3123750000 | M34: 3197250000 | N34: 3234000000 | O34: 3160500000 | P34: 3087000000 | Q34: 3050250000 | R34: 3013500000 | S34: 3197250000
A35: 五级 | B35: 资产余额 | C35: B01.10.01.01.02 | D35: 战略部分 | H35: 1968750000 | I35: 2047500000 | J35: 2152500000 | K35: 2178750000 | L35: 2231250000 | M35: 2283750000 | N35: 2310000000 | O35: 2257500000 | P35: 2205000000 | Q35: 2178750000 | R35: 2152500000 | S35: 2283750000
A36: 四级 | B36: 资产余额 | C36: B01.10.01.02 | D36: 票据融资 | H36: =H37+H38 -> 787500000 | I36: =I37+I38 -> 819000000 | J36: =J37+J38 -> 861000000 | K36: =K37+K38 -> 871500000 | L36: =L37+L38 -> 892500000 | M36: =M37+M38 -> 913500000 | N36: =N37+N38 -> 924000000 | O36: =O37+O38 -> 903000000 | ... S36: =S37+S38 -> 913500000
A37: 五级 | B37: 资产余额 | C37: B01.10.01.02.01 | D37: 票据贴现 | H37: 472500000 | I37: 491400000 | J37: 516600000 | K37: 522900000 | L37: 535500000 | M37: 548100000 | N37: 554400000 | O37: 541800000 | P37: 529200000 | Q37: 522900000 | R37: 516600000 | S37: 548100000
A38: 五级 | B38: 资产余额 | C38: B01.10.01.02.02 | D38: 贸易融资 | H38: 315000000 | I38: 327600000 | J38: 344400000 | K38: 348600000 | L38: 357000000 | M38: 365400000 | N38: 369600000 | O38: 361200000 | P38: 352800000 | Q38: 348600000 | R38: 344400000 | S38: 365400000
A39: 三级 | B39: 资产余额 | C39: B01.10.02 | D39: 联贷 | H39: 1181250000 | I39: 1228500000 | J39: 1291500000 | K39: 1307250000 | L39: 1338750000 | M39: 1370250000 | N39: 1386000000 | O39: 1354500000 | P39: 1323000000 | Q39: 1307250000 | R39: 1291500000 | S39: 1370250000
A40: 三级 | B40: 资产余额 | C40: B01.10.03 | D40: 流转 | H40: =H41+H42+H43 -> 0 | I40: =I41+I42+I43 -> 0 | J40: =J41+J42+J43 -> 0 | K40: =K41+K42+K43 -> 0 | L40: =L41+L42+L43 -> 0 | M40: =M41+M42+M43 -> 0 | N40: =N41+N42+N43 -> 0 | O40: =O41+O42+O43 -> 0 | ... S40: =S41+S42+S43 -> 0
...

Sheet B01企业金融业务支出评估
A1: 科目层级 | B1: 科目性质 | C1: 科目代码 | D1: 科目名称 | E1: 25年实际 | F1: 26年预算 | G1: 26年预测 | H1: 26年1月实际 | I1: 26年2月实际 | J1: 26年3月实际 | K1: 26年4月预测 | L1: 26年5月预测 | M1: 26年6月预测 | N1: 26年7月预测 | O1: 26年8月预测 | P1: 26年9月预测 | Q1: 26年10月预测 | R1: 26年11月预测 | S1: 26年12月预测
A2: 一级 | B2: 其他 | C2: B01.91 | D2: 业务支出评估
A3: 二级 | B3: 其他 | C3: B01.91.01 | D3: 客户经营指标
A4: 三级 | B4: 其他 | C4: B01.91.01.01 | D4: 客户营销与投入
A5: 四级 | B5: 其他 | C5: B01.91.01.01.001 | D5: 新客营销支出 | H5: 21000000 | I5: 19500000 | J5: 23400000 | K5: 24000000 | L5: 24600000 | M5: 25500000 | N5: 26400000 | O5: 26100000 | P5: 25500000 | Q5: 27900000 | R5: 27600000 | S5: 28500000
A6: 四级 | B6: 其他 | C6: B01.91.01.01.002 | D6: 存客营销支出 | H6: 14000000 | I6: 13000000 | J6: 15600000 | K6: 16000000 | L6: 16400000 | M6: 17000000 | N6: 17600000 | O6: 17400000 | P6: 17000000 | Q6: 18600000 | R6: 18400000 | S6: 19000000
A7: 四级 | B7: 其他 | C7: B01.91.01.01.003 | D7: 新开通客户投入 | H7: 8400000 | I7: 7800000 | J7: 9360000 | K7: 9600000 | L7: 9840000 | M7: 10200000 | N7: 10560000 | O7: 10440000 | P7: 10200000 | Q7: 11160000 | R7: 11040000 | S7: 11400000
A8: 四级 | B8: 其他 | C8: B01.91.01.01.004 | D8: 新发放投入 | H8: 7000000 | I8: 6500000 | J8: 7800000 | K8: 8000000 | L8: 8200000 | M8: 8500000 | N8: 8800000 | O8: 8700000 | P8: 8500000 | Q8: 9300000 | R8: 9200000 | S8: 9500000
A9: 三级 | B9: 其他 | C9: B01.91.01.02 | D9: 客户规模与数量
A10: 四级 | B10: 其他 | C10: B01.91.01.02.101 | D10: LUM规模 | H10: 6000000000 | I10: 6240000000 | J10: 6560000000 | K10: 6640000000 | L10: 6800000000 | M10: 6960000000 | N10: 7040000000 | O10: 6880000000 | P10: 6720000000 | Q10: 6640000000 | R10: 6560000000 | S10: 6960000000
A11: 四级 | B11: 其他 | C11: B01.91.01.02.001 | D11: 新客日均LUM | H11: 2100000000 | I11: 1950000000 | J11: 2340000000 | K11: 2400000000 | L11: 2460000000 | M11: 2550000000 | N11: 2640000000 | O11: 2610000000 | P11: 2550000000 | Q11: 2790000000 | R11: 2760000000 | S11: 2850000000
A12: 四级 | B12: 其他 | C12: B01.91.01.02.002 | D12: 存客日均LUM | H12: 3500000000 | I12: 3250000000 | J12: 3900000000 | K12: 4000000000 | L12: 4100000000 | M12: 4250000000 | N12: 4400000000 | O12: 4350000000 | P12: 4250000000 | Q12: 4650000000 | R12: 4600000000 | S12: 4750000000
A13: 四级 | B13: 其他 | C13: B01.91.01.02.005 | D13: 新发放LUM | H13: 840000000 | I13: 780000000 | J13: 936000000 | K13: 960000000 | L13: 984000000 | M13: 1020000000 | N13: 1056000000 | O13: 1044000000 | P13: 1020000000 | Q13: 1116000000 | R13: 1104000000 | S13: 1140000000
A14: 四级 | B14: 其他 | C14: B01.91.01.02.006 | D14: 新发放LUM(标服) | H14: 350000000 | I14: 325000000 | J14: 390000000 | K14: 400000000 | L14: 410000000 | M14: 425000000 | N14: 440000000 | O14: 435000000 | P14: 425000000 | Q14: 465000000 | R14: 460000000 | S14: 475000000
A15: 四级 | B15: 其他 | C15: B01.91.01.02.010 | D15: 日均LUM | H15: 5600000000 | I15: 5200000000 | J15: 6240000000 | K15: 6400000000 | L15: 6560000000 | M15: 6800000000 | N15: 7040000000 | O15: 6960000000 | P15: 6800000000 | Q15: 7440000000 | R15: 7360000000 | S15: 7600000000
A16: 四级 | B16: 其他 | C16: B01.91.01.02.102 | D16: AuM规模 | H16: 4500000000 | I16: 4680000000 | J16: 4920000000 | K16: 4980000000 | L16: 5100000000 | M16: 5220000000 | N16: 5280000000 | O16: 5160000000 | P16: 5040000000 | Q16: 4980000000 | R16: 4920000000 | S16: 5220000000
A17: 四级 | B17: 其他 | C17: B01.91.01.02.007 | D17: 存客日均AuM | H17: 2450000000 | I17: 2275000000 | J17: 2730000000 | K17: 2800000000 | L17: 2870000000 | M17: 2975000000 | N17: 3080000000 | O17: 3045000000 | P17: 2975000000 | Q17: 3255000000 | R17: 3220000000 | S17: 3325000000
A18: 四级 | B18: 其他 | C18: B01.91.01.02.008 | D18: 新客AuM余额 | H18: 1050000000 | I18: 975000000 | J18: 1170000000 | K18: 1200000000 | L18: 1230000000 | M18: 1275000000 | N18: 1320000000 | O18: 1305000000 | P18: 1275000000 | Q18: 1395000000 | R18: 1380000000 | S18: 1425000000
A19: 四级 | B19: 其他 | C19: B01.91.01.02.011 | D19: 日均AuM | H19: 4200000000 | I19: 3900000000 | J19: 4680000000 | K19: 4800000000 | L19: 4920000000 | M19: 5100000000 | N19: 5280000000 | O19: 5220000000 | P19: 5100000000 | Q19: 5580000000 | R19: 5520000000 | S19: 5700000000
A20: 四级 | B20: 其他 | C20: B01.91.01.02.103 | D20: 客户数量 | H20: 6000000000 | I20: 6240000000 | J20: 6560000000 | K20: 6640000000 | L20: 6800000000 | M20: 6960000000 | N20: 7040000000 | O20: 6880000000 | P20: 6720000000 | Q20: 6640000000 | R20: 6560000000 | S20: 6960000000
A21: 四级 | B21: 其他 | C21: B01.91.01.02.003 | D21: 新开通客户数 | H21: 1400000000 | I21: 1300000000 | J21: 1560000000 | K21: 1600000000 | L21: 1640000000 | M21: 1700000000 | N21: 1760000000 | O21: 1740000000 | P21: 1700000000 | Q21: 1860000000 | R21: 1840000000 | S21: 1900000000
... A23: 四级 | B23: 其他 | C23: B01.91.01.02.009 | D23: MFAU客户数 | H23: 3500000000 | I23: 3250000000 | J23: 3900000000 | K23: 4000000000 | L23: 4100000000 | M23: 4250000000 | N23: 4400000000 | O23: 4350000000 | P23: 4250000000 | Q23: 4650000000 | R23: 4600000000 | S23: 4750000000
A24: 三级 | B24: 其他 | C24: B01.91.01.03 | D24: 客户回收与催收
A25: 四级 | B25: 其他 | C25: B01.91.01.03.001 | D25: 内催回收额 | H25: 35000000 | I25: 32500000 | J25: 39000000 | K25: 40000000 | L25: 41000000 | M25: 42500000 | N25: 44000000 | O25: 43500000 | P25: 42500000 | Q25: 46500000 | R25: 46000000 | S25: 47500000
A26: 四级 | B26: 其他 | C26: B01.91.01.03.002 | D26: M6-压降金额 | H26: 17500000 | I26: 16250000 | J26: 19500000 | K26: 20000000 | L26: 20500000 | M26: 21250000 | N26: 22000000 | O26: 21750000 | P26: 21250000 | Q26: 23250000 | R26: 23000000 | S26: 23750000
A27: 四级 | B27: 其他 | C27: B01.91.01.03.003 | D27: M7+现金回收额 | H27: 10500000 | I27: 9750000 | J27: 11700000 | K27: 12000000 | L27: 12300000 | M27: 12750000 | N27: 13200000 | O27: 13050000 | P27: 12750000 | Q27: 13950000 | R27: 13800000 | S27: 14250000

Sheet AA微众银行业务状况表
A1: 科目层级 | B1: 科目性质 | C1: 科目代码 | D1: 科目名称 | E1: 25年实际 | F1: 26年预算 | G1: 26年预测 | H1: 26年1月实际 | I1: 26年2月实际 | J1: 26年3月实际 | K1: 26年4月预测 | L1: 26年5月预测 | M1: 26年6月预测 | N1: 26年7月预测 | O1: 26年8月预测 | P1: 26年9月预测 | Q1: 26年10月预测 | R1: 26年11月预测 | S1: 26年12月预测
A2: 二级 | B2: 收入 | C2: AA.01 | D2: 营业收入 | H2: =H3+H6+H9 -> 2660000000 | I2: =I3+I6+I9 -> 2470000000 | J2: =J3+J6+J9 -> 2964000000 | K2: =K3+K6+K9 -> 3040000000 | L2: =L3+L6+L9 -> 3116000000 | M2: =M3+M6+M9 -> 3230000000 | N2: =N3+N6+N9 -> 3344000000 | O2: =O3+O6+O9 -> 3306000000 | ... S2: =S3+S6+S9 -> 3610000000
A3: 三级 | B3: 收入 | C3: AA.01.01 | D3: 利息净收入 | H3: =H4-H5 -> 1470000000 | I3: =I4-I5 -> 1365000000 | J3: =J4-J5 -> 1638000000 | K3: =K4-K5 -> 1680000000 | L3: =L4-L5 -> 1722000000 | M3: =M4-M5 -> 1785000000 | N3: =N4-N5 -> 1848000000 | O3: =O4-O5 -> 1827000000 | ... S3: =S4-S5 -> 1995000000
A4: 二级 | B4: 收入 | C4: AA.14 | D4: 利息收入 | H4: 2646000000 | I4: 2457000000 | J4: 2948400000 | K4: 3024000000 | L4: 3099600000 | M4: 3213000000 | N4: 3326400000 | O4: 3288600000 | P4: 3213000000 | Q4: 3515400000 | R4: 3477600000 | S4: 3591000000
A5: 二级 | B5: 支出 | C5: AA.16 | D5: 利息支出 | H5: 1176000000 | I5: 1092000000 | J5: 1310400000 | K5: 1344000000 | L5: 1377600000 | M5: 1428000000 | N5: 1478400000 | O5: 1461600000 | P5: 1428000000 | Q5: 1562400000 | R5: 1545600000 | S5: 1596000000
A6: 三级 | B6: 收入 | C6: AA.01.02 | D6: 净手续费收入 | H6: =H7-H8 -> 840000000 | I6: =I7-I8 -> 780000000 | J6: =J7-J8 -> 936000000 | K6: =K7-K8 -> 960000000 | L6: =L7-L8 -> 984000000 | M6: =M7-M8 -> 1020000000 | N6: =N7-N8 -> 1056000000 | O6: =O7-O8 -> 1044000000 | ... S6: =S7-S8 -> 1140000000
A7: 二级 | B7: 收入 | C7: AA.18 | D7: 手续费收入 | H7: 1050000000 | I7: 975000000 | J7: 1170000000 | K7: 1200000000 | L7: 1230000000 | M7: 1275000000 | N7: 1320000000 | O7: 1305000000 | P7: 1275000000 | Q7: 1395000000 | R7: 1380000000 | S7: 1425000000
A8: 二级 | B8: 支出 | C8: AA.19 | D8: 手续费支出 | H8: 210000000 | I8: 195000000 | J8: 234000000 | K8: 240000000 | L8: 246000000 | M8: 255000000 | N8: 264000000 | O8: 261000000 | P8: 255000000 | Q8: 279000000 | R8: 276000000 | S8: 285000000
A9: 三级 | B9: 收入 | C9: AA.01.03 | D9: 其他营收 | H9: 350000000 | I9: 325000000 | J9: 390000000 | K9: 400000000 | L9: 410000000 | M9: 425000000 | N9: 440000000 | O9: 435000000 | P9: 425000000 | Q9: 465000000 | R9: 460000000 | S9: 475000000
A10: 二级 | B10: 支出 | C10: AA.02 | D10: 减:资产减值损失 | H10: =H11+H14 -> 840000000 | I10: =I11+I14 -> 780000000 | J10: =J11+J14 -> 936000000 | K10: =K11+K14 -> 960000000 | L10: =L11+L14 -> 984000000 | M10: =M11+M14 -> 1020000000 | N10: =N11+N14 -> 1056000000 | O10: =O11+O14 -> 1044000000 | ... S10: =S11+S14 -> 1140000000
A11: 三级 | B11: 支出 | C11: AA.02.01 | D11: 贷款减值损失 | H11: =H12+H13 -> 798000000 | I11: =I12+I13 -> 741000000 | J11: =J12+J13 -> 889200000 | K11: =K12+K13 -> 912000000 | L11: =L12+L13 -> 934800000 | M11: =M12+M13 -> 969000000 | N11: =N12+N13 -> 1003200000 | O11: =O12+O13 -> 991800000 | ... S11: =S12+S13 -> 1083000000
A12: 四级 | B12: 支出 | C12: AA.02.01.01 | D12: 实际风险成本 | H12: 714000000 | I12: 663000000 | J12: 795600000 | K12: 816000000 | L12: 836400000 | M12: 867000000 | N12: 897600000 | O12: 887400000 | P12: 867000000 | Q12: 948600000 | R12: 938400000 | S12: 969000000
A13: 四级 | B13: 支出 | C13: AA.02.01.02 | D13: 超额拨备 | H13: 84000000 | I13: 78000000 | J13: 93600000 | K13: 96000000 | L13: 98400000 | M13: 102000000 | N13: 105600000 | O13: 104400000 | P13: 102000000 | Q13: 111600000 | R13: 110400000 | S13: 114000000
A14: 三级 | B14: 支出 | C14: AA.02.02 | D14: 非贷减值损失 | H14: 42000000 | I14: 39000000 | J14: 46800000 | K14: 48000000 | L14: 49200000 | M14: 51000000 | N14: 52800000 | O14: 52200000 | P14: 51000000 | Q14: 55800000 | R14: 55200000 | S14: 57000000
A15: 二级 | B15: 收入 | C15: AA.03 | D15: 净收入 | H15: =H2-H10 -> 1820000000 | I15: =I2-I10 -> 1690000000 | J15: =J2-J10 -> 2028000000 | K15: =K2-K10 -> 2080000000 | L15: =L2-L10 -> 2132000000 | M15: =M2-M10 -> 2210000000 | N15: =N2-N10 -> 2288000000 | O15: =O2-O10 -> 2262000000 | ... S15: =S2-S10 -> 2470000000
A16: 二级 | B16: 支出 | C16: AA.04 | D16: 减:税金及附加 | H16: 35000000 | I16: 32500000 | J16: 39000000 | K16: 40000000 | L16: 41000000 | M16: 42500000 | N16: 44000000 | O16: 43500000 | P16: 42500000 | Q16: 46500000 | R16: 46000000 | S16: 47500000
A17: 二级 | B17: 支出 | C17: AA.05 | D17: 减:业务及管理费 | H17: =H18+H22+H25+H25 -> 504000000 | I17: =I18+I22+I25+I25 -> 468000000 | J17: =J18+J22+J25+J25 -> 561600000 | K17: =K18+K22+K25+K25 -> 576000000 | L17: =L18+L22+L25+L25 -> 590400000 | M17: =M18+M22+M25+M25 -> 612000000 | N17: =N18+N22+N25+N25 -> 633600000 | O17: =O18+O22+O25+O25 -> 626400000 | ... S17: =S18+S22+S25+S25 -> 684000000
A18: 三级 | B18: 支出 | C18: AA.05.01 | D18: 人力费用 | H18: =H19+H20+H21 -> 210000000 | I18: =I19+I20+I21 -> 195000000 | J18: =J19+J20+J21 -> 234000000 | K18: =K19+K20+K21 -> 240000000 | L18: =L19+L20+L21 -> 246000000 | M18: =M19+M20+M21 -> 255000000 | N18: =N19+N20+N21 -> 264000000 | O18: =O19+O20+O21 -> 261000000 | ... S18: =S19+S20+S21 -> 285000000
A19: 四级 | B19: 支出 | C19: AA.05.01.01 | D19: 常规人力 | H19: 147000000 | I19: 136500000 | J19: 163800000 | K19: 168000000 | L19: 172200000 | M19: 178500000 | N19: 184800000 | O19: 182700000 | P19: 178500000 | Q19: 195300000 | R19: 193200000 | S19: 199500000
A20: 四级 | B20: 支出 | C20: AA.05.01.02 | D20: 利润分享 | H20: 42000000 | I20: 39000000 | J20: 46800000 | K20: 48000000 | L20: 49200000 | M20: 51000000 | N20: 52800000 | O20: 52200000 | P20: 51000000 | Q20: 55800000 | R20: 55200000 | S20: 57000000
A21: 四级 | B21: 支出 | C21: AA.05.01.03 | D21: 专项费用 | H21: 21000000 | I21: 19500000 | J21: 23400000 | K21: 24000000 | L21: 24600000 | M21: 25500000 | N21: 26400000 | O21: 26100000 | P21: 25500000 | Q21: 27900000 | R21: 27600000 | S21: 28500000
A22: 三级 | B22: 支出 | C22: AA.05.02 | D22: 业务费用 | H22: =H24+H23 -> 126000000 | I22: =I24+I23 -> 117000000 | J22: =J24+J23 -> 140400000 | K22: =K24+K23 -> 144000000 | L22: =L24+L23 -> 147600000 | M22: =M24+M23 -> 153000000 | N22: =N24+N23 -> 158400000 | O22: =O24+O23 -> 156600000 | ... S22: =S24+S23 -> 171000000
A23: 四级 | B23: 支出 | C23: AA.05.02.01 | D23: 营销费用 | H23: 75600000 | I23: 70200000 | J23: 84240000 | K23: 86400000 | L23: 88560000 | M23: 91800000 | N23: 95040000 | O23: 93960000 | P23: 91800000 | Q23: 100440000 | R23: 99360000 | S23: 102600000
A24: 四级 | B24: 支出 | C24: AA.05.02.02 | D24: 运营费用 | H24: 50400000 | I24: 46800000 | J24: 56160000 | K24: 57600000 | L24: 59040000 | M24: 61200000 | N24: 63360000 | O24: 62640000 | P24: 61200000 | Q24: 66960000 | R24: 66240000 | S24: 68400000
A25: 三级 | B25: 支出 | C25: AA.05.03 | D25: 日常费用 | H25: 84000000 | I25: 78000000 | J25: 93600000 | K25: 96000000 | L25: 98400000 | M25: 102000000 | N25: 105600000 | O25: 104400000 | P25: 102000000 | Q25: 111600000 | R25: 110400000 | S25: 114000000
A26: 二级 | B26: 收入 | C26: AA.06 | D26: 加:营业外净收入 | H26: 14000000 | I26: 13000000 | J26: 15600000 | K26: 16000000 | L26: 16400000 | M26: 17000000 | N26: 17600000 | O26: 17400000 | P26: 17000000 | Q26: 18600000 | R26: 18400000 | S26: 19000000
A27: 二级 | B27: 利润 | C27: AA.09 | D27: 税前利润 | H27: =H15-H16-H17 -> 1281000000 | I27: =I15-I16-I17 -> 1189500000 | J27: =J15-J16-J17 -> 1427400000 | K27: =K15-K16-K17 -> 1464000000 | L27: =L15-L16-L17 -> 1500600000 | M27: =M15-M16-M17 -> 1555500000 | N27: =N15-N16-N17 -> 1610400000 | O27: =O15-O16-O17 -> 1592100000 | ... S27: =S15-S16-S17 -> 1738500000
A28: 二级 | B28: 支出 | C28: AA.30 | D28: 减:所得税 | H28: 344400000 | I28: 319800000 | J28: 383760000 | K28: 393600000 | L28: 403440000 | M28: 418200000 | N28: 432960000 | O28: 428040000 | P28: 418200000 | Q28: 457560000 | R28: 452640000 | S28: 467400000
A29: 二级 | B29: 利润 | C29: AA.31 | D29: 净利润 | H29: =H27-H28 -> 936600000 | I29: =I27-I28 -> 869700000 | J29: =J27-J28 -> 1043640000 | K29: =K27-K28 -> 1070400000 | L29: =L27-L28 -> 1097160000 | M29: =M27-M28 -> 1137300000 | N29: =N27-N28 -> 1177440000 | O29: =O27-O28 -> 1164060000 | ... S29: =S27-S28 -> 1271100000
A30: 二级 | B30: 资产余额 | C30: AA.10 | D30: 管理贷款余额 | H30: =H31+H36+H35+H34 -> 26250000000 | I30: =I31+I36+I35+I34 -> 27300000000 | J30: =J31+J36+J35+J34 -> 28700000000 | K30: =K31+K36+K35+K34 -> 29050000000 | L30: =L31+L36+L35+L34 -> 29750000000 | M30: =M31+M36+M35+M34 -> 30450000000 | N30: =N31+N36+N35+N34 -> 30800000000 | O30: =O31+O36+O35+O34 -> 30100000000 | ... S30: =S31+S36+S35+S34 -> 30450000000
A31: 三级 | B31: 资产余额 | C31: AA.10.01 | D31: 自持余额 | H31: =H32+H33 -> 18375000000 | I31: =I32+I33 -> 19110000000 | J31: =J32+J33 -> 20090000000 | K31: =K32+K33 -> 20335000000 | L31: =L32+L33 -> 20825000000 | M31: =M32+M33 -> 21315000000 | N31: =N32+N33 -> 21560000000 | O31: =O32+O33 -> 21070000000 | ... S31: =S32+S33 -> 21315000000
A32: 四级 | B32: 资产余额 | C32: AA.10.01.01 | D32: 一般贷款 | H32: 15750000000 | I32: 16380000000 | J32: 17220000000 | K32: 17430000000 | L32: 17850000000 | M32: 18270000000 | N32: 18480000000 | O32: 18060000000 | P32: 17640000000 | Q32: 17430000000 | R32: 17220000000 | S32: 18270000000
A33: 四级 | B33: 资产余额 | C33: AA.10.01.02 | D33: 票据融资 | H33: 2625000000 | I33: 2730000000 | J33: 2870000000 | K33: 2905000000 | L33: 2975000000 | M33: 3045000000 | N33: 3080000000 | O33: 3010000000 | P33: 2940000000 | Q33: 2905000000 | R33: 2870000000 | S33: 3045000000
A34: 三级 | B34: 资产余额 | C34: AA.10.02 | D34: 联贷 | H34: 4725000000 | I34: 4914000000 | J34: 5166000000 | K34: 5229000000 | L34: 5355000000 | M34: 5481000000 | N34: 5544000000 | O34: 5418000000 | P34: 5292000000 | Q34: 5229000000 | R34: 5166000000 | S34: 5481000000
A35: 三级 | B35: 资产余额 | C35: AA.10.03 | D35: 流转 | H35: 2100000000 | I35: 2184000000 | J35: 2296000000 | K35: 2324000000 | L35: 2380000000 | M35: 2436000000 | N35: 2464000000 | O35: 2408000000 | P35: 2352000000 | Q35: 2324000000 | R35: 2296000000 | S35: 2436000000
A36: 三级 | B36: 资产余额 | C36: AA.10.04 | D36: 银承保函 | H36: 1050000000 | I36: 1092000000 | J36: 1148000000 | K36: 1162000000 | L36: 1190000000 | M36: 1218000000 | N36: 1232000000 | O36: 1204000000 | P36: 1176000000 | Q36: 1162000000 | R36: 1148000000 | S36: 1218000000
A37: 二级 | B37: 负债余额 | C37: AA.12 | D37: 管理资产余额 | H37: =H38+H39+H40+H41 -> 37500000000 | I37: =I38+I39+I40+I41 -> 39000000000 | J37: =J38+J39+J40+J41 -> 41000000000 | K37: =K38+K39+K40+K41 -> 41500000000 | L37: =L38+L39+L40+L41 -> 42500000000 | M37: =M38+M39+M40+M41 -> 43500000000 | N37: =N38+N39+N40+N41 -> 44000000000 | O37: =O38+O39+O40+O41 -> 43000000000 | ... S37: =S38+S39+S40+S41 -> 43500000000
A38: 三级 | B38: 负债余额 | C38: AA.12.01 | D38: 各项存款 | H38: 33750000000 | I38: 35100000000 | J38: 36900000000 | K38: 37350000000 | L38: 38250000000 | M38: 39150000000 | N38: 39600000000 | O38: 38700000000 | P38: 37800000000 | Q38: 37350000000 | R38: 36900000000 | S38: 39150000000
A39: 三级 | B39: 负债余额 | C39: AA.12.02 | D39: 代销理财 | H39: 2250000000 | I39: 2340000000 | J39: 2460000000 | K39: 2490000000 | L39: 2550000000 | M39: 2610000000 | N39: 2640000000 | O39: 2580000000 | P39: 2520000000 | Q39: 2490000000 | R39: 2460000000 | S39: 2610000000
A40: 三级 | B40: 负债余额 | C40: AA.12.03 | D40: 商户结算便利应付款 | H40: 750000000 | I40: 780000000 | J40: 820000000 | K40: 830000000 | L40: 850000000 | M40: 870000000 | N40: 880000000 | O40: 860000000 | P40: 840000000 | Q40: 830000000 | R40: 820000000 | S40: 870000000
...

Sheet AA微众银行业务支出评估
A1: 科目层级 | B1: 科目性质 | C1: 科目代码 | D1: 科目名称 | E1: 25年实际 | F1: 26年预算 | G1: 26年预测 | H1: 26年1月实际 | I1: 26年2月实际 | J1: 26年3月实际 | K1: 26年4月预测 | L1: 26年5月预测 | M1: 26年6月预测 | N1: 26年7月预测 | O1: 26年8月预测 | P1: 26年9月预测 | Q1: 26年10月预测 | R1: 26年11月预测 | S1: 26年12月预测
A2: 一级 | B2: 其他 | C2: AA.91 | D2: 业务支出评估
A3: 二级 | B3: 其他 | C3: AA.91.01 | D3: 客户经营指标
A4: 三级 | B4: 其他 | C4: AA.91.01.01 | D4: 客户营销与投入
A5: 四级 | B5: 其他 | C5: AA.91.01.01.001 | D5: 新客营销支出
A6: 四级 | B6: 其他 | C6: AA.91.01.01.002 | D6: 存客营销支出
A7: 四级 | B7: 其他 | C7: AA.91.01.01.003 | D7: 新开通客户投入
A8: 四级 | B8: 其他 | C8: AA.91.01.01.004 | D8: 新发放投入
A9: 三级 | B9: 其他 | C9: AA.91.01.02 | D9: 客户规模与数量
A10: 四级 | B10: 其他 | C10: AA.91.01.02.101 | D10: LUM规模
A11: 四级 | B11: 其他 | C11: AA.91.01.02.001 | D11: 新客日均LUM
A12: 四级 | B12: 其他 | C12: AA.91.01.02.002 | D12: 存客日均LUM
A13: 四级 | B13: 其他 | C13: AA.91.01.02.005 | D13: 新发放LUM
... A27: 四级 | B27: 其他 | C27: AA.91.01.03.003 | D27: M7+现金回收额

Sheet AA微众银行损益表
A1: 科目层级 | B1: 科目性质 | C1: 科目代码 | D1: 科目名称 | E1: 25年实际 | F1: 26年预算 | G1: 26年预测 | H1: 26年1月实际 | I1: 26年2月实际 | J1: 26年3月实际 | K1: 26年4月预测 | L1: 26年5月预测 | M1: 26年6月预测 | N1: 26年7月预测 | O1: 26年8月预测 | P1: 26年9月预测 | Q1: 26年10月预测 | R1: 26年11月预测 | S1: 26年12月预测
A2: 一级 | B2: 其他 | C2: AA.46 | D2: 营业收入 | H2: 0.25 | I2: 0.23 | J2: 0.27 | K2: 0.28 | L2: 0.29 | M2: 0.3 | N2: 0.31 | O2: 0.3 | P2: 0.3 | Q2: 0.33 | R2: 0.32 | S2: 0.33
A3: 一级 | B3: 资产余额 | C3: AA.47 | D3: 减:资产减值损失 | H3: =H4+H6 -> 857500000 | I3: =I4+I6 -> 796250000 | J3: =J4+J6 -> 955500000 | K3: =K4+K6 -> 980000000 | L3: =L4+L6 -> 1004500000 | M3: =M4+M6 -> 1041250000 | N3: =N4+N6 -> 1078000000 | O3: =O4+O6 -> 1065750000 | ... S3: =S4+S6 -> 1163750000
A4: 二级 | B4: 资产余额 | C4: AA.47.01 | D4: 贷款减值损失 | H4: 808500000 | I4: 750750000 | J4: 900900000 | K4: 924000000 | L4: 947100000 | M4: 981750000 | N4: 1016400000 | O4: 1004850000 | P4: 981750000 | Q4: 1074150000 | R4: 1062600000 | S4: 1097250000
A5: 三级 | B5: 资产余额 | C5: AA.47.01.01 | D5: 实际风险成本 | H5: 122500000 | I5: 113750000 | J5: 136500000 | K5: 140000000 | L5: 143500000 | M5: 148750000 | N5: 154000000 | O5: 152250000 | P5: 148750000 | Q5: 162750000 | R5: 161000000 | S5: 166250000
A6: 二级 | B6: 资产余额 | C6: AA.47.02 | D6: 非贷减值损失 | H6: 49000000 | I6: 45500000 | J6: 54600000 | K6: 56000000 | L6: 57400000 | M6: 59500000 | N6: 61600000 | O6: 60900000 | P6: 59500000 | Q6: 65100000 | R6: 64400000 | S6: 66500000

Sheet AA微众银行资产质量表
A1: 科目层级 | B1: 科目性质 | C1: 科目代码 | D1: 科目名称 | E1: 25年实际 | F1: 26年预算 | G1: 26年预测 | H1: 26年1月实际 | I1: 26年2月实际 | J1: 26年3月实际 | K1: 26年4月预测 | L1: 26年5月预测 | M1: 26年6月预测 | N1: 26年7月预测 | O1: 26年8月预测 | P1: 26年9月预测 | Q1: 26年10月预测 | R1: 26年11月预测 | S1: 26年12月预测
A2: 二级 | B2: 其他 | C2: AA.38 | D2: 风险成本率 | H2: 0.21 | I2: 0.22 | J2: 0.23 | K2: 0.23 | L2: 0.24 | M2: 0.24 | N2: 0.25 | O2: 0.24 | P2: 0.24 | Q2: 0.23 | R2: 0.23 | S2: 0.24
A3: 三级 | B3: 其他 | C3: AA.38.01 | D3: 泛微粒贷
A4: 四级 | B4: 其他 | C4: AA.38.01.01 | D4: 微粒贷
A5: 四级 | B5: 其他 | C5: AA.38.01.02 | D5: 分付
A6: 三级 | B6: 其他 | C6: AA.38.02 | D6: 汽车金融
A7: 三级 | B7: 其他 | C7: AA.38.03 | D7: 财富
A8: 三级 | B8: 其他 | C8: AA.38.04 | D8: 小鹅
A9: 三级 | B9: 其他 | C9: AA.38.05 | D9: 企业金融
A10: 四级 | B10: 其他 | C10: AA.38.05.01 | D10: 一般贷款
A11: 二级 | B11: 支出 | C11: AA.02 | D11: 风险成本 | H11: 900000000 | I11: 936000000 | J11: 984000000 | K11: 996000000 | L11: 1020000000 | M11: 1044000000 | N11: 1056000000 | O11: 1032000000 | P11: 1008000000 | Q11: 996000000 | R11: 984000000 | S11: 1044000000
A12: 二级 | B12: 其他 | C12: AA.39 | D12: 不良贷款率
A13: 三级 | B13: 其他 | C13: AA.39.01 | D13: 泛微粒贷
A14: 四级 | B14: 其他 | C14: AA.39.01.01 | D14: 微粒贷
A15: 四级 | B15: 其他 | C15: AA.39.01.02 | D15: 分付
A16: 三级 | B16: 其他 | C16: AA.39.02 | D16: 汽车金融
A17: 三级 | B17: 其他 | C17: AA.39.03 | D17: 财富
A18: 三级 | B18: 其他 | C18: AA.39.04 | D18: 小鹅
A19: 三级 | B19: 其他 | C19: AA.39.05 | D19: 企业金融
A20: 四级 | B20: 其他 | C20: AA.39.05.01 | D20: 一般贷款
A21: 二级 | B21: 资产余额 | C21: AA.40 | D21: 不良贷款余额 | H21: =H22+H25+H26+H27+H28 -> 0 | I21: =I22+I25+I26+I27+I28 -> 0 | J21: =J22+J25+J26+J27+J28 -> 0 | K21: =K22+K25+K26+K27+K28 -> 0 | L21: =L22+L25+L26+L27+L28 -> 0 | M21: =M22+M25+M26+M27+M28 -> 0 | N21: =N22+N25+N26+N27+N28 -> 0 | O21: =O22+O25+O26+O27+O28 -> 0 | ... S21: =S22+S25+S26+S27+S28 -> 0
A22: 三级 | B22: 资产余额 | C22: AA.40.01 | D22: 泛微粒贷 | H22: =H23+H24 -> 0 | I22: =I23+I24 -> 0 | J22: =J23+J24 -> 0 | K22: =K23+K24 -> 0 | L22: =L23+L24 -> 0 | M22: =M23+M24 -> 0 | N22: =N23+N24 -> 0 | O22: =O23+O24 -> 0 | ... S22: =S23+S24 -> 0
A23: 四级 | B23: 资产余额 | C23: AA.40.01.01 | D23: 微粒贷
A24: 四级 | B24: 资产余额 | C24: AA.40.01.02 | D24: 分付
A25: 三级 | B25: 资产余额 | C25: AA.40.02 | D25: 汽车金融
A26: 三级 | B26: 资产余额 | C26: AA.40.03 | D26: 财富
A27: 三级 | B27: 资产余额 | C27: AA.40.04 | D27: 小鹅
A28: 三级 | B28: 资产余额 | C28: AA.40.05 | D28: 企业金融
A29: 四级 | B29: 资产余额 | C29: AA.40.05.01 | D29: 一般贷款
A30: 二级 | B30: 资产余额 | C30: AA.41 | D30: 不良贷款原值余额 | H30: =H31+H34+H35+H36+H37 -> 0 | I30: =I31+I34+I35+I36+I37 -> 0 | J30: =J31+J34+J35+J36+J37 -> 0 | K30: =K31+K34+K35+K36+K37 -> 0 | L30: =L31+L34+L35+L36+L37 -> 0 | M30: =M31+M34+M35+M36+M37 -> 0 | N30: =N31+N34+N35+N36+N37 -> 0 | O30: =O31+O34+O35+O36+O37 -> 0 | ... S30: =S31+S34+S35+S36+S37 -> 0
A31: 三级 | B31: 资产余额 | C31: AA.41.01 | D31: 泛微粒贷 | H31: =H32+H33 -> 0 | I31: =I32+I33 -> 0 | J31: =J32+J33 -> 0 | K31: =K32+K33 -> 0 | L31: =L32+L33 -> 0 | M31: =M32+M33 -> 0 | N31: =N32+N33 -> 0 | O31: =O32+O33 -> 0 | ... S31: =S32+S33 -> 0
A32: 四级 | B32: 资产余额 | C32: AA.41.01.01 | D32: 微粒贷
A33: 四级 | B33: 资产余额 | C33: AA.41.01.02 | D33: 分付
A34: 三级 | B34: 资产余额 | C34: AA.41.02 | D34: 汽车金融
A35: 三级 | B35: 资产余额 | C35: AA.41.03 | D35: 财富
A36: 三级 | B36: 资产余额 | C36: AA.41.04 | D36: 小鹅
A37: 三级 | B37: 资产余额 | C37: AA.41.05 | D37: 企业金融
A38: 四级 | B38: 资产余额 | C38: AA.41.05.01 | D38: 一般贷款
A39: 二级 | B39: 资产余额 | C39: AA.42 | D39: 年初不良贷款原值余额 | H39: =H40+H43+H44+H45+H46 -> 0 | I39: =I40+I43+I44+I45+I46 -> 0 | J39: =J40+J43+J44+J45+J46 -> 0 | K39: =K40+K43+K44+K45+K46 -> 0 | L39: =L40+L43+L44+L45+L46 -> 0 | M39: =M40+M43+M44+M45+M46 -> 0 | N39: =N40+N43+N44+N45+N46 -> 0 | O39: =O40+O43+O44+O45+O46 -> 0 | ... S39: =S40+S43+S44+S45+S46 -> 0
A40: 三级 | B40: 资产余额 | C40: AA.42.01 | D40: 泛微粒贷 | H40: =H41+H42 -> 0 | I40: =I41+I42 -> 0 | J40: =J41+J42 -> 0 | K40: =K41+K42 -> 0 | L40: =L41+L42 -> 0 | M40: =M41+M42 -> 0 | N40: =N41+N42 -> 0 | O40: =O41+O42 -> 0 | ... S40: =S41+S42 -> 0
...

Sheet AA微众银行利息净收入表
A1: 科目层级 | B1: 科目性质 | C1: 科目代码 | D1: 科目名称 | E1: 25年实际 | F1: 26年预算 | G1: 26年预测 | H1: 26年1月实际 | I1: 26年2月实际 | J1: 26年3月实际 | K1: 26年4月预测 | L1: 26年5月预测 | M1: 26年6月预测 | N1: 26年7月预测 | O1: 26年8月预测 | P1: 26年9月预测 | Q1: 26年10月预测 | R1: 26年11月预测 | S1: 26年12月预测
A2: 二级 | B2: 资产日均 | C2: AA.50 | D2: 生息资产日均规模 | H2: =H3+H4+H5 -> 36750000000 | I2: =I3+I4+I5 -> 38220000000 | J2: =J3+J4+J5 -> 40180000000 | K2: =K3+K4+K5 -> 40670000000 | L2: =L3+L4+L5 -> 41650000000 | M2: =M3+M4+M5 -> 42630000000 | N2: =N3+N4+N5 -> 43120000000 | O2: =O3+O4+O5 -> 42140000000 | ... S2: =S3+S4+S5 -> 42630000000
A3: 三级 | B3: 资产日均 | C3: AA.11.01 | D3: 各项贷款 | H3: 26250000000 | I3: 27300000000 | J3: 28700000000 | K3: 29050000000 | L3: 29750000000 | M3: 30450000000 | N3: 30800000000 | O3: 30100000000 | P3: 29400000000 | Q3: 29050000000 | R3: 28700000000 | S3: 30450000000
A4: 二级 | B4: 资产日均 | C4: AA.23 | D4: 存放央行
A5: 二级 | B5: 资产日均 | C5: AA.25 | D5: 同业资产 | H5: =H6+H7+H8+H9+H10 -> 10500000000 | I5: =I6+I7+I8+I9+I10 -> 10920000000 | J5: =J6+J7+J8+J9+J10 -> 11480000000 | K5: =K6+K7+K8+K9+K10 -> 11620000000 | L5: =L6+L7+L8+L9+L10 -> 11900000000 | M5: =M6+M7+M8+M9+M10 -> 12180000000 | N5: =N6+N7+N8+N9+N10 -> 12320000000 | O5: =O6+O7+O8+O9+O10 -> 12040000000 | ... S5: =S6+S7+S8+S9+S10 -> 12180000000
A6: 三级 | B6: 资产日均 | C6: AA.25.01 | D6: 存放同业 | H6: 10500000000 | I6: 10920000000 | J6: 11480000000 | K6: 11620000000 | L6: 11900000000 | M6: 12180000000 | N6: 12320000000 | O6: 12040000000 | P6: 11760000000 | Q6: 11620000000 | R6: 11480000000 | S6: 12180000000
A7: 三级 | B7: 资产日均 | C7: AA.25.02 | D7: 拆放同业
A8: 三级 | B8: 资产日均 | C8: AA.25.03 | D8: 买入返售
A9: 三级 | B9: 资产日均 | C9: AA.25.04 | D9: 债券投资
A10: 三级 | B10: 资产日均 | C10: AA.25.05 | D10: 同业存单投资
A11: 二级 | B11: 负债日均 | C11: AA.51 | D11: 付息负债日均规模 | H11: =H12+H13 -> 44250000000 | I11: =I12+I13 -> 46020000000 | J11: =J12+J13 -> 48380000000 | K11: =K12+K13 -> 48970000000 | L11: =L12+L13 -> 50150000000 | M11: =M12+M13 -> 51330000000 | N11: =N12+N13 -> 51920000000 | O11: =O12+O13 -> 50740000000 | ... S11: =S12+S13 -> 51330000000
A12: 三级 | B12: 负债日均 | C12: AA.13.01 | D12: 各项存款 | H12: 33750000000 | I12: 35100000000 | J12: 36900000000 | K12: 37350000000 | L12: 38250000000 | M12: 39150000000 | N12: 39600000000 | O12: 38700000000 | P12: 37800000000 | Q12: 37350000000 | R12: 36900000000 | S12: 39150000000
A13: 二级 | B13: 负债日均 | C13: AA.27 | D13: 同业负债 | H13: =H14+H15+H16+H17+H19+H18 -> 10500000000 | I13: =I14+I15+I16+I17+I19+I18 -> 10920000000 | J13: =J14+J15+J16+J17+J19+J18 -> 11480000000 | K13: =K14+K15+K16+K17+K19+K18 -> 11620000000 | L13: =L14+L15+L16+L17+L19+L18 -> 11900000000 | M13: =M14+M15+M16+M17+M19+M18 -> 12180000000 | N13: =N14+N15+N16+N17+N19+N18 -> 12320000000 | O13: =O14+O15+O16+O17+O19+O18 -> 12040000000 | ... S13: =S14+S15+S16+S17+S19+S18 -> 12180000000
A14: 三级 | B14: 负债日均 | C14: AA.27.01 | D14: 向央行借款
A15: 三级 | B15: 负债日均 | C15: AA.27.02 | D15: 同业存放 | H15: 10500000000 | I15: 10920000000 | J15: 11480000000 | K15: 11620000000 | L15: 11900000000 | M15: 12180000000 | N15: 12320000000 | O15: 12040000000 | P15: 11760000000 | Q15: 11620000000 | R15: 11480000000 | S15: 12180000000
A16: 三级 | B16: 负债日均 | C16: AA.27.03 | D16: 同业拆入
A17: 三级 | B17: 负债日均 | C17: AA.27.04 | D17: 转贷款
A18: 三级 | B18: 负债日均 | C18: AA.27.05 | D18: 卖出回购
A19: 三级 | B19: 负债日均 | C19: AA.27.06 | D19: 发行同业存单
A20: 二级 | B20: 收入 | C20: AA.14 | D20: 生息资产利息收入 | H20: =H21+H22+H23 -> 2693250000 | I20: =I21+I22+I23 -> 2800980000 | J20: =J21+J22+J23 -> 2944620000 | K20: =K21+K22+K23 -> 2980530000 | L20: =L21+L22+L23 -> 3052350000 | M20: =M21+M22+M23 -> 3124170000 | N20: =N21+N22+N23 -> 3160080000 | O20: =O21+O22+O23 -> 3088260000 | ... S20: =S21+S22+S23 -> 3124170000
A21: 三级 | B21: 收入 | C21: AA.14.01 | D21: 各项贷款 | H21: 2409750000 | I21: 2506140000 | J21: 2634660000 | K21: 2666790000 | L21: 2731050000 | M21: 2795310000 | N21: 2827440000 | O21: 2763180000 | P21: 2698920000 | Q21: 2666790000 | R21: 2634660000 | S21: 2795310000
A22: 三级 | B22: 收入 | C22: AA.14.02 | D22: 存放央行 | H22: 283500000 | I22: 294840000 | J22: 309960000 | K22: 313740000 | L22: 321300000 | M22: 328860000 | N22: 332640000 | O22: 325080000 | P22: 317520000 | Q22: 313740000 | R22: 309960000 | S22: 328860000
A23: 三级 | B23: 收入 | C23: AA.14.03 | D23: 同业资产 | H23: =H24+H25+H26+H27+H28 -> 0 | I23: =I24+I25+I26+I27+I28 -> 0 | J23: =J24+J25+J26+J27+J28 -> 0 | K23: =K24+K25+K26+K27+K28 -> 0 | L23: =L24+L25+L26+L27+L28 -> 0 | M23: =M24+M25+M26+M27+M28 -> 0 | N23: =N24+N25+N26+N27+N28 -> 0 | O23: =O24+O25+O26+O27+O28 -> 0 | ... S23: =S24+S25+S26+S27+S28 -> 0
A24: 四级 | B24: 收入 | C24: AA.14.03.01 | D24: 存放同业
A25: 四级 | B25: 收入 | C25: AA.14.03.02 | D25: 拆放同业
A26: 四级 | B26: 收入 | C26: AA.14.03.03 | D26: 买入返售
A27: 四级 | B27: 收入 | C27: AA.14.03.04 | D27: 债券投资
A28: 四级 | B28: 收入 | C28: AA.14.03.05 | D28: 同业存单投资
A29: 二级 | B29: 支出 | C29: AA.16 | D29: 付息负债利息支出 | H29: =H30+H31 -> 756000000 | I29: =I30+I31 -> 786240000 | J29: =J30+J31 -> 826560000 | K29: =K30+K31 -> 836640000 | L29: =L30+L31 -> 856800000 | M29: =M30+M31 -> 876960000 | N29: =N30+N31 -> 887040000 | O29: =O30+O31 -> 866880000 | ... S29: =S30+S31 -> 876960000
A30: 三级 | B30: 支出 | C30: AA.16.01 | D30: 各项存款 | H30: 756000000 | I30: 786240000 | J30: 826560000 | K30: 836640000 | L30: 856800000 | M30: 876960000 | N30: 887040000 | O30: 866880000 | P30: 846720000 | Q30: 836640000 | R30: 826560000 | S30: 876960000
A31: 三级 | B31: 支出 | C31: AA.16.02 | D31: 同业负债 | H31: =H32+H33+H34+H35+H37+H36 -> 0 | I31: =I32+I33+I34+I35+I37+I36 -> 0 | J31: =J32+J33+J34+J35+J37+J36 -> 0 | K31: =K32+K33+K34+K35+K37+K36 -> 0 | L31: =L32+L33+L34+L35+L37+L36 -> 0 | M31: =M32+M33+M34+M35+M37+M36 -> 0 | N31: =N32+N33+N34+N35+N37+N36 -> 0 | O31: =O32+O33+O34+O35+O37+O36 -> 0 | ... S31: =S32+S33+S34+S35+S37+S36 -> 0
A32: 四级 | B32: 支出 | C32: AA.16.02.01 | D32: 向央行借款
A33: 四级 | B33: 支出 | C33: AA.16.02.02 | D33: 同业存放
A34: 四级 | B34: 支出 | C34: AA.16.02.03 | D34: 同业拆入
A35: 四级 | B35: 支出 | C35: AA.16.02.04 | D35: 转贷款
A36: 四级 | B36: 支出 | C36: AA.16.02.05 | D36: 卖出回购
A37: 四级 | B37: 支出 | C37: AA.16.02.06 | D37: 发行同业存单
A38: 二级 | B38: 其他 | C38: AA.52 | D38: 生息资产收息率 | H38: =H20/H2 -> 0.073285714 | I38: =I20/I2 -> 0.073285714 | J38: =J20/J2 -> 0.073285714 | K38: =K20/K2 -> 0.073285714 | L38: =L20/L2 -> 0.073285714 | M38: =M20/M2 -> 0.073285714 | N38: =N20/N2 -> 0.073285714 | O38: =O20/O2 -> 0.073285714 | ... S38: =S20/S2 -> 0.073285714
A39: 三级 | B39: 其他 | C39: AA.52.01 | D39: 各项贷款 | H39: =H21/H3 -> 0.0918 | I39: =I21/I3 -> 0.0918 | J39: =J21/J3 -> 0.0918 | K39: =K21/K3 -> 0.0918 | L39: =L21/L3 -> 0.0918 | M39: =M21/M3 -> 0.0918 | N39: =N21/N3 -> 0.0918 | O39: =O21/O3 -> 0.0918 | ... S39: =S21/S3 -> 0.0918
A40: 三级 | B40: 其他 | C40: AA.52.02 | D40: 存放央行 | H40: =H22/H4 -> #DIV/0! | I40: =I22/I4 -> #DIV/0! | J40: =J22/J4 -> #DIV/0! | K40: =K22/K4 -> #DIV/0! | L40: =L22/L4 -> #DIV/0! | M40: =M22/M4 -> #DIV/0! | N40: =N22/N4 -> #DIV/0! | O40: =O22/O4 -> #DIV/0! | ... S40: =S22/S4 -> #DIV/0!
...

Sheet A个金群业务状况表
A1: 科目层级 | B1: 科目性质 | C1: 科目代码 | D1: 科目名称 | E1: 25年实际 | F1: 26年预算 | G1: 26年预测 | H1: 26年1月实际 | I1: 26年2月实际 | J1: 26年3月实际 | K1: 26年4月预测 | L1: 26年5月预测 | M1: 26年6月预测 | N1: 26年7月预测 | O1: 26年8月预测 | P1: 26年9月预测 | Q1: 26年10月预测 | R1: 26年11月预测 | S1: 26年12月预测
A2: 二级 | B2: 收入 | C2: A.01 | D2: 营业收入
A3: 三级 | B3: 收入 | C3: A.01.01 | D3: 利息净收入
A4: 四级 | B4: 收入 | C4: A.01.01.01 | D4: 资产业务
A5: 二级 | B5: 收入 | C5: A.14 | D5: 利息收入
A6: 二级 | B6: 支出 | C6: A.15 | D6: FTP成本
A7: 四级 | B7: 收入 | C7: A.01.01.02 | D7: 负债业务
A8: 二级 | B8: 支出 | C8: A.16 | D8: 利息支出
A9: 二级 | B9: 支出 | C9: A.17 | D9: FTP收入
A10: 三级 | B10: 收入 | C10: A.01.02 | D10: 净手续费收入
A11: 二级 | B11: 收入 | C11: A.18 | D11: 手续费收入
A12: 二级 | B12: 支出 | C12: A.19 | D12: 手续费支出
A13: 三级 | B13: 收入 | C13: A.01.03 | D13: 其他营收
... A115: 五级 | B115: 投入产出 | C115: A.91.01.03.003 | D115: M7+现金回收额

Sheet A个金群业务支出评估
A1: 科目层级 | B1: 科目性质 | C1: 科目代码 | D1: 科目名称 | E1: 25年实际 | F1: 26年预算 | G1: 26年预测 | H1: 26年1月实际 | I1: 26年2月实际 | J1: 26年3月实际 | K1: 26年4月预测 | L1: 26年5月预测 | M1: 26年6月预测 | N1: 26年7月预测 | O1: 26年8月预测 | P1: 26年9月预测 | Q1: 26年10月预测 | R1: 26年11月预测 | S1: 26年12月预测
A2: 一级 | B2: 其他 | C2: A.91 | D2: 业务支出评估
A3: 二级 | B3: 其他 | C3: A.91.01 | D3: 客户经营指标
A4: 三级 | B4: 其他 | C4: A.91.01.01 | D4: 客户营销与投入
A5: 四级 | B5: 其他 | C5: A.91.01.01.001 | D5: 新客营销支出
A6: 四级 | B6: 其他 | C6: A.91.01.01.002 | D6: 存客营销支出
A7: 四级 | B7: 其他 | C7: A.91.01.01.003 | D7: 新开通客户投入
A8: 四级 | B8: 其他 | C8: A.91.01.01.004 | D8: 新发放投入
A9: 三级 | B9: 其他 | C9: A.91.01.02 | D9: 客户规模与数量
A10: 四级 | B10: 其他 | C10: A.91.01.02.101 | D10: LUM规模
A11: 四级 | B11: 其他 | C11: A.91.01.02.001 | D11: 新客日均LUM
A12: 四级 | B12: 其他 | C12: A.91.01.02.002 | D12: 存客日均LUM
A13: 四级 | B13: 其他 | C13: A.91.01.02.005 | D13: 新发放LUM
... A27: 四级 | B27: 其他 | C27: A.91.01.03.003 | D27: M7+现金回收额

Sheet A01泛微粒贷业务状况表
A1: 科目层级 | B1: 科目性质 | C1: 科目代码 | D1: 科目名称 | E1: 25年实际 | F1: 26年预算 | G1: 26年预测 | H1: 26年1月实际 | I1: 26年2月实际 | J1: 26年3月实际 | K1: 26年4月预测 | L1: 26年5月预测 | M1: 26年6月预测 | N1: 26年7月预测 | O1: 26年8月预测 | P1: 26年9月预测 | Q1: 26年10月预测 | R1: 26年11月预测 | S1: 26年12月预测
A2: 二级 | B2: 收入 | C2: A01.01 | D2: 营业收入 | H2: =H3+H6+H7 -> 1341900000 | I2: =I3+I6+I7 -> 1246050000 | J2: =J3+J6+J7 -> 1495260000 | K2: =K3+K6+K7 -> 498400000 | L2: =L3+L6+L7 -> 510860000 | M2: =M3+M6+M7 -> 529550000 | N2: =N3+N6+N7 -> 548240000 | O2: =O3+O6+O7 -> 542010000 | ... S2: =S3+S6+S7 -> 591850000
A3: 三级 | B3: 收入 | C3: A01.01.01 | D3: 利息净收入 | H3: =H4+H5 -> 748300000 | I3: =I4+I5 -> 694850000 | J3: =J4+J5 -> 833820000 | K3: =K4+K5 -> -24000000 | L3: =L4+L5 -> -24600000 | M3: =M4+M5 -> -25500000 | N3: =N4+N5 -> -26400000 | O3: =O4+O5 -> -26100000 | ... S3: =S4+S5 -> -28500000
A4: 四级 | B4: 收入 | C4: A01.01.01.01 | D4: 资产业务 | H4: =H59-H90 -> 769300000 | I4: =I59-I90 -> 714350000 | J4: =J59-J90 -> 857220000 | K4: =K59-K90 -> -24000000 | L4: =L59-L90 -> -24600000 | M4: =M59-M90 -> -25500000 | N4: =N59-N90 -> -26400000 | O4: =O59-O90 -> -26100000 | ... S4: =S59-S90 -> -28500000
A5: 四级 | B5: 收入 | C5: A01.01.01.02 | D5: 负债业务 | H5: =H107-H101 -> -21000000 | I5: =I107-I101 -> -19500000 | J5: =J107-J101 -> -23400000 | K5: =K107-K101 -> 0 | L5: =L107-L101 -> 0 | M5: =M107-M101 -> 0 | N5: =N107-N101 -> 0 | O5: =O107-O101 -> 0 | ... S5: =S107-S101 -> 0
A6: 三级 | B6: 收入 | C6: A01.01.02 | D6: 手续费净收入 | H6: =H113-H129 -> 465500000 | I6: =I113-I129 -> 432250000 | J6: =J113-J129 -> 518700000 | K6: =K113-K129 -> 376000000 | L6: =L113-L129 -> 385400000 | M6: =M113-M129 -> 399500000 | N6: =N113-N129 -> 413600000 | O6: =O113-O129 -> 408900000 | ... S6: =S113-S129 -> 446500000
A7: 三级 | B7: 收入 | C7: A01.01.03 | D7: 其他营收 | H7: =H150+H151 -> 128100000 | I7: =I150+I151 -> 118950000 | J7: =J150+J151 -> 142740000 | K7: =K150+K151 -> 146400000 | L7: =L150+L151 -> 150060000 | M7: =M150+M151 -> 155550000 | N7: =N150+N151 -> 161040000 | O7: =O150+O151 -> 159210000 | ... S7: =S150+S151 -> 173850000
A8: 二级 | B8: 支出 | C8: A01.02 | D8: 减:风险成本 | H8: 600600000 | I8: 557700000 | J8: 669240000 | K8: 686400000 | L8: 703560000 | M8: 729300000 | N8: 755040000 | O8: 746460000 | P8: 729300000 | Q8: 797940000 | R8: 789360000 | S8: 815100000
A9: 二级 | B9: 收入 | C9: A01.03 | D9: 净收入 | H9: =H2-H8 -> 741300000 | I9: =I2-I8 -> 688350000 | J9: =J2-J8 -> 826020000 | K9: =K2-K8 -> -188000000 | L9: =L2-L8 -> -192700000 | M9: =M2-M8 -> -199750000 | N9: =N2-N8 -> -206800000 | O9: =O2-O8 -> -204450000 | ... S9: =S2-S8 -> -223250000
A10: 二级 | B10: 支出 | C10: A01.04 | D10: 减:税金及附加 | H10: 24500000 | I10: 22750000 | J10: 27300000 | K10: 28000000 | L10: 28700000 | M10: 29750000 | N10: 30800000 | O10: 30450000 | P10: 29750000 | Q10: 32550000 | R10: 32200000 | S10: 33250000
A11: 二级 | B11: 支出 | C11: A01.05 | D11: 减:直接费用 | H11: =H12+H15+H18+H25+H26 -> 338100000 | I11: =I12+I15+I18+I25+I26 -> 313950000 | J11: =J12+J15+J18+J25+J26 -> 376740000 | K11: =K12+K15+K18+K25+K26 -> 386400000 | L11: =L12+L15+L18+L25+L26 -> 396060000 | M11: =M12+M15+M18+M25+M26 -> 410550000 | N11: =N12+N15+N18+N25+N26 -> 425040000 | O11: =O12+O15+O18+O25+O26 -> 420210000 | ... S11: =S12+S15+S18+S25+S26 -> 458850000
A12: 三级 | B12: 支出 | C12: A01.05.01 | D12: 人力费用(不含IT) | H12: =H13+H14 -> 132300000 | I12: =I13+I14 -> 122850000 | J12: =J13+J14 -> 147420000 | K12: =K13+K14 -> 151200000 | L12: =L13+L14 -> 154980000 | M12: =M13+M14 -> 160650000 | N12: =N13+N14 -> 166320000 | O12: =O13+O14 -> 164430000 | ... S12: =S13+S14 -> 179550000
A13: 四级 | B13: 支出 | C13: A01.05.01.01 | D13: 常规人力 | H13: 88200000 | I13: 81900000 | J13: 98280000 | K13: 100800000 | L13: 103320000 | M13: 107100000 | N13: 110880000 | O13: 109620000 | P13: 107100000 | Q13: 117180000 | R13: 115920000 | S13: 119700000
A14: 四级 | B14: 支出 | C14: A01.05.01.02 | D14: 特别人力 | H14: 44100000 | I14: 40950000 | J14: 49140000 | K14: 50400000 | L14: 51660000 | M14: 53550000 | N14: 55440000 | O14: 54810000 | P14: 53550000 | Q14: 58590000 | R14: 57960000 | S14: 59850000
A15: 三级 | B15: 支出 | C15: A01.05.02 | D15: 业务费用 | H15: =H16+H17 -> 88200000 | I15: =I16+I17 -> 81900000 | J15: =J16+J17 -> 98280000 | K15: =K16+K17 -> 100800000 | L15: =L16+L17 -> 103320000 | M15: =M16+M17 -> 107100000 | N15: =N16+N17 -> 110880000 | O15: =O16+O17 -> 109620000 | ... S15: =S16+S17 -> 119700000
A16: 四级 | B16: 支出 | C16: A01.05.02.01 | D16: 营销费用 | H16: 53200000 | I16: 49400000 | J16: 59280000 | K16: 60800000 | L16: 62320000 | M16: 64600000 | N16: 66880000 | O16: 66120000 | P16: 64600000 | Q16: 70680000 | R16: 69920000 | S16: 72200000
A17: 四级 | B17: 支出 | C17: A01.05.02.02 | D17: 运营费用 | H17: 35000000 | I17: 32500000 | J17: 39000000 | K17: 40000000 | L17: 41000000 | M17: 42500000 | N17: 44000000 | O17: 43500000 | P17: 42500000 | Q17: 46500000 | R17: 46000000 | S17: 47500000
A18: 三级 | B18: 支出 | C18: A01.05.03 | D18: IT费用 | H18: =H19+H22+H23+H24 -> 73500000 | I18: =I19+I22+I23+I24 -> 68250000 | J18: =J19+J22+J23+J24 -> 81900000 | K18: =K19+K22+K23+K24 -> 84000000 | L18: =L19+L22+L23+L24 -> 86100000 | M18: =M19+M22+M23+M24 -> 89250000 | N18: =N19+N22+N23+N24 -> 92400000 | O18: =O19+O22+O23+O24 -> 91350000 | ... S18: =S19+S22+S23+S24 -> 99750000
A19: 四级 | B19: 支出 | C19: A01.05.03.01 | D19: IT人力 | H19: =H20+H21 -> 35000000 | I19: =I20+I21 -> 32500000 | J19: =J20+J21 -> 39000000 | K19: =K20+K21 -> 40000000 | L19: =L20+L21 -> 41000000 | M19: =M20+M21 -> 42500000 | N19: =N20+N21 -> 44000000 | O19: =O20+O21 -> 43500000 | ... S19: =S20+S21 -> 47500000
A20: 五级 | B20: 支出 | C20: A01.05.03.01.01 | D20: IT常规人力 | H20: 20300000 | I20: 18850000 | J20: 22620000 | K20: 23200000 | L20: 23780000 | M20: 24650000 | N20: 25520000 | O20: 25230000 | P20: 24650000 | Q20: 26970000 | R20: 26680000 | S20: 27550000
A21: 五级 | B21: 支出 | C21: A01.05.03.01.02 | D21: IT特别人力 | H21: 14700000 | I21: 13650000 | J21: 16380000 | K21: 16800000 | L21: 17220000 | M21: 17850000 | N21: 18480000 | O21: 18270000 | P21: 17850000 | Q21: 19530000 | R21: 19320000 | S21: 19950000
A22: 四级 | B22: 支出 | C22: A01.05.03.02 | D22: 科技费用 | H22: 14700000 | I22: 13650000 | J22: 16380000 | K22: 16800000 | L22: 17220000 | M22: 17850000 | N22: 18480000 | O22: 18270000 | P22: 17850000 | Q22: 19530000 | R22: 19320000 | S22: 19950000
A23: 四级 | B23: 支出 | C23: A01.05.03.03 | D23: IT职场 | H23: 11900000 | I23: 11050000 | J23: 13260000 | K23: 13600000 | L23: 13940000 | M23: 14450000 | N23: 14960000 | O23: 14790000 | P23: 14450000 | Q23: 15810000 | R23: 15640000 | S23: 16150000
A24: 四级 | B24: 支出 | C24: A01.05.03.04 | D24: IT日常 | H24: 11900000 | I24: 11050000 | J24: 13260000 | K24: 13600000 | L24: 13940000 | M24: 14450000 | N24: 14960000 | O24: 14790000 | P24: 14450000 | Q24: 15810000 | R24: 15640000 | S24: 16150000
A25: 三级 | B25: 支出 | C25: A01.05.04 | D25: 职场费用 | H25: 23800000 | I25: 22100000 | J25: 26520000 | K25: 27200000 | L25: 27880000 | M25: 28900000 | N25: 29920000 | O25: 29580000 | P25: 28900000 | Q25: 31620000 | R25: 31280000 | S25: 32300000
A26: 三级 | B26: 支出 | C26: A01.05.05 | D26: 日常费用 | H26: 20300000 | I26: 18850000 | J26: 22620000 | K26: 23200000 | L26: 23780000 | M26: 24650000 | N26: 25520000 | O26: 25230000 | P26: 24650000 | Q26: 26970000 | R26: 26680000 | S26: 27550000
A27: 二级 | B27: 收入 | C27: A01.06 | D27: 加:营业外净收入 | H27: 9800000 | I27: 9100000 | J27: 10920000 | K27: 11200000 | L27: 11480000 | M27: 11900000 | N27: 12320000 | O27: 12180000 | P27: 11900000 | Q27: 13020000 | R27: 12880000 | S27: 13300000
A28: 二级 | B28: 利润 | C28: A01.07 | D28: 分摊前利润 | H28: =H9-H10-H11+H27 -> 388500000 | I28: =I9-I10-I11+I27 -> 360750000 | J28: =J9-J10-J11+J27 -> 432900000 | K28: =K9-K10-K11+K27 -> -591200000 | L28: =L9-L10-L11+L27 -> -605980000 | M28: =M9-M10-M11+M27 -> -628150000 | N28: =N9-N10-N11+N27 -> -650320000 | O28: =O9-O10-O11+O27 -> -642930000 | ... S28: =S9-S10-S11+S27 -> -702050000
A29: 二级 | B29: 支出 | C29: A01.08 | D29: 减:固定管理费 | H29: 35000000 | I29: 32500000 | J29: 39000000 | K29: 40000000 | L29: 41000000 | M29: 42500000 | N29: 44000000 | O29: 43500000 | P29: 42500000 | Q29: 46500000 | R29: 46000000 | S29: 47500000
A30: 二级 | B30: 利润 | C30: A01.09 | D30: 税前利润 | H30: =H28-H29 -> 353500000 | I30: =I28-I29 -> 328250000 | J30: =J28-J29 -> 393900000 | K30: =K28-K29 -> -631200000 | L30: =L28-L29 -> -646980000 | M30: =M28-M29 -> -670650000 | N30: =N28-N29 -> -694320000 | O30: =O28-O29 -> -686430000 | ... S30: =S28-S29 -> -749550000
A31: 二级 | B31: 资产余额 | C31: A01.10 | D31: 管理贷款余额 | H31: =H32+H37+H38 -> 18375000000 | I31: =I32+I37+I38 -> 19110000000 | J31: =J32+J37+J38 -> 20090000000 | K31: =K32+K37+K38 -> 20335000000 | L31: =L32+L37+L38 -> 20825000000 | M31: =M32+M37+M38 -> 21315000000 | N31: =N32+N37+N38 -> 21560000000 | O31: =O32+O37+O38 -> 21070000000 | ... S31: =S32+S37+S38 -> 21315000000
A32: 三级 | B32: 资产余额 | C32: A01.10.01 | D32: 自持余额 | H32: =H33 -> 14700000000 | I32: =I33 -> 15288000000 | J32: =J33 -> 16072000000 | K32: =K33 -> 16268000000 | L32: =L33 -> 16660000000 | M32: =M33 -> 17052000000 | N32: =N33 -> 17248000000 | O32: =O33 -> 16856000000 | ... S32: =S33 -> 17052000000
A33: 四级 | B33: 资产余额 | C33: A01.10.01.01 | D33: 一般贷款 | H33: =H34+H36 -> 14700000000 | I33: =I34+I36 -> 15288000000 | J33: =J34+J36 -> 16072000000 | K33: =K34+K36 -> 16268000000 | L33: =L34+L36 -> 16660000000 | M33: =M34+M36 -> 17052000000 | N33: =N34+N36 -> 17248000000 | O33: =O34+O36 -> 16856000000 | ... S33: =S34+S36 -> 17052000000
A34: 五级 | B34: 资产余额 | C34: A01.10.01.01.01 | D34: 微粒贷 | H34: 10106250000 | I34: 10510500000 | J34: 11049500000 | K34: 11184250000 | L34: 11453750000 | M34: 11723250000 | N34: 11858000000 | O34: 11588500000 | P34: 11319000000 | Q34: 11184250000 | R34: 11049500000 | S34: 11723250000
A35: 六级 | B35: 资产余额 | C35: A01.10.01.01.01.01 | D35: 其中:分期 | H35: 3675000000 | I35: 3822000000 | J35: 4018000000 | K35: 4067000000 | L35: 4165000000 | M35: 4263000000 | N35: 4312000000 | O35: 4214000000 | P35: 4116000000 | Q35: 4067000000 | R35: 4018000000 | S35: 4263000000
A36: 五级 | B36: 资产余额 | C36: A01.10.01.01.02 | D36: 分付 | H36: 4593750000 | I36: 4777500000 | J36: 5022500000 | K36: 5083750000 | L36: 5206250000 | M36: 5328750000 | N36: 5390000000 | O36: 5267500000 | P36: 5145000000 | Q36: 5083750000 | R36: 5022500000 | S36: 5328750000
A37: 三级 | B37: 资产余额 | C37: A01.10.02 | D37: 联贷 | H37: 2205000000 | I37: 2293200000 | J37: 2410800000 | K37: 2440200000 | L37: 2499000000 | M37: 2557800000 | N37: 2587200000 | O37: 2528400000 | P37: 2469600000 | Q37: 2440200000 | R37: 2410800000 | S37: 2557800000
A38: 三级 | B38: 资产余额 | C38: A01.10.03 | D38: 流转 | H38: 1470000000 | I38: 1528800000 | J38: 1607200000 | K38: 1626800000 | L38: 1666000000 | M38: 1705200000 | N38: 1724800000 | O38: 1685600000 | P38: 1646400000 | Q38: 1626800000 | R38: 1607200000 | S38: 1705200000
A39: 二级 | B39: 资产日均 | C39: A01.11 | D39: 管理贷款日均 | H39: =H40+H45+H46 -> 18375000000 | I39: =I40+I45+I46 -> 19110000000 | J39: =J40+J45+J46 -> 20090000000 | K39: =K40+K45+K46 -> 20335000000 | L39: =L40+L45+L46 -> 20825000000 | M39: =M40+M45+M46 -> 21315000000 | N39: =N40+N45+N46 -> 21560000000 | O39: =O40+O45+O46 -> 21070000000 | ... S39: =S40+S45+S46 -> 21315000000
A40: 三级 | B40: 资产日均 | C40: A01.11.01 | D40: 自持 | H40: =H41 -> 14700000000 | I40: =I41 -> 15288000000 | J40: =J41 -> 16072000000 | K40: =K41 -> 16268000000 | L40: =L41 -> 16660000000 | M40: =M41 -> 17052000000 | N40: =N41 -> 17248000000 | O40: =O41 -> 16856000000 | ... S40: =S41 -> 17052000000
...

Sheet A01泛微粒贷业务支出评估
A1: 科目层级 | B1: 科目性质 | C1: 科目代码 | D1: 科目名称 | E1: 25年实际 | F1: 26年预算 | G1: 26年预测 | H1: 26年1月实际 | I1: 26年2月实际 | J1: 26年3月实际 | K1: 26年4月预测 | L1: 26年5月预测 | M1: 26年6月预测 | N1: 26年7月预测 | O1: 26年8月预测 | P1: 26年9月预测 | Q1: 26年10月预测 | R1: 26年11月预测 | S1: 26年12月预测
A2: 一级 | B2: 其他 | C2: A01.91 | D2: 业务支出评估
A3: 二级 | B3: 其他 | C3: A01.91.01 | D3: 客户经营指标
A4: 三级 | B4: 其他 | C4: A01.91.01.01 | D4: 客户营销与投入
A5: 四级 | B5: 其他 | C5: A01.91.01.01.001 | D5: 新客营销支出 | H5: 35000000 | I5: 32500000 | J5: 39000000 | K5: 40000000 | L5: 41000000 | M5: 42500000 | N5: 44000000 | O5: 43500000 | P5: 42500000 | Q5: 46500000 | R5: 46000000 | S5: 47500000
A6: 四级 | B6: 其他 | C6: A01.91.01.01.002 | D6: 存客营销支出 | H6: 24500000 | I6: 22750000 | J6: 27300000 | K6: 28000000 | L6: 28700000 | M6: 29750000 | N6: 30800000 | O6: 30450000 | P6: 29750000 | Q6: 32550000 | R6: 32200000 | S6: 33250000
A7: 四级 | B7: 其他 | C7: A01.91.01.01.003 | D7: 新开通客户投入 | H7: 14000000 | I7: 13000000 | J7: 15600000 | K7: 16000000 | L7: 16400000 | M7: 17000000 | N7: 17600000 | O7: 17400000 | P7: 17000000 | Q7: 18600000 | R7: 18400000 | S7: 19000000
A8: 四级 | B8: 其他 | C8: A01.91.01.01.004 | D8: 新发放投入 | H8: 10500000 | I8: 9750000 | J8: 11700000 | K8: 12000000 | L8: 12300000 | M8: 12750000 | N8: 13200000 | O8: 13050000 | P8: 12750000 | Q8: 13950000 | R8: 13800000 | S8: 14250000
A9: 三级 | B9: 其他 | C9: A01.91.01.02 | D9: 客户规模与数量
A10: 四级 | B10: 其他 | C10: A01.91.01.02.101 | D10: LUM规模 | H10: 15000000000 | I10: 15600000000 | J10: 16400000000 | K10: 16600000000 | L10: 17000000000 | M10: 17400000000 | N10: 17600000000 | O10: 17200000000 | P10: 16800000000 | Q10: 16600000000 | R10: 16400000000 | S10: 17400000000
A11: 四级 | B11: 其他 | C11: A01.91.01.02.001 | D11: 新客日均LUM | H11: 5600000000 | I11: 5200000000 | J11: 6240000000 | K11: 6400000000 | L11: 6560000000 | M11: 6800000000 | N11: 7040000000 | O11: 6960000000 | P11: 6800000000 | Q11: 7440000000 | R11: 7360000000 | S11: 7600000000
A12: 四级 | B12: 其他 | C12: A01.91.01.02.002 | D12: 存客日均LUM | H12: 8400000000 | I12: 7800000000 | J12: 9360000000 | K12: 9600000000 | L12: 9840000000 | M12: 10200000000 | N12: 10560000000 | O12: 10440000000 | P12: 10200000000 | Q12: 11160000000 | R12: 11040000000 | S12: 11400000000
A13: 四级 | B13: 其他 | C13: A01.91.01.02.005 | D13: 新发放LUM | H13: 1750000000 | I13: 1625000000 | J13: 1950000000 | K13: 2000000000 | L13: 2050000000 | M13: 2125000000 | N13: 2200000000 | O13: 2175000000 | P13: 2125000000 | Q13: 2325000000 | R13: 2300000000 | S13: 2375000000
A14: 四级 | B14: 其他 | C14: A01.91.01.02.006 | D14: 新发放LUM(标服) | H14: 700000000 | I14: 650000000 | J14: 780000000 | K14: 800000000 | L14: 820000000 | M14: 850000000 | N14: 880000000 | O14: 870000000 | P14: 850000000 | Q14: 930000000 | R14: 920000000 | S14: 950000000
A15: 四级 | B15: 其他 | C15: A01.91.01.02.010 | D15: 日均LUM | H15: 14000000000 | I15: 13000000000 | J15: 15600000000 | K15: 16000000000 | L15: 16400000000 | M15: 17000000000 | N15: 17600000000 | O15: 17400000000 | P15: 17000000000 | Q15: 18600000000 | R15: 18400000000 | S15: 19000000000
A16: 四级 | B16: 其他 | C16: A01.91.01.02.102 | D16: AuM规模 | H16: 3750000000 | I16: 3900000000 | J16: 4100000000 | K16: 4150000000 | L16: 4250000000 | M16: 4350000000 | N16: 4400000000 | O16: 4300000000 | P16: 4200000000 | Q16: 4150000000 | R16: 4100000000 | S16: 4350000000
A17: 四级 | B17: 其他 | C17: A01.91.01.02.007 | D17: 存客日均AuM | H17: 1750000000 | I17: 1625000000 | J17: 1950000000 | K17: 2000000000 | L17: 2050000000 | M17: 2125000000 | N17: 2200000000 | O17: 2175000000 | P17: 2125000000 | Q17: 2325000000 | R17: 2300000000 | S17: 2375000000
A18: 四级 | B18: 其他 | C18: A01.91.01.02.008 | D18: 新客AuM余额 | H18: 1050000000 | I18: 975000000 | J18: 1170000000 | K18: 1200000000 | L18: 1230000000 | M18: 1275000000 | N18: 1320000000 | O18: 1305000000 | P18: 1275000000 | Q18: 1395000000 | R18: 1380000000 | S18: 1425000000
A19: 四级 | B19: 其他 | C19: A01.91.01.02.011 | D19: 日均AuM | H19: 3500000000 | I19: 3250000000 | J19: 3900000000 | K19: 4000000000 | L19: 4100000000 | M19: 4250000000 | N19: 4400000000 | O19: 4350000000 | P19: 4250000000 | Q19: 4650000000 | R19: 4600000000 | S19: 4750000000
A20: 四级 | B20: 其他 | C20: A01.91.01.02.103 | D20: 客户数量 | H20: 15000000000 | I20: 15600000000 | J20: 16400000000 | K20: 16600000000 | L20: 17000000000 | M20: 17400000000 | N20: 17600000000 | O20: 17200000000 | P20: 16800000000 | Q20: 16600000000 | R20: 16400000000 | S20: 17400000000
A21: 四级 | B21: 其他 | C21: A01.91.01.02.003 | D21: 新开通客户数 | H21: 3500000000 | I21: 3250000000 | J21: 3900000000 | K21: 4000000000 | L21: 4100000000 | M21: 4250000000 | N21: 4400000000 | O21: 4350000000 | P21: 4250000000 | Q21: 4650000000 | R21: 4600000000 | S21: 4750000000
... A23: 四级 | B23: 其他 | C23: A01.91.01.02.009 | D23: MFAU客户数 | H23: 8400000000 | I23: 7800000000 | J23: 9360000000 | K23: 9600000000 | L23: 9840000000 | M23: 10200000000 | N23: 10560000000 | O23: 10440000000 | P23: 10200000000 | Q23: 11160000000 | R23: 11040000000 | S23: 11400000000
A24: 三级 | B24: 其他 | C24: A01.91.01.03 | D24: 客户回收与催收
A25: 四级 | B25: 其他 | C25: A01.91.01.03.001 | D25: 内催回收额 | H25: 70000000 | I25: 65000000 | J25: 78000000 | K25: 80000000 | L25: 82000000 | M25: 85000000 | N25: 88000000 | O25: 87000000 | P25: 85000000 | Q25: 93000000 | R25: 92000000 | S25: 95000000
A26: 四级 | B26: 其他 | C26: A01.91.01.03.002 | D26: M6-压降金额 | H26: 35000000 | I26: 32500000 | J26: 39000000 | K26: 40000000 | L26: 41000000 | M26: 42500000 | N26: 44000000 | O26: 43500000 | P26: 42500000 | Q26: 46500000 | R26: 46000000 | S26: 47500000
